[1m[31mERROR   [0m pykwalify.core:core.py:190 validation.invalid
[1m[31mERROR   [0m pykwalify.core:core.py:191  --- All found errors ---
[1m[31mERROR   [0m pykwalify.core:core.py:192 ["Enum 'in-progress' does not exist. Path: '/transitionStatus' Enum: ['completed']"]
[1m[31mERROR   [0m tavern.schemas.files:files.py:108 Error validating {'transitionID': 'b03025ba-051f-404b-9635-d7dfba4ec3eb', 'operation': 'Force-Off', 'createTime': '2024-03-20T08:23:02.382769589Z', 'automaticExpirationTime': '2024-03-21T08:23:02.382769649Z', 'transitionStatus': 'in-progress', 'taskCounts': {'total': 1, 'new': 1, 'in-progress': 0, 'failed': 0, 'succeeded': 0, 'un-supported': 0}, 'tasks': [{'xname': 'x3000c0s6b0n0', 'taskStatus': 'new', 'taskStatusDescription': 'Applying transition, forceoff'}]}
Traceback (most recent call last):
  File "/usr/lib/python3.9/site-packages/tavern/schemas/files.py", line 106, in verify_generic
    verifier.validate()
  File "/usr/lib/python3.9/site-packages/pykwalify/core.py", line 194, in validate
    raise SchemaError(u"Schema validation failed:\n - {error_msg}.".format(
pykwalify.errors.SchemaError: <SchemaError: error code 2: Schema validation failed:
 - Enum 'in-progress' does not exist. Path: '/transitionStatus' Enum: ['completed'].: Path: '/'>
[1m[31mERROR   [0m tavern.response.base:base.py:41 Error calling validate function '<function validate_pykwalify at 0x7f39ae9164c0>':
    Traceback (most recent call last):
      File "/usr/lib/python3.9/site-packages/tavern/schemas/files.py", line 106, in verify_generic
        verifier.validate()
      File "/usr/lib/python3.9/site-packages/pykwalify/core.py", line 194, in validate
        raise SchemaError(u"Schema validation failed:\n - {error_msg}.".format(
    pykwalify.errors.SchemaError: <SchemaError: error code 2: Schema validation failed:
     - Enum 'in-progress' does not exist. Path: '/transitionStatus' Enum: ['completed'].: Path: '/'>

    The above exception was the direct cause of the following exception:

    Traceback (most recent call last):
      File "/usr/lib/python3.9/site-packages/tavern/response/base.py", line 152, in _maybe_run_validate_functions
        vf(response)
      File "/usr/lib/python3.9/site-packages/tavern/util/extfunctions.py", line 98, in inner
        result = func(response, *args, **kwargs)
      File "/usr/lib/python3.9/site-packages/tavern/testutils/helpers.py", line 103, in validate_pykwalify
        verify_generic(to_verify, schema)
      File "/usr/lib/python3.9/site-packages/tavern/schemas/files.py", line 109, in verify_generic
        raise BadSchemaError() from e
    tavern.util.exceptions.BadSchemaError
Traceback (most recent call last):
  File "/usr/lib/python3.9/site-packages/tavern/schemas/files.py", line 106, in verify_generic
    verifier.validate()
  File "/usr/lib/python3.9/site-packages/pykwalify/core.py", line 194, in validate
    raise SchemaError(u"Schema validation failed:\n - {error_msg}.".format(
pykwalify.errors.SchemaError: <SchemaError: error code 2: Schema validation failed:
 - Enum 'in-progress' does not exist. Path: '/transitionStatus' Enum: ['completed'].: Path: '/'>

The above exception was the direct cause of the following exception:

Traceback (most recent call last):
  File "/usr/lib/python3.9/site-packages/tavern/response/base.py", line 152, in _maybe_run_validate_functions
    vf(response)
  File "/usr/lib/python3.9/site-packages/tavern/util/extfunctions.py", line 98, in inner
    result = func(response, *args, **kwargs)
  File "/usr/lib/python3.9/site-packages/tavern/testutils/helpers.py", line 103, in validate_pykwalify
    verify_generic(to_verify, schema)
  File "/usr/lib/python3.9/site-packages/tavern/schemas/files.py", line 109, in verify_generic
    raise BadSchemaError() from e
tavern.util.exceptions.BadSchemaError
[1m[31mERROR   [0m pykwalify.core:core.py:190 validation.invalid
[1m[31mERROR   [0m pykwalify.core:core.py:191  --- All found errors ---
[1m[31mERROR   [0m pykwalify.core:core.py:192 ["Enum 'in-progress' does not exist. Path: '/transitionStatus' Enum: ['completed']"]
[1m[31mERROR   [0m tavern.schemas.files:files.py:108 Error validating {'transitionID': 'b03025ba-051f-404b-9635-d7dfba4ec3eb', 'operation': 'Force-Off', 'createTime': '2024-03-20T08:23:02.382769589Z', 'automaticExpirationTime': '2024-03-21T08:23:02.382769649Z', 'transitionStatus': 'in-progress', 'taskCounts': {'total': 1, 'new': 0, 'in-progress': 1, 'failed': 0, 'succeeded': 0, 'un-supported': 0}, 'tasks': [{'xname': 'x3000c0s6b0n0', 'taskStatus': 'in-progress', 'taskStatusDescription': 'Confirming successful transition, forceoff'}]}
Traceback (most recent call last):
  File "/usr/lib/python3.9/site-packages/tavern/schemas/files.py", line 106, in verify_generic
    verifier.validate()
  File "/usr/lib/python3.9/site-packages/pykwalify/core.py", line 194, in validate
    raise SchemaError(u"Schema validation failed:\n - {error_msg}.".format(
pykwalify.errors.SchemaError: <SchemaError: error code 2: Schema validation failed:
 - Enum 'in-progress' does not exist. Path: '/transitionStatus' Enum: ['completed'].: Path: '/'>
[1m[31mERROR   [0m tavern.response.base:base.py:41 Error calling validate function '<function validate_pykwalify at 0x7f39ae9164c0>':
    Traceback (most recent call last):
      File "/usr/lib/python3.9/site-packages/tavern/schemas/files.py", line 106, in verify_generic
        verifier.validate()
      File "/usr/lib/python3.9/site-packages/pykwalify/core.py", line 194, in validate
        raise SchemaError(u"Schema validation failed:\n - {error_msg}.".format(
    pykwalify.errors.SchemaError: <SchemaError: error code 2: Schema validation failed:
     - Enum 'in-progress' does not exist. Path: '/transitionStatus' Enum: ['completed'].: Path: '/'>

    The above exception was the direct cause of the following exception:

    Traceback (most recent call last):
      File "/usr/lib/python3.9/site-packages/tavern/response/base.py", line 152, in _maybe_run_validate_functions
        vf(response)
      File "/usr/lib/python3.9/site-packages/tavern/util/extfunctions.py", line 98, in inner
        result = func(response, *args, **kwargs)
      File "/usr/lib/python3.9/site-packages/tavern/testutils/helpers.py", line 103, in validate_pykwalify
        verify_generic(to_verify, schema)
      File "/usr/lib/python3.9/site-packages/tavern/schemas/files.py", line 109, in verify_generic
        raise BadSchemaError() from e
    tavern.util.exceptions.BadSchemaError
Traceback (most recent call last):
  File "/usr/lib/python3.9/site-packages/tavern/schemas/files.py", line 106, in verify_generic
    verifier.validate()
  File "/usr/lib/python3.9/site-packages/pykwalify/core.py", line 194, in validate
    raise SchemaError(u"Schema validation failed:\n - {error_msg}.".format(
pykwalify.errors.SchemaError: <SchemaError: error code 2: Schema validation failed:
 - Enum 'in-progress' does not exist. Path: '/transitionStatus' Enum: ['completed'].: Path: '/'>

The above exception was the direct cause of the following exception:

Traceback (most recent call last):
  File "/usr/lib/python3.9/site-packages/tavern/response/base.py", line 152, in _maybe_run_validate_functions
    vf(response)
  File "/usr/lib/python3.9/site-packages/tavern/util/extfunctions.py", line 98, in inner
    result = func(response, *args, **kwargs)
  File "/usr/lib/python3.9/site-packages/tavern/testutils/helpers.py", line 103, in validate_pykwalify
    verify_generic(to_verify, schema)
  File "/usr/lib/python3.9/site-packages/tavern/schemas/files.py", line 109, in verify_generic
    raise BadSchemaError() from e
tavern.util.exceptions.BadSchemaError
[1m[31mERROR   [0m pykwalify.core:core.py:190 validation.invalid
[1m[31mERROR   [0m pykwalify.core:core.py:191  --- All found errors ---
[1m[31mERROR   [0m pykwalify.core:core.py:192 ["Enum 'in-progress' does not exist. Path: '/transitionStatus' Enum: ['completed']"]
[1m[31mERROR   [0m tavern.schemas.files:files.py:108 Error validating {'transitionID': 'b03025ba-051f-404b-9635-d7dfba4ec3eb', 'operation': 'Force-Off', 'createTime': '2024-03-20T08:23:02.382769589Z', 'automaticExpirationTime': '2024-03-21T08:23:02.382769649Z', 'transitionStatus': 'in-progress', 'taskCounts': {'total': 1, 'new': 0, 'in-progress': 1, 'failed': 0, 'succeeded': 0, 'un-supported': 0}, 'tasks': [{'xname': 'x3000c0s6b0n0', 'taskStatus': 'in-progress', 'taskStatusDescription': 'Confirming successful transition, forceoff'}]}
Traceback (most recent call last):
  File "/usr/lib/python3.9/site-packages/tavern/schemas/files.py", line 106, in verify_generic
    verifier.validate()
  File "/usr/lib/python3.9/site-packages/pykwalify/core.py", line 194, in validate
    raise SchemaError(u"Schema validation failed:\n - {error_msg}.".format(
pykwalify.errors.SchemaError: <SchemaError: error code 2: Schema validation failed:
 - Enum 'in-progress' does not exist. Path: '/transitionStatus' Enum: ['completed'].: Path: '/'>
[1m[31mERROR   [0m tavern.response.base:base.py:41 Error calling validate function '<function validate_pykwalify at 0x7f39ae9164c0>':
    Traceback (most recent call last):
      File "/usr/lib/python3.9/site-packages/tavern/schemas/files.py", line 106, in verify_generic
        verifier.validate()
      File "/usr/lib/python3.9/site-packages/pykwalify/core.py", line 194, in validate
        raise SchemaError(u"Schema validation failed:\n - {error_msg}.".format(
    pykwalify.errors.SchemaError: <SchemaError: error code 2: Schema validation failed:
     - Enum 'in-progress' does not exist. Path: '/transitionStatus' Enum: ['completed'].: Path: '/'>

    The above exception was the direct cause of the following exception:

    Traceback (most recent call last):
      File "/usr/lib/python3.9/site-packages/tavern/response/base.py", line 152, in _maybe_run_validate_functions
        vf(response)
      File "/usr/lib/python3.9/site-packages/tavern/util/extfunctions.py", line 98, in inner
        result = func(response, *args, **kwargs)
      File "/usr/lib/python3.9/site-packages/tavern/testutils/helpers.py", line 103, in validate_pykwalify
        verify_generic(to_verify, schema)
      File "/usr/lib/python3.9/site-packages/tavern/schemas/files.py", line 109, in verify_generic
        raise BadSchemaError() from e
    tavern.util.exceptions.BadSchemaError
Traceback (most recent call last):
  File "/usr/lib/python3.9/site-packages/tavern/schemas/files.py", line 106, in verify_generic
    verifier.validate()
  File "/usr/lib/python3.9/site-packages/pykwalify/core.py", line 194, in validate
    raise SchemaError(u"Schema validation failed:\n - {error_msg}.".format(
pykwalify.errors.SchemaError: <SchemaError: error code 2: Schema validation failed:
 - Enum 'in-progress' does not exist. Path: '/transitionStatus' Enum: ['completed'].: Path: '/'>

The above exception was the direct cause of the following exception:

Traceback (most recent call last):
  File "/usr/lib/python3.9/site-packages/tavern/response/base.py", line 152, in _maybe_run_validate_functions
    vf(response)
  File "/usr/lib/python3.9/site-packages/tavern/util/extfunctions.py", line 98, in inner
    result = func(response, *args, **kwargs)
  File "/usr/lib/python3.9/site-packages/tavern/testutils/helpers.py", line 103, in validate_pykwalify
    verify_generic(to_verify, schema)
  File "/usr/lib/python3.9/site-packages/tavern/schemas/files.py", line 109, in verify_generic
    raise BadSchemaError() from e
tavern.util.exceptions.BadSchemaError
[1m[31mERROR   [0m pykwalify.core:core.py:190 validation.invalid
[1m[31mERROR   [0m pykwalify.core:core.py:191  --- All found errors ---
[1m[31mERROR   [0m pykwalify.core:core.py:192 ["Enum 'in-progress' does not exist. Path: '/transitionStatus' Enum: ['completed']"]
[1m[31mERROR   [0m tavern.schemas.files:files.py:108 Error validating {'transitionID': 'b03025ba-051f-404b-9635-d7dfba4ec3eb', 'operation': 'Force-Off', 'createTime': '2024-03-20T08:23:02.382769589Z', 'automaticExpirationTime': '2024-03-21T08:23:02.382769649Z', 'transitionStatus': 'in-progress', 'taskCounts': {'total': 1, 'new': 0, 'in-progress': 1, 'failed': 0, 'succeeded': 0, 'un-supported': 0}, 'tasks': [{'xname': 'x3000c0s6b0n0', 'taskStatus': 'in-progress', 'taskStatusDescription': 'Confirming successful transition, forceoff'}]}
Traceback (most recent call last):
  File "/usr/lib/python3.9/site-packages/tavern/schemas/files.py", line 106, in verify_generic
    verifier.validate()
  File "/usr/lib/python3.9/site-packages/pykwalify/core.py", line 194, in validate
    raise SchemaError(u"Schema validation failed:\n - {error_msg}.".format(
pykwalify.errors.SchemaError: <SchemaError: error code 2: Schema validation failed:
 - Enum 'in-progress' does not exist. Path: '/transitionStatus' Enum: ['completed'].: Path: '/'>
[1m[31mERROR   [0m tavern.response.base:base.py:41 Error calling validate function '<function validate_pykwalify at 0x7f39ae9164c0>':
    Traceback (most recent call last):
      File "/usr/lib/python3.9/site-packages/tavern/schemas/files.py", line 106, in verify_generic
        verifier.validate()
      File "/usr/lib/python3.9/site-packages/pykwalify/core.py", line 194, in validate
        raise SchemaError(u"Schema validation failed:\n - {error_msg}.".format(
    pykwalify.errors.SchemaError: <SchemaError: error code 2: Schema validation failed:
     - Enum 'in-progress' does not exist. Path: '/transitionStatus' Enum: ['completed'].: Path: '/'>

    The above exception was the direct cause of the following exception:

    Traceback (most recent call last):
      File "/usr/lib/python3.9/site-packages/tavern/response/base.py", line 152, in _maybe_run_validate_functions
        vf(response)
      File "/usr/lib/python3.9/site-packages/tavern/util/extfunctions.py", line 98, in inner
        result = func(response, *args, **kwargs)
      File "/usr/lib/python3.9/site-packages/tavern/testutils/helpers.py", line 103, in validate_pykwalify
        verify_generic(to_verify, schema)
      File "/usr/lib/python3.9/site-packages/tavern/schemas/files.py", line 109, in verify_generic
        raise BadSchemaError() from e
    tavern.util.exceptions.BadSchemaError
Traceback (most recent call last):
  File "/usr/lib/python3.9/site-packages/tavern/schemas/files.py", line 106, in verify_generic
    verifier.validate()
  File "/usr/lib/python3.9/site-packages/pykwalify/core.py", line 194, in validate
    raise SchemaError(u"Schema validation failed:\n - {error_msg}.".format(
pykwalify.errors.SchemaError: <SchemaError: error code 2: Schema validation failed:
 - Enum 'in-progress' does not exist. Path: '/transitionStatus' Enum: ['completed'].: Path: '/'>

The above exception was the direct cause of the following exception:

Traceback (most recent call last):
  File "/usr/lib/python3.9/site-packages/tavern/response/base.py", line 152, in _maybe_run_validate_functions
    vf(response)
  File "/usr/lib/python3.9/site-packages/tavern/util/extfunctions.py", line 98, in inner
    result = func(response, *args, **kwargs)
  File "/usr/lib/python3.9/site-packages/tavern/testutils/helpers.py", line 103, in validate_pykwalify
    verify_generic(to_verify, schema)
  File "/usr/lib/python3.9/site-packages/tavern/schemas/files.py", line 109, in verify_generic
    raise BadSchemaError() from e
tavern.util.exceptions.BadSchemaError
[1m[31mERROR   [0m pykwalify.core:core.py:190 validation.invalid
[1m[31mERROR   [0m pykwalify.core:core.py:191  --- All found errors ---
[1m[31mERROR   [0m pykwalify.core:core.py:192 ["Enum 'in-progress' does not exist. Path: '/transitionStatus' Enum: ['completed']"]
[1m[31mERROR   [0m tavern.schemas.files:files.py:108 Error validating {'transitionID': 'b03025ba-051f-404b-9635-d7dfba4ec3eb', 'operation': 'Force-Off', 'createTime': '2024-03-20T08:23:02.382769589Z', 'automaticExpirationTime': '2024-03-21T08:23:02.382769649Z', 'transitionStatus': 'in-progress', 'taskCounts': {'total': 1, 'new': 0, 'in-progress': 1, 'failed': 0, 'succeeded': 0, 'un-supported': 0}, 'tasks': [{'xname': 'x3000c0s6b0n0', 'taskStatus': 'in-progress', 'taskStatusDescription': 'Confirming successful transition, forceoff'}]}
Traceback (most recent call last):
  File "/usr/lib/python3.9/site-packages/tavern/schemas/files.py", line 106, in verify_generic
    verifier.validate()
  File "/usr/lib/python3.9/site-packages/pykwalify/core.py", line 194, in validate
    raise SchemaError(u"Schema validation failed:\n - {error_msg}.".format(
pykwalify.errors.SchemaError: <SchemaError: error code 2: Schema validation failed:
 - Enum 'in-progress' does not exist. Path: '/transitionStatus' Enum: ['completed'].: Path: '/'>
[1m[31mERROR   [0m tavern.response.base:base.py:41 Error calling validate function '<function validate_pykwalify at 0x7f39ae9164c0>':
    Traceback (most recent call last):
      File "/usr/lib/python3.9/site-packages/tavern/schemas/files.py", line 106, in verify_generic
        verifier.validate()
      File "/usr/lib/python3.9/site-packages/pykwalify/core.py", line 194, in validate
        raise SchemaError(u"Schema validation failed:\n - {error_msg}.".format(
    pykwalify.errors.SchemaError: <SchemaError: error code 2: Schema validation failed:
     - Enum 'in-progress' does not exist. Path: '/transitionStatus' Enum: ['completed'].: Path: '/'>

    The above exception was the direct cause of the following exception:

    Traceback (most recent call last):
      File "/usr/lib/python3.9/site-packages/tavern/response/base.py", line 152, in _maybe_run_validate_functions
        vf(response)
      File "/usr/lib/python3.9/site-packages/tavern/util/extfunctions.py", line 98, in inner
        result = func(response, *args, **kwargs)
      File "/usr/lib/python3.9/site-packages/tavern/testutils/helpers.py", line 103, in validate_pykwalify
        verify_generic(to_verify, schema)
      File "/usr/lib/python3.9/site-packages/tavern/schemas/files.py", line 109, in verify_generic
        raise BadSchemaError() from e
    tavern.util.exceptions.BadSchemaError
Traceback (most recent call last):
  File "/usr/lib/python3.9/site-packages/tavern/schemas/files.py", line 106, in verify_generic
    verifier.validate()
  File "/usr/lib/python3.9/site-packages/pykwalify/core.py", line 194, in validate
    raise SchemaError(u"Schema validation failed:\n - {error_msg}.".format(
pykwalify.errors.SchemaError: <SchemaError: error code 2: Schema validation failed:
 - Enum 'in-progress' does not exist. Path: '/transitionStatus' Enum: ['completed'].: Path: '/'>

The above exception was the direct cause of the following exception:

Traceback (most recent call last):
  File "/usr/lib/python3.9/site-packages/tavern/response/base.py", line 152, in _maybe_run_validate_functions
    vf(response)
  File "/usr/lib/python3.9/site-packages/tavern/util/extfunctions.py", line 98, in inner
    result = func(response, *args, **kwargs)
  File "/usr/lib/python3.9/site-packages/tavern/testutils/helpers.py", line 103, in validate_pykwalify
    verify_generic(to_verify, schema)
  File "/usr/lib/python3.9/site-packages/tavern/schemas/files.py", line 109, in verify_generic
    raise BadSchemaError() from e
tavern.util.exceptions.BadSchemaError
[1m[31mERROR   [0m pykwalify.core:core.py:190 validation.invalid
[1m[31mERROR   [0m pykwalify.core:core.py:191  --- All found errors ---
[1m[31mERROR   [0m pykwalify.core:core.py:192 ["Enum 'in-progress' does not exist. Path: '/transitionStatus' Enum: ['completed']"]
[1m[31mERROR   [0m tavern.schemas.files:files.py:108 Error validating {'transitionID': 'b03025ba-051f-404b-9635-d7dfba4ec3eb', 'operation': 'Force-Off', 'createTime': '2024-03-20T08:23:02.382769589Z', 'automaticExpirationTime': '2024-03-21T08:23:02.382769649Z', 'transitionStatus': 'in-progress', 'taskCounts': {'total': 1, 'new': 0, 'in-progress': 1, 'failed': 0, 'succeeded': 0, 'un-supported': 0}, 'tasks': [{'xname': 'x3000c0s6b0n0', 'taskStatus': 'in-progress', 'taskStatusDescription': 'Confirming successful transition, forceoff'}]}
Traceback (most recent call last):
  File "/usr/lib/python3.9/site-packages/tavern/schemas/files.py", line 106, in verify_generic
    verifier.validate()
  File "/usr/lib/python3.9/site-packages/pykwalify/core.py", line 194, in validate
    raise SchemaError(u"Schema validation failed:\n - {error_msg}.".format(
pykwalify.errors.SchemaError: <SchemaError: error code 2: Schema validation failed:
 - Enum 'in-progress' does not exist. Path: '/transitionStatus' Enum: ['completed'].: Path: '/'>
[1m[31mERROR   [0m tavern.response.base:base.py:41 Error calling validate function '<function validate_pykwalify at 0x7f39ae9164c0>':
    Traceback (most recent call last):
      File "/usr/lib/python3.9/site-packages/tavern/schemas/files.py", line 106, in verify_generic
        verifier.validate()
      File "/usr/lib/python3.9/site-packages/pykwalify/core.py", line 194, in validate
        raise SchemaError(u"Schema validation failed:\n - {error_msg}.".format(
    pykwalify.errors.SchemaError: <SchemaError: error code 2: Schema validation failed:
     - Enum 'in-progress' does not exist. Path: '/transitionStatus' Enum: ['completed'].: Path: '/'>

    The above exception was the direct cause of the following exception:

    Traceback (most recent call last):
      File "/usr/lib/python3.9/site-packages/tavern/response/base.py", line 152, in _maybe_run_validate_functions
        vf(response)
      File "/usr/lib/python3.9/site-packages/tavern/util/extfunctions.py", line 98, in inner
        result = func(response, *args, **kwargs)
      File "/usr/lib/python3.9/site-packages/tavern/testutils/helpers.py", line 103, in validate_pykwalify
        verify_generic(to_verify, schema)
      File "/usr/lib/python3.9/site-packages/tavern/schemas/files.py", line 109, in verify_generic
        raise BadSchemaError() from e
    tavern.util.exceptions.BadSchemaError
Traceback (most recent call last):
  File "/usr/lib/python3.9/site-packages/tavern/schemas/files.py", line 106, in verify_generic
    verifier.validate()
  File "/usr/lib/python3.9/site-packages/pykwalify/core.py", line 194, in validate
    raise SchemaError(u"Schema validation failed:\n - {error_msg}.".format(
pykwalify.errors.SchemaError: <SchemaError: error code 2: Schema validation failed:
 - Enum 'in-progress' does not exist. Path: '/transitionStatus' Enum: ['completed'].: Path: '/'>

The above exception was the direct cause of the following exception:

Traceback (most recent call last):
  File "/usr/lib/python3.9/site-packages/tavern/response/base.py", line 152, in _maybe_run_validate_functions
    vf(response)
  File "/usr/lib/python3.9/site-packages/tavern/util/extfunctions.py", line 98, in inner
    result = func(response, *args, **kwargs)
  File "/usr/lib/python3.9/site-packages/tavern/testutils/helpers.py", line 103, in validate_pykwalify
    verify_generic(to_verify, schema)
  File "/usr/lib/python3.9/site-packages/tavern/schemas/files.py", line 109, in verify_generic
    raise BadSchemaError() from e
tavern.util.exceptions.BadSchemaError
[1m[31mERROR   [0m pykwalify.core:core.py:190 validation.invalid
[1m[31mERROR   [0m pykwalify.core:core.py:191  --- All found errors ---
[1m[31mERROR   [0m pykwalify.core:core.py:192 ["Enum 'in-progress' does not exist. Path: '/transitionStatus' Enum: ['completed']"]
[1m[31mERROR   [0m tavern.schemas.files:files.py:108 Error validating {'transitionID': 'b03025ba-051f-404b-9635-d7dfba4ec3eb', 'operation': 'Force-Off', 'createTime': '2024-03-20T08:23:02.382769589Z', 'automaticExpirationTime': '2024-03-21T08:23:02.382769649Z', 'transitionStatus': 'in-progress', 'taskCounts': {'total': 1, 'new': 0, 'in-progress': 1, 'failed': 0, 'succeeded': 0, 'un-supported': 0}, 'tasks': [{'xname': 'x3000c0s6b0n0', 'taskStatus': 'in-progress', 'taskStatusDescription': 'Confirming successful transition, forceoff'}]}
Traceback (most recent call last):
  File "/usr/lib/python3.9/site-packages/tavern/schemas/files.py", line 106, in verify_generic
    verifier.validate()
  File "/usr/lib/python3.9/site-packages/pykwalify/core.py", line 194, in validate
    raise SchemaError(u"Schema validation failed:\n - {error_msg}.".format(
pykwalify.errors.SchemaError: <SchemaError: error code 2: Schema validation failed:
 - Enum 'in-progress' does not exist. Path: '/transitionStatus' Enum: ['completed'].: Path: '/'>
[1m[31mERROR   [0m tavern.response.base:base.py:41 Error calling validate function '<function validate_pykwalify at 0x7f39ae9164c0>':
    Traceback (most recent call last):
      File "/usr/lib/python3.9/site-packages/tavern/schemas/files.py", line 106, in verify_generic
        verifier.validate()
      File "/usr/lib/python3.9/site-packages/pykwalify/core.py", line 194, in validate
        raise SchemaError(u"Schema validation failed:\n - {error_msg}.".format(
    pykwalify.errors.SchemaError: <SchemaError: error code 2: Schema validation failed:
     - Enum 'in-progress' does not exist. Path: '/transitionStatus' Enum: ['completed'].: Path: '/'>

    The above exception was the direct cause of the following exception:

    Traceback (most recent call last):
      File "/usr/lib/python3.9/site-packages/tavern/response/base.py", line 152, in _maybe_run_validate_functions
        vf(response)
      File "/usr/lib/python3.9/site-packages/tavern/util/extfunctions.py", line 98, in inner
        result = func(response, *args, **kwargs)
      File "/usr/lib/python3.9/site-packages/tavern/testutils/helpers.py", line 103, in validate_pykwalify
        verify_generic(to_verify, schema)
      File "/usr/lib/python3.9/site-packages/tavern/schemas/files.py", line 109, in verify_generic
        raise BadSchemaError() from e
    tavern.util.exceptions.BadSchemaError
Traceback (most recent call last):
  File "/usr/lib/python3.9/site-packages/tavern/schemas/files.py", line 106, in verify_generic
    verifier.validate()
  File "/usr/lib/python3.9/site-packages/pykwalify/core.py", line 194, in validate
    raise SchemaError(u"Schema validation failed:\n - {error_msg}.".format(
pykwalify.errors.SchemaError: <SchemaError: error code 2: Schema validation failed:
 - Enum 'in-progress' does not exist. Path: '/transitionStatus' Enum: ['completed'].: Path: '/'>

The above exception was the direct cause of the following exception:

Traceback (most recent call last):
  File "/usr/lib/python3.9/site-packages/tavern/response/base.py", line 152, in _maybe_run_validate_functions
    vf(response)
  File "/usr/lib/python3.9/site-packages/tavern/util/extfunctions.py", line 98, in inner
    result = func(response, *args, **kwargs)
  File "/usr/lib/python3.9/site-packages/tavern/testutils/helpers.py", line 103, in validate_pykwalify
    verify_generic(to_verify, schema)
  File "/usr/lib/python3.9/site-packages/tavern/schemas/files.py", line 109, in verify_generic
    raise BadSchemaError() from e
tavern.util.exceptions.BadSchemaError
[1m[31mERROR   [0m pykwalify.core:core.py:190 validation.invalid
[1m[31mERROR   [0m pykwalify.core:core.py:191  --- All found errors ---
[1m[31mERROR   [0m pykwalify.core:core.py:192 ["Enum 'in-progress' does not exist. Path: '/transitionStatus' Enum: ['completed']"]
[1m[31mERROR   [0m tavern.schemas.files:files.py:108 Error validating {'transitionID': 'b03025ba-051f-404b-9635-d7dfba4ec3eb', 'operation': 'Force-Off', 'createTime': '2024-03-20T08:23:02.382769589Z', 'automaticExpirationTime': '2024-03-21T08:23:02.382769649Z', 'transitionStatus': 'in-progress', 'taskCounts': {'total': 1, 'new': 0, 'in-progress': 1, 'failed': 0, 'succeeded': 0, 'un-supported': 0}, 'tasks': [{'xname': 'x3000c0s6b0n0', 'taskStatus': 'in-progress', 'taskStatusDescription': 'Confirming successful transition, forceoff'}]}
Traceback (most recent call last):
  File "/usr/lib/python3.9/site-packages/tavern/schemas/files.py", line 106, in verify_generic
    verifier.validate()
  File "/usr/lib/python3.9/site-packages/pykwalify/core.py", line 194, in validate
    raise SchemaError(u"Schema validation failed:\n - {error_msg}.".format(
pykwalify.errors.SchemaError: <SchemaError: error code 2: Schema validation failed:
 - Enum 'in-progress' does not exist. Path: '/transitionStatus' Enum: ['completed'].: Path: '/'>
[1m[31mERROR   [0m tavern.response.base:base.py:41 Error calling validate function '<function validate_pykwalify at 0x7f39ae9164c0>':
    Traceback (most recent call last):
      File "/usr/lib/python3.9/site-packages/tavern/schemas/files.py", line 106, in verify_generic
        verifier.validate()
      File "/usr/lib/python3.9/site-packages/pykwalify/core.py", line 194, in validate
        raise SchemaError(u"Schema validation failed:\n - {error_msg}.".format(
    pykwalify.errors.SchemaError: <SchemaError: error code 2: Schema validation failed:
     - Enum 'in-progress' does not exist. Path: '/transitionStatus' Enum: ['completed'].: Path: '/'>

    The above exception was the direct cause of the following exception:

    Traceback (most recent call last):
      File "/usr/lib/python3.9/site-packages/tavern/response/base.py", line 152, in _maybe_run_validate_functions
        vf(response)
      File "/usr/lib/python3.9/site-packages/tavern/util/extfunctions.py", line 98, in inner
        result = func(response, *args, **kwargs)
      File "/usr/lib/python3.9/site-packages/tavern/testutils/helpers.py", line 103, in validate_pykwalify
        verify_generic(to_verify, schema)
      File "/usr/lib/python3.9/site-packages/tavern/schemas/files.py", line 109, in verify_generic
        raise BadSchemaError() from e
    tavern.util.exceptions.BadSchemaError
Traceback (most recent call last):
  File "/usr/lib/python3.9/site-packages/tavern/schemas/files.py", line 106, in verify_generic
    verifier.validate()
  File "/usr/lib/python3.9/site-packages/pykwalify/core.py", line 194, in validate
    raise SchemaError(u"Schema validation failed:\n - {error_msg}.".format(
pykwalify.errors.SchemaError: <SchemaError: error code 2: Schema validation failed:
 - Enum 'in-progress' does not exist. Path: '/transitionStatus' Enum: ['completed'].: Path: '/'>

The above exception was the direct cause of the following exception:

Traceback (most recent call last):
  File "/usr/lib/python3.9/site-packages/tavern/response/base.py", line 152, in _maybe_run_validate_functions
    vf(response)
  File "/usr/lib/python3.9/site-packages/tavern/util/extfunctions.py", line 98, in inner
    result = func(response, *args, **kwargs)
  File "/usr/lib/python3.9/site-packages/tavern/testutils/helpers.py", line 103, in validate_pykwalify
    verify_generic(to_verify, schema)
  File "/usr/lib/python3.9/site-packages/tavern/schemas/files.py", line 109, in verify_generic
    raise BadSchemaError() from e
tavern.util.exceptions.BadSchemaError
[1m[31mERROR   [0m pykwalify.core:core.py:190 validation.invalid
[1m[31mERROR   [0m pykwalify.core:core.py:191  --- All found errors ---
[1m[31mERROR   [0m pykwalify.core:core.py:192 ["Enum 'in-progress' does not exist. Path: '/transitionStatus' Enum: ['completed']"]
[1m[31mERROR   [0m tavern.schemas.files:files.py:108 Error validating {'transitionID': 'b03025ba-051f-404b-9635-d7dfba4ec3eb', 'operation': 'Force-Off', 'createTime': '2024-03-20T08:23:02.382769589Z', 'automaticExpirationTime': '2024-03-21T08:23:02.382769649Z', 'transitionStatus': 'in-progress', 'taskCounts': {'total': 1, 'new': 0, 'in-progress': 1, 'failed': 0, 'succeeded': 0, 'un-supported': 0}, 'tasks': [{'xname': 'x3000c0s6b0n0', 'taskStatus': 'in-progress', 'taskStatusDescription': 'Confirming successful transition, forceoff'}]}
Traceback (most recent call last):
  File "/usr/lib/python3.9/site-packages/tavern/schemas/files.py", line 106, in verify_generic
    verifier.validate()
  File "/usr/lib/python3.9/site-packages/pykwalify/core.py", line 194, in validate
    raise SchemaError(u"Schema validation failed:\n - {error_msg}.".format(
pykwalify.errors.SchemaError: <SchemaError: error code 2: Schema validation failed:
 - Enum 'in-progress' does not exist. Path: '/transitionStatus' Enum: ['completed'].: Path: '/'>
[1m[31mERROR   [0m tavern.response.base:base.py:41 Error calling validate function '<function validate_pykwalify at 0x7f39ae9164c0>':
    Traceback (most recent call last):
      File "/usr/lib/python3.9/site-packages/tavern/schemas/files.py", line 106, in verify_generic
        verifier.validate()
      File "/usr/lib/python3.9/site-packages/pykwalify/core.py", line 194, in validate
        raise SchemaError(u"Schema validation failed:\n - {error_msg}.".format(
    pykwalify.errors.SchemaError: <SchemaError: error code 2: Schema validation failed:
     - Enum 'in-progress' does not exist. Path: '/transitionStatus' Enum: ['completed'].: Path: '/'>

    The above exception was the direct cause of the following exception:

    Traceback (most recent call last):
      File "/usr/lib/python3.9/site-packages/tavern/response/base.py", line 152, in _maybe_run_validate_functions
        vf(response)
      File "/usr/lib/python3.9/site-packages/tavern/util/extfunctions.py", line 98, in inner
        result = func(response, *args, **kwargs)
      File "/usr/lib/python3.9/site-packages/tavern/testutils/helpers.py", line 103, in validate_pykwalify
        verify_generic(to_verify, schema)
      File "/usr/lib/python3.9/site-packages/tavern/schemas/files.py", line 109, in verify_generic
        raise BadSchemaError() from e
    tavern.util.exceptions.BadSchemaError
Traceback (most recent call last):
  File "/usr/lib/python3.9/site-packages/tavern/schemas/files.py", line 106, in verify_generic
    verifier.validate()
  File "/usr/lib/python3.9/site-packages/pykwalify/core.py", line 194, in validate
    raise SchemaError(u"Schema validation failed:\n - {error_msg}.".format(
pykwalify.errors.SchemaError: <SchemaError: error code 2: Schema validation failed:
 - Enum 'in-progress' does not exist. Path: '/transitionStatus' Enum: ['completed'].: Path: '/'>

The above exception was the direct cause of the following exception:

Traceback (most recent call last):
  File "/usr/lib/python3.9/site-packages/tavern/response/base.py", line 152, in _maybe_run_validate_functions
    vf(response)
  File "/usr/lib/python3.9/site-packages/tavern/util/extfunctions.py", line 98, in inner
    result = func(response, *args, **kwargs)
  File "/usr/lib/python3.9/site-packages/tavern/testutils/helpers.py", line 103, in validate_pykwalify
    verify_generic(to_verify, schema)
  File "/usr/lib/python3.9/site-packages/tavern/schemas/files.py", line 109, in verify_generic
    raise BadSchemaError() from e
tavern.util.exceptions.BadSchemaError
[1m[31mERROR   [0m pykwalify.core:core.py:190 validation.invalid
[1m[31mERROR   [0m pykwalify.core:core.py:191  --- All found errors ---
[1m[31mERROR   [0m pykwalify.core:core.py:192 ["Enum 'in-progress' does not exist. Path: '/transitionStatus' Enum: ['completed']"]
[1m[31mERROR   [0m tavern.schemas.files:files.py:108 Error validating {'transitionID': 'b03025ba-051f-404b-9635-d7dfba4ec3eb', 'operation': 'Force-Off', 'createTime': '2024-03-20T08:23:02.382769589Z', 'automaticExpirationTime': '2024-03-21T08:23:02.382769649Z', 'transitionStatus': 'in-progress', 'taskCounts': {'total': 1, 'new': 0, 'in-progress': 1, 'failed': 0, 'succeeded': 0, 'un-supported': 0}, 'tasks': [{'xname': 'x3000c0s6b0n0', 'taskStatus': 'in-progress', 'taskStatusDescription': 'Confirming successful transition, forceoff'}]}
Traceback (most recent call last):
  File "/usr/lib/python3.9/site-packages/tavern/schemas/files.py", line 106, in verify_generic
    verifier.validate()
  File "/usr/lib/python3.9/site-packages/pykwalify/core.py", line 194, in validate
    raise SchemaError(u"Schema validation failed:\n - {error_msg}.".format(
pykwalify.errors.SchemaError: <SchemaError: error code 2: Schema validation failed:
 - Enum 'in-progress' does not exist. Path: '/transitionStatus' Enum: ['completed'].: Path: '/'>
[1m[31mERROR   [0m tavern.response.base:base.py:41 Error calling validate function '<function validate_pykwalify at 0x7f39ae9164c0>':
    Traceback (most recent call last):
      File "/usr/lib/python3.9/site-packages/tavern/schemas/files.py", line 106, in verify_generic
        verifier.validate()
      File "/usr/lib/python3.9/site-packages/pykwalify/core.py", line 194, in validate
        raise SchemaError(u"Schema validation failed:\n - {error_msg}.".format(
    pykwalify.errors.SchemaError: <SchemaError: error code 2: Schema validation failed:
     - Enum 'in-progress' does not exist. Path: '/transitionStatus' Enum: ['completed'].: Path: '/'>

    The above exception was the direct cause of the following exception:

    Traceback (most recent call last):
      File "/usr/lib/python3.9/site-packages/tavern/response/base.py", line 152, in _maybe_run_validate_functions
        vf(response)
      File "/usr/lib/python3.9/site-packages/tavern/util/extfunctions.py", line 98, in inner
        result = func(response, *args, **kwargs)
      File "/usr/lib/python3.9/site-packages/tavern/testutils/helpers.py", line 103, in validate_pykwalify
        verify_generic(to_verify, schema)
      File "/usr/lib/python3.9/site-packages/tavern/schemas/files.py", line 109, in verify_generic
        raise BadSchemaError() from e
    tavern.util.exceptions.BadSchemaError
Traceback (most recent call last):
  File "/usr/lib/python3.9/site-packages/tavern/schemas/files.py", line 106, in verify_generic
    verifier.validate()
  File "/usr/lib/python3.9/site-packages/pykwalify/core.py", line 194, in validate
    raise SchemaError(u"Schema validation failed:\n - {error_msg}.".format(
pykwalify.errors.SchemaError: <SchemaError: error code 2: Schema validation failed:
 - Enum 'in-progress' does not exist. Path: '/transitionStatus' Enum: ['completed'].: Path: '/'>

The above exception was the direct cause of the following exception:

Traceback (most recent call last):
  File "/usr/lib/python3.9/site-packages/tavern/response/base.py", line 152, in _maybe_run_validate_functions
    vf(response)
  File "/usr/lib/python3.9/site-packages/tavern/util/extfunctions.py", line 98, in inner
    result = func(response, *args, **kwargs)
  File "/usr/lib/python3.9/site-packages/tavern/testutils/helpers.py", line 103, in validate_pykwalify
    verify_generic(to_verify, schema)
  File "/usr/lib/python3.9/site-packages/tavern/schemas/files.py", line 109, in verify_generic
    raise BadSchemaError() from e
tavern.util.exceptions.BadSchemaError
[1m[31mERROR   [0m pykwalify.core:core.py:190 validation.invalid
[1m[31mERROR   [0m pykwalify.core:core.py:191  --- All found errors ---
[1m[31mERROR   [0m pykwalify.core:core.py:192 ["Enum 'in-progress' does not exist. Path: '/transitionStatus' Enum: ['completed']"]
[1m[31mERROR   [0m tavern.schemas.files:files.py:108 Error validating {'transitionID': 'b03025ba-051f-404b-9635-d7dfba4ec3eb', 'operation': 'Force-Off', 'createTime': '2024-03-20T08:23:02.382769589Z', 'automaticExpirationTime': '2024-03-21T08:23:02.382769649Z', 'transitionStatus': 'in-progress', 'taskCounts': {'total': 1, 'new': 0, 'in-progress': 1, 'failed': 0, 'succeeded': 0, 'un-supported': 0}, 'tasks': [{'xname': 'x3000c0s6b0n0', 'taskStatus': 'in-progress', 'taskStatusDescription': 'Confirming successful transition, forceoff'}]}
Traceback (most recent call last):
  File "/usr/lib/python3.9/site-packages/tavern/schemas/files.py", line 106, in verify_generic
    verifier.validate()
  File "/usr/lib/python3.9/site-packages/pykwalify/core.py", line 194, in validate
    raise SchemaError(u"Schema validation failed:\n - {error_msg}.".format(
pykwalify.errors.SchemaError: <SchemaError: error code 2: Schema validation failed:
 - Enum 'in-progress' does not exist. Path: '/transitionStatus' Enum: ['completed'].: Path: '/'>
[1m[31mERROR   [0m tavern.response.base:base.py:41 Error calling validate function '<function validate_pykwalify at 0x7f39ae9164c0>':
    Traceback (most recent call last):
      File "/usr/lib/python3.9/site-packages/tavern/schemas/files.py", line 106, in verify_generic
        verifier.validate()
      File "/usr/lib/python3.9/site-packages/pykwalify/core.py", line 194, in validate
        raise SchemaError(u"Schema validation failed:\n - {error_msg}.".format(
    pykwalify.errors.SchemaError: <SchemaError: error code 2: Schema validation failed:
     - Enum 'in-progress' does not exist. Path: '/transitionStatus' Enum: ['completed'].: Path: '/'>

    The above exception was the direct cause of the following exception:

    Traceback (most recent call last):
      File "/usr/lib/python3.9/site-packages/tavern/response/base.py", line 152, in _maybe_run_validate_functions
        vf(response)
      File "/usr/lib/python3.9/site-packages/tavern/util/extfunctions.py", line 98, in inner
        result = func(response, *args, **kwargs)
      File "/usr/lib/python3.9/site-packages/tavern/testutils/helpers.py", line 103, in validate_pykwalify
        verify_generic(to_verify, schema)
      File "/usr/lib/python3.9/site-packages/tavern/schemas/files.py", line 109, in verify_generic
        raise BadSchemaError() from e
    tavern.util.exceptions.BadSchemaError
Traceback (most recent call last):
  File "/usr/lib/python3.9/site-packages/tavern/schemas/files.py", line 106, in verify_generic
    verifier.validate()
  File "/usr/lib/python3.9/site-packages/pykwalify/core.py", line 194, in validate
    raise SchemaError(u"Schema validation failed:\n - {error_msg}.".format(
pykwalify.errors.SchemaError: <SchemaError: error code 2: Schema validation failed:
 - Enum 'in-progress' does not exist. Path: '/transitionStatus' Enum: ['completed'].: Path: '/'>

The above exception was the direct cause of the following exception:

Traceback (most recent call last):
  File "/usr/lib/python3.9/site-packages/tavern/response/base.py", line 152, in _maybe_run_validate_functions
    vf(response)
  File "/usr/lib/python3.9/site-packages/tavern/util/extfunctions.py", line 98, in inner
    result = func(response, *args, **kwargs)
  File "/usr/lib/python3.9/site-packages/tavern/testutils/helpers.py", line 103, in validate_pykwalify
    verify_generic(to_verify, schema)
  File "/usr/lib/python3.9/site-packages/tavern/schemas/files.py", line 109, in verify_generic
    raise BadSchemaError() from e
tavern.util.exceptions.BadSchemaError
[1m[31mERROR   [0m pykwalify.core:core.py:190 validation.invalid
[1m[31mERROR   [0m pykwalify.core:core.py:191  --- All found errors ---
[1m[31mERROR   [0m pykwalify.core:core.py:192 ["Enum 'in-progress' does not exist. Path: '/transitionStatus' Enum: ['completed']"]
[1m[31mERROR   [0m tavern.schemas.files:files.py:108 Error validating {'transitionID': 'b03025ba-051f-404b-9635-d7dfba4ec3eb', 'operation': 'Force-Off', 'createTime': '2024-03-20T08:23:02.382769589Z', 'automaticExpirationTime': '2024-03-21T08:23:02.382769649Z', 'transitionStatus': 'in-progress', 'taskCounts': {'total': 1, 'new': 0, 'in-progress': 1, 'failed': 0, 'succeeded': 0, 'un-supported': 0}, 'tasks': [{'xname': 'x3000c0s6b0n0', 'taskStatus': 'in-progress', 'taskStatusDescription': 'Confirming successful transition, forceoff'}]}
Traceback (most recent call last):
  File "/usr/lib/python3.9/site-packages/tavern/schemas/files.py", line 106, in verify_generic
    verifier.validate()
  File "/usr/lib/python3.9/site-packages/pykwalify/core.py", line 194, in validate
    raise SchemaError(u"Schema validation failed:\n - {error_msg}.".format(
pykwalify.errors.SchemaError: <SchemaError: error code 2: Schema validation failed:
 - Enum 'in-progress' does not exist. Path: '/transitionStatus' Enum: ['completed'].: Path: '/'>
[1m[31mERROR   [0m tavern.response.base:base.py:41 Error calling validate function '<function validate_pykwalify at 0x7f39ae9164c0>':
    Traceback (most recent call last):
      File "/usr/lib/python3.9/site-packages/tavern/schemas/files.py", line 106, in verify_generic
        verifier.validate()
      File "/usr/lib/python3.9/site-packages/pykwalify/core.py", line 194, in validate
        raise SchemaError(u"Schema validation failed:\n - {error_msg}.".format(
    pykwalify.errors.SchemaError: <SchemaError: error code 2: Schema validation failed:
     - Enum 'in-progress' does not exist. Path: '/transitionStatus' Enum: ['completed'].: Path: '/'>

    The above exception was the direct cause of the following exception:

    Traceback (most recent call last):
      File "/usr/lib/python3.9/site-packages/tavern/response/base.py", line 152, in _maybe_run_validate_functions
        vf(response)
      File "/usr/lib/python3.9/site-packages/tavern/util/extfunctions.py", line 98, in inner
        result = func(response, *args, **kwargs)
      File "/usr/lib/python3.9/site-packages/tavern/testutils/helpers.py", line 103, in validate_pykwalify
        verify_generic(to_verify, schema)
      File "/usr/lib/python3.9/site-packages/tavern/schemas/files.py", line 109, in verify_generic
        raise BadSchemaError() from e
    tavern.util.exceptions.BadSchemaError
Traceback (most recent call last):
  File "/usr/lib/python3.9/site-packages/tavern/schemas/files.py", line 106, in verify_generic
    verifier.validate()
  File "/usr/lib/python3.9/site-packages/pykwalify/core.py", line 194, in validate
    raise SchemaError(u"Schema validation failed:\n - {error_msg}.".format(
pykwalify.errors.SchemaError: <SchemaError: error code 2: Schema validation failed:
 - Enum 'in-progress' does not exist. Path: '/transitionStatus' Enum: ['completed'].: Path: '/'>

The above exception was the direct cause of the following exception:

Traceback (most recent call last):
  File "/usr/lib/python3.9/site-packages/tavern/response/base.py", line 152, in _maybe_run_validate_functions
    vf(response)
  File "/usr/lib/python3.9/site-packages/tavern/util/extfunctions.py", line 98, in inner
    result = func(response, *args, **kwargs)
  File "/usr/lib/python3.9/site-packages/tavern/testutils/helpers.py", line 103, in validate_pykwalify
    verify_generic(to_verify, schema)
  File "/usr/lib/python3.9/site-packages/tavern/schemas/files.py", line 109, in verify_generic
    raise BadSchemaError() from e
tavern.util.exceptions.BadSchemaError
[1m[31mERROR   [0m pykwalify.core:core.py:190 validation.invalid
[1m[31mERROR   [0m pykwalify.core:core.py:191  --- All found errors ---
[1m[31mERROR   [0m pykwalify.core:core.py:192 ["Enum 'in-progress' does not exist. Path: '/transitionStatus' Enum: ['completed']"]
[1m[31mERROR   [0m tavern.schemas.files:files.py:108 Error validating {'transitionID': 'b03025ba-051f-404b-9635-d7dfba4ec3eb', 'operation': 'Force-Off', 'createTime': '2024-03-20T08:23:02.382769589Z', 'automaticExpirationTime': '2024-03-21T08:23:02.382769649Z', 'transitionStatus': 'in-progress', 'taskCounts': {'total': 1, 'new': 0, 'in-progress': 1, 'failed': 0, 'succeeded': 0, 'un-supported': 0}, 'tasks': [{'xname': 'x3000c0s6b0n0', 'taskStatus': 'in-progress', 'taskStatusDescription': 'Confirming successful transition, forceoff'}]}
Traceback (most recent call last):
  File "/usr/lib/python3.9/site-packages/tavern/schemas/files.py", line 106, in verify_generic
    verifier.validate()
  File "/usr/lib/python3.9/site-packages/pykwalify/core.py", line 194, in validate
    raise SchemaError(u"Schema validation failed:\n - {error_msg}.".format(
pykwalify.errors.SchemaError: <SchemaError: error code 2: Schema validation failed:
 - Enum 'in-progress' does not exist. Path: '/transitionStatus' Enum: ['completed'].: Path: '/'>
[1m[31mERROR   [0m tavern.response.base:base.py:41 Error calling validate function '<function validate_pykwalify at 0x7f39ae9164c0>':
    Traceback (most recent call last):
      File "/usr/lib/python3.9/site-packages/tavern/schemas/files.py", line 106, in verify_generic
        verifier.validate()
      File "/usr/lib/python3.9/site-packages/pykwalify/core.py", line 194, in validate
        raise SchemaError(u"Schema validation failed:\n - {error_msg}.".format(
    pykwalify.errors.SchemaError: <SchemaError: error code 2: Schema validation failed:
     - Enum 'in-progress' does not exist. Path: '/transitionStatus' Enum: ['completed'].: Path: '/'>

    The above exception was the direct cause of the following exception:

    Traceback (most recent call last):
      File "/usr/lib/python3.9/site-packages/tavern/response/base.py", line 152, in _maybe_run_validate_functions
        vf(response)
      File "/usr/lib/python3.9/site-packages/tavern/util/extfunctions.py", line 98, in inner
        result = func(response, *args, **kwargs)
      File "/usr/lib/python3.9/site-packages/tavern/testutils/helpers.py", line 103, in validate_pykwalify
        verify_generic(to_verify, schema)
      File "/usr/lib/python3.9/site-packages/tavern/schemas/files.py", line 109, in verify_generic
        raise BadSchemaError() from e
    tavern.util.exceptions.BadSchemaError
Traceback (most recent call last):
  File "/usr/lib/python3.9/site-packages/tavern/schemas/files.py", line 106, in verify_generic
    verifier.validate()
  File "/usr/lib/python3.9/site-packages/pykwalify/core.py", line 194, in validate
    raise SchemaError(u"Schema validation failed:\n - {error_msg}.".format(
pykwalify.errors.SchemaError: <SchemaError: error code 2: Schema validation failed:
 - Enum 'in-progress' does not exist. Path: '/transitionStatus' Enum: ['completed'].: Path: '/'>

The above exception was the direct cause of the following exception:

Traceback (most recent call last):
  File "/usr/lib/python3.9/site-packages/tavern/response/base.py", line 152, in _maybe_run_validate_functions
    vf(response)
  File "/usr/lib/python3.9/site-packages/tavern/util/extfunctions.py", line 98, in inner
    result = func(response, *args, **kwargs)
  File "/usr/lib/python3.9/site-packages/tavern/testutils/helpers.py", line 103, in validate_pykwalify
    verify_generic(to_verify, schema)
  File "/usr/lib/python3.9/site-packages/tavern/schemas/files.py", line 109, in verify_generic
    raise BadSchemaError() from e
tavern.util.exceptions.BadSchemaError
[1m[31mERROR   [0m pykwalify.core:core.py:190 validation.invalid
[1m[31mERROR   [0m pykwalify.core:core.py:191  --- All found errors ---
[1m[31mERROR   [0m pykwalify.core:core.py:192 ["Enum 'in-progress' does not exist. Path: '/transitionStatus' Enum: ['completed']"]
[1m[31mERROR   [0m tavern.schemas.files:files.py:108 Error validating {'transitionID': 'b03025ba-051f-404b-9635-d7dfba4ec3eb', 'operation': 'Force-Off', 'createTime': '2024-03-20T08:23:02.382769589Z', 'automaticExpirationTime': '2024-03-21T08:23:02.382769649Z', 'transitionStatus': 'in-progress', 'taskCounts': {'total': 1, 'new': 0, 'in-progress': 1, 'failed': 0, 'succeeded': 0, 'un-supported': 0}, 'tasks': [{'xname': 'x3000c0s6b0n0', 'taskStatus': 'in-progress', 'taskStatusDescription': 'Confirming successful transition, forceoff'}]}
Traceback (most recent call last):
  File "/usr/lib/python3.9/site-packages/tavern/schemas/files.py", line 106, in verify_generic
    verifier.validate()
  File "/usr/lib/python3.9/site-packages/pykwalify/core.py", line 194, in validate
    raise SchemaError(u"Schema validation failed:\n - {error_msg}.".format(
pykwalify.errors.SchemaError: <SchemaError: error code 2: Schema validation failed:
 - Enum 'in-progress' does not exist. Path: '/transitionStatus' Enum: ['completed'].: Path: '/'>
[1m[31mERROR   [0m tavern.response.base:base.py:41 Error calling validate function '<function validate_pykwalify at 0x7f39ae9164c0>':
    Traceback (most recent call last):
      File "/usr/lib/python3.9/site-packages/tavern/schemas/files.py", line 106, in verify_generic
        verifier.validate()
      File "/usr/lib/python3.9/site-packages/pykwalify/core.py", line 194, in validate
        raise SchemaError(u"Schema validation failed:\n - {error_msg}.".format(
    pykwalify.errors.SchemaError: <SchemaError: error code 2: Schema validation failed:
     - Enum 'in-progress' does not exist. Path: '/transitionStatus' Enum: ['completed'].: Path: '/'>

    The above exception was the direct cause of the following exception:

    Traceback (most recent call last):
      File "/usr/lib/python3.9/site-packages/tavern/response/base.py", line 152, in _maybe_run_validate_functions
        vf(response)
      File "/usr/lib/python3.9/site-packages/tavern/util/extfunctions.py", line 98, in inner
        result = func(response, *args, **kwargs)
      File "/usr/lib/python3.9/site-packages/tavern/testutils/helpers.py", line 103, in validate_pykwalify
        verify_generic(to_verify, schema)
      File "/usr/lib/python3.9/site-packages/tavern/schemas/files.py", line 109, in verify_generic
        raise BadSchemaError() from e
    tavern.util.exceptions.BadSchemaError
Traceback (most recent call last):
  File "/usr/lib/python3.9/site-packages/tavern/schemas/files.py", line 106, in verify_generic
    verifier.validate()
  File "/usr/lib/python3.9/site-packages/pykwalify/core.py", line 194, in validate
    raise SchemaError(u"Schema validation failed:\n - {error_msg}.".format(
pykwalify.errors.SchemaError: <SchemaError: error code 2: Schema validation failed:
 - Enum 'in-progress' does not exist. Path: '/transitionStatus' Enum: ['completed'].: Path: '/'>

The above exception was the direct cause of the following exception:

Traceback (most recent call last):
  File "/usr/lib/python3.9/site-packages/tavern/response/base.py", line 152, in _maybe_run_validate_functions
    vf(response)
  File "/usr/lib/python3.9/site-packages/tavern/util/extfunctions.py", line 98, in inner
    result = func(response, *args, **kwargs)
  File "/usr/lib/python3.9/site-packages/tavern/testutils/helpers.py", line 103, in validate_pykwalify
    verify_generic(to_verify, schema)
  File "/usr/lib/python3.9/site-packages/tavern/schemas/files.py", line 109, in verify_generic
    raise BadSchemaError() from e
tavern.util.exceptions.BadSchemaError
[1m[31mERROR   [0m pykwalify.core:core.py:190 validation.invalid
[1m[31mERROR   [0m pykwalify.core:core.py:191  --- All found errors ---
[1m[31mERROR   [0m pykwalify.core:core.py:192 ["Enum 'in-progress' does not exist. Path: '/transitionStatus' Enum: ['completed']"]
[1m[31mERROR   [0m tavern.schemas.files:files.py:108 Error validating {'transitionID': 'b03025ba-051f-404b-9635-d7dfba4ec3eb', 'operation': 'Force-Off', 'createTime': '2024-03-20T08:23:02.382769589Z', 'automaticExpirationTime': '2024-03-21T08:23:02.382769649Z', 'transitionStatus': 'in-progress', 'taskCounts': {'total': 1, 'new': 0, 'in-progress': 1, 'failed': 0, 'succeeded': 0, 'un-supported': 0}, 'tasks': [{'xname': 'x3000c0s6b0n0', 'taskStatus': 'in-progress', 'taskStatusDescription': 'Confirming successful transition, forceoff'}]}
Traceback (most recent call last):
  File "/usr/lib/python3.9/site-packages/tavern/schemas/files.py", line 106, in verify_generic
    verifier.validate()
  File "/usr/lib/python3.9/site-packages/pykwalify/core.py", line 194, in validate
    raise SchemaError(u"Schema validation failed:\n - {error_msg}.".format(
pykwalify.errors.SchemaError: <SchemaError: error code 2: Schema validation failed:
 - Enum 'in-progress' does not exist. Path: '/transitionStatus' Enum: ['completed'].: Path: '/'>
[1m[31mERROR   [0m tavern.response.base:base.py:41 Error calling validate function '<function validate_pykwalify at 0x7f39ae9164c0>':
    Traceback (most recent call last):
      File "/usr/lib/python3.9/site-packages/tavern/schemas/files.py", line 106, in verify_generic
        verifier.validate()
      File "/usr/lib/python3.9/site-packages/pykwalify/core.py", line 194, in validate
        raise SchemaError(u"Schema validation failed:\n - {error_msg}.".format(
    pykwalify.errors.SchemaError: <SchemaError: error code 2: Schema validation failed:
     - Enum 'in-progress' does not exist. Path: '/transitionStatus' Enum: ['completed'].: Path: '/'>

    The above exception was the direct cause of the following exception:

    Traceback (most recent call last):
      File "/usr/lib/python3.9/site-packages/tavern/response/base.py", line 152, in _maybe_run_validate_functions
        vf(response)
      File "/usr/lib/python3.9/site-packages/tavern/util/extfunctions.py", line 98, in inner
        result = func(response, *args, **kwargs)
      File "/usr/lib/python3.9/site-packages/tavern/testutils/helpers.py", line 103, in validate_pykwalify
        verify_generic(to_verify, schema)
      File "/usr/lib/python3.9/site-packages/tavern/schemas/files.py", line 109, in verify_generic
        raise BadSchemaError() from e
    tavern.util.exceptions.BadSchemaError
Traceback (most recent call last):
  File "/usr/lib/python3.9/site-packages/tavern/schemas/files.py", line 106, in verify_generic
    verifier.validate()
  File "/usr/lib/python3.9/site-packages/pykwalify/core.py", line 194, in validate
    raise SchemaError(u"Schema validation failed:\n - {error_msg}.".format(
pykwalify.errors.SchemaError: <SchemaError: error code 2: Schema validation failed:
 - Enum 'in-progress' does not exist. Path: '/transitionStatus' Enum: ['completed'].: Path: '/'>

The above exception was the direct cause of the following exception:

Traceback (most recent call last):
  File "/usr/lib/python3.9/site-packages/tavern/response/base.py", line 152, in _maybe_run_validate_functions
    vf(response)
  File "/usr/lib/python3.9/site-packages/tavern/util/extfunctions.py", line 98, in inner
    result = func(response, *args, **kwargs)
  File "/usr/lib/python3.9/site-packages/tavern/testutils/helpers.py", line 103, in validate_pykwalify
    verify_generic(to_verify, schema)
  File "/usr/lib/python3.9/site-packages/tavern/schemas/files.py", line 109, in verify_generic
    raise BadSchemaError() from e
tavern.util.exceptions.BadSchemaError
[1m[31mERROR   [0m pykwalify.core:core.py:190 validation.invalid
[1m[31mERROR   [0m pykwalify.core:core.py:191  --- All found errors ---
[1m[31mERROR   [0m pykwalify.core:core.py:192 ["Enum 'in-progress' does not exist. Path: '/transitionStatus' Enum: ['completed']"]
[1m[31mERROR   [0m tavern.schemas.files:files.py:108 Error validating {'transitionID': '72974046-5a01-4604-a841-ae35918d5e3e', 'operation': 'On', 'createTime': '2024-03-20T08:23:18.625636003Z', 'automaticExpirationTime': '2024-03-21T08:23:18.625636073Z', 'transitionStatus': 'in-progress', 'taskCounts': {'total': 1, 'new': 1, 'in-progress': 0, 'failed': 0, 'succeeded': 0, 'un-supported': 0}, 'tasks': [{'xname': 'x3000c0s6b0n0', 'taskStatus': 'new', 'taskStatusDescription': 'Applying transition, on'}]}
Traceback (most recent call last):
  File "/usr/lib/python3.9/site-packages/tavern/schemas/files.py", line 106, in verify_generic
    verifier.validate()
  File "/usr/lib/python3.9/site-packages/pykwalify/core.py", line 194, in validate
    raise SchemaError(u"Schema validation failed:\n - {error_msg}.".format(
pykwalify.errors.SchemaError: <SchemaError: error code 2: Schema validation failed:
 - Enum 'in-progress' does not exist. Path: '/transitionStatus' Enum: ['completed'].: Path: '/'>
[1m[31mERROR   [0m tavern.response.base:base.py:41 Error calling validate function '<function validate_pykwalify at 0x7f39ae9164c0>':
    Traceback (most recent call last):
      File "/usr/lib/python3.9/site-packages/tavern/schemas/files.py", line 106, in verify_generic
        verifier.validate()
      File "/usr/lib/python3.9/site-packages/pykwalify/core.py", line 194, in validate
        raise SchemaError(u"Schema validation failed:\n - {error_msg}.".format(
    pykwalify.errors.SchemaError: <SchemaError: error code 2: Schema validation failed:
     - Enum 'in-progress' does not exist. Path: '/transitionStatus' Enum: ['completed'].: Path: '/'>

    The above exception was the direct cause of the following exception:

    Traceback (most recent call last):
      File "/usr/lib/python3.9/site-packages/tavern/response/base.py", line 152, in _maybe_run_validate_functions
        vf(response)
      File "/usr/lib/python3.9/site-packages/tavern/util/extfunctions.py", line 98, in inner
        result = func(response, *args, **kwargs)
      File "/usr/lib/python3.9/site-packages/tavern/testutils/helpers.py", line 103, in validate_pykwalify
        verify_generic(to_verify, schema)
      File "/usr/lib/python3.9/site-packages/tavern/schemas/files.py", line 109, in verify_generic
        raise BadSchemaError() from e
    tavern.util.exceptions.BadSchemaError
Traceback (most recent call last):
  File "/usr/lib/python3.9/site-packages/tavern/schemas/files.py", line 106, in verify_generic
    verifier.validate()
  File "/usr/lib/python3.9/site-packages/pykwalify/core.py", line 194, in validate
    raise SchemaError(u"Schema validation failed:\n - {error_msg}.".format(
pykwalify.errors.SchemaError: <SchemaError: error code 2: Schema validation failed:
 - Enum 'in-progress' does not exist. Path: '/transitionStatus' Enum: ['completed'].: Path: '/'>

The above exception was the direct cause of the following exception:

Traceback (most recent call last):
  File "/usr/lib/python3.9/site-packages/tavern/response/base.py", line 152, in _maybe_run_validate_functions
    vf(response)
  File "/usr/lib/python3.9/site-packages/tavern/util/extfunctions.py", line 98, in inner
    result = func(response, *args, **kwargs)
  File "/usr/lib/python3.9/site-packages/tavern/testutils/helpers.py", line 103, in validate_pykwalify
    verify_generic(to_verify, schema)
  File "/usr/lib/python3.9/site-packages/tavern/schemas/files.py", line 109, in verify_generic
    raise BadSchemaError() from e
tavern.util.exceptions.BadSchemaError
[1m[31mERROR   [0m pykwalify.core:core.py:190 validation.invalid
[1m[31mERROR   [0m pykwalify.core:core.py:191  --- All found errors ---
[1m[31mERROR   [0m pykwalify.core:core.py:192 ["Enum 'in-progress' does not exist. Path: '/transitionStatus' Enum: ['completed']"]
[1m[31mERROR   [0m tavern.schemas.files:files.py:108 Error validating {'transitionID': '72974046-5a01-4604-a841-ae35918d5e3e', 'operation': 'On', 'createTime': '2024-03-20T08:23:18.625636003Z', 'automaticExpirationTime': '2024-03-21T08:23:18.625636073Z', 'transitionStatus': 'in-progress', 'taskCounts': {'total': 1, 'new': 0, 'in-progress': 1, 'failed': 0, 'succeeded': 0, 'un-supported': 0}, 'tasks': [{'xname': 'x3000c0s6b0n0', 'taskStatus': 'in-progress', 'taskStatusDescription': 'Confirming successful transition, on'}]}
Traceback (most recent call last):
  File "/usr/lib/python3.9/site-packages/tavern/schemas/files.py", line 106, in verify_generic
    verifier.validate()
  File "/usr/lib/python3.9/site-packages/pykwalify/core.py", line 194, in validate
    raise SchemaError(u"Schema validation failed:\n - {error_msg}.".format(
pykwalify.errors.SchemaError: <SchemaError: error code 2: Schema validation failed:
 - Enum 'in-progress' does not exist. Path: '/transitionStatus' Enum: ['completed'].: Path: '/'>
[1m[31mERROR   [0m tavern.response.base:base.py:41 Error calling validate function '<function validate_pykwalify at 0x7f39ae9164c0>':
    Traceback (most recent call last):
      File "/usr/lib/python3.9/site-packages/tavern/schemas/files.py", line 106, in verify_generic
        verifier.validate()
      File "/usr/lib/python3.9/site-packages/pykwalify/core.py", line 194, in validate
        raise SchemaError(u"Schema validation failed:\n - {error_msg}.".format(
    pykwalify.errors.SchemaError: <SchemaError: error code 2: Schema validation failed:
     - Enum 'in-progress' does not exist. Path: '/transitionStatus' Enum: ['completed'].: Path: '/'>

    The above exception was the direct cause of the following exception:

    Traceback (most recent call last):
      File "/usr/lib/python3.9/site-packages/tavern/response/base.py", line 152, in _maybe_run_validate_functions
        vf(response)
      File "/usr/lib/python3.9/site-packages/tavern/util/extfunctions.py", line 98, in inner
        result = func(response, *args, **kwargs)
      File "/usr/lib/python3.9/site-packages/tavern/testutils/helpers.py", line 103, in validate_pykwalify
        verify_generic(to_verify, schema)
      File "/usr/lib/python3.9/site-packages/tavern/schemas/files.py", line 109, in verify_generic
        raise BadSchemaError() from e
    tavern.util.exceptions.BadSchemaError
Traceback (most recent call last):
  File "/usr/lib/python3.9/site-packages/tavern/schemas/files.py", line 106, in verify_generic
    verifier.validate()
  File "/usr/lib/python3.9/site-packages/pykwalify/core.py", line 194, in validate
    raise SchemaError(u"Schema validation failed:\n - {error_msg}.".format(
pykwalify.errors.SchemaError: <SchemaError: error code 2: Schema validation failed:
 - Enum 'in-progress' does not exist. Path: '/transitionStatus' Enum: ['completed'].: Path: '/'>

The above exception was the direct cause of the following exception:

Traceback (most recent call last):
  File "/usr/lib/python3.9/site-packages/tavern/response/base.py", line 152, in _maybe_run_validate_functions
    vf(response)
  File "/usr/lib/python3.9/site-packages/tavern/util/extfunctions.py", line 98, in inner
    result = func(response, *args, **kwargs)
  File "/usr/lib/python3.9/site-packages/tavern/testutils/helpers.py", line 103, in validate_pykwalify
    verify_generic(to_verify, schema)
  File "/usr/lib/python3.9/site-packages/tavern/schemas/files.py", line 109, in verify_generic
    raise BadSchemaError() from e
tavern.util.exceptions.BadSchemaError
[1m[31mERROR   [0m pykwalify.core:core.py:190 validation.invalid
[1m[31mERROR   [0m pykwalify.core:core.py:191  --- All found errors ---
[1m[31mERROR   [0m pykwalify.core:core.py:192 ["Enum 'in-progress' does not exist. Path: '/transitionStatus' Enum: ['completed']"]
[1m[31mERROR   [0m tavern.schemas.files:files.py:108 Error validating {'transitionID': '72974046-5a01-4604-a841-ae35918d5e3e', 'operation': 'On', 'createTime': '2024-03-20T08:23:18.625636003Z', 'automaticExpirationTime': '2024-03-21T08:23:18.625636073Z', 'transitionStatus': 'in-progress', 'taskCounts': {'total': 1, 'new': 0, 'in-progress': 1, 'failed': 0, 'succeeded': 0, 'un-supported': 0}, 'tasks': [{'xname': 'x3000c0s6b0n0', 'taskStatus': 'in-progress', 'taskStatusDescription': 'Confirming successful transition, on'}]}
Traceback (most recent call last):
  File "/usr/lib/python3.9/site-packages/tavern/schemas/files.py", line 106, in verify_generic
    verifier.validate()
  File "/usr/lib/python3.9/site-packages/pykwalify/core.py", line 194, in validate
    raise SchemaError(u"Schema validation failed:\n - {error_msg}.".format(
pykwalify.errors.SchemaError: <SchemaError: error code 2: Schema validation failed:
 - Enum 'in-progress' does not exist. Path: '/transitionStatus' Enum: ['completed'].: Path: '/'>
[1m[31mERROR   [0m tavern.response.base:base.py:41 Error calling validate function '<function validate_pykwalify at 0x7f39ae9164c0>':
    Traceback (most recent call last):
      File "/usr/lib/python3.9/site-packages/tavern/schemas/files.py", line 106, in verify_generic
        verifier.validate()
      File "/usr/lib/python3.9/site-packages/pykwalify/core.py", line 194, in validate
        raise SchemaError(u"Schema validation failed:\n - {error_msg}.".format(
    pykwalify.errors.SchemaError: <SchemaError: error code 2: Schema validation failed:
     - Enum 'in-progress' does not exist. Path: '/transitionStatus' Enum: ['completed'].: Path: '/'>

    The above exception was the direct cause of the following exception:

    Traceback (most recent call last):
      File "/usr/lib/python3.9/site-packages/tavern/response/base.py", line 152, in _maybe_run_validate_functions
        vf(response)
      File "/usr/lib/python3.9/site-packages/tavern/util/extfunctions.py", line 98, in inner
        result = func(response, *args, **kwargs)
      File "/usr/lib/python3.9/site-packages/tavern/testutils/helpers.py", line 103, in validate_pykwalify
        verify_generic(to_verify, schema)
      File "/usr/lib/python3.9/site-packages/tavern/schemas/files.py", line 109, in verify_generic
        raise BadSchemaError() from e
    tavern.util.exceptions.BadSchemaError
Traceback (most recent call last):
  File "/usr/lib/python3.9/site-packages/tavern/schemas/files.py", line 106, in verify_generic
    verifier.validate()
  File "/usr/lib/python3.9/site-packages/pykwalify/core.py", line 194, in validate
    raise SchemaError(u"Schema validation failed:\n - {error_msg}.".format(
pykwalify.errors.SchemaError: <SchemaError: error code 2: Schema validation failed:
 - Enum 'in-progress' does not exist. Path: '/transitionStatus' Enum: ['completed'].: Path: '/'>

The above exception was the direct cause of the following exception:

Traceback (most recent call last):
  File "/usr/lib/python3.9/site-packages/tavern/response/base.py", line 152, in _maybe_run_validate_functions
    vf(response)
  File "/usr/lib/python3.9/site-packages/tavern/util/extfunctions.py", line 98, in inner
    result = func(response, *args, **kwargs)
  File "/usr/lib/python3.9/site-packages/tavern/testutils/helpers.py", line 103, in validate_pykwalify
    verify_generic(to_verify, schema)
  File "/usr/lib/python3.9/site-packages/tavern/schemas/files.py", line 109, in verify_generic
    raise BadSchemaError() from e
tavern.util.exceptions.BadSchemaError
[1m[31mERROR   [0m pykwalify.core:core.py:190 validation.invalid
[1m[31mERROR   [0m pykwalify.core:core.py:191  --- All found errors ---
[1m[31mERROR   [0m pykwalify.core:core.py:192 ["Enum 'in-progress' does not exist. Path: '/transitionStatus' Enum: ['completed']"]
[1m[31mERROR   [0m tavern.schemas.files:files.py:108 Error validating {'transitionID': '72974046-5a01-4604-a841-ae35918d5e3e', 'operation': 'On', 'createTime': '2024-03-20T08:23:18.625636003Z', 'automaticExpirationTime': '2024-03-21T08:23:18.625636073Z', 'transitionStatus': 'in-progress', 'taskCounts': {'total': 1, 'new': 0, 'in-progress': 1, 'failed': 0, 'succeeded': 0, 'un-supported': 0}, 'tasks': [{'xname': 'x3000c0s6b0n0', 'taskStatus': 'in-progress', 'taskStatusDescription': 'Confirming successful transition, on'}]}
Traceback (most recent call last):
  File "/usr/lib/python3.9/site-packages/tavern/schemas/files.py", line 106, in verify_generic
    verifier.validate()
  File "/usr/lib/python3.9/site-packages/pykwalify/core.py", line 194, in validate
    raise SchemaError(u"Schema validation failed:\n - {error_msg}.".format(
pykwalify.errors.SchemaError: <SchemaError: error code 2: Schema validation failed:
 - Enum 'in-progress' does not exist. Path: '/transitionStatus' Enum: ['completed'].: Path: '/'>
[1m[31mERROR   [0m tavern.response.base:base.py:41 Error calling validate function '<function validate_pykwalify at 0x7f39ae9164c0>':
    Traceback (most recent call last):
      File "/usr/lib/python3.9/site-packages/tavern/schemas/files.py", line 106, in verify_generic
        verifier.validate()
      File "/usr/lib/python3.9/site-packages/pykwalify/core.py", line 194, in validate
        raise SchemaError(u"Schema validation failed:\n - {error_msg}.".format(
    pykwalify.errors.SchemaError: <SchemaError: error code 2: Schema validation failed:
     - Enum 'in-progress' does not exist. Path: '/transitionStatus' Enum: ['completed'].: Path: '/'>

    The above exception was the direct cause of the following exception:

    Traceback (most recent call last):
      File "/usr/lib/python3.9/site-packages/tavern/response/base.py", line 152, in _maybe_run_validate_functions
        vf(response)
      File "/usr/lib/python3.9/site-packages/tavern/util/extfunctions.py", line 98, in inner
        result = func(response, *args, **kwargs)
      File "/usr/lib/python3.9/site-packages/tavern/testutils/helpers.py", line 103, in validate_pykwalify
        verify_generic(to_verify, schema)
      File "/usr/lib/python3.9/site-packages/tavern/schemas/files.py", line 109, in verify_generic
        raise BadSchemaError() from e
    tavern.util.exceptions.BadSchemaError
Traceback (most recent call last):
  File "/usr/lib/python3.9/site-packages/tavern/schemas/files.py", line 106, in verify_generic
    verifier.validate()
  File "/usr/lib/python3.9/site-packages/pykwalify/core.py", line 194, in validate
    raise SchemaError(u"Schema validation failed:\n - {error_msg}.".format(
pykwalify.errors.SchemaError: <SchemaError: error code 2: Schema validation failed:
 - Enum 'in-progress' does not exist. Path: '/transitionStatus' Enum: ['completed'].: Path: '/'>

The above exception was the direct cause of the following exception:

Traceback (most recent call last):
  File "/usr/lib/python3.9/site-packages/tavern/response/base.py", line 152, in _maybe_run_validate_functions
    vf(response)
  File "/usr/lib/python3.9/site-packages/tavern/util/extfunctions.py", line 98, in inner
    result = func(response, *args, **kwargs)
  File "/usr/lib/python3.9/site-packages/tavern/testutils/helpers.py", line 103, in validate_pykwalify
    verify_generic(to_verify, schema)
  File "/usr/lib/python3.9/site-packages/tavern/schemas/files.py", line 109, in verify_generic
    raise BadSchemaError() from e
tavern.util.exceptions.BadSchemaError
[1m[31mERROR   [0m pykwalify.core:core.py:190 validation.invalid
[1m[31mERROR   [0m pykwalify.core:core.py:191  --- All found errors ---
[1m[31mERROR   [0m pykwalify.core:core.py:192 ["Enum 'in-progress' does not exist. Path: '/transitionStatus' Enum: ['completed']"]
[1m[31mERROR   [0m tavern.schemas.files:files.py:108 Error validating {'transitionID': '72974046-5a01-4604-a841-ae35918d5e3e', 'operation': 'On', 'createTime': '2024-03-20T08:23:18.625636003Z', 'automaticExpirationTime': '2024-03-21T08:23:18.625636073Z', 'transitionStatus': 'in-progress', 'taskCounts': {'total': 1, 'new': 0, 'in-progress': 1, 'failed': 0, 'succeeded': 0, 'un-supported': 0}, 'tasks': [{'xname': 'x3000c0s6b0n0', 'taskStatus': 'in-progress', 'taskStatusDescription': 'Confirming successful transition, on'}]}
Traceback (most recent call last):
  File "/usr/lib/python3.9/site-packages/tavern/schemas/files.py", line 106, in verify_generic
    verifier.validate()
  File "/usr/lib/python3.9/site-packages/pykwalify/core.py", line 194, in validate
    raise SchemaError(u"Schema validation failed:\n - {error_msg}.".format(
pykwalify.errors.SchemaError: <SchemaError: error code 2: Schema validation failed:
 - Enum 'in-progress' does not exist. Path: '/transitionStatus' Enum: ['completed'].: Path: '/'>
[1m[31mERROR   [0m tavern.response.base:base.py:41 Error calling validate function '<function validate_pykwalify at 0x7f39ae9164c0>':
    Traceback (most recent call last):
      File "/usr/lib/python3.9/site-packages/tavern/schemas/files.py", line 106, in verify_generic
        verifier.validate()
      File "/usr/lib/python3.9/site-packages/pykwalify/core.py", line 194, in validate
        raise SchemaError(u"Schema validation failed:\n - {error_msg}.".format(
    pykwalify.errors.SchemaError: <SchemaError: error code 2: Schema validation failed:
     - Enum 'in-progress' does not exist. Path: '/transitionStatus' Enum: ['completed'].: Path: '/'>

    The above exception was the direct cause of the following exception:

    Traceback (most recent call last):
      File "/usr/lib/python3.9/site-packages/tavern/response/base.py", line 152, in _maybe_run_validate_functions
        vf(response)
      File "/usr/lib/python3.9/site-packages/tavern/util/extfunctions.py", line 98, in inner
        result = func(response, *args, **kwargs)
      File "/usr/lib/python3.9/site-packages/tavern/testutils/helpers.py", line 103, in validate_pykwalify
        verify_generic(to_verify, schema)
      File "/usr/lib/python3.9/site-packages/tavern/schemas/files.py", line 109, in verify_generic
        raise BadSchemaError() from e
    tavern.util.exceptions.BadSchemaError
Traceback (most recent call last):
  File "/usr/lib/python3.9/site-packages/tavern/schemas/files.py", line 106, in verify_generic
    verifier.validate()
  File "/usr/lib/python3.9/site-packages/pykwalify/core.py", line 194, in validate
    raise SchemaError(u"Schema validation failed:\n - {error_msg}.".format(
pykwalify.errors.SchemaError: <SchemaError: error code 2: Schema validation failed:
 - Enum 'in-progress' does not exist. Path: '/transitionStatus' Enum: ['completed'].: Path: '/'>

The above exception was the direct cause of the following exception:

Traceback (most recent call last):
  File "/usr/lib/python3.9/site-packages/tavern/response/base.py", line 152, in _maybe_run_validate_functions
    vf(response)
  File "/usr/lib/python3.9/site-packages/tavern/util/extfunctions.py", line 98, in inner
    result = func(response, *args, **kwargs)
  File "/usr/lib/python3.9/site-packages/tavern/testutils/helpers.py", line 103, in validate_pykwalify
    verify_generic(to_verify, schema)
  File "/usr/lib/python3.9/site-packages/tavern/schemas/files.py", line 109, in verify_generic
    raise BadSchemaError() from e
tavern.util.exceptions.BadSchemaError
[1m[31mERROR   [0m pykwalify.core:core.py:190 validation.invalid
[1m[31mERROR   [0m pykwalify.core:core.py:191  --- All found errors ---
[1m[31mERROR   [0m pykwalify.core:core.py:192 ["Enum 'in-progress' does not exist. Path: '/transitionStatus' Enum: ['completed']"]
[1m[31mERROR   [0m tavern.schemas.files:files.py:108 Error validating {'transitionID': '72974046-5a01-4604-a841-ae35918d5e3e', 'operation': 'On', 'createTime': '2024-03-20T08:23:18.625636003Z', 'automaticExpirationTime': '2024-03-21T08:23:18.625636073Z', 'transitionStatus': 'in-progress', 'taskCounts': {'total': 1, 'new': 0, 'in-progress': 1, 'failed': 0, 'succeeded': 0, 'un-supported': 0}, 'tasks': [{'xname': 'x3000c0s6b0n0', 'taskStatus': 'in-progress', 'taskStatusDescription': 'Confirming successful transition, on'}]}
Traceback (most recent call last):
  File "/usr/lib/python3.9/site-packages/tavern/schemas/files.py", line 106, in verify_generic
    verifier.validate()
  File "/usr/lib/python3.9/site-packages/pykwalify/core.py", line 194, in validate
    raise SchemaError(u"Schema validation failed:\n - {error_msg}.".format(
pykwalify.errors.SchemaError: <SchemaError: error code 2: Schema validation failed:
 - Enum 'in-progress' does not exist. Path: '/transitionStatus' Enum: ['completed'].: Path: '/'>
[1m[31mERROR   [0m tavern.response.base:base.py:41 Error calling validate function '<function validate_pykwalify at 0x7f39ae9164c0>':
    Traceback (most recent call last):
      File "/usr/lib/python3.9/site-packages/tavern/schemas/files.py", line 106, in verify_generic
        verifier.validate()
      File "/usr/lib/python3.9/site-packages/pykwalify/core.py", line 194, in validate
        raise SchemaError(u"Schema validation failed:\n - {error_msg}.".format(
    pykwalify.errors.SchemaError: <SchemaError: error code 2: Schema validation failed:
     - Enum 'in-progress' does not exist. Path: '/transitionStatus' Enum: ['completed'].: Path: '/'>

    The above exception was the direct cause of the following exception:

    Traceback (most recent call last):
      File "/usr/lib/python3.9/site-packages/tavern/response/base.py", line 152, in _maybe_run_validate_functions
        vf(response)
      File "/usr/lib/python3.9/site-packages/tavern/util/extfunctions.py", line 98, in inner
        result = func(response, *args, **kwargs)
      File "/usr/lib/python3.9/site-packages/tavern/testutils/helpers.py", line 103, in validate_pykwalify
        verify_generic(to_verify, schema)
      File "/usr/lib/python3.9/site-packages/tavern/schemas/files.py", line 109, in verify_generic
        raise BadSchemaError() from e
    tavern.util.exceptions.BadSchemaError
Traceback (most recent call last):
  File "/usr/lib/python3.9/site-packages/tavern/schemas/files.py", line 106, in verify_generic
    verifier.validate()
  File "/usr/lib/python3.9/site-packages/pykwalify/core.py", line 194, in validate
    raise SchemaError(u"Schema validation failed:\n - {error_msg}.".format(
pykwalify.errors.SchemaError: <SchemaError: error code 2: Schema validation failed:
 - Enum 'in-progress' does not exist. Path: '/transitionStatus' Enum: ['completed'].: Path: '/'>

The above exception was the direct cause of the following exception:

Traceback (most recent call last):
  File "/usr/lib/python3.9/site-packages/tavern/response/base.py", line 152, in _maybe_run_validate_functions
    vf(response)
  File "/usr/lib/python3.9/site-packages/tavern/util/extfunctions.py", line 98, in inner
    result = func(response, *args, **kwargs)
  File "/usr/lib/python3.9/site-packages/tavern/testutils/helpers.py", line 103, in validate_pykwalify
    verify_generic(to_verify, schema)
  File "/usr/lib/python3.9/site-packages/tavern/schemas/files.py", line 109, in verify_generic
    raise BadSchemaError() from e
tavern.util.exceptions.BadSchemaError
[1m[31mERROR   [0m pykwalify.core:core.py:190 validation.invalid
[1m[31mERROR   [0m pykwalify.core:core.py:191  --- All found errors ---
[1m[31mERROR   [0m pykwalify.core:core.py:192 ["Enum 'in-progress' does not exist. Path: '/transitionStatus' Enum: ['completed']"]
[1m[31mERROR   [0m tavern.schemas.files:files.py:108 Error validating {'transitionID': '72974046-5a01-4604-a841-ae35918d5e3e', 'operation': 'On', 'createTime': '2024-03-20T08:23:18.625636003Z', 'automaticExpirationTime': '2024-03-21T08:23:18.625636073Z', 'transitionStatus': 'in-progress', 'taskCounts': {'total': 1, 'new': 0, 'in-progress': 1, 'failed': 0, 'succeeded': 0, 'un-supported': 0}, 'tasks': [{'xname': 'x3000c0s6b0n0', 'taskStatus': 'in-progress', 'taskStatusDescription': 'Confirming successful transition, on'}]}
Traceback (most recent call last):
  File "/usr/lib/python3.9/site-packages/tavern/schemas/files.py", line 106, in verify_generic
    verifier.validate()
  File "/usr/lib/python3.9/site-packages/pykwalify/core.py", line 194, in validate
    raise SchemaError(u"Schema validation failed:\n - {error_msg}.".format(
pykwalify.errors.SchemaError: <SchemaError: error code 2: Schema validation failed:
 - Enum 'in-progress' does not exist. Path: '/transitionStatus' Enum: ['completed'].: Path: '/'>
[1m[31mERROR   [0m tavern.response.base:base.py:41 Error calling validate function '<function validate_pykwalify at 0x7f39ae9164c0>':
    Traceback (most recent call last):
      File "/usr/lib/python3.9/site-packages/tavern/schemas/files.py", line 106, in verify_generic
        verifier.validate()
      File "/usr/lib/python3.9/site-packages/pykwalify/core.py", line 194, in validate
        raise SchemaError(u"Schema validation failed:\n - {error_msg}.".format(
    pykwalify.errors.SchemaError: <SchemaError: error code 2: Schema validation failed:
     - Enum 'in-progress' does not exist. Path: '/transitionStatus' Enum: ['completed'].: Path: '/'>

    The above exception was the direct cause of the following exception:

    Traceback (most recent call last):
      File "/usr/lib/python3.9/site-packages/tavern/response/base.py", line 152, in _maybe_run_validate_functions
        vf(response)
      File "/usr/lib/python3.9/site-packages/tavern/util/extfunctions.py", line 98, in inner
        result = func(response, *args, **kwargs)
      File "/usr/lib/python3.9/site-packages/tavern/testutils/helpers.py", line 103, in validate_pykwalify
        verify_generic(to_verify, schema)
      File "/usr/lib/python3.9/site-packages/tavern/schemas/files.py", line 109, in verify_generic
        raise BadSchemaError() from e
    tavern.util.exceptions.BadSchemaError
Traceback (most recent call last):
  File "/usr/lib/python3.9/site-packages/tavern/schemas/files.py", line 106, in verify_generic
    verifier.validate()
  File "/usr/lib/python3.9/site-packages/pykwalify/core.py", line 194, in validate
    raise SchemaError(u"Schema validation failed:\n - {error_msg}.".format(
pykwalify.errors.SchemaError: <SchemaError: error code 2: Schema validation failed:
 - Enum 'in-progress' does not exist. Path: '/transitionStatus' Enum: ['completed'].: Path: '/'>

The above exception was the direct cause of the following exception:

Traceback (most recent call last):
  File "/usr/lib/python3.9/site-packages/tavern/response/base.py", line 152, in _maybe_run_validate_functions
    vf(response)
  File "/usr/lib/python3.9/site-packages/tavern/util/extfunctions.py", line 98, in inner
    result = func(response, *args, **kwargs)
  File "/usr/lib/python3.9/site-packages/tavern/testutils/helpers.py", line 103, in validate_pykwalify
    verify_generic(to_verify, schema)
  File "/usr/lib/python3.9/site-packages/tavern/schemas/files.py", line 109, in verify_generic
    raise BadSchemaError() from e
tavern.util.exceptions.BadSchemaError
[1m[31mERROR   [0m pykwalify.core:core.py:190 validation.invalid
[1m[31mERROR   [0m pykwalify.core:core.py:191  --- All found errors ---
[1m[31mERROR   [0m pykwalify.core:core.py:192 ["Enum 'in-progress' does not exist. Path: '/transitionStatus' Enum: ['completed']"]
[1m[31mERROR   [0m tavern.schemas.files:files.py:108 Error validating {'transitionID': '72974046-5a01-4604-a841-ae35918d5e3e', 'operation': 'On', 'createTime': '2024-03-20T08:23:18.625636003Z', 'automaticExpirationTime': '2024-03-21T08:23:18.625636073Z', 'transitionStatus': 'in-progress', 'taskCounts': {'total': 1, 'new': 0, 'in-progress': 1, 'failed': 0, 'succeeded': 0, 'un-supported': 0}, 'tasks': [{'xname': 'x3000c0s6b0n0', 'taskStatus': 'in-progress', 'taskStatusDescription': 'Confirming successful transition, on'}]}
Traceback (most recent call last):
  File "/usr/lib/python3.9/site-packages/tavern/schemas/files.py", line 106, in verify_generic
    verifier.validate()
  File "/usr/lib/python3.9/site-packages/pykwalify/core.py", line 194, in validate
    raise SchemaError(u"Schema validation failed:\n - {error_msg}.".format(
pykwalify.errors.SchemaError: <SchemaError: error code 2: Schema validation failed:
 - Enum 'in-progress' does not exist. Path: '/transitionStatus' Enum: ['completed'].: Path: '/'>
[1m[31mERROR   [0m tavern.response.base:base.py:41 Error calling validate function '<function validate_pykwalify at 0x7f39ae9164c0>':
    Traceback (most recent call last):
      File "/usr/lib/python3.9/site-packages/tavern/schemas/files.py", line 106, in verify_generic
        verifier.validate()
      File "/usr/lib/python3.9/site-packages/pykwalify/core.py", line 194, in validate
        raise SchemaError(u"Schema validation failed:\n - {error_msg}.".format(
    pykwalify.errors.SchemaError: <SchemaError: error code 2: Schema validation failed:
     - Enum 'in-progress' does not exist. Path: '/transitionStatus' Enum: ['completed'].: Path: '/'>

    The above exception was the direct cause of the following exception:

    Traceback (most recent call last):
      File "/usr/lib/python3.9/site-packages/tavern/response/base.py", line 152, in _maybe_run_validate_functions
        vf(response)
      File "/usr/lib/python3.9/site-packages/tavern/util/extfunctions.py", line 98, in inner
        result = func(response, *args, **kwargs)
      File "/usr/lib/python3.9/site-packages/tavern/testutils/helpers.py", line 103, in validate_pykwalify
        verify_generic(to_verify, schema)
      File "/usr/lib/python3.9/site-packages/tavern/schemas/files.py", line 109, in verify_generic
        raise BadSchemaError() from e
    tavern.util.exceptions.BadSchemaError
Traceback (most recent call last):
  File "/usr/lib/python3.9/site-packages/tavern/schemas/files.py", line 106, in verify_generic
    verifier.validate()
  File "/usr/lib/python3.9/site-packages/pykwalify/core.py", line 194, in validate
    raise SchemaError(u"Schema validation failed:\n - {error_msg}.".format(
pykwalify.errors.SchemaError: <SchemaError: error code 2: Schema validation failed:
 - Enum 'in-progress' does not exist. Path: '/transitionStatus' Enum: ['completed'].: Path: '/'>

The above exception was the direct cause of the following exception:

Traceback (most recent call last):
  File "/usr/lib/python3.9/site-packages/tavern/response/base.py", line 152, in _maybe_run_validate_functions
    vf(response)
  File "/usr/lib/python3.9/site-packages/tavern/util/extfunctions.py", line 98, in inner
    result = func(response, *args, **kwargs)
  File "/usr/lib/python3.9/site-packages/tavern/testutils/helpers.py", line 103, in validate_pykwalify
    verify_generic(to_verify, schema)
  File "/usr/lib/python3.9/site-packages/tavern/schemas/files.py", line 109, in verify_generic
    raise BadSchemaError() from e
tavern.util.exceptions.BadSchemaError
[1m[31mERROR   [0m pykwalify.core:core.py:190 validation.invalid
[1m[31mERROR   [0m pykwalify.core:core.py:191  --- All found errors ---
[1m[31mERROR   [0m pykwalify.core:core.py:192 ["Enum 'in-progress' does not exist. Path: '/transitionStatus' Enum: ['completed']"]
[1m[31mERROR   [0m tavern.schemas.files:files.py:108 Error validating {'transitionID': '72974046-5a01-4604-a841-ae35918d5e3e', 'operation': 'On', 'createTime': '2024-03-20T08:23:18.625636003Z', 'automaticExpirationTime': '2024-03-21T08:23:18.625636073Z', 'transitionStatus': 'in-progress', 'taskCounts': {'total': 1, 'new': 0, 'in-progress': 1, 'failed': 0, 'succeeded': 0, 'un-supported': 0}, 'tasks': [{'xname': 'x3000c0s6b0n0', 'taskStatus': 'in-progress', 'taskStatusDescription': 'Confirming successful transition, on'}]}
Traceback (most recent call last):
  File "/usr/lib/python3.9/site-packages/tavern/schemas/files.py", line 106, in verify_generic
    verifier.validate()
  File "/usr/lib/python3.9/site-packages/pykwalify/core.py", line 194, in validate
    raise SchemaError(u"Schema validation failed:\n - {error_msg}.".format(
pykwalify.errors.SchemaError: <SchemaError: error code 2: Schema validation failed:
 - Enum 'in-progress' does not exist. Path: '/transitionStatus' Enum: ['completed'].: Path: '/'>
[1m[31mERROR   [0m tavern.response.base:base.py:41 Error calling validate function '<function validate_pykwalify at 0x7f39ae9164c0>':
    Traceback (most recent call last):
      File "/usr/lib/python3.9/site-packages/tavern/schemas/files.py", line 106, in verify_generic
        verifier.validate()
      File "/usr/lib/python3.9/site-packages/pykwalify/core.py", line 194, in validate
        raise SchemaError(u"Schema validation failed:\n - {error_msg}.".format(
    pykwalify.errors.SchemaError: <SchemaError: error code 2: Schema validation failed:
     - Enum 'in-progress' does not exist. Path: '/transitionStatus' Enum: ['completed'].: Path: '/'>

    The above exception was the direct cause of the following exception:

    Traceback (most recent call last):
      File "/usr/lib/python3.9/site-packages/tavern/response/base.py", line 152, in _maybe_run_validate_functions
        vf(response)
      File "/usr/lib/python3.9/site-packages/tavern/util/extfunctions.py", line 98, in inner
        result = func(response, *args, **kwargs)
      File "/usr/lib/python3.9/site-packages/tavern/testutils/helpers.py", line 103, in validate_pykwalify
        verify_generic(to_verify, schema)
      File "/usr/lib/python3.9/site-packages/tavern/schemas/files.py", line 109, in verify_generic
        raise BadSchemaError() from e
    tavern.util.exceptions.BadSchemaError
Traceback (most recent call last):
  File "/usr/lib/python3.9/site-packages/tavern/schemas/files.py", line 106, in verify_generic
    verifier.validate()
  File "/usr/lib/python3.9/site-packages/pykwalify/core.py", line 194, in validate
    raise SchemaError(u"Schema validation failed:\n - {error_msg}.".format(
pykwalify.errors.SchemaError: <SchemaError: error code 2: Schema validation failed:
 - Enum 'in-progress' does not exist. Path: '/transitionStatus' Enum: ['completed'].: Path: '/'>

The above exception was the direct cause of the following exception:

Traceback (most recent call last):
  File "/usr/lib/python3.9/site-packages/tavern/response/base.py", line 152, in _maybe_run_validate_functions
    vf(response)
  File "/usr/lib/python3.9/site-packages/tavern/util/extfunctions.py", line 98, in inner
    result = func(response, *args, **kwargs)
  File "/usr/lib/python3.9/site-packages/tavern/testutils/helpers.py", line 103, in validate_pykwalify
    verify_generic(to_verify, schema)
  File "/usr/lib/python3.9/site-packages/tavern/schemas/files.py", line 109, in verify_generic
    raise BadSchemaError() from e
tavern.util.exceptions.BadSchemaError
[1m[31mERROR   [0m pykwalify.core:core.py:190 validation.invalid
[1m[31mERROR   [0m pykwalify.core:core.py:191  --- All found errors ---
[1m[31mERROR   [0m pykwalify.core:core.py:192 ["Enum 'in-progress' does not exist. Path: '/transitionStatus' Enum: ['completed']"]
[1m[31mERROR   [0m tavern.schemas.files:files.py:108 Error validating {'transitionID': '72974046-5a01-4604-a841-ae35918d5e3e', 'operation': 'On', 'createTime': '2024-03-20T08:23:18.625636003Z', 'automaticExpirationTime': '2024-03-21T08:23:18.625636073Z', 'transitionStatus': 'in-progress', 'taskCounts': {'total': 1, 'new': 0, 'in-progress': 1, 'failed': 0, 'succeeded': 0, 'un-supported': 0}, 'tasks': [{'xname': 'x3000c0s6b0n0', 'taskStatus': 'in-progress', 'taskStatusDescription': 'Confirming successful transition, on'}]}
Traceback (most recent call last):
  File "/usr/lib/python3.9/site-packages/tavern/schemas/files.py", line 106, in verify_generic
    verifier.validate()
  File "/usr/lib/python3.9/site-packages/pykwalify/core.py", line 194, in validate
    raise SchemaError(u"Schema validation failed:\n - {error_msg}.".format(
pykwalify.errors.SchemaError: <SchemaError: error code 2: Schema validation failed:
 - Enum 'in-progress' does not exist. Path: '/transitionStatus' Enum: ['completed'].: Path: '/'>
[1m[31mERROR   [0m tavern.response.base:base.py:41 Error calling validate function '<function validate_pykwalify at 0x7f39ae9164c0>':
    Traceback (most recent call last):
      File "/usr/lib/python3.9/site-packages/tavern/schemas/files.py", line 106, in verify_generic
        verifier.validate()
      File "/usr/lib/python3.9/site-packages/pykwalify/core.py", line 194, in validate
        raise SchemaError(u"Schema validation failed:\n - {error_msg}.".format(
    pykwalify.errors.SchemaError: <SchemaError: error code 2: Schema validation failed:
     - Enum 'in-progress' does not exist. Path: '/transitionStatus' Enum: ['completed'].: Path: '/'>

    The above exception was the direct cause of the following exception:

    Traceback (most recent call last):
      File "/usr/lib/python3.9/site-packages/tavern/response/base.py", line 152, in _maybe_run_validate_functions
        vf(response)
      File "/usr/lib/python3.9/site-packages/tavern/util/extfunctions.py", line 98, in inner
        result = func(response, *args, **kwargs)
      File "/usr/lib/python3.9/site-packages/tavern/testutils/helpers.py", line 103, in validate_pykwalify
        verify_generic(to_verify, schema)
      File "/usr/lib/python3.9/site-packages/tavern/schemas/files.py", line 109, in verify_generic
        raise BadSchemaError() from e
    tavern.util.exceptions.BadSchemaError
Traceback (most recent call last):
  File "/usr/lib/python3.9/site-packages/tavern/schemas/files.py", line 106, in verify_generic
    verifier.validate()
  File "/usr/lib/python3.9/site-packages/pykwalify/core.py", line 194, in validate
    raise SchemaError(u"Schema validation failed:\n - {error_msg}.".format(
pykwalify.errors.SchemaError: <SchemaError: error code 2: Schema validation failed:
 - Enum 'in-progress' does not exist. Path: '/transitionStatus' Enum: ['completed'].: Path: '/'>

The above exception was the direct cause of the following exception:

Traceback (most recent call last):
  File "/usr/lib/python3.9/site-packages/tavern/response/base.py", line 152, in _maybe_run_validate_functions
    vf(response)
  File "/usr/lib/python3.9/site-packages/tavern/util/extfunctions.py", line 98, in inner
    result = func(response, *args, **kwargs)
  File "/usr/lib/python3.9/site-packages/tavern/testutils/helpers.py", line 103, in validate_pykwalify
    verify_generic(to_verify, schema)
  File "/usr/lib/python3.9/site-packages/tavern/schemas/files.py", line 109, in verify_generic
    raise BadSchemaError() from e
tavern.util.exceptions.BadSchemaError
[1m[31mERROR   [0m pykwalify.core:core.py:190 validation.invalid
[1m[31mERROR   [0m pykwalify.core:core.py:191  --- All found errors ---
[1m[31mERROR   [0m pykwalify.core:core.py:192 ["Enum 'in-progress' does not exist. Path: '/transitionStatus' Enum: ['completed']"]
[1m[31mERROR   [0m tavern.schemas.files:files.py:108 Error validating {'transitionID': '72974046-5a01-4604-a841-ae35918d5e3e', 'operation': 'On', 'createTime': '2024-03-20T08:23:18.625636003Z', 'automaticExpirationTime': '2024-03-21T08:23:18.625636073Z', 'transitionStatus': 'in-progress', 'taskCounts': {'total': 1, 'new': 0, 'in-progress': 1, 'failed': 0, 'succeeded': 0, 'un-supported': 0}, 'tasks': [{'xname': 'x3000c0s6b0n0', 'taskStatus': 'in-progress', 'taskStatusDescription': 'Confirming successful transition, on'}]}
Traceback (most recent call last):
  File "/usr/lib/python3.9/site-packages/tavern/schemas/files.py", line 106, in verify_generic
    verifier.validate()
  File "/usr/lib/python3.9/site-packages/pykwalify/core.py", line 194, in validate
    raise SchemaError(u"Schema validation failed:\n - {error_msg}.".format(
pykwalify.errors.SchemaError: <SchemaError: error code 2: Schema validation failed:
 - Enum 'in-progress' does not exist. Path: '/transitionStatus' Enum: ['completed'].: Path: '/'>
[1m[31mERROR   [0m tavern.response.base:base.py:41 Error calling validate function '<function validate_pykwalify at 0x7f39ae9164c0>':
    Traceback (most recent call last):
      File "/usr/lib/python3.9/site-packages/tavern/schemas/files.py", line 106, in verify_generic
        verifier.validate()
      File "/usr/lib/python3.9/site-packages/pykwalify/core.py", line 194, in validate
        raise SchemaError(u"Schema validation failed:\n - {error_msg}.".format(
    pykwalify.errors.SchemaError: <SchemaError: error code 2: Schema validation failed:
     - Enum 'in-progress' does not exist. Path: '/transitionStatus' Enum: ['completed'].: Path: '/'>

    The above exception was the direct cause of the following exception:

    Traceback (most recent call last):
      File "/usr/lib/python3.9/site-packages/tavern/response/base.py", line 152, in _maybe_run_validate_functions
        vf(response)
      File "/usr/lib/python3.9/site-packages/tavern/util/extfunctions.py", line 98, in inner
        result = func(response, *args, **kwargs)
      File "/usr/lib/python3.9/site-packages/tavern/testutils/helpers.py", line 103, in validate_pykwalify
        verify_generic(to_verify, schema)
      File "/usr/lib/python3.9/site-packages/tavern/schemas/files.py", line 109, in verify_generic
        raise BadSchemaError() from e
    tavern.util.exceptions.BadSchemaError
Traceback (most recent call last):
  File "/usr/lib/python3.9/site-packages/tavern/schemas/files.py", line 106, in verify_generic
    verifier.validate()
  File "/usr/lib/python3.9/site-packages/pykwalify/core.py", line 194, in validate
    raise SchemaError(u"Schema validation failed:\n - {error_msg}.".format(
pykwalify.errors.SchemaError: <SchemaError: error code 2: Schema validation failed:
 - Enum 'in-progress' does not exist. Path: '/transitionStatus' Enum: ['completed'].: Path: '/'>

The above exception was the direct cause of the following exception:

Traceback (most recent call last):
  File "/usr/lib/python3.9/site-packages/tavern/response/base.py", line 152, in _maybe_run_validate_functions
    vf(response)
  File "/usr/lib/python3.9/site-packages/tavern/util/extfunctions.py", line 98, in inner
    result = func(response, *args, **kwargs)
  File "/usr/lib/python3.9/site-packages/tavern/testutils/helpers.py", line 103, in validate_pykwalify
    verify_generic(to_verify, schema)
  File "/usr/lib/python3.9/site-packages/tavern/schemas/files.py", line 109, in verify_generic
    raise BadSchemaError() from e
tavern.util.exceptions.BadSchemaError
[1m[31mERROR   [0m pykwalify.core:core.py:190 validation.invalid
[1m[31mERROR   [0m pykwalify.core:core.py:191  --- All found errors ---
[1m[31mERROR   [0m pykwalify.core:core.py:192 ["Enum 'in-progress' does not exist. Path: '/transitionStatus' Enum: ['completed']"]
[1m[31mERROR   [0m tavern.schemas.files:files.py:108 Error validating {'transitionID': '72974046-5a01-4604-a841-ae35918d5e3e', 'operation': 'On', 'createTime': '2024-03-20T08:23:18.625636003Z', 'automaticExpirationTime': '2024-03-21T08:23:18.625636073Z', 'transitionStatus': 'in-progress', 'taskCounts': {'total': 1, 'new': 0, 'in-progress': 1, 'failed': 0, 'succeeded': 0, 'un-supported': 0}, 'tasks': [{'xname': 'x3000c0s6b0n0', 'taskStatus': 'in-progress', 'taskStatusDescription': 'Confirming successful transition, on'}]}
Traceback (most recent call last):
  File "/usr/lib/python3.9/site-packages/tavern/schemas/files.py", line 106, in verify_generic
    verifier.validate()
  File "/usr/lib/python3.9/site-packages/pykwalify/core.py", line 194, in validate
    raise SchemaError(u"Schema validation failed:\n - {error_msg}.".format(
pykwalify.errors.SchemaError: <SchemaError: error code 2: Schema validation failed:
 - Enum 'in-progress' does not exist. Path: '/transitionStatus' Enum: ['completed'].: Path: '/'>
[1m[31mERROR   [0m tavern.response.base:base.py:41 Error calling validate function '<function validate_pykwalify at 0x7f39ae9164c0>':
    Traceback (most recent call last):
      File "/usr/lib/python3.9/site-packages/tavern/schemas/files.py", line 106, in verify_generic
        verifier.validate()
      File "/usr/lib/python3.9/site-packages/pykwalify/core.py", line 194, in validate
        raise SchemaError(u"Schema validation failed:\n - {error_msg}.".format(
    pykwalify.errors.SchemaError: <SchemaError: error code 2: Schema validation failed:
     - Enum 'in-progress' does not exist. Path: '/transitionStatus' Enum: ['completed'].: Path: '/'>

    The above exception was the direct cause of the following exception:

    Traceback (most recent call last):
      File "/usr/lib/python3.9/site-packages/tavern/response/base.py", line 152, in _maybe_run_validate_functions
        vf(response)
      File "/usr/lib/python3.9/site-packages/tavern/util/extfunctions.py", line 98, in inner
        result = func(response, *args, **kwargs)
      File "/usr/lib/python3.9/site-packages/tavern/testutils/helpers.py", line 103, in validate_pykwalify
        verify_generic(to_verify, schema)
      File "/usr/lib/python3.9/site-packages/tavern/schemas/files.py", line 109, in verify_generic
        raise BadSchemaError() from e
    tavern.util.exceptions.BadSchemaError
Traceback (most recent call last):
  File "/usr/lib/python3.9/site-packages/tavern/schemas/files.py", line 106, in verify_generic
    verifier.validate()
  File "/usr/lib/python3.9/site-packages/pykwalify/core.py", line 194, in validate
    raise SchemaError(u"Schema validation failed:\n - {error_msg}.".format(
pykwalify.errors.SchemaError: <SchemaError: error code 2: Schema validation failed:
 - Enum 'in-progress' does not exist. Path: '/transitionStatus' Enum: ['completed'].: Path: '/'>

The above exception was the direct cause of the following exception:

Traceback (most recent call last):
  File "/usr/lib/python3.9/site-packages/tavern/response/base.py", line 152, in _maybe_run_validate_functions
    vf(response)
  File "/usr/lib/python3.9/site-packages/tavern/util/extfunctions.py", line 98, in inner
    result = func(response, *args, **kwargs)
  File "/usr/lib/python3.9/site-packages/tavern/testutils/helpers.py", line 103, in validate_pykwalify
    verify_generic(to_verify, schema)
  File "/usr/lib/python3.9/site-packages/tavern/schemas/files.py", line 109, in verify_generic
    raise BadSchemaError() from e
tavern.util.exceptions.BadSchemaError
[1m[31mERROR   [0m pykwalify.core:core.py:190 validation.invalid
[1m[31mERROR   [0m pykwalify.core:core.py:191  --- All found errors ---
[1m[31mERROR   [0m pykwalify.core:core.py:192 ["Enum 'in-progress' does not exist. Path: '/transitionStatus' Enum: ['completed']"]
[1m[31mERROR   [0m tavern.schemas.files:files.py:108 Error validating {'transitionID': '72974046-5a01-4604-a841-ae35918d5e3e', 'operation': 'On', 'createTime': '2024-03-20T08:23:18.625636003Z', 'automaticExpirationTime': '2024-03-21T08:23:18.625636073Z', 'transitionStatus': 'in-progress', 'taskCounts': {'total': 1, 'new': 0, 'in-progress': 1, 'failed': 0, 'succeeded': 0, 'un-supported': 0}, 'tasks': [{'xname': 'x3000c0s6b0n0', 'taskStatus': 'in-progress', 'taskStatusDescription': 'Confirming successful transition, on'}]}
Traceback (most recent call last):
  File "/usr/lib/python3.9/site-packages/tavern/schemas/files.py", line 106, in verify_generic
    verifier.validate()
  File "/usr/lib/python3.9/site-packages/pykwalify/core.py", line 194, in validate
    raise SchemaError(u"Schema validation failed:\n - {error_msg}.".format(
pykwalify.errors.SchemaError: <SchemaError: error code 2: Schema validation failed:
 - Enum 'in-progress' does not exist. Path: '/transitionStatus' Enum: ['completed'].: Path: '/'>
[1m[31mERROR   [0m tavern.response.base:base.py:41 Error calling validate function '<function validate_pykwalify at 0x7f39ae9164c0>':
    Traceback (most recent call last):
      File "/usr/lib/python3.9/site-packages/tavern/schemas/files.py", line 106, in verify_generic
        verifier.validate()
      File "/usr/lib/python3.9/site-packages/pykwalify/core.py", line 194, in validate
        raise SchemaError(u"Schema validation failed:\n - {error_msg}.".format(
    pykwalify.errors.SchemaError: <SchemaError: error code 2: Schema validation failed:
     - Enum 'in-progress' does not exist. Path: '/transitionStatus' Enum: ['completed'].: Path: '/'>

    The above exception was the direct cause of the following exception:

    Traceback (most recent call last):
      File "/usr/lib/python3.9/site-packages/tavern/response/base.py", line 152, in _maybe_run_validate_functions
        vf(response)
      File "/usr/lib/python3.9/site-packages/tavern/util/extfunctions.py", line 98, in inner
        result = func(response, *args, **kwargs)
      File "/usr/lib/python3.9/site-packages/tavern/testutils/helpers.py", line 103, in validate_pykwalify
        verify_generic(to_verify, schema)
      File "/usr/lib/python3.9/site-packages/tavern/schemas/files.py", line 109, in verify_generic
        raise BadSchemaError() from e
    tavern.util.exceptions.BadSchemaError
Traceback (most recent call last):
  File "/usr/lib/python3.9/site-packages/tavern/schemas/files.py", line 106, in verify_generic
    verifier.validate()
  File "/usr/lib/python3.9/site-packages/pykwalify/core.py", line 194, in validate
    raise SchemaError(u"Schema validation failed:\n - {error_msg}.".format(
pykwalify.errors.SchemaError: <SchemaError: error code 2: Schema validation failed:
 - Enum 'in-progress' does not exist. Path: '/transitionStatus' Enum: ['completed'].: Path: '/'>

The above exception was the direct cause of the following exception:

Traceback (most recent call last):
  File "/usr/lib/python3.9/site-packages/tavern/response/base.py", line 152, in _maybe_run_validate_functions
    vf(response)
  File "/usr/lib/python3.9/site-packages/tavern/util/extfunctions.py", line 98, in inner
    result = func(response, *args, **kwargs)
  File "/usr/lib/python3.9/site-packages/tavern/testutils/helpers.py", line 103, in validate_pykwalify
    verify_generic(to_verify, schema)
  File "/usr/lib/python3.9/site-packages/tavern/schemas/files.py", line 109, in verify_generic
    raise BadSchemaError() from e
tavern.util.exceptions.BadSchemaError
[1m[31mERROR   [0m pykwalify.core:core.py:190 validation.invalid
[1m[31mERROR   [0m pykwalify.core:core.py:191  --- All found errors ---
[1m[31mERROR   [0m pykwalify.core:core.py:192 ["Enum 'in-progress' does not exist. Path: '/transitionStatus' Enum: ['completed']"]
[1m[31mERROR   [0m tavern.schemas.files:files.py:108 Error validating {'transitionID': '72974046-5a01-4604-a841-ae35918d5e3e', 'operation': 'On', 'createTime': '2024-03-20T08:23:18.625636003Z', 'automaticExpirationTime': '2024-03-21T08:23:18.625636073Z', 'transitionStatus': 'in-progress', 'taskCounts': {'total': 1, 'new': 0, 'in-progress': 1, 'failed': 0, 'succeeded': 0, 'un-supported': 0}, 'tasks': [{'xname': 'x3000c0s6b0n0', 'taskStatus': 'in-progress', 'taskStatusDescription': 'Confirming successful transition, on'}]}
Traceback (most recent call last):
  File "/usr/lib/python3.9/site-packages/tavern/schemas/files.py", line 106, in verify_generic
    verifier.validate()
  File "/usr/lib/python3.9/site-packages/pykwalify/core.py", line 194, in validate
    raise SchemaError(u"Schema validation failed:\n - {error_msg}.".format(
pykwalify.errors.SchemaError: <SchemaError: error code 2: Schema validation failed:
 - Enum 'in-progress' does not exist. Path: '/transitionStatus' Enum: ['completed'].: Path: '/'>
[1m[31mERROR   [0m tavern.response.base:base.py:41 Error calling validate function '<function validate_pykwalify at 0x7f39ae9164c0>':
    Traceback (most recent call last):
      File "/usr/lib/python3.9/site-packages/tavern/schemas/files.py", line 106, in verify_generic
        verifier.validate()
      File "/usr/lib/python3.9/site-packages/pykwalify/core.py", line 194, in validate
        raise SchemaError(u"Schema validation failed:\n - {error_msg}.".format(
    pykwalify.errors.SchemaError: <SchemaError: error code 2: Schema validation failed:
     - Enum 'in-progress' does not exist. Path: '/transitionStatus' Enum: ['completed'].: Path: '/'>

    The above exception was the direct cause of the following exception:

    Traceback (most recent call last):
      File "/usr/lib/python3.9/site-packages/tavern/response/base.py", line 152, in _maybe_run_validate_functions
        vf(response)
      File "/usr/lib/python3.9/site-packages/tavern/util/extfunctions.py", line 98, in inner
        result = func(response, *args, **kwargs)
      File "/usr/lib/python3.9/site-packages/tavern/testutils/helpers.py", line 103, in validate_pykwalify
        verify_generic(to_verify, schema)
      File "/usr/lib/python3.9/site-packages/tavern/schemas/files.py", line 109, in verify_generic
        raise BadSchemaError() from e
    tavern.util.exceptions.BadSchemaError
Traceback (most recent call last):
  File "/usr/lib/python3.9/site-packages/tavern/schemas/files.py", line 106, in verify_generic
    verifier.validate()
  File "/usr/lib/python3.9/site-packages/pykwalify/core.py", line 194, in validate
    raise SchemaError(u"Schema validation failed:\n - {error_msg}.".format(
pykwalify.errors.SchemaError: <SchemaError: error code 2: Schema validation failed:
 - Enum 'in-progress' does not exist. Path: '/transitionStatus' Enum: ['completed'].: Path: '/'>

The above exception was the direct cause of the following exception:

Traceback (most recent call last):
  File "/usr/lib/python3.9/site-packages/tavern/response/base.py", line 152, in _maybe_run_validate_functions
    vf(response)
  File "/usr/lib/python3.9/site-packages/tavern/util/extfunctions.py", line 98, in inner
    result = func(response, *args, **kwargs)
  File "/usr/lib/python3.9/site-packages/tavern/testutils/helpers.py", line 103, in validate_pykwalify
    verify_generic(to_verify, schema)
  File "/usr/lib/python3.9/site-packages/tavern/schemas/files.py", line 109, in verify_generic
    raise BadSchemaError() from e
tavern.util.exceptions.BadSchemaError
[1m[31mERROR   [0m pykwalify.core:core.py:190 validation.invalid
[1m[31mERROR   [0m pykwalify.core:core.py:191  --- All found errors ---
[1m[31mERROR   [0m pykwalify.core:core.py:192 ["Enum 'in-progress' does not exist. Path: '/transitionStatus' Enum: ['completed']"]
[1m[31mERROR   [0m tavern.schemas.files:files.py:108 Error validating {'transitionID': '72974046-5a01-4604-a841-ae35918d5e3e', 'operation': 'On', 'createTime': '2024-03-20T08:23:18.625636003Z', 'automaticExpirationTime': '2024-03-21T08:23:18.625636073Z', 'transitionStatus': 'in-progress', 'taskCounts': {'total': 1, 'new': 0, 'in-progress': 1, 'failed': 0, 'succeeded': 0, 'un-supported': 0}, 'tasks': [{'xname': 'x3000c0s6b0n0', 'taskStatus': 'in-progress', 'taskStatusDescription': 'Confirming successful transition, on'}]}
Traceback (most recent call last):
  File "/usr/lib/python3.9/site-packages/tavern/schemas/files.py", line 106, in verify_generic
    verifier.validate()
  File "/usr/lib/python3.9/site-packages/pykwalify/core.py", line 194, in validate
    raise SchemaError(u"Schema validation failed:\n - {error_msg}.".format(
pykwalify.errors.SchemaError: <SchemaError: error code 2: Schema validation failed:
 - Enum 'in-progress' does not exist. Path: '/transitionStatus' Enum: ['completed'].: Path: '/'>
[1m[31mERROR   [0m tavern.response.base:base.py:41 Error calling validate function '<function validate_pykwalify at 0x7f39ae9164c0>':
    Traceback (most recent call last):
      File "/usr/lib/python3.9/site-packages/tavern/schemas/files.py", line 106, in verify_generic
        verifier.validate()
      File "/usr/lib/python3.9/site-packages/pykwalify/core.py", line 194, in validate
        raise SchemaError(u"Schema validation failed:\n - {error_msg}.".format(
    pykwalify.errors.SchemaError: <SchemaError: error code 2: Schema validation failed:
     - Enum 'in-progress' does not exist. Path: '/transitionStatus' Enum: ['completed'].: Path: '/'>

    The above exception was the direct cause of the following exception:

    Traceback (most recent call last):
      File "/usr/lib/python3.9/site-packages/tavern/response/base.py", line 152, in _maybe_run_validate_functions
        vf(response)
      File "/usr/lib/python3.9/site-packages/tavern/util/extfunctions.py", line 98, in inner
        result = func(response, *args, **kwargs)
      File "/usr/lib/python3.9/site-packages/tavern/testutils/helpers.py", line 103, in validate_pykwalify
        verify_generic(to_verify, schema)
      File "/usr/lib/python3.9/site-packages/tavern/schemas/files.py", line 109, in verify_generic
        raise BadSchemaError() from e
    tavern.util.exceptions.BadSchemaError
Traceback (most recent call last):
  File "/usr/lib/python3.9/site-packages/tavern/schemas/files.py", line 106, in verify_generic
    verifier.validate()
  File "/usr/lib/python3.9/site-packages/pykwalify/core.py", line 194, in validate
    raise SchemaError(u"Schema validation failed:\n - {error_msg}.".format(
pykwalify.errors.SchemaError: <SchemaError: error code 2: Schema validation failed:
 - Enum 'in-progress' does not exist. Path: '/transitionStatus' Enum: ['completed'].: Path: '/'>

The above exception was the direct cause of the following exception:

Traceback (most recent call last):
  File "/usr/lib/python3.9/site-packages/tavern/response/base.py", line 152, in _maybe_run_validate_functions
    vf(response)
  File "/usr/lib/python3.9/site-packages/tavern/util/extfunctions.py", line 98, in inner
    result = func(response, *args, **kwargs)
  File "/usr/lib/python3.9/site-packages/tavern/testutils/helpers.py", line 103, in validate_pykwalify
    verify_generic(to_verify, schema)
  File "/usr/lib/python3.9/site-packages/tavern/schemas/files.py", line 109, in verify_generic
    raise BadSchemaError() from e
tavern.util.exceptions.BadSchemaError
[1m[31mERROR   [0m pykwalify.core:core.py:190 validation.invalid
[1m[31mERROR   [0m pykwalify.core:core.py:191  --- All found errors ---
[1m[31mERROR   [0m pykwalify.core:core.py:192 ["Enum 'in-progress' does not exist. Path: '/transitionStatus' Enum: ['completed']"]
[1m[31mERROR   [0m tavern.schemas.files:files.py:108 Error validating {'transitionID': '72974046-5a01-4604-a841-ae35918d5e3e', 'operation': 'On', 'createTime': '2024-03-20T08:23:18.625636003Z', 'automaticExpirationTime': '2024-03-21T08:23:18.625636073Z', 'transitionStatus': 'in-progress', 'taskCounts': {'total': 1, 'new': 0, 'in-progress': 1, 'failed': 0, 'succeeded': 0, 'un-supported': 0}, 'tasks': [{'xname': 'x3000c0s6b0n0', 'taskStatus': 'in-progress', 'taskStatusDescription': 'Confirming successful transition, on'}]}
Traceback (most recent call last):
  File "/usr/lib/python3.9/site-packages/tavern/schemas/files.py", line 106, in verify_generic
    verifier.validate()
  File "/usr/lib/python3.9/site-packages/pykwalify/core.py", line 194, in validate
    raise SchemaError(u"Schema validation failed:\n - {error_msg}.".format(
pykwalify.errors.SchemaError: <SchemaError: error code 2: Schema validation failed:
 - Enum 'in-progress' does not exist. Path: '/transitionStatus' Enum: ['completed'].: Path: '/'>
[1m[31mERROR   [0m tavern.response.base:base.py:41 Error calling validate function '<function validate_pykwalify at 0x7f39ae9164c0>':
    Traceback (most recent call last):
      File "/usr/lib/python3.9/site-packages/tavern/schemas/files.py", line 106, in verify_generic
        verifier.validate()
      File "/usr/lib/python3.9/site-packages/pykwalify/core.py", line 194, in validate
        raise SchemaError(u"Schema validation failed:\n - {error_msg}.".format(
    pykwalify.errors.SchemaError: <SchemaError: error code 2: Schema validation failed:
     - Enum 'in-progress' does not exist. Path: '/transitionStatus' Enum: ['completed'].: Path: '/'>

    The above exception was the direct cause of the following exception:

    Traceback (most recent call last):
      File "/usr/lib/python3.9/site-packages/tavern/response/base.py", line 152, in _maybe_run_validate_functions
        vf(response)
      File "/usr/lib/python3.9/site-packages/tavern/util/extfunctions.py", line 98, in inner
        result = func(response, *args, **kwargs)
      File "/usr/lib/python3.9/site-packages/tavern/testutils/helpers.py", line 103, in validate_pykwalify
        verify_generic(to_verify, schema)
      File "/usr/lib/python3.9/site-packages/tavern/schemas/files.py", line 109, in verify_generic
        raise BadSchemaError() from e
    tavern.util.exceptions.BadSchemaError
Traceback (most recent call last):
  File "/usr/lib/python3.9/site-packages/tavern/schemas/files.py", line 106, in verify_generic
    verifier.validate()
  File "/usr/lib/python3.9/site-packages/pykwalify/core.py", line 194, in validate
    raise SchemaError(u"Schema validation failed:\n - {error_msg}.".format(
pykwalify.errors.SchemaError: <SchemaError: error code 2: Schema validation failed:
 - Enum 'in-progress' does not exist. Path: '/transitionStatus' Enum: ['completed'].: Path: '/'>

The above exception was the direct cause of the following exception:

Traceback (most recent call last):
  File "/usr/lib/python3.9/site-packages/tavern/response/base.py", line 152, in _maybe_run_validate_functions
    vf(response)
  File "/usr/lib/python3.9/site-packages/tavern/util/extfunctions.py", line 98, in inner
    result = func(response, *args, **kwargs)
  File "/usr/lib/python3.9/site-packages/tavern/testutils/helpers.py", line 103, in validate_pykwalify
    verify_generic(to_verify, schema)
  File "/usr/lib/python3.9/site-packages/tavern/schemas/files.py", line 109, in verify_generic
    raise BadSchemaError() from e
tavern.util.exceptions.BadSchemaError
[1m[31mERROR   [0m pykwalify.core:core.py:190 validation.invalid
[1m[31mERROR   [0m pykwalify.core:core.py:191  --- All found errors ---
[1m[31mERROR   [0m pykwalify.core:core.py:192 ["Enum 'in-progress' does not exist. Path: '/transitionStatus' Enum: ['completed']"]
[1m[31mERROR   [0m tavern.schemas.files:files.py:108 Error validating {'transitionID': '72974046-5a01-4604-a841-ae35918d5e3e', 'operation': 'On', 'createTime': '2024-03-20T08:23:18.625636003Z', 'automaticExpirationTime': '2024-03-21T08:23:18.625636073Z', 'transitionStatus': 'in-progress', 'taskCounts': {'total': 1, 'new': 0, 'in-progress': 1, 'failed': 0, 'succeeded': 0, 'un-supported': 0}, 'tasks': [{'xname': 'x3000c0s6b0n0', 'taskStatus': 'in-progress', 'taskStatusDescription': 'Confirming successful transition, on'}]}
Traceback (most recent call last):
  File "/usr/lib/python3.9/site-packages/tavern/schemas/files.py", line 106, in verify_generic
    verifier.validate()
  File "/usr/lib/python3.9/site-packages/pykwalify/core.py", line 194, in validate
    raise SchemaError(u"Schema validation failed:\n - {error_msg}.".format(
pykwalify.errors.SchemaError: <SchemaError: error code 2: Schema validation failed:
 - Enum 'in-progress' does not exist. Path: '/transitionStatus' Enum: ['completed'].: Path: '/'>
[1m[31mERROR   [0m tavern.response.base:base.py:41 Error calling validate function '<function validate_pykwalify at 0x7f39ae9164c0>':
    Traceback (most recent call last):
      File "/usr/lib/python3.9/site-packages/tavern/schemas/files.py", line 106, in verify_generic
        verifier.validate()
      File "/usr/lib/python3.9/site-packages/pykwalify/core.py", line 194, in validate
        raise SchemaError(u"Schema validation failed:\n - {error_msg}.".format(
    pykwalify.errors.SchemaError: <SchemaError: error code 2: Schema validation failed:
     - Enum 'in-progress' does not exist. Path: '/transitionStatus' Enum: ['completed'].: Path: '/'>

    The above exception was the direct cause of the following exception:

    Traceback (most recent call last):
      File "/usr/lib/python3.9/site-packages/tavern/response/base.py", line 152, in _maybe_run_validate_functions
        vf(response)
      File "/usr/lib/python3.9/site-packages/tavern/util/extfunctions.py", line 98, in inner
        result = func(response, *args, **kwargs)
      File "/usr/lib/python3.9/site-packages/tavern/testutils/helpers.py", line 103, in validate_pykwalify
        verify_generic(to_verify, schema)
      File "/usr/lib/python3.9/site-packages/tavern/schemas/files.py", line 109, in verify_generic
        raise BadSchemaError() from e
    tavern.util.exceptions.BadSchemaError
Traceback (most recent call last):
  File "/usr/lib/python3.9/site-packages/tavern/schemas/files.py", line 106, in verify_generic
    verifier.validate()
  File "/usr/lib/python3.9/site-packages/pykwalify/core.py", line 194, in validate
    raise SchemaError(u"Schema validation failed:\n - {error_msg}.".format(
pykwalify.errors.SchemaError: <SchemaError: error code 2: Schema validation failed:
 - Enum 'in-progress' does not exist. Path: '/transitionStatus' Enum: ['completed'].: Path: '/'>

The above exception was the direct cause of the following exception:

Traceback (most recent call last):
  File "/usr/lib/python3.9/site-packages/tavern/response/base.py", line 152, in _maybe_run_validate_functions
    vf(response)
  File "/usr/lib/python3.9/site-packages/tavern/util/extfunctions.py", line 98, in inner
    result = func(response, *args, **kwargs)
  File "/usr/lib/python3.9/site-packages/tavern/testutils/helpers.py", line 103, in validate_pykwalify
    verify_generic(to_verify, schema)
  File "/usr/lib/python3.9/site-packages/tavern/schemas/files.py", line 109, in verify_generic
    raise BadSchemaError() from e
tavern.util.exceptions.BadSchemaError
[1m[31mERROR   [0m pykwalify.core:core.py:190 validation.invalid
[1m[31mERROR   [0m pykwalify.core:core.py:191  --- All found errors ---
[1m[31mERROR   [0m pykwalify.core:core.py:192 ["Enum 'in-progress' does not exist. Path: '/transitionStatus' Enum: ['completed']"]
[1m[31mERROR   [0m tavern.schemas.files:files.py:108 Error validating {'transitionID': '72974046-5a01-4604-a841-ae35918d5e3e', 'operation': 'On', 'createTime': '2024-03-20T08:23:18.625636003Z', 'automaticExpirationTime': '2024-03-21T08:23:18.625636073Z', 'transitionStatus': 'in-progress', 'taskCounts': {'total': 1, 'new': 0, 'in-progress': 1, 'failed': 0, 'succeeded': 0, 'un-supported': 0}, 'tasks': [{'xname': 'x3000c0s6b0n0', 'taskStatus': 'in-progress', 'taskStatusDescription': 'Confirming successful transition, on'}]}
Traceback (most recent call last):
  File "/usr/lib/python3.9/site-packages/tavern/schemas/files.py", line 106, in verify_generic
    verifier.validate()
  File "/usr/lib/python3.9/site-packages/pykwalify/core.py", line 194, in validate
    raise SchemaError(u"Schema validation failed:\n - {error_msg}.".format(
pykwalify.errors.SchemaError: <SchemaError: error code 2: Schema validation failed:
 - Enum 'in-progress' does not exist. Path: '/transitionStatus' Enum: ['completed'].: Path: '/'>
[1m[31mERROR   [0m tavern.response.base:base.py:41 Error calling validate function '<function validate_pykwalify at 0x7f39ae9164c0>':
    Traceback (most recent call last):
      File "/usr/lib/python3.9/site-packages/tavern/schemas/files.py", line 106, in verify_generic
        verifier.validate()
      File "/usr/lib/python3.9/site-packages/pykwalify/core.py", line 194, in validate
        raise SchemaError(u"Schema validation failed:\n - {error_msg}.".format(
    pykwalify.errors.SchemaError: <SchemaError: error code 2: Schema validation failed:
     - Enum 'in-progress' does not exist. Path: '/transitionStatus' Enum: ['completed'].: Path: '/'>

    The above exception was the direct cause of the following exception:

    Traceback (most recent call last):
      File "/usr/lib/python3.9/site-packages/tavern/response/base.py", line 152, in _maybe_run_validate_functions
        vf(response)
      File "/usr/lib/python3.9/site-packages/tavern/util/extfunctions.py", line 98, in inner
        result = func(response, *args, **kwargs)
      File "/usr/lib/python3.9/site-packages/tavern/testutils/helpers.py", line 103, in validate_pykwalify
        verify_generic(to_verify, schema)
      File "/usr/lib/python3.9/site-packages/tavern/schemas/files.py", line 109, in verify_generic
        raise BadSchemaError() from e
    tavern.util.exceptions.BadSchemaError
Traceback (most recent call last):
  File "/usr/lib/python3.9/site-packages/tavern/schemas/files.py", line 106, in verify_generic
    verifier.validate()
  File "/usr/lib/python3.9/site-packages/pykwalify/core.py", line 194, in validate
    raise SchemaError(u"Schema validation failed:\n - {error_msg}.".format(
pykwalify.errors.SchemaError: <SchemaError: error code 2: Schema validation failed:
 - Enum 'in-progress' does not exist. Path: '/transitionStatus' Enum: ['completed'].: Path: '/'>

The above exception was the direct cause of the following exception:

Traceback (most recent call last):
  File "/usr/lib/python3.9/site-packages/tavern/response/base.py", line 152, in _maybe_run_validate_functions
    vf(response)
  File "/usr/lib/python3.9/site-packages/tavern/util/extfunctions.py", line 98, in inner
    result = func(response, *args, **kwargs)
  File "/usr/lib/python3.9/site-packages/tavern/testutils/helpers.py", line 103, in validate_pykwalify
    verify_generic(to_verify, schema)
  File "/usr/lib/python3.9/site-packages/tavern/schemas/files.py", line 109, in verify_generic
    raise BadSchemaError() from e
tavern.util.exceptions.BadSchemaError
[1m[31mERROR   [0m pykwalify.core:core.py:190 validation.invalid
[1m[31mERROR   [0m pykwalify.core:core.py:191  --- All found errors ---
[1m[31mERROR   [0m pykwalify.core:core.py:192 ["Enum 'in-progress' does not exist. Path: '/transitionStatus' Enum: ['completed']"]
[1m[31mERROR   [0m tavern.schemas.files:files.py:108 Error validating {'transitionID': '72974046-5a01-4604-a841-ae35918d5e3e', 'operation': 'On', 'createTime': '2024-03-20T08:23:18.625636003Z', 'automaticExpirationTime': '2024-03-21T08:23:18.625636073Z', 'transitionStatus': 'in-progress', 'taskCounts': {'total': 1, 'new': 0, 'in-progress': 1, 'failed': 0, 'succeeded': 0, 'un-supported': 0}, 'tasks': [{'xname': 'x3000c0s6b0n0', 'taskStatus': 'in-progress', 'taskStatusDescription': 'Confirming successful transition, on'}]}
Traceback (most recent call last):
  File "/usr/lib/python3.9/site-packages/tavern/schemas/files.py", line 106, in verify_generic
    verifier.validate()
  File "/usr/lib/python3.9/site-packages/pykwalify/core.py", line 194, in validate
    raise SchemaError(u"Schema validation failed:\n - {error_msg}.".format(
pykwalify.errors.SchemaError: <SchemaError: error code 2: Schema validation failed:
 - Enum 'in-progress' does not exist. Path: '/transitionStatus' Enum: ['completed'].: Path: '/'>
[1m[31mERROR   [0m tavern.response.base:base.py:41 Error calling validate function '<function validate_pykwalify at 0x7f39ae9164c0>':
    Traceback (most recent call last):
      File "/usr/lib/python3.9/site-packages/tavern/schemas/files.py", line 106, in verify_generic
        verifier.validate()
      File "/usr/lib/python3.9/site-packages/pykwalify/core.py", line 194, in validate
        raise SchemaError(u"Schema validation failed:\n - {error_msg}.".format(
    pykwalify.errors.SchemaError: <SchemaError: error code 2: Schema validation failed:
     - Enum 'in-progress' does not exist. Path: '/transitionStatus' Enum: ['completed'].: Path: '/'>

    The above exception was the direct cause of the following exception:

    Traceback (most recent call last):
      File "/usr/lib/python3.9/site-packages/tavern/response/base.py", line 152, in _maybe_run_validate_functions
        vf(response)
      File "/usr/lib/python3.9/site-packages/tavern/util/extfunctions.py", line 98, in inner
        result = func(response, *args, **kwargs)
      File "/usr/lib/python3.9/site-packages/tavern/testutils/helpers.py", line 103, in validate_pykwalify
        verify_generic(to_verify, schema)
      File "/usr/lib/python3.9/site-packages/tavern/schemas/files.py", line 109, in verify_generic
        raise BadSchemaError() from e
    tavern.util.exceptions.BadSchemaError
Traceback (most recent call last):
  File "/usr/lib/python3.9/site-packages/tavern/schemas/files.py", line 106, in verify_generic
    verifier.validate()
  File "/usr/lib/python3.9/site-packages/pykwalify/core.py", line 194, in validate
    raise SchemaError(u"Schema validation failed:\n - {error_msg}.".format(
pykwalify.errors.SchemaError: <SchemaError: error code 2: Schema validation failed:
 - Enum 'in-progress' does not exist. Path: '/transitionStatus' Enum: ['completed'].: Path: '/'>

The above exception was the direct cause of the following exception:

Traceback (most recent call last):
  File "/usr/lib/python3.9/site-packages/tavern/response/base.py", line 152, in _maybe_run_validate_functions
    vf(response)
  File "/usr/lib/python3.9/site-packages/tavern/util/extfunctions.py", line 98, in inner
    result = func(response, *args, **kwargs)
  File "/usr/lib/python3.9/site-packages/tavern/testutils/helpers.py", line 103, in validate_pykwalify
    verify_generic(to_verify, schema)
  File "/usr/lib/python3.9/site-packages/tavern/schemas/files.py", line 109, in verify_generic
    raise BadSchemaError() from e
tavern.util.exceptions.BadSchemaError
[1m[31mERROR   [0m pykwalify.core:core.py:190 validation.invalid
[1m[31mERROR   [0m pykwalify.core:core.py:191  --- All found errors ---
[1m[31mERROR   [0m pykwalify.core:core.py:192 ["Enum 'in-progress' does not exist. Path: '/transitionStatus' Enum: ['completed']"]
[1m[31mERROR   [0m tavern.schemas.files:files.py:108 Error validating {'transitionID': '72974046-5a01-4604-a841-ae35918d5e3e', 'operation': 'On', 'createTime': '2024-03-20T08:23:18.625636003Z', 'automaticExpirationTime': '2024-03-21T08:23:18.625636073Z', 'transitionStatus': 'in-progress', 'taskCounts': {'total': 1, 'new': 0, 'in-progress': 1, 'failed': 0, 'succeeded': 0, 'un-supported': 0}, 'tasks': [{'xname': 'x3000c0s6b0n0', 'taskStatus': 'in-progress', 'taskStatusDescription': 'Confirming successful transition, on'}]}
Traceback (most recent call last):
  File "/usr/lib/python3.9/site-packages/tavern/schemas/files.py", line 106, in verify_generic
    verifier.validate()
  File "/usr/lib/python3.9/site-packages/pykwalify/core.py", line 194, in validate
    raise SchemaError(u"Schema validation failed:\n - {error_msg}.".format(
pykwalify.errors.SchemaError: <SchemaError: error code 2: Schema validation failed:
 - Enum 'in-progress' does not exist. Path: '/transitionStatus' Enum: ['completed'].: Path: '/'>
[1m[31mERROR   [0m tavern.response.base:base.py:41 Error calling validate function '<function validate_pykwalify at 0x7f39ae9164c0>':
    Traceback (most recent call last):
      File "/usr/lib/python3.9/site-packages/tavern/schemas/files.py", line 106, in verify_generic
        verifier.validate()
      File "/usr/lib/python3.9/site-packages/pykwalify/core.py", line 194, in validate
        raise SchemaError(u"Schema validation failed:\n - {error_msg}.".format(
    pykwalify.errors.SchemaError: <SchemaError: error code 2: Schema validation failed:
     - Enum 'in-progress' does not exist. Path: '/transitionStatus' Enum: ['completed'].: Path: '/'>

    The above exception was the direct cause of the following exception:

    Traceback (most recent call last):
      File "/usr/lib/python3.9/site-packages/tavern/response/base.py", line 152, in _maybe_run_validate_functions
        vf(response)
      File "/usr/lib/python3.9/site-packages/tavern/util/extfunctions.py", line 98, in inner
        result = func(response, *args, **kwargs)
      File "/usr/lib/python3.9/site-packages/tavern/testutils/helpers.py", line 103, in validate_pykwalify
        verify_generic(to_verify, schema)
      File "/usr/lib/python3.9/site-packages/tavern/schemas/files.py", line 109, in verify_generic
        raise BadSchemaError() from e
    tavern.util.exceptions.BadSchemaError
Traceback (most recent call last):
  File "/usr/lib/python3.9/site-packages/tavern/schemas/files.py", line 106, in verify_generic
    verifier.validate()
  File "/usr/lib/python3.9/site-packages/pykwalify/core.py", line 194, in validate
    raise SchemaError(u"Schema validation failed:\n - {error_msg}.".format(
pykwalify.errors.SchemaError: <SchemaError: error code 2: Schema validation failed:
 - Enum 'in-progress' does not exist. Path: '/transitionStatus' Enum: ['completed'].: Path: '/'>

The above exception was the direct cause of the following exception:

Traceback (most recent call last):
  File "/usr/lib/python3.9/site-packages/tavern/response/base.py", line 152, in _maybe_run_validate_functions
    vf(response)
  File "/usr/lib/python3.9/site-packages/tavern/util/extfunctions.py", line 98, in inner
    result = func(response, *args, **kwargs)
  File "/usr/lib/python3.9/site-packages/tavern/testutils/helpers.py", line 103, in validate_pykwalify
    verify_generic(to_verify, schema)
  File "/usr/lib/python3.9/site-packages/tavern/schemas/files.py", line 109, in verify_generic
    raise BadSchemaError() from e
tavern.util.exceptions.BadSchemaError
[1m[31mERROR   [0m pykwalify.core:core.py:190 validation.invalid
[1m[31mERROR   [0m pykwalify.core:core.py:191  --- All found errors ---
[1m[31mERROR   [0m pykwalify.core:core.py:192 ["Enum 'in-progress' does not exist. Path: '/transitionStatus' Enum: ['completed']"]
[1m[31mERROR   [0m tavern.schemas.files:files.py:108 Error validating {'transitionID': '72974046-5a01-4604-a841-ae35918d5e3e', 'operation': 'On', 'createTime': '2024-03-20T08:23:18.625636003Z', 'automaticExpirationTime': '2024-03-21T08:23:18.625636073Z', 'transitionStatus': 'in-progress', 'taskCounts': {'total': 1, 'new': 0, 'in-progress': 1, 'failed': 0, 'succeeded': 0, 'un-supported': 0}, 'tasks': [{'xname': 'x3000c0s6b0n0', 'taskStatus': 'in-progress', 'taskStatusDescription': 'Confirming successful transition, on'}]}
Traceback (most recent call last):
  File "/usr/lib/python3.9/site-packages/tavern/schemas/files.py", line 106, in verify_generic
    verifier.validate()
  File "/usr/lib/python3.9/site-packages/pykwalify/core.py", line 194, in validate
    raise SchemaError(u"Schema validation failed:\n - {error_msg}.".format(
pykwalify.errors.SchemaError: <SchemaError: error code 2: Schema validation failed:
 - Enum 'in-progress' does not exist. Path: '/transitionStatus' Enum: ['completed'].: Path: '/'>
[1m[31mERROR   [0m tavern.response.base:base.py:41 Error calling validate function '<function validate_pykwalify at 0x7f39ae9164c0>':
    Traceback (most recent call last):
      File "/usr/lib/python3.9/site-packages/tavern/schemas/files.py", line 106, in verify_generic
        verifier.validate()
      File "/usr/lib/python3.9/site-packages/pykwalify/core.py", line 194, in validate
        raise SchemaError(u"Schema validation failed:\n - {error_msg}.".format(
    pykwalify.errors.SchemaError: <SchemaError: error code 2: Schema validation failed:
     - Enum 'in-progress' does not exist. Path: '/transitionStatus' Enum: ['completed'].: Path: '/'>

    The above exception was the direct cause of the following exception:

    Traceback (most recent call last):
      File "/usr/lib/python3.9/site-packages/tavern/response/base.py", line 152, in _maybe_run_validate_functions
        vf(response)
      File "/usr/lib/python3.9/site-packages/tavern/util/extfunctions.py", line 98, in inner
        result = func(response, *args, **kwargs)
      File "/usr/lib/python3.9/site-packages/tavern/testutils/helpers.py", line 103, in validate_pykwalify
        verify_generic(to_verify, schema)
      File "/usr/lib/python3.9/site-packages/tavern/schemas/files.py", line 109, in verify_generic
        raise BadSchemaError() from e
    tavern.util.exceptions.BadSchemaError
Traceback (most recent call last):
  File "/usr/lib/python3.9/site-packages/tavern/schemas/files.py", line 106, in verify_generic
    verifier.validate()
  File "/usr/lib/python3.9/site-packages/pykwalify/core.py", line 194, in validate
    raise SchemaError(u"Schema validation failed:\n - {error_msg}.".format(
pykwalify.errors.SchemaError: <SchemaError: error code 2: Schema validation failed:
 - Enum 'in-progress' does not exist. Path: '/transitionStatus' Enum: ['completed'].: Path: '/'>

The above exception was the direct cause of the following exception:

Traceback (most recent call last):
  File "/usr/lib/python3.9/site-packages/tavern/response/base.py", line 152, in _maybe_run_validate_functions
    vf(response)
  File "/usr/lib/python3.9/site-packages/tavern/util/extfunctions.py", line 98, in inner
    result = func(response, *args, **kwargs)
  File "/usr/lib/python3.9/site-packages/tavern/testutils/helpers.py", line 103, in validate_pykwalify
    verify_generic(to_verify, schema)
  File "/usr/lib/python3.9/site-packages/tavern/schemas/files.py", line 109, in verify_generic
    raise BadSchemaError() from e
tavern.util.exceptions.BadSchemaError
[1m[31mERROR   [0m pykwalify.core:core.py:190 validation.invalid
[1m[31mERROR   [0m pykwalify.core:core.py:191  --- All found errors ---
[1m[31mERROR   [0m pykwalify.core:core.py:192 ["Enum 'in-progress' does not exist. Path: '/transitionStatus' Enum: ['completed']"]
[1m[31mERROR   [0m tavern.schemas.files:files.py:108 Error validating {'transitionID': '72974046-5a01-4604-a841-ae35918d5e3e', 'operation': 'On', 'createTime': '2024-03-20T08:23:18.625636003Z', 'automaticExpirationTime': '2024-03-21T08:23:18.625636073Z', 'transitionStatus': 'in-progress', 'taskCounts': {'total': 1, 'new': 0, 'in-progress': 1, 'failed': 0, 'succeeded': 0, 'un-supported': 0}, 'tasks': [{'xname': 'x3000c0s6b0n0', 'taskStatus': 'in-progress', 'taskStatusDescription': 'Confirming successful transition, on'}]}
Traceback (most recent call last):
  File "/usr/lib/python3.9/site-packages/tavern/schemas/files.py", line 106, in verify_generic
    verifier.validate()
  File "/usr/lib/python3.9/site-packages/pykwalify/core.py", line 194, in validate
    raise SchemaError(u"Schema validation failed:\n - {error_msg}.".format(
pykwalify.errors.SchemaError: <SchemaError: error code 2: Schema validation failed:
 - Enum 'in-progress' does not exist. Path: '/transitionStatus' Enum: ['completed'].: Path: '/'>
[1m[31mERROR   [0m tavern.response.base:base.py:41 Error calling validate function '<function validate_pykwalify at 0x7f39ae9164c0>':
    Traceback (most recent call last):
      File "/usr/lib/python3.9/site-packages/tavern/schemas/files.py", line 106, in verify_generic
        verifier.validate()
      File "/usr/lib/python3.9/site-packages/pykwalify/core.py", line 194, in validate
        raise SchemaError(u"Schema validation failed:\n - {error_msg}.".format(
    pykwalify.errors.SchemaError: <SchemaError: error code 2: Schema validation failed:
     - Enum 'in-progress' does not exist. Path: '/transitionStatus' Enum: ['completed'].: Path: '/'>

    The above exception was the direct cause of the following exception:

    Traceback (most recent call last):
      File "/usr/lib/python3.9/site-packages/tavern/response/base.py", line 152, in _maybe_run_validate_functions
        vf(response)
      File "/usr/lib/python3.9/site-packages/tavern/util/extfunctions.py", line 98, in inner
        result = func(response, *args, **kwargs)
      File "/usr/lib/python3.9/site-packages/tavern/testutils/helpers.py", line 103, in validate_pykwalify
        verify_generic(to_verify, schema)
      File "/usr/lib/python3.9/site-packages/tavern/schemas/files.py", line 109, in verify_generic
        raise BadSchemaError() from e
    tavern.util.exceptions.BadSchemaError
Traceback (most recent call last):
  File "/usr/lib/python3.9/site-packages/tavern/schemas/files.py", line 106, in verify_generic
    verifier.validate()
  File "/usr/lib/python3.9/site-packages/pykwalify/core.py", line 194, in validate
    raise SchemaError(u"Schema validation failed:\n - {error_msg}.".format(
pykwalify.errors.SchemaError: <SchemaError: error code 2: Schema validation failed:
 - Enum 'in-progress' does not exist. Path: '/transitionStatus' Enum: ['completed'].: Path: '/'>

The above exception was the direct cause of the following exception:

Traceback (most recent call last):
  File "/usr/lib/python3.9/site-packages/tavern/response/base.py", line 152, in _maybe_run_validate_functions
    vf(response)
  File "/usr/lib/python3.9/site-packages/tavern/util/extfunctions.py", line 98, in inner
    result = func(response, *args, **kwargs)
  File "/usr/lib/python3.9/site-packages/tavern/testutils/helpers.py", line 103, in validate_pykwalify
    verify_generic(to_verify, schema)
  File "/usr/lib/python3.9/site-packages/tavern/schemas/files.py", line 109, in verify_generic
    raise BadSchemaError() from e
tavern.util.exceptions.BadSchemaError
[1m[31mERROR   [0m pykwalify.core:core.py:190 validation.invalid
[1m[31mERROR   [0m pykwalify.core:core.py:191  --- All found errors ---
[1m[31mERROR   [0m pykwalify.core:core.py:192 ["Enum 'in-progress' does not exist. Path: '/transitionStatus' Enum: ['completed']"]
[1m[31mERROR   [0m tavern.schemas.files:files.py:108 Error validating {'transitionID': '72974046-5a01-4604-a841-ae35918d5e3e', 'operation': 'On', 'createTime': '2024-03-20T08:23:18.625636003Z', 'automaticExpirationTime': '2024-03-21T08:23:18.625636073Z', 'transitionStatus': 'in-progress', 'taskCounts': {'total': 1, 'new': 0, 'in-progress': 1, 'failed': 0, 'succeeded': 0, 'un-supported': 0}, 'tasks': [{'xname': 'x3000c0s6b0n0', 'taskStatus': 'in-progress', 'taskStatusDescription': 'Confirming successful transition, on'}]}
Traceback (most recent call last):
  File "/usr/lib/python3.9/site-packages/tavern/schemas/files.py", line 106, in verify_generic
    verifier.validate()
  File "/usr/lib/python3.9/site-packages/pykwalify/core.py", line 194, in validate
    raise SchemaError(u"Schema validation failed:\n - {error_msg}.".format(
pykwalify.errors.SchemaError: <SchemaError: error code 2: Schema validation failed:
 - Enum 'in-progress' does not exist. Path: '/transitionStatus' Enum: ['completed'].: Path: '/'>
[1m[31mERROR   [0m tavern.response.base:base.py:41 Error calling validate function '<function validate_pykwalify at 0x7f39ae9164c0>':
    Traceback (most recent call last):
      File "/usr/lib/python3.9/site-packages/tavern/schemas/files.py", line 106, in verify_generic
        verifier.validate()
      File "/usr/lib/python3.9/site-packages/pykwalify/core.py", line 194, in validate
        raise SchemaError(u"Schema validation failed:\n - {error_msg}.".format(
    pykwalify.errors.SchemaError: <SchemaError: error code 2: Schema validation failed:
     - Enum 'in-progress' does not exist. Path: '/transitionStatus' Enum: ['completed'].: Path: '/'>

    The above exception was the direct cause of the following exception:

    Traceback (most recent call last):
      File "/usr/lib/python3.9/site-packages/tavern/response/base.py", line 152, in _maybe_run_validate_functions
        vf(response)
      File "/usr/lib/python3.9/site-packages/tavern/util/extfunctions.py", line 98, in inner
        result = func(response, *args, **kwargs)
      File "/usr/lib/python3.9/site-packages/tavern/testutils/helpers.py", line 103, in validate_pykwalify
        verify_generic(to_verify, schema)
      File "/usr/lib/python3.9/site-packages/tavern/schemas/files.py", line 109, in verify_generic
        raise BadSchemaError() from e
    tavern.util.exceptions.BadSchemaError
Traceback (most recent call last):
  File "/usr/lib/python3.9/site-packages/tavern/schemas/files.py", line 106, in verify_generic
    verifier.validate()
  File "/usr/lib/python3.9/site-packages/pykwalify/core.py", line 194, in validate
    raise SchemaError(u"Schema validation failed:\n - {error_msg}.".format(
pykwalify.errors.SchemaError: <SchemaError: error code 2: Schema validation failed:
 - Enum 'in-progress' does not exist. Path: '/transitionStatus' Enum: ['completed'].: Path: '/'>

The above exception was the direct cause of the following exception:

Traceback (most recent call last):
  File "/usr/lib/python3.9/site-packages/tavern/response/base.py", line 152, in _maybe_run_validate_functions
    vf(response)
  File "/usr/lib/python3.9/site-packages/tavern/util/extfunctions.py", line 98, in inner
    result = func(response, *args, **kwargs)
  File "/usr/lib/python3.9/site-packages/tavern/testutils/helpers.py", line 103, in validate_pykwalify
    verify_generic(to_verify, schema)
  File "/usr/lib/python3.9/site-packages/tavern/schemas/files.py", line 109, in verify_generic
    raise BadSchemaError() from e
tavern.util.exceptions.BadSchemaError
[1m[31mERROR   [0m pykwalify.core:core.py:190 validation.invalid
[1m[31mERROR   [0m pykwalify.core:core.py:191  --- All found errors ---
[1m[31mERROR   [0m pykwalify.core:core.py:192 ["Enum 'in-progress' does not exist. Path: '/transitionStatus' Enum: ['completed']"]
[1m[31mERROR   [0m tavern.schemas.files:files.py:108 Error validating {'transitionID': '72974046-5a01-4604-a841-ae35918d5e3e', 'operation': 'On', 'createTime': '2024-03-20T08:23:18.625636003Z', 'automaticExpirationTime': '2024-03-21T08:23:18.625636073Z', 'transitionStatus': 'in-progress', 'taskCounts': {'total': 1, 'new': 0, 'in-progress': 1, 'failed': 0, 'succeeded': 0, 'un-supported': 0}, 'tasks': [{'xname': 'x3000c0s6b0n0', 'taskStatus': 'in-progress', 'taskStatusDescription': 'Confirming successful transition, on'}]}
Traceback (most recent call last):
  File "/usr/lib/python3.9/site-packages/tavern/schemas/files.py", line 106, in verify_generic
    verifier.validate()
  File "/usr/lib/python3.9/site-packages/pykwalify/core.py", line 194, in validate
    raise SchemaError(u"Schema validation failed:\n - {error_msg}.".format(
pykwalify.errors.SchemaError: <SchemaError: error code 2: Schema validation failed:
 - Enum 'in-progress' does not exist. Path: '/transitionStatus' Enum: ['completed'].: Path: '/'>
[1m[31mERROR   [0m tavern.response.base:base.py:41 Error calling validate function '<function validate_pykwalify at 0x7f39ae9164c0>':
    Traceback (most recent call last):
      File "/usr/lib/python3.9/site-packages/tavern/schemas/files.py", line 106, in verify_generic
        verifier.validate()
      File "/usr/lib/python3.9/site-packages/pykwalify/core.py", line 194, in validate
        raise SchemaError(u"Schema validation failed:\n - {error_msg}.".format(
    pykwalify.errors.SchemaError: <SchemaError: error code 2: Schema validation failed:
     - Enum 'in-progress' does not exist. Path: '/transitionStatus' Enum: ['completed'].: Path: '/'>

    The above exception was the direct cause of the following exception:

    Traceback (most recent call last):
      File "/usr/lib/python3.9/site-packages/tavern/response/base.py", line 152, in _maybe_run_validate_functions
        vf(response)
      File "/usr/lib/python3.9/site-packages/tavern/util/extfunctions.py", line 98, in inner
        result = func(response, *args, **kwargs)
      File "/usr/lib/python3.9/site-packages/tavern/testutils/helpers.py", line 103, in validate_pykwalify
        verify_generic(to_verify, schema)
      File "/usr/lib/python3.9/site-packages/tavern/schemas/files.py", line 109, in verify_generic
        raise BadSchemaError() from e
    tavern.util.exceptions.BadSchemaError
Traceback (most recent call last):
  File "/usr/lib/python3.9/site-packages/tavern/schemas/files.py", line 106, in verify_generic
    verifier.validate()
  File "/usr/lib/python3.9/site-packages/pykwalify/core.py", line 194, in validate
    raise SchemaError(u"Schema validation failed:\n - {error_msg}.".format(
pykwalify.errors.SchemaError: <SchemaError: error code 2: Schema validation failed:
 - Enum 'in-progress' does not exist. Path: '/transitionStatus' Enum: ['completed'].: Path: '/'>

The above exception was the direct cause of the following exception:

Traceback (most recent call last):
  File "/usr/lib/python3.9/site-packages/tavern/response/base.py", line 152, in _maybe_run_validate_functions
    vf(response)
  File "/usr/lib/python3.9/site-packages/tavern/util/extfunctions.py", line 98, in inner
    result = func(response, *args, **kwargs)
  File "/usr/lib/python3.9/site-packages/tavern/testutils/helpers.py", line 103, in validate_pykwalify
    verify_generic(to_verify, schema)
  File "/usr/lib/python3.9/site-packages/tavern/schemas/files.py", line 109, in verify_generic
    raise BadSchemaError() from e
tavern.util.exceptions.BadSchemaError
[1m[31mERROR   [0m pykwalify.core:core.py:190 validation.invalid
[1m[31mERROR   [0m pykwalify.core:core.py:191  --- All found errors ---
[1m[31mERROR   [0m pykwalify.core:core.py:192 ["Enum 'in-progress' does not exist. Path: '/transitionStatus' Enum: ['completed']"]
[1m[31mERROR   [0m tavern.schemas.files:files.py:108 Error validating {'transitionID': '72974046-5a01-4604-a841-ae35918d5e3e', 'operation': 'On', 'createTime': '2024-03-20T08:23:18.625636003Z', 'automaticExpirationTime': '2024-03-21T08:23:18.625636073Z', 'transitionStatus': 'in-progress', 'taskCounts': {'total': 1, 'new': 0, 'in-progress': 1, 'failed': 0, 'succeeded': 0, 'un-supported': 0}, 'tasks': [{'xname': 'x3000c0s6b0n0', 'taskStatus': 'in-progress', 'taskStatusDescription': 'Confirming successful transition, on'}]}
Traceback (most recent call last):
  File "/usr/lib/python3.9/site-packages/tavern/schemas/files.py", line 106, in verify_generic
    verifier.validate()
  File "/usr/lib/python3.9/site-packages/pykwalify/core.py", line 194, in validate
    raise SchemaError(u"Schema validation failed:\n - {error_msg}.".format(
pykwalify.errors.SchemaError: <SchemaError: error code 2: Schema validation failed:
 - Enum 'in-progress' does not exist. Path: '/transitionStatus' Enum: ['completed'].: Path: '/'>
[1m[31mERROR   [0m tavern.response.base:base.py:41 Error calling validate function '<function validate_pykwalify at 0x7f39ae9164c0>':
    Traceback (most recent call last):
      File "/usr/lib/python3.9/site-packages/tavern/schemas/files.py", line 106, in verify_generic
        verifier.validate()
      File "/usr/lib/python3.9/site-packages/pykwalify/core.py", line 194, in validate
        raise SchemaError(u"Schema validation failed:\n - {error_msg}.".format(
    pykwalify.errors.SchemaError: <SchemaError: error code 2: Schema validation failed:
     - Enum 'in-progress' does not exist. Path: '/transitionStatus' Enum: ['completed'].: Path: '/'>

    The above exception was the direct cause of the following exception:

    Traceback (most recent call last):
      File "/usr/lib/python3.9/site-packages/tavern/response/base.py", line 152, in _maybe_run_validate_functions
        vf(response)
      File "/usr/lib/python3.9/site-packages/tavern/util/extfunctions.py", line 98, in inner
        result = func(response, *args, **kwargs)
      File "/usr/lib/python3.9/site-packages/tavern/testutils/helpers.py", line 103, in validate_pykwalify
        verify_generic(to_verify, schema)
      File "/usr/lib/python3.9/site-packages/tavern/schemas/files.py", line 109, in verify_generic
        raise BadSchemaError() from e
    tavern.util.exceptions.BadSchemaError
Traceback (most recent call last):
  File "/usr/lib/python3.9/site-packages/tavern/schemas/files.py", line 106, in verify_generic
    verifier.validate()
  File "/usr/lib/python3.9/site-packages/pykwalify/core.py", line 194, in validate
    raise SchemaError(u"Schema validation failed:\n - {error_msg}.".format(
pykwalify.errors.SchemaError: <SchemaError: error code 2: Schema validation failed:
 - Enum 'in-progress' does not exist. Path: '/transitionStatus' Enum: ['completed'].: Path: '/'>

The above exception was the direct cause of the following exception:

Traceback (most recent call last):
  File "/usr/lib/python3.9/site-packages/tavern/response/base.py", line 152, in _maybe_run_validate_functions
    vf(response)
  File "/usr/lib/python3.9/site-packages/tavern/util/extfunctions.py", line 98, in inner
    result = func(response, *args, **kwargs)
  File "/usr/lib/python3.9/site-packages/tavern/testutils/helpers.py", line 103, in validate_pykwalify
    verify_generic(to_verify, schema)
  File "/usr/lib/python3.9/site-packages/tavern/schemas/files.py", line 109, in verify_generic
    raise BadSchemaError() from e
tavern.util.exceptions.BadSchemaError
[1m[31mERROR   [0m pykwalify.core:core.py:190 validation.invalid
[1m[31mERROR   [0m pykwalify.core:core.py:191  --- All found errors ---
[1m[31mERROR   [0m pykwalify.core:core.py:192 ["Enum 'in-progress' does not exist. Path: '/transitionStatus' Enum: ['completed']"]
[1m[31mERROR   [0m tavern.schemas.files:files.py:108 Error validating {'transitionID': '72974046-5a01-4604-a841-ae35918d5e3e', 'operation': 'On', 'createTime': '2024-03-20T08:23:18.625636003Z', 'automaticExpirationTime': '2024-03-21T08:23:18.625636073Z', 'transitionStatus': 'in-progress', 'taskCounts': {'total': 1, 'new': 0, 'in-progress': 1, 'failed': 0, 'succeeded': 0, 'un-supported': 0}, 'tasks': [{'xname': 'x3000c0s6b0n0', 'taskStatus': 'in-progress', 'taskStatusDescription': 'Confirming successful transition, on'}]}
Traceback (most recent call last):
  File "/usr/lib/python3.9/site-packages/tavern/schemas/files.py", line 106, in verify_generic
    verifier.validate()
  File "/usr/lib/python3.9/site-packages/pykwalify/core.py", line 194, in validate
    raise SchemaError(u"Schema validation failed:\n - {error_msg}.".format(
pykwalify.errors.SchemaError: <SchemaError: error code 2: Schema validation failed:
 - Enum 'in-progress' does not exist. Path: '/transitionStatus' Enum: ['completed'].: Path: '/'>
[1m[31mERROR   [0m tavern.response.base:base.py:41 Error calling validate function '<function validate_pykwalify at 0x7f39ae9164c0>':
    Traceback (most recent call last):
      File "/usr/lib/python3.9/site-packages/tavern/schemas/files.py", line 106, in verify_generic
        verifier.validate()
      File "/usr/lib/python3.9/site-packages/pykwalify/core.py", line 194, in validate
        raise SchemaError(u"Schema validation failed:\n - {error_msg}.".format(
    pykwalify.errors.SchemaError: <SchemaError: error code 2: Schema validation failed:
     - Enum 'in-progress' does not exist. Path: '/transitionStatus' Enum: ['completed'].: Path: '/'>

    The above exception was the direct cause of the following exception:

    Traceback (most recent call last):
      File "/usr/lib/python3.9/site-packages/tavern/response/base.py", line 152, in _maybe_run_validate_functions
        vf(response)
      File "/usr/lib/python3.9/site-packages/tavern/util/extfunctions.py", line 98, in inner
        result = func(response, *args, **kwargs)
      File "/usr/lib/python3.9/site-packages/tavern/testutils/helpers.py", line 103, in validate_pykwalify
        verify_generic(to_verify, schema)
      File "/usr/lib/python3.9/site-packages/tavern/schemas/files.py", line 109, in verify_generic
        raise BadSchemaError() from e
    tavern.util.exceptions.BadSchemaError
Traceback (most recent call last):
  File "/usr/lib/python3.9/site-packages/tavern/schemas/files.py", line 106, in verify_generic
    verifier.validate()
  File "/usr/lib/python3.9/site-packages/pykwalify/core.py", line 194, in validate
    raise SchemaError(u"Schema validation failed:\n - {error_msg}.".format(
pykwalify.errors.SchemaError: <SchemaError: error code 2: Schema validation failed:
 - Enum 'in-progress' does not exist. Path: '/transitionStatus' Enum: ['completed'].: Path: '/'>

The above exception was the direct cause of the following exception:

Traceback (most recent call last):
  File "/usr/lib/python3.9/site-packages/tavern/response/base.py", line 152, in _maybe_run_validate_functions
    vf(response)
  File "/usr/lib/python3.9/site-packages/tavern/util/extfunctions.py", line 98, in inner
    result = func(response, *args, **kwargs)
  File "/usr/lib/python3.9/site-packages/tavern/testutils/helpers.py", line 103, in validate_pykwalify
    verify_generic(to_verify, schema)
  File "/usr/lib/python3.9/site-packages/tavern/schemas/files.py", line 109, in verify_generic
    raise BadSchemaError() from e
tavern.util.exceptions.BadSchemaError
[1m[31mERROR   [0m pykwalify.core:core.py:190 validation.invalid
[1m[31mERROR   [0m pykwalify.core:core.py:191  --- All found errors ---
[1m[31mERROR   [0m pykwalify.core:core.py:192 ["Enum 'in-progress' does not exist. Path: '/transitionStatus' Enum: ['completed']"]
[1m[31mERROR   [0m tavern.schemas.files:files.py:108 Error validating {'transitionID': '72974046-5a01-4604-a841-ae35918d5e3e', 'operation': 'On', 'createTime': '2024-03-20T08:23:18.625636003Z', 'automaticExpirationTime': '2024-03-21T08:23:18.625636073Z', 'transitionStatus': 'in-progress', 'taskCounts': {'total': 1, 'new': 0, 'in-progress': 1, 'failed': 0, 'succeeded': 0, 'un-supported': 0}, 'tasks': [{'xname': 'x3000c0s6b0n0', 'taskStatus': 'in-progress', 'taskStatusDescription': 'Confirming successful transition, on'}]}
Traceback (most recent call last):
  File "/usr/lib/python3.9/site-packages/tavern/schemas/files.py", line 106, in verify_generic
    verifier.validate()
  File "/usr/lib/python3.9/site-packages/pykwalify/core.py", line 194, in validate
    raise SchemaError(u"Schema validation failed:\n - {error_msg}.".format(
pykwalify.errors.SchemaError: <SchemaError: error code 2: Schema validation failed:
 - Enum 'in-progress' does not exist. Path: '/transitionStatus' Enum: ['completed'].: Path: '/'>
[1m[31mERROR   [0m tavern.response.base:base.py:41 Error calling validate function '<function validate_pykwalify at 0x7f39ae9164c0>':
    Traceback (most recent call last):
      File "/usr/lib/python3.9/site-packages/tavern/schemas/files.py", line 106, in verify_generic
        verifier.validate()
      File "/usr/lib/python3.9/site-packages/pykwalify/core.py", line 194, in validate
        raise SchemaError(u"Schema validation failed:\n - {error_msg}.".format(
    pykwalify.errors.SchemaError: <SchemaError: error code 2: Schema validation failed:
     - Enum 'in-progress' does not exist. Path: '/transitionStatus' Enum: ['completed'].: Path: '/'>

    The above exception was the direct cause of the following exception:

    Traceback (most recent call last):
      File "/usr/lib/python3.9/site-packages/tavern/response/base.py", line 152, in _maybe_run_validate_functions
        vf(response)
      File "/usr/lib/python3.9/site-packages/tavern/util/extfunctions.py", line 98, in inner
        result = func(response, *args, **kwargs)
      File "/usr/lib/python3.9/site-packages/tavern/testutils/helpers.py", line 103, in validate_pykwalify
        verify_generic(to_verify, schema)
      File "/usr/lib/python3.9/site-packages/tavern/schemas/files.py", line 109, in verify_generic
        raise BadSchemaError() from e
    tavern.util.exceptions.BadSchemaError
Traceback (most recent call last):
  File "/usr/lib/python3.9/site-packages/tavern/schemas/files.py", line 106, in verify_generic
    verifier.validate()
  File "/usr/lib/python3.9/site-packages/pykwalify/core.py", line 194, in validate
    raise SchemaError(u"Schema validation failed:\n - {error_msg}.".format(
pykwalify.errors.SchemaError: <SchemaError: error code 2: Schema validation failed:
 - Enum 'in-progress' does not exist. Path: '/transitionStatus' Enum: ['completed'].: Path: '/'>

The above exception was the direct cause of the following exception:

Traceback (most recent call last):
  File "/usr/lib/python3.9/site-packages/tavern/response/base.py", line 152, in _maybe_run_validate_functions
    vf(response)
  File "/usr/lib/python3.9/site-packages/tavern/util/extfunctions.py", line 98, in inner
    result = func(response, *args, **kwargs)
  File "/usr/lib/python3.9/site-packages/tavern/testutils/helpers.py", line 103, in validate_pykwalify
    verify_generic(to_verify, schema)
  File "/usr/lib/python3.9/site-packages/tavern/schemas/files.py", line 109, in verify_generic
    raise BadSchemaError() from e
tavern.util.exceptions.BadSchemaError
[1m[31mERROR   [0m pykwalify.core:core.py:190 validation.invalid
[1m[31mERROR   [0m pykwalify.core:core.py:191  --- All found errors ---
[1m[31mERROR   [0m pykwalify.core:core.py:192 ["Enum 'in-progress' does not exist. Path: '/transitionStatus' Enum: ['completed']"]
[1m[31mERROR   [0m tavern.schemas.files:files.py:108 Error validating {'transitionID': '72974046-5a01-4604-a841-ae35918d5e3e', 'operation': 'On', 'createTime': '2024-03-20T08:23:18.625636003Z', 'automaticExpirationTime': '2024-03-21T08:23:18.625636073Z', 'transitionStatus': 'in-progress', 'taskCounts': {'total': 1, 'new': 0, 'in-progress': 1, 'failed': 0, 'succeeded': 0, 'un-supported': 0}, 'tasks': [{'xname': 'x3000c0s6b0n0', 'taskStatus': 'in-progress', 'taskStatusDescription': 'Confirming successful transition, on'}]}
Traceback (most recent call last):
  File "/usr/lib/python3.9/site-packages/tavern/schemas/files.py", line 106, in verify_generic
    verifier.validate()
  File "/usr/lib/python3.9/site-packages/pykwalify/core.py", line 194, in validate
    raise SchemaError(u"Schema validation failed:\n - {error_msg}.".format(
pykwalify.errors.SchemaError: <SchemaError: error code 2: Schema validation failed:
 - Enum 'in-progress' does not exist. Path: '/transitionStatus' Enum: ['completed'].: Path: '/'>
[1m[31mERROR   [0m tavern.response.base:base.py:41 Error calling validate function '<function validate_pykwalify at 0x7f39ae9164c0>':
    Traceback (most recent call last):
      File "/usr/lib/python3.9/site-packages/tavern/schemas/files.py", line 106, in verify_generic
        verifier.validate()
      File "/usr/lib/python3.9/site-packages/pykwalify/core.py", line 194, in validate
        raise SchemaError(u"Schema validation failed:\n - {error_msg}.".format(
    pykwalify.errors.SchemaError: <SchemaError: error code 2: Schema validation failed:
     - Enum 'in-progress' does not exist. Path: '/transitionStatus' Enum: ['completed'].: Path: '/'>

    The above exception was the direct cause of the following exception:

    Traceback (most recent call last):
      File "/usr/lib/python3.9/site-packages/tavern/response/base.py", line 152, in _maybe_run_validate_functions
        vf(response)
      File "/usr/lib/python3.9/site-packages/tavern/util/extfunctions.py", line 98, in inner
        result = func(response, *args, **kwargs)
      File "/usr/lib/python3.9/site-packages/tavern/testutils/helpers.py", line 103, in validate_pykwalify
        verify_generic(to_verify, schema)
      File "/usr/lib/python3.9/site-packages/tavern/schemas/files.py", line 109, in verify_generic
        raise BadSchemaError() from e
    tavern.util.exceptions.BadSchemaError
Traceback (most recent call last):
  File "/usr/lib/python3.9/site-packages/tavern/schemas/files.py", line 106, in verify_generic
    verifier.validate()
  File "/usr/lib/python3.9/site-packages/pykwalify/core.py", line 194, in validate
    raise SchemaError(u"Schema validation failed:\n - {error_msg}.".format(
pykwalify.errors.SchemaError: <SchemaError: error code 2: Schema validation failed:
 - Enum 'in-progress' does not exist. Path: '/transitionStatus' Enum: ['completed'].: Path: '/'>

The above exception was the direct cause of the following exception:

Traceback (most recent call last):
  File "/usr/lib/python3.9/site-packages/tavern/response/base.py", line 152, in _maybe_run_validate_functions
    vf(response)
  File "/usr/lib/python3.9/site-packages/tavern/util/extfunctions.py", line 98, in inner
    result = func(response, *args, **kwargs)
  File "/usr/lib/python3.9/site-packages/tavern/testutils/helpers.py", line 103, in validate_pykwalify
    verify_generic(to_verify, schema)
  File "/usr/lib/python3.9/site-packages/tavern/schemas/files.py", line 109, in verify_generic
    raise BadSchemaError() from e
tavern.util.exceptions.BadSchemaError
[1m[31mERROR   [0m pykwalify.core:core.py:190 validation.invalid
[1m[31mERROR   [0m pykwalify.core:core.py:191  --- All found errors ---
[1m[31mERROR   [0m pykwalify.core:core.py:192 ["Enum 'in-progress' does not exist. Path: '/transitionStatus' Enum: ['completed']"]
[1m[31mERROR   [0m tavern.schemas.files:files.py:108 Error validating {'transitionID': '72974046-5a01-4604-a841-ae35918d5e3e', 'operation': 'On', 'createTime': '2024-03-20T08:23:18.625636003Z', 'automaticExpirationTime': '2024-03-21T08:23:18.625636073Z', 'transitionStatus': 'in-progress', 'taskCounts': {'total': 1, 'new': 0, 'in-progress': 1, 'failed': 0, 'succeeded': 0, 'un-supported': 0}, 'tasks': [{'xname': 'x3000c0s6b0n0', 'taskStatus': 'in-progress', 'taskStatusDescription': 'Confirming successful transition, on'}]}
Traceback (most recent call last):
  File "/usr/lib/python3.9/site-packages/tavern/schemas/files.py", line 106, in verify_generic
    verifier.validate()
  File "/usr/lib/python3.9/site-packages/pykwalify/core.py", line 194, in validate
    raise SchemaError(u"Schema validation failed:\n - {error_msg}.".format(
pykwalify.errors.SchemaError: <SchemaError: error code 2: Schema validation failed:
 - Enum 'in-progress' does not exist. Path: '/transitionStatus' Enum: ['completed'].: Path: '/'>
[1m[31mERROR   [0m tavern.response.base:base.py:41 Error calling validate function '<function validate_pykwalify at 0x7f39ae9164c0>':
    Traceback (most recent call last):
      File "/usr/lib/python3.9/site-packages/tavern/schemas/files.py", line 106, in verify_generic
        verifier.validate()
      File "/usr/lib/python3.9/site-packages/pykwalify/core.py", line 194, in validate
        raise SchemaError(u"Schema validation failed:\n - {error_msg}.".format(
    pykwalify.errors.SchemaError: <SchemaError: error code 2: Schema validation failed:
     - Enum 'in-progress' does not exist. Path: '/transitionStatus' Enum: ['completed'].: Path: '/'>

    The above exception was the direct cause of the following exception:

    Traceback (most recent call last):
      File "/usr/lib/python3.9/site-packages/tavern/response/base.py", line 152, in _maybe_run_validate_functions
        vf(response)
      File "/usr/lib/python3.9/site-packages/tavern/util/extfunctions.py", line 98, in inner
        result = func(response, *args, **kwargs)
      File "/usr/lib/python3.9/site-packages/tavern/testutils/helpers.py", line 103, in validate_pykwalify
        verify_generic(to_verify, schema)
      File "/usr/lib/python3.9/site-packages/tavern/schemas/files.py", line 109, in verify_generic
        raise BadSchemaError() from e
    tavern.util.exceptions.BadSchemaError
Traceback (most recent call last):
  File "/usr/lib/python3.9/site-packages/tavern/schemas/files.py", line 106, in verify_generic
    verifier.validate()
  File "/usr/lib/python3.9/site-packages/pykwalify/core.py", line 194, in validate
    raise SchemaError(u"Schema validation failed:\n - {error_msg}.".format(
pykwalify.errors.SchemaError: <SchemaError: error code 2: Schema validation failed:
 - Enum 'in-progress' does not exist. Path: '/transitionStatus' Enum: ['completed'].: Path: '/'>

The above exception was the direct cause of the following exception:

Traceback (most recent call last):
  File "/usr/lib/python3.9/site-packages/tavern/response/base.py", line 152, in _maybe_run_validate_functions
    vf(response)
  File "/usr/lib/python3.9/site-packages/tavern/util/extfunctions.py", line 98, in inner
    result = func(response, *args, **kwargs)
  File "/usr/lib/python3.9/site-packages/tavern/testutils/helpers.py", line 103, in validate_pykwalify
    verify_generic(to_verify, schema)
  File "/usr/lib/python3.9/site-packages/tavern/schemas/files.py", line 109, in verify_generic
    raise BadSchemaError() from e
tavern.util.exceptions.BadSchemaError
[1m[31mERROR   [0m pykwalify.core:core.py:190 validation.invalid
[1m[31mERROR   [0m pykwalify.core:core.py:191  --- All found errors ---
[1m[31mERROR   [0m pykwalify.core:core.py:192 ["Enum 'in-progress' does not exist. Path: '/transitionStatus' Enum: ['completed']"]
[1m[31mERROR   [0m tavern.schemas.files:files.py:108 Error validating {'transitionID': '72974046-5a01-4604-a841-ae35918d5e3e', 'operation': 'On', 'createTime': '2024-03-20T08:23:18.625636003Z', 'automaticExpirationTime': '2024-03-21T08:23:18.625636073Z', 'transitionStatus': 'in-progress', 'taskCounts': {'total': 1, 'new': 0, 'in-progress': 1, 'failed': 0, 'succeeded': 0, 'un-supported': 0}, 'tasks': [{'xname': 'x3000c0s6b0n0', 'taskStatus': 'in-progress', 'taskStatusDescription': 'Confirming successful transition, on'}]}
Traceback (most recent call last):
  File "/usr/lib/python3.9/site-packages/tavern/schemas/files.py", line 106, in verify_generic
    verifier.validate()
  File "/usr/lib/python3.9/site-packages/pykwalify/core.py", line 194, in validate
    raise SchemaError(u"Schema validation failed:\n - {error_msg}.".format(
pykwalify.errors.SchemaError: <SchemaError: error code 2: Schema validation failed:
 - Enum 'in-progress' does not exist. Path: '/transitionStatus' Enum: ['completed'].: Path: '/'>
[1m[31mERROR   [0m tavern.response.base:base.py:41 Error calling validate function '<function validate_pykwalify at 0x7f39ae9164c0>':
    Traceback (most recent call last):
      File "/usr/lib/python3.9/site-packages/tavern/schemas/files.py", line 106, in verify_generic
        verifier.validate()
      File "/usr/lib/python3.9/site-packages/pykwalify/core.py", line 194, in validate
        raise SchemaError(u"Schema validation failed:\n - {error_msg}.".format(
    pykwalify.errors.SchemaError: <SchemaError: error code 2: Schema validation failed:
     - Enum 'in-progress' does not exist. Path: '/transitionStatus' Enum: ['completed'].: Path: '/'>

    The above exception was the direct cause of the following exception:

    Traceback (most recent call last):
      File "/usr/lib/python3.9/site-packages/tavern/response/base.py", line 152, in _maybe_run_validate_functions
        vf(response)
      File "/usr/lib/python3.9/site-packages/tavern/util/extfunctions.py", line 98, in inner
        result = func(response, *args, **kwargs)
      File "/usr/lib/python3.9/site-packages/tavern/testutils/helpers.py", line 103, in validate_pykwalify
        verify_generic(to_verify, schema)
      File "/usr/lib/python3.9/site-packages/tavern/schemas/files.py", line 109, in verify_generic
        raise BadSchemaError() from e
    tavern.util.exceptions.BadSchemaError
Traceback (most recent call last):
  File "/usr/lib/python3.9/site-packages/tavern/schemas/files.py", line 106, in verify_generic
    verifier.validate()
  File "/usr/lib/python3.9/site-packages/pykwalify/core.py", line 194, in validate
    raise SchemaError(u"Schema validation failed:\n - {error_msg}.".format(
pykwalify.errors.SchemaError: <SchemaError: error code 2: Schema validation failed:
 - Enum 'in-progress' does not exist. Path: '/transitionStatus' Enum: ['completed'].: Path: '/'>

The above exception was the direct cause of the following exception:

Traceback (most recent call last):
  File "/usr/lib/python3.9/site-packages/tavern/response/base.py", line 152, in _maybe_run_validate_functions
    vf(response)
  File "/usr/lib/python3.9/site-packages/tavern/util/extfunctions.py", line 98, in inner
    result = func(response, *args, **kwargs)
  File "/usr/lib/python3.9/site-packages/tavern/testutils/helpers.py", line 103, in validate_pykwalify
    verify_generic(to_verify, schema)
  File "/usr/lib/python3.9/site-packages/tavern/schemas/files.py", line 109, in verify_generic
    raise BadSchemaError() from e
tavern.util.exceptions.BadSchemaError