{"uid":"4b4757e66a1912dae1a509f688f20b0f","children":[{"name":"Product defects","children":[{"name":"tavern.util.exceptions.TestFailError: Test 'hsmAPIinventoryHardwareGET - Retrieve multiple Hardware Inventory entries using GET.' failed:\n- Error calling validate function '<function validate_pykwalify at 0x7f797b309e50>':\n    Traceback (most recent call last):\n      File \"/usr/lib/python3.9/site-packages/tavern/schemas/files.py\", line 106, in verify_generic\n        verifier.validate()\n      File \"/usr/lib/python3.9/site-packages/pykwalify/core.py\", line 194, in validate\n        raise SchemaError(u\"Schema validation failed:\\n - {error_msg}.\".format(\n    pykwalify.errors.SchemaError: <SchemaError: error code 2: Schema validation failed:\n     - Cannot find required key 'PopulatedFRU'. Path: '/6'.\n     - Cannot find required key 'PopulatedFRU'. Path: '/7'.\n     - Cannot find required key 'PopulatedFRU'. Path: '/8'.\n     - Cannot find required key 'PopulatedFRU'. Path: '/9'.\n     - Cannot find required key 'PopulatedFRU'. Path: '/11'.\n     - Cannot find required key 'PopulatedFRU'. Path: '/13'.\n     - Cannot find required key 'PopulatedFRU'. Path: '/14'.\n     - Cannot find required key 'PopulatedFRU'. Path: '/15'.\n     - Cannot find required key 'PopulatedFRU'. Path: '/16'.\n     - Cannot find required key 'PopulatedFRU'. Path: '/18'.\n     - Cannot find required key 'PopulatedFRU'. Path: '/19'.\n     - Cannot find required key 'PopulatedFRU'. Path: '/20'.\n     - Cannot find required key 'PopulatedFRU'. Path: '/25'.\n     - Cannot find required key 'PopulatedFRU'. Path: '/26'.\n     - Cannot find required key 'PopulatedFRU'. Path: '/42'.\n     - Cannot find required key 'PopulatedFRU'. Path: '/44'.\n     - Cannot find required key 'PopulatedFRU'. Path: '/46'.\n     - Cannot find required key 'PopulatedFRU'. Path: '/48'.\n     - Cannot find required key 'PopulatedFRU'. Path: '/50'.\n     - Cannot find required key 'PopulatedFRU'. Path: '/55'.\n     - Cannot find required key 'PopulatedFRU'. Path: '/56'.\n     - Cannot find required key 'PopulatedFRU'. Path: '/57'.\n     - Cannot find required key 'PopulatedFRU'. Path: '/58'.\n     - Cannot find required key 'PopulatedFRU'. Path: '/59'.\n     - Cannot find required key 'PopulatedFRU'. Path: '/61'.\n     - Cannot find required key 'PopulatedFRU'. Path: '/62'.\n     - Cannot find required key 'PopulatedFRU'. Path: '/68'.\n     - Cannot find required key 'PopulatedFRU'. Path: '/69'.\n     - Cannot find required key 'PopulatedFRU'. Path: '/71'.\n     - Cannot find required key 'PopulatedFRU'. Path: '/73'.\n     - Cannot find required key 'PopulatedFRU'. Path: '/107'.\n     - Cannot find required key 'PopulatedFRU'. Path: '/111'.\n     - Cannot find required key 'PopulatedFRU'. Path: '/113'.\n     - Cannot find required key 'PopulatedFRU'. Path: '/114'.: Path: '/'>\n\n    The above exception was the direct cause of the following exception:\n\n    Traceback (most recent call last):\n      File \"/usr/lib/python3.9/site-packages/tavern/response/base.py\", line 152, in _maybe_run_validate_functions\n        vf(response)\n      File \"/usr/lib/python3.9/site-packages/tavern/util/extfunctions.py\", line 98, in inner\n        result = func(response, *args, **kwargs)\n      File \"/usr/lib/python3.9/site-packages/tavern/testutils/helpers.py\", line 103, in validate_pykwalify\n        verify_generic(to_verify, schema)\n      File \"/usr/lib/python3.9/site-packages/tavern/schemas/files.py\", line 109, in verify_generic\n        raise BadSchemaError() from e\n    tavern.util.exceptions.BadSchemaError","children":[{"name":"hsmAPIinventoryHardwareDisruptive","uid":"58047db1d99bc6d4","parentUid":"57803a146c8506a64001f05ce27ac667","status":"failed","time":{"start":1711268292428,"stop":1711268294692,"duration":2264},"flaky":false,"newFailed":false,"newPassed":false,"newBroken":false,"retriesCount":0,"retriesStatusChange":false,"parameters":[],"tags":[]}],"uid":"57803a146c8506a64001f05ce27ac667"},{"name":"tavern.util.exceptions.TestFailError: Test 'hsmAPIinventoryHardwareQueryXnameGETnonExistentNode - Attempt to query for Node Hardware Inventory entries with an xname that doesn't exist using GET.' failed:\n- Error calling validate function '<function validate_pykwalify at 0x7f797b309e50>':\n    Traceback (most recent call last):\n      File \"/usr/lib/python3.9/site-packages/tavern/schemas/files.py\", line 106, in verify_generic\n        verifier.validate()\n      File \"/usr/lib/python3.9/site-packages/pykwalify/core.py\", line 194, in validate\n        raise SchemaError(u\"Schema validation failed:\\n - {error_msg}.\".format(\n    pykwalify.errors.SchemaError: <SchemaError: error code 2: Schema validation failed:\n     - Key 'Nodes' was not defined. Path: ''.: Path: '/'>\n\n    The above exception was the direct cause of the following exception:\n\n    Traceback (most recent call last):\n      File \"/usr/lib/python3.9/site-packages/tavern/response/base.py\", line 152, in _maybe_run_validate_functions\n        vf(response)\n      File \"/usr/lib/python3.9/site-packages/tavern/util/extfunctions.py\", line 98, in inner\n        result = func(response, *args, **kwargs)\n      File \"/usr/lib/python3.9/site-packages/tavern/testutils/helpers.py\", line 103, in validate_pykwalify\n        verify_generic(to_verify, schema)\n      File \"/usr/lib/python3.9/site-packages/tavern/schemas/files.py\", line 109, in verify_generic\n        raise BadSchemaError() from e\n    tavern.util.exceptions.BadSchemaError","children":[{"name":"hsmAPIinventoryHardwareNegative","uid":"208ea4c429c7f78","parentUid":"706babf5ac63385ca5c4ce80f8b0006a","status":"failed","time":{"start":1711268294758,"stop":1711268294853,"duration":95},"flaky":false,"newFailed":false,"newPassed":false,"newBroken":false,"retriesCount":0,"retriesStatusChange":false,"parameters":[],"tags":[]}],"uid":"706babf5ac63385ca5c4ce80f8b0006a"},{"name":"tavern.util.exceptions.TestFailError: Test 'Query bootscript by xname' failed:\n- Error calling validate function '<function better_validate_regex at 0x7f72848a6310>':\n    Traceback (most recent call last):\n      File \"/usr/lib/python3.9/site-packages/tavern/response/base.py\", line 152, in _maybe_run_validate_functions\n        vf(response)\n      File \"/usr/lib/python3.9/site-packages/tavern/util/extfunctions.py\", line 98, in inner\n        result = func(response, *args, **kwargs)\n      File \"/src/libs/bss_test_utils.py\", line 65, in better_validate_regex\n        raise exceptions.RegexAccessError(f\"No match for regex '{expression}' in response:\\n{response.text}\")\n    tavern.util.exceptions.RegexAccessError: No match for regex 'kernel http[s]?:\\/\\/.+/boot-images/00000000-0000-0000-0000-000000000000\\/kernel' in response:\n    #!ipxe\n    sleep 10\n    chain https://api-gw-service-nmn.local/apis/bss/boot/v1/bootscript?mac=00:40:a6:17:1d:3d&retry=1\n\n\n\n- Error calling validate function '<function better_validate_regex at 0x7f72848a6310>':\n    Traceback (most recent call last):\n      File \"/usr/lib/python3.9/site-packages/tavern/response/base.py\", line 152, in _maybe_run_validate_functions\n        vf(response)\n      File \"/usr/lib/python3.9/site-packages/tavern/util/extfunctions.py\", line 98, in inner\n        result = func(response, *args, **kwargs)\n      File \"/src/libs/bss_test_utils.py\", line 65, in better_validate_regex\n        raise exceptions.RegexAccessError(f\"No match for regex '{expression}' in response:\\n{response.text}\")\n    tavern.util.exceptions.RegexAccessError: No match for regex 'initrd http[s]?:\\/\\/.+/boot-images/00000000-0000-0000-0000-000000000000\\/initrd' in response:\n    #!ipxe\n    sleep 10\n    chain https://api-gw-service-nmn.local/apis/bss/boot/v1/bootscript?mac=00:40:a6:17:1d:3d&retry=1\n\n\n\n- Error calling validate function '<function better_validate_regex at 0x7f72848a6310>':\n    Traceback (most recent call last):\n      File \"/usr/lib/python3.9/site-packages/tavern/response/base.py\", line 152, in _maybe_run_validate_functions\n        vf(response)\n      File \"/usr/lib/python3.9/site-packages/tavern/util/extfunctions.py\", line 98, in inner\n        result = func(response, *args, **kwargs)\n      File \"/src/libs/bss_test_utils.py\", line 65, in better_validate_regex\n        raise exceptions.RegexAccessError(f\"No match for regex '{expression}' in response:\\n{response.text}\")\n    tavern.util.exceptions.RegexAccessError: No match for regex 'kernel --name .+console.tty0' in response:\n    #!ipxe\n    sleep 10\n    chain https://api-gw-service-nmn.local/apis/bss/boot/v1/bootscript?mac=00:40:a6:17:1d:3d&retry=1\n\n\n\n- Error calling validate function '<function better_validate_regex at 0x7f72848a6310>':\n    Traceback (most recent call last):\n      File \"/usr/lib/python3.9/site-packages/tavern/response/base.py\", line 152, in _maybe_run_validate_functions\n        vf(response)\n      File \"/usr/lib/python3.9/site-packages/tavern/util/extfunctions.py\", line 98, in inner\n        result = func(response, *args, **kwargs)\n      File \"/src/libs/bss_test_utils.py\", line 65, in better_validate_regex\n        raise exceptions.RegexAccessError(f\"No match for regex '{expression}' in response:\\n{response.text}\")\n    tavern.util.exceptions.RegexAccessError: No match for regex 'kernel --name .+xname=x1000c0s7b1n0' in response:\n    #!ipxe\n    sleep 10\n    chain https://api-gw-service-nmn.local/apis/bss/boot/v1/bootscript?mac=00:40:a6:17:1d:3d&retry=1\n\n\n\n- Error calling validate function '<function better_validate_regex at 0x7f72848a6310>':\n    Traceback (most recent call last):\n      File \"/usr/lib/python3.9/site-packages/tavern/response/base.py\", line 152, in _maybe_run_validate_functions\n        vf(response)\n      File \"/usr/lib/python3.9/site-packages/tavern/util/extfunctions.py\", line 98, in inner\n        result = func(response, *args, **kwargs)\n      File \"/src/libs/bss_test_utils.py\", line 65, in better_validate_regex\n        raise exceptions.RegexAccessError(f\"No match for regex '{expression}' in response:\\n{response.text}\")\n    tavern.util.exceptions.RegexAccessError: No match for regex 'kernel --name .+nid=1030' in response:\n    #!ipxe\n    sleep 10\n    chain https://api-gw-service-nmn.local/apis/bss/boot/v1/bootscript?mac=00:40:a6:17:1d:3d&retry=1\n\n\n\n- Error calling validate function '<function better_validate_regex at 0x7f72848a6310>':\n    Traceback (most recent call last):\n      File \"/usr/lib/python3.9/site-packages/tavern/response/base.py\", line 152, in _maybe_run_validate_functions\n        vf(response)\n      File \"/usr/lib/python3.9/site-packages/tavern/util/extfunctions.py\", line 98, in inner\n        result = func(response, *args, **kwargs)\n      File \"/src/libs/bss_test_utils.py\", line 65, in better_validate_regex\n        raise exceptions.RegexAccessError(f\"No match for regex '{expression}' in response:\\n{response.text}\")\n    tavern.util.exceptions.RegexAccessError: No match for regex 'kernel --name .+bss_referral_token=' in response:\n    #!ipxe\n    sleep 10\n    chain https://api-gw-service-nmn.local/apis/bss/boot/v1/bootscript?mac=00:40:a6:17:1d:3d&retry=1","children":[{"name":"bssAPIbootscript","uid":"99a7a076362f751a","parentUid":"b54c028715dfd456a4518c5a719caac1","status":"failed","time":{"start":1711269324525,"stop":1711269324601,"duration":76},"flaky":false,"newFailed":false,"newPassed":false,"newBroken":false,"retriesCount":0,"retriesStatusChange":false,"parameters":[],"tags":[]}],"uid":"b54c028715dfd456a4518c5a719caac1"}],"uid":"8fb3a91ba5aaf9de24cc8a92edc82b5d"}],"name":"categories"}