[1m[31mERROR   [0m pykwalify.core:core.py:190 validation.invalid
[1m[31mERROR   [0m pykwalify.core:core.py:191  --- All found errors ---
[1m[31mERROR   [0m pykwalify.core:core.py:192 ["Enum 'in-progress' does not exist. Path: '/transitionStatus' Enum: ['completed']"]
[1m[31mERROR   [0m tavern.schemas.files:files.py:108 Error validating {'transitionID': 'ef523e08-69c3-41ae-8ff0-b6e333b4f6ba', 'operation': 'On', 'createTime': '2023-07-14T08:31:38.663097055Z', 'automaticExpirationTime': '2023-07-15T08:31:38.663097155Z', 'transitionStatus': 'in-progress', 'taskCounts': {'total': 1, 'new': 1, 'in-progress': 0, 'failed': 0, 'succeeded': 0, 'un-supported': 0}, 'tasks': [{'xname': 'x3000c0s5b0', 'taskStatus': 'new', 'taskStatusDescription': 'Gathering data'}]}
Traceback (most recent call last):
  File "/usr/lib/python3.9/site-packages/tavern/schemas/files.py", line 106, in verify_generic
    verifier.validate()
  File "/usr/lib/python3.9/site-packages/pykwalify/core.py", line 194, in validate
    raise SchemaError(u"Schema validation failed:\n - {error_msg}.".format(
pykwalify.errors.SchemaError: <SchemaError: error code 2: Schema validation failed:
 - Enum 'in-progress' does not exist. Path: '/transitionStatus' Enum: ['completed'].: Path: '/'>
[1m[31mERROR   [0m tavern.response.base:base.py:41 Error calling validate function '<function validate_pykwalify at 0x7feecccc0430>':
    Traceback (most recent call last):
      File "/usr/lib/python3.9/site-packages/tavern/schemas/files.py", line 106, in verify_generic
        verifier.validate()
      File "/usr/lib/python3.9/site-packages/pykwalify/core.py", line 194, in validate
        raise SchemaError(u"Schema validation failed:\n - {error_msg}.".format(
    pykwalify.errors.SchemaError: <SchemaError: error code 2: Schema validation failed:
     - Enum 'in-progress' does not exist. Path: '/transitionStatus' Enum: ['completed'].: Path: '/'>

    The above exception was the direct cause of the following exception:

    Traceback (most recent call last):
      File "/usr/lib/python3.9/site-packages/tavern/response/base.py", line 152, in _maybe_run_validate_functions
        vf(response)
      File "/usr/lib/python3.9/site-packages/tavern/util/extfunctions.py", line 98, in inner
        result = func(response, *args, **kwargs)
      File "/usr/lib/python3.9/site-packages/tavern/testutils/helpers.py", line 103, in validate_pykwalify
        verify_generic(to_verify, schema)
      File "/usr/lib/python3.9/site-packages/tavern/schemas/files.py", line 109, in verify_generic
        raise BadSchemaError() from e
    tavern.util.exceptions.BadSchemaError
Traceback (most recent call last):
  File "/usr/lib/python3.9/site-packages/tavern/schemas/files.py", line 106, in verify_generic
    verifier.validate()
  File "/usr/lib/python3.9/site-packages/pykwalify/core.py", line 194, in validate
    raise SchemaError(u"Schema validation failed:\n - {error_msg}.".format(
pykwalify.errors.SchemaError: <SchemaError: error code 2: Schema validation failed:
 - Enum 'in-progress' does not exist. Path: '/transitionStatus' Enum: ['completed'].: Path: '/'>

The above exception was the direct cause of the following exception:

Traceback (most recent call last):
  File "/usr/lib/python3.9/site-packages/tavern/response/base.py", line 152, in _maybe_run_validate_functions
    vf(response)
  File "/usr/lib/python3.9/site-packages/tavern/util/extfunctions.py", line 98, in inner
    result = func(response, *args, **kwargs)
  File "/usr/lib/python3.9/site-packages/tavern/testutils/helpers.py", line 103, in validate_pykwalify
    verify_generic(to_verify, schema)
  File "/usr/lib/python3.9/site-packages/tavern/schemas/files.py", line 109, in verify_generic
    raise BadSchemaError() from e
tavern.util.exceptions.BadSchemaError