{"uid":"885f40754028d244","name":"capmcAPISetPowerCap","fullName":"api.4-build-pipeline-only.test_set_power_cap.tavern#capmcAPISetPowerCap","historyId":"dd408b17f7b8e55258fcff9f663cd89b","time":{"start":1710836951201,"stop":1710836951347,"duration":146},"status":"failed","statusMessage":"tavern.util.exceptions.TestFailError: Test 'capmcAPISetPowerCap - test2 - set_power_cap for two ready nodes' failed:\n- Error calling validate function '<function validate_pykwalify at 0x78edf8f685e0>':\n    Traceback (most recent call last):\n      File \"/usr/lib/python3.9/site-packages/tavern/schemas/files.py\", line 106, in verify_generic\n        verifier.validate()\n      File \"/usr/lib/python3.9/site-packages/pykwalify/core.py\", line 194, in validate\n        raise SchemaError(u\"Schema validation failed:\\n - {error_msg}.\".format(\n    pykwalify.errors.SchemaError: <SchemaError: error code 2: Schema validation failed:\n     - Enum '22' does not exist. Path: '/e' Enum: [0].\n     - Value '[{'nid': 20, 'e': 22, 'err_msg': 'No NID supported controls specified'}, {'nid': 1018, 'e': 22, 'err_msg': 'Control (Node Power Limit) value (5036) is greater than maximum (925)'}]' is not of type 'none'. Path: '/nids'.: Path: '/'>\n\n    The above exception was the direct cause of the following exception:\n\n    Traceback (most recent call last):\n      File \"/usr/lib/python3.9/site-packages/tavern/response/base.py\", line 152, in _maybe_run_validate_functions\n        vf(response)\n      File \"/usr/lib/python3.9/site-packages/tavern/util/extfunctions.py\", line 98, in inner\n        result = func(response, *args, **kwargs)\n      File \"/usr/lib/python3.9/site-packages/tavern/testutils/helpers.py\", line 103, in validate_pykwalify\n        verify_generic(to_verify, schema)\n      File \"/usr/lib/python3.9/site-packages/tavern/schemas/files.py\", line 109, in verify_generic\n        raise BadSchemaError() from e\n    tavern.util.exceptions.BadSchemaError","statusTrace":"Format variables:\n  capmc_base_url = 'http://cray-capmc:27777'\n  nid0:d = '20'\n  min0:d = '5036'\n  nid1:d = '1018'\n  min1:d = '5036'\n  verify = 'False'\n\nSource test stage (line 184):\n  - name: capmcAPISetPowerCap - test2 - set_power_cap for two ready nodes\n    request:\n      url: \"{capmc_base_url}/capmc/v1/set_power_cap\"\n      json:\n        nids:\n          - nid: !int \"{nid0:d}\"\n            controls:\n              - name: Node Power Limit\n                val: !int \"{min0:d}\"\n          - nid: !int \"{nid1:d}\"\n            controls:\n              - name: Node Power Limit\n                val: !int \"{min1:d}\"\n      method: POST\n      verify: !bool \"{verify}\"\n    response:\n      status_code: 200\n      verify_response_with:\n        function: tavern.testutils.helpers:validate_pykwalify\n        extra_kwargs:\n\n\n\n\n\n\n          schema:\n            type: map\n            mapping:\n              e:\n                type: int\n                required: True\n                enum:\n                  - 0\n              err_msg:\n                type: str\n                required: True\n              nids:\n                type: none\n                required: False\n\n\nFormatted stage:\n  name: capmcAPISetPowerCap - test2 - set_power_cap for two ready nodes\n  request:\n    json:\n      nids:\n      - controls:\n        - name: Node Power Limit\n          val: !int '5036'\n        nid: !int '20'\n      - controls:\n        - name: Node Power Limit\n          val: !int '5036'\n        nid: !int '1018'\n    method: POST\n    url: 'http://cray-capmc:27777/capmc/v1/set_power_cap'\n    verify: !bool 'False'\n  response:\n    status_code: 200\n    verify_response_with:\n      extra_kwargs:\n        schema:\n          mapping:\n            e:\n              enum:\n              - 0\n              required: true\n              type: int\n            err_msg:\n              required: true\n              type: str\n            nids:\n              required: false\n              type: none\n          type: map\n      function: tavern.testutils.helpers:validate_pykwalify\n\nErrors:\nE   tavern.util.exceptions.TestFailError: Test 'capmcAPISetPowerCap - test2 - set_power_cap for two ready nodes' failed:\n    - Error calling validate function '<function validate_pykwalify at 0x78edf8f685e0>':\n        Traceback (most recent call last):\n          File \"/usr/lib/python3.9/site-packages/tavern/schemas/files.py\", line 106, in verify_generic\n            verifier.validate()\n          File \"/usr/lib/python3.9/site-packages/pykwalify/core.py\", line 194, in validate\n            raise SchemaError(u\"Schema validation failed:\\n - {error_msg}.\".format(\n        pykwalify.errors.SchemaError: <SchemaError: error code 2: Schema validation failed:\n         - Enum '22' does not exist. Path: '/e' Enum: [0].\n         - Value '[{'nid': 20, 'e': 22, 'err_msg': 'No NID supported controls specified'}, {'nid': 1018, 'e': 22, 'err_msg': 'Control (Node Power Limit) value (5036) is greater than maximum (925)'}]' is not of type 'none'. Path: '/nids'.: Path: '/'>\n    \n        The above exception was the direct cause of the following exception:\n    \n        Traceback (most recent call last):\n          File \"/usr/lib/python3.9/site-packages/tavern/response/base.py\", line 152, in _maybe_run_validate_functions\n            vf(response)\n          File \"/usr/lib/python3.9/site-packages/tavern/util/extfunctions.py\", line 98, in inner\n            result = func(response, *args, **kwargs)\n          File \"/usr/lib/python3.9/site-packages/tavern/testutils/helpers.py\", line 103, in validate_pykwalify\n            verify_generic(to_verify, schema)\n          File \"/usr/lib/python3.9/site-packages/tavern/schemas/files.py\", line 109, in verify_generic\n            raise BadSchemaError() from e\n        tavern.util.exceptions.BadSchemaError","flaky":true,"newFailed":true,"newBroken":false,"newPassed":false,"retriesCount":0,"retriesStatusChange":false,"beforeStages":[],"testStage":{"status":"failed","statusMessage":"tavern.util.exceptions.TestFailError: Test 'capmcAPISetPowerCap - test2 - set_power_cap for two ready nodes' failed:\n- Error calling validate function '<function validate_pykwalify at 0x78edf8f685e0>':\n    Traceback (most recent call last):\n      File \"/usr/lib/python3.9/site-packages/tavern/schemas/files.py\", line 106, in verify_generic\n        verifier.validate()\n      File \"/usr/lib/python3.9/site-packages/pykwalify/core.py\", line 194, in validate\n        raise SchemaError(u\"Schema validation failed:\\n - {error_msg}.\".format(\n    pykwalify.errors.SchemaError: <SchemaError: error code 2: Schema validation failed:\n     - Enum '22' does not exist. Path: '/e' Enum: [0].\n     - Value '[{'nid': 20, 'e': 22, 'err_msg': 'No NID supported controls specified'}, {'nid': 1018, 'e': 22, 'err_msg': 'Control (Node Power Limit) value (5036) is greater than maximum (925)'}]' is not of type 'none'. Path: '/nids'.: Path: '/'>\n\n    The above exception was the direct cause of the following exception:\n\n    Traceback (most recent call last):\n      File \"/usr/lib/python3.9/site-packages/tavern/response/base.py\", line 152, in _maybe_run_validate_functions\n        vf(response)\n      File \"/usr/lib/python3.9/site-packages/tavern/util/extfunctions.py\", line 98, in inner\n        result = func(response, *args, **kwargs)\n      File \"/usr/lib/python3.9/site-packages/tavern/testutils/helpers.py\", line 103, in validate_pykwalify\n        verify_generic(to_verify, schema)\n      File \"/usr/lib/python3.9/site-packages/tavern/schemas/files.py\", line 109, in verify_generic\n        raise BadSchemaError() from e\n    tavern.util.exceptions.BadSchemaError","statusTrace":"Format variables:\n  capmc_base_url = 'http://cray-capmc:27777'\n  nid0:d = '20'\n  min0:d = '5036'\n  nid1:d = '1018'\n  min1:d = '5036'\n  verify = 'False'\n\nSource test stage (line 184):\n  - name: capmcAPISetPowerCap - test2 - set_power_cap for two ready nodes\n    request:\n      url: \"{capmc_base_url}/capmc/v1/set_power_cap\"\n      json:\n        nids:\n          - nid: !int \"{nid0:d}\"\n            controls:\n              - name: Node Power Limit\n                val: !int \"{min0:d}\"\n          - nid: !int \"{nid1:d}\"\n            controls:\n              - name: Node Power Limit\n                val: !int \"{min1:d}\"\n      method: POST\n      verify: !bool \"{verify}\"\n    response:\n      status_code: 200\n      verify_response_with:\n        function: tavern.testutils.helpers:validate_pykwalify\n        extra_kwargs:\n\n\n\n\n\n\n          schema:\n            type: map\n            mapping:\n              e:\n                type: int\n                required: True\n                enum:\n                  - 0\n              err_msg:\n                type: str\n                required: True\n              nids:\n                type: none\n                required: False\n\n\nFormatted stage:\n  name: capmcAPISetPowerCap - test2 - set_power_cap for two ready nodes\n  request:\n    json:\n      nids:\n      - controls:\n        - name: Node Power Limit\n          val: !int '5036'\n        nid: !int '20'\n      - controls:\n        - name: Node Power Limit\n          val: !int '5036'\n        nid: !int '1018'\n    method: POST\n    url: 'http://cray-capmc:27777/capmc/v1/set_power_cap'\n    verify: !bool 'False'\n  response:\n    status_code: 200\n    verify_response_with:\n      extra_kwargs:\n        schema:\n          mapping:\n            e:\n              enum:\n              - 0\n              required: true\n              type: int\n            err_msg:\n              required: true\n              type: str\n            nids:\n              required: false\n              type: none\n          type: map\n      function: tavern.testutils.helpers:validate_pykwalify\n\nErrors:\nE   tavern.util.exceptions.TestFailError: Test 'capmcAPISetPowerCap - test2 - set_power_cap for two ready nodes' failed:\n    - Error calling validate function '<function validate_pykwalify at 0x78edf8f685e0>':\n        Traceback (most recent call last):\n          File \"/usr/lib/python3.9/site-packages/tavern/schemas/files.py\", line 106, in verify_generic\n            verifier.validate()\n          File \"/usr/lib/python3.9/site-packages/pykwalify/core.py\", line 194, in validate\n            raise SchemaError(u\"Schema validation failed:\\n - {error_msg}.\".format(\n        pykwalify.errors.SchemaError: <SchemaError: error code 2: Schema validation failed:\n         - Enum '22' does not exist. Path: '/e' Enum: [0].\n         - Value '[{'nid': 20, 'e': 22, 'err_msg': 'No NID supported controls specified'}, {'nid': 1018, 'e': 22, 'err_msg': 'Control (Node Power Limit) value (5036) is greater than maximum (925)'}]' is not of type 'none'. Path: '/nids'.: Path: '/'>\n    \n        The above exception was the direct cause of the following exception:\n    \n        Traceback (most recent call last):\n          File \"/usr/lib/python3.9/site-packages/tavern/response/base.py\", line 152, in _maybe_run_validate_functions\n            vf(response)\n          File \"/usr/lib/python3.9/site-packages/tavern/util/extfunctions.py\", line 98, in inner\n            result = func(response, *args, **kwargs)\n          File \"/usr/lib/python3.9/site-packages/tavern/testutils/helpers.py\", line 103, in validate_pykwalify\n            verify_generic(to_verify, schema)\n          File \"/usr/lib/python3.9/site-packages/tavern/schemas/files.py\", line 109, in verify_generic\n            raise BadSchemaError() from e\n        tavern.util.exceptions.BadSchemaError","steps":[{"name":"Stage 0: capmcAPISetPowerCap - setup1 - Get HSM Nodes","time":{"start":1710836951211,"stop":1710836951241,"duration":30},"status":"passed","steps":[],"attachments":[{"uid":"c4ac41a2acb4b1e","name":"stage_yaml","source":"c4ac41a2acb4b1e.yaml","type":"application/yaml","size":457},{"uid":"4d740b024001e7ff","name":"rest_request","source":"4d740b024001e7ff.yaml","type":"application/yaml","size":149},{"uid":"30914da59903b0a4","name":"rest_response","source":"30914da59903b0a4.yaml","type":"application/yaml","size":5772}],"parameters":[],"stepsCount":0,"attachmentsCount":3,"shouldDisplayMessage":false,"hasContent":true},{"name":"Stage 1: capmcAPISetPowerCap - setup2 - get_power_cap_capabilities","time":{"start":1710836951242,"stop":1710836951281,"duration":39},"status":"passed","steps":[],"attachments":[{"uid":"99bc3658c6154844","name":"stage_yaml","source":"99bc3658c6154844.yaml","type":"application/yaml","size":472},{"uid":"fd0d72c42c207e5d","name":"rest_request","source":"fd0d72c42c207e5d.yaml","type":"application/yaml","size":171},{"uid":"59b9e2ddff82113a","name":"rest_response","source":"59b9e2ddff82113a.yaml","type":"application/yaml","size":980}],"parameters":[],"stepsCount":0,"attachmentsCount":3,"shouldDisplayMessage":false,"hasContent":true},{"name":"Stage 2: capmcAPISetPowerCap - setup3 - Set HSM Node 0 to Off","time":{"start":1710836951282,"stop":1710836951293,"duration":11},"status":"passed","steps":[],"attachments":[{"uid":"9feee13bfc5d892e","name":"stage_yaml","source":"9feee13bfc5d892e.yaml","type":"application/yaml","size":247},{"uid":"4d328afc4408b1e1","name":"rest_request","source":"4d328afc4408b1e1.yaml","type":"application/yaml","size":173},{"uid":"5f171768834a824a","name":"rest_response","source":"5f171768834a824a.yaml","type":"application/yaml","size":134}],"parameters":[],"stepsCount":0,"attachmentsCount":3,"shouldDisplayMessage":false,"hasContent":true},{"name":"Stage 3: capmcAPISetPowerCap - setup4 - Set HSM Node 1 to Off","time":{"start":1710836951293,"stop":1710836951300,"duration":7},"status":"passed","steps":[],"attachments":[{"uid":"6f0423e59b720bb6","name":"stage_yaml","source":"6f0423e59b720bb6.yaml","type":"application/yaml","size":247},{"uid":"b54ae67a1956f14b","name":"rest_request","source":"b54ae67a1956f14b.yaml","type":"application/yaml","size":173},{"uid":"7a6689785796a95","name":"rest_response","source":"7a6689785796a95.yaml","type":"application/yaml","size":134}],"parameters":[],"stepsCount":0,"attachmentsCount":3,"shouldDisplayMessage":false,"hasContent":true},{"name":"Stage 4: capmcAPISetPowerCap - test1 - POST set_power_cap for powered off node - failure test","time":{"start":1710836951301,"stop":1710836951314,"duration":13},"status":"passed","steps":[],"attachments":[{"uid":"2c5bdcdc434ddc65","name":"stage_yaml","source":"2c5bdcdc434ddc65.yaml","type":"application/yaml","size":1395},{"uid":"247778c246188650","name":"rest_request","source":"247778c246188650.yaml","type":"application/yaml","size":212},{"uid":"8f97559c36fc404c","name":"rest_response","source":"8f97559c36fc404c.yaml","type":"application/yaml","size":285}],"parameters":[],"stepsCount":0,"attachmentsCount":3,"shouldDisplayMessage":false,"hasContent":true},{"name":"Stage 5: capmcAPISetPowerCap - setup5 - Set HSM Node 0 to Ready","time":{"start":1710836951314,"stop":1710836951322,"duration":8},"status":"passed","steps":[],"attachments":[{"uid":"5620f24001c00dc2","name":"stage_yaml","source":"5620f24001c00dc2.yaml","type":"application/yaml","size":251},{"uid":"8d497462becc661","name":"rest_request","source":"8d497462becc661.yaml","type":"application/yaml","size":173},{"uid":"1551e31f3d590a29","name":"rest_response","source":"1551e31f3d590a29.yaml","type":"application/yaml","size":134}],"parameters":[],"stepsCount":0,"attachmentsCount":3,"shouldDisplayMessage":false,"hasContent":true},{"name":"Stage 6: capmcAPISetPowerCap - setup6 - Set HSM Node 1 to Ready","time":{"start":1710836951323,"stop":1710836951331,"duration":8},"status":"passed","steps":[],"attachments":[{"uid":"db6cb0abf917b69e","name":"stage_yaml","source":"db6cb0abf917b69e.yaml","type":"application/yaml","size":251},{"uid":"3215e0c55300955c","name":"rest_request","source":"3215e0c55300955c.yaml","type":"application/yaml","size":173},{"uid":"7b24afe2cd09e1e3","name":"rest_response","source":"7b24afe2cd09e1e3.yaml","type":"application/yaml","size":134}],"parameters":[],"stepsCount":0,"attachmentsCount":3,"shouldDisplayMessage":false,"hasContent":true},{"name":"Stage 7: capmcAPISetPowerCap - test2 - set_power_cap for two ready nodes","time":{"start":1710836951332,"stop":1710836951346,"duration":14},"status":"failed","statusMessage":"tavern.util.exceptions.TestFailError: Test 'capmcAPISetPowerCap - test2 - set_power_cap for two ready nodes' failed:\n- Error calling validate function '<function validate_pykwalify at 0x78edf8f685e0>':\n    Traceback (most recent call last):\n      File \"/usr/lib/python3.9/site-packages/tavern/schemas/files.py\", line 106, in verify_generic\n        verifier.validate()\n      File \"/usr/lib/python3.9/site-packages/pykwalify/core.py\", line 194, in validate\n        raise SchemaError(u\"Schema validation failed:\\n - {error_msg}.\".format(\n    pykwalify.errors.SchemaError: <SchemaError: error code 2: Schema validation failed:\n     - Enum '22' does not exist. Path: '/e' Enum: [0].\n     - Value '[{'nid': 20, 'e': 22, 'err_msg': 'No NID supported controls specified'}, {'nid': 1018, 'e': 22, 'err_msg': 'Control (Node Power Limit) value (5036) is greater than maximum (925)'}]' is not of type 'none'. Path: '/nids'.: Path: '/'>\n\n    The above exception was the direct cause of the following exception:\n\n    Traceback (most recent call last):\n      File \"/usr/lib/python3.9/site-packages/tavern/response/base.py\", line 152, in _maybe_run_validate_functions\n        vf(response)\n      File \"/usr/lib/python3.9/site-packages/tavern/util/extfunctions.py\", line 98, in inner\n        result = func(response, *args, **kwargs)\n      File \"/usr/lib/python3.9/site-packages/tavern/testutils/helpers.py\", line 103, in validate_pykwalify\n        verify_generic(to_verify, schema)\n      File \"/usr/lib/python3.9/site-packages/tavern/schemas/files.py\", line 109, in verify_generic\n        raise BadSchemaError() from e\n    tavern.util.exceptions.BadSchemaError\n\n","statusTrace":"  File \"/usr/lib/python3.9/site-packages/allure_commons/_allure.py\", line 192, in impl\n    return func(*a, **kw)\n  File \"/usr/lib/python3.9/site-packages/tavern/util/retry.py\", line 31, in wrapped\n    res = fn(*args, **kwargs)\n  File \"/usr/lib/python3.9/site-packages/tavern/core.py\", line 270, in run_stage\n    saved = v.verify(response)\n  File \"/usr/lib/python3.9/site-packages/tavern/_plugins/rest/response.py\", line 201, in verify\n    raise exceptions.TestFailError(\n","steps":[],"attachments":[{"uid":"efbeb4fcb36c5f4c","name":"stage_yaml","source":"efbeb4fcb36c5f4c.yaml","type":"application/yaml","size":903},{"uid":"1233a29e67d58606","name":"rest_request","source":"1233a29e67d58606.yaml","type":"application/yaml","size":286},{"uid":"5cf24ed763ecb6a3","name":"rest_response","source":"5cf24ed763ecb6a3.yaml","type":"application/yaml","size":394}],"parameters":[],"stepsCount":0,"attachmentsCount":3,"shouldDisplayMessage":true,"hasContent":true}],"attachments":[{"uid":"384dcc17264126fd","name":"error_output","source":"384dcc17264126fd.attach","type":"text/plain","size":3773},{"uid":"e9e7c59f384ecff5","name":"log","source":"e9e7c59f384ecff5.txt","type":"text/plain","size":4427}],"parameters":[],"stepsCount":8,"attachmentsCount":26,"shouldDisplayMessage":true,"hasContent":true},"afterStages":[],"labels":[{"name":"parentSuite","value":"cray-capmc-hmth-test"},{"name":"suite","value":"build-pipeline-only"},{"name":"host","value":"6e9373388157"},{"name":"thread","value":"8-MainThread"},{"name":"framework","value":"pytest"},{"name":"language","value":"cpython3"},{"name":"package","value":"api.4-build-pipeline-only.test_set_power_cap.tavern"},{"name":"resultFormat","value":"allure2"}],"parameters":[],"links":[],"hidden":false,"retry":false,"extra":{"severity":"normal","retries":[],"categories":[{"name":"Product defects","matchedStatuses":[],"flaky":false}],"history":{"statistic":{"failed":37,"broken":0,"skipped":0,"passed":321,"unknown":0,"total":358},"items":[{"uid":"1d643dcc95c90dfe","status":"passed","time":{"start":1710750621824,"stop":1710750622104,"duration":280}},{"uid":"8a244bb04401595","status":"passed","time":{"start":1710664005401,"stop":1710664005657,"duration":256}},{"uid":"1e23a14ca4e891ae","status":"failed","statusDetails":"tavern.util.exceptions.TestFailError: Test 'capmcAPISetPowerCap - test2 - set_power_cap for two ready nodes' failed:\n- Error calling validate function '<function validate_pykwalify at 0x7492f42105e0>':\n    Traceback (most recent call last):\n      File \"/usr/lib/python3.9/site-packages/tavern/schemas/files.py\", line 106, in verify_generic\n        verifier.validate()\n      File \"/usr/lib/python3.9/site-packages/pykwalify/core.py\", line 194, in validate\n        raise SchemaError(u\"Schema validation failed:\\n - {error_msg}.\".format(\n    pykwalify.errors.SchemaError: <SchemaError: error code 2: Schema validation failed:\n     - Enum '22' does not exist. Path: '/e' Enum: [0].\n     - Value '[{'nid': 20, 'e': 22, 'err_msg': 'No NID supported controls specified'}, {'nid': 1021, 'e': 22, 'err_msg': 'Control (Node Power Limit) value (5036) is greater than maximum (925)'}]' is not of type 'none'. Path: '/nids'.: Path: '/'>\n\n    The above exception was the direct cause of the following exception:\n\n    Traceback (most recent call last):\n      File \"/usr/lib/python3.9/site-packages/tavern/response/base.py\", line 152, in _maybe_run_validate_functions\n        vf(response)\n      File \"/usr/lib/python3.9/site-packages/tavern/util/extfunctions.py\", line 98, in inner\n        result = func(response, *args, **kwargs)\n      File \"/usr/lib/python3.9/site-packages/tavern/testutils/helpers.py\", line 103, in validate_pykwalify\n        verify_generic(to_verify, schema)\n      File \"/usr/lib/python3.9/site-packages/tavern/schemas/files.py\", line 109, in verify_generic\n        raise BadSchemaError() from e\n    tavern.util.exceptions.BadSchemaError","time":{"start":1710577746155,"stop":1710577746292,"duration":137}},{"uid":"79547bbb0a87f717","status":"failed","statusDetails":"tavern.util.exceptions.TestFailError: Test 'capmcAPISetPowerCap - test2 - set_power_cap for two ready nodes' failed:\n- Error calling validate function '<function validate_pykwalify at 0x778b942d85e0>':\n    Traceback (most recent call last):\n      File \"/usr/lib/python3.9/site-packages/tavern/schemas/files.py\", line 106, in verify_generic\n        verifier.validate()\n      File \"/usr/lib/python3.9/site-packages/pykwalify/core.py\", line 194, in validate\n        raise SchemaError(u\"Schema validation failed:\\n - {error_msg}.\".format(\n    pykwalify.errors.SchemaError: <SchemaError: error code 2: Schema validation failed:\n     - Enum '22' does not exist. Path: '/e' Enum: [0].\n     - Value '[{'nid': 20, 'e': 22, 'err_msg': 'No NID supported controls specified'}, {'nid': 1005, 'e': 22, 'err_msg': 'Control (Node Power Limit) value (5036) is greater than maximum (925)'}]' is not of type 'none'. Path: '/nids'.: Path: '/'>\n\n    The above exception was the direct cause of the following exception:\n\n    Traceback (most recent call last):\n      File \"/usr/lib/python3.9/site-packages/tavern/response/base.py\", line 152, in _maybe_run_validate_functions\n        vf(response)\n      File \"/usr/lib/python3.9/site-packages/tavern/util/extfunctions.py\", line 98, in inner\n        result = func(response, *args, **kwargs)\n      File \"/usr/lib/python3.9/site-packages/tavern/testutils/helpers.py\", line 103, in validate_pykwalify\n        verify_generic(to_verify, schema)\n      File \"/usr/lib/python3.9/site-packages/tavern/schemas/files.py\", line 109, in verify_generic\n        raise BadSchemaError() from e\n    tavern.util.exceptions.BadSchemaError","time":{"start":1710491341499,"stop":1710491341646,"duration":147}},{"uid":"27a37366f179be8f","status":"failed","statusDetails":"tavern.util.exceptions.TestFailError: Test 'capmcAPISetPowerCap - test2 - set_power_cap for two ready nodes' failed:\n- Error calling validate function '<function validate_pykwalify at 0x7946947235e0>':\n    Traceback (most recent call last):\n      File \"/usr/lib/python3.9/site-packages/tavern/schemas/files.py\", line 106, in verify_generic\n        verifier.validate()\n      File \"/usr/lib/python3.9/site-packages/pykwalify/core.py\", line 194, in validate\n        raise SchemaError(u\"Schema validation failed:\\n - {error_msg}.\".format(\n    pykwalify.errors.SchemaError: <SchemaError: error code 2: Schema validation failed:\n     - Enum '22' does not exist. Path: '/e' Enum: [0].\n     - Value '[{'nid': 20, 'e': 22, 'err_msg': 'No NID supported controls specified'}, {'nid': 1010, 'e': 22, 'err_msg': 'Control (Node Power Limit) value (5036) is greater than maximum (925)'}]' is not of type 'none'. Path: '/nids'.: Path: '/'>\n\n    The above exception was the direct cause of the following exception:\n\n    Traceback (most recent call last):\n      File \"/usr/lib/python3.9/site-packages/tavern/response/base.py\", line 152, in _maybe_run_validate_functions\n        vf(response)\n      File \"/usr/lib/python3.9/site-packages/tavern/util/extfunctions.py\", line 98, in inner\n        result = func(response, *args, **kwargs)\n      File \"/usr/lib/python3.9/site-packages/tavern/testutils/helpers.py\", line 103, in validate_pykwalify\n        verify_generic(to_verify, schema)\n      File \"/usr/lib/python3.9/site-packages/tavern/schemas/files.py\", line 109, in verify_generic\n        raise BadSchemaError() from e\n    tavern.util.exceptions.BadSchemaError","time":{"start":1710404860415,"stop":1710404860555,"duration":140}},{"uid":"c68f0fcd398db721","status":"failed","statusDetails":"tavern.util.exceptions.TestFailError: Test 'capmcAPISetPowerCap - test2 - set_power_cap for two ready nodes' failed:\n- Error calling validate function '<function validate_pykwalify at 0x70c1dd9a45e0>':\n    Traceback (most recent call last):\n      File \"/usr/lib/python3.9/site-packages/tavern/schemas/files.py\", line 106, in verify_generic\n        verifier.validate()\n      File \"/usr/lib/python3.9/site-packages/pykwalify/core.py\", line 194, in validate\n        raise SchemaError(u\"Schema validation failed:\\n - {error_msg}.\".format(\n    pykwalify.errors.SchemaError: <SchemaError: error code 2: Schema validation failed:\n     - Enum '22' does not exist. Path: '/e' Enum: [0].\n     - Value '[{'nid': 1028, 'e': 22, 'err_msg': 'Control (Node Power Limit) value (5036) is greater than maximum (925)'}, {'nid': 20, 'e': 22, 'err_msg': 'No NID supported controls specified'}]' is not of type 'none'. Path: '/nids'.: Path: '/'>\n\n    The above exception was the direct cause of the following exception:\n\n    Traceback (most recent call last):\n      File \"/usr/lib/python3.9/site-packages/tavern/response/base.py\", line 152, in _maybe_run_validate_functions\n        vf(response)\n      File \"/usr/lib/python3.9/site-packages/tavern/util/extfunctions.py\", line 98, in inner\n        result = func(response, *args, **kwargs)\n      File \"/usr/lib/python3.9/site-packages/tavern/testutils/helpers.py\", line 103, in validate_pykwalify\n        verify_generic(to_verify, schema)\n      File \"/usr/lib/python3.9/site-packages/tavern/schemas/files.py\", line 109, in verify_generic\n        raise BadSchemaError() from e\n    tavern.util.exceptions.BadSchemaError","time":{"start":1710318531050,"stop":1710318531195,"duration":145}},{"uid":"bd4d10c14034b2a6","status":"passed","time":{"start":1710232059663,"stop":1710232059919,"duration":256}},{"uid":"8248955122190c98","status":"passed","time":{"start":1710145744726,"stop":1710145744982,"duration":256}},{"uid":"a53daacc38a34b92","status":"passed","time":{"start":1710059282287,"stop":1710059282543,"duration":256}},{"uid":"6cc094426a81dd9","status":"passed","time":{"start":1709972897626,"stop":1709972897875,"duration":249}},{"uid":"97ff3e54a763fdfb","status":"failed","statusDetails":"tavern.util.exceptions.TestFailError: Test 'capmcAPISetPowerCap - test2 - set_power_cap for two ready nodes' failed:\n- Error calling validate function '<function validate_pykwalify at 0x7f905718b5e0>':\n    Traceback (most recent call last):\n      File \"/usr/lib/python3.9/site-packages/tavern/schemas/files.py\", line 106, in verify_generic\n        verifier.validate()\n      File \"/usr/lib/python3.9/site-packages/pykwalify/core.py\", line 194, in validate\n        raise SchemaError(u\"Schema validation failed:\\n - {error_msg}.\".format(\n    pykwalify.errors.SchemaError: <SchemaError: error code 2: Schema validation failed:\n     - Enum '22' does not exist. Path: '/e' Enum: [0].\n     - Value '[{'nid': 20, 'e': 22, 'err_msg': 'No NID supported controls specified'}]' is not of type 'none'. Path: '/nids'.: Path: '/'>\n\n    The above exception was the direct cause of the following exception:\n\n    Traceback (most recent call last):\n      File \"/usr/lib/python3.9/site-packages/tavern/response/base.py\", line 152, in _maybe_run_validate_functions\n        vf(response)\n      File \"/usr/lib/python3.9/site-packages/tavern/util/extfunctions.py\", line 98, in inner\n        result = func(response, *args, **kwargs)\n      File \"/usr/lib/python3.9/site-packages/tavern/testutils/helpers.py\", line 103, in validate_pykwalify\n        verify_generic(to_verify, schema)\n      File \"/usr/lib/python3.9/site-packages/tavern/schemas/files.py\", line 109, in verify_generic\n        raise BadSchemaError() from e\n    tavern.util.exceptions.BadSchemaError","time":{"start":1709886526260,"stop":1709886526401,"duration":141}},{"uid":"b8d9bf0cca6e719c","status":"passed","time":{"start":1709800109297,"stop":1709800109546,"duration":249}},{"uid":"5fc2223786f9d2c","status":"passed","time":{"start":1709713809280,"stop":1709713809530,"duration":250}},{"uid":"1263a94f6d5a25fe","status":"passed","time":{"start":1709627296860,"stop":1709627297106,"duration":246}},{"uid":"8c26fa917345fe24","status":"passed","time":{"start":1709541705938,"stop":1709541706191,"duration":253}},{"uid":"16c885959b059329","status":"passed","time":{"start":1709454607284,"stop":1709454607538,"duration":254}},{"uid":"39045baa6262459e","status":"passed","time":{"start":1709368114468,"stop":1709368114732,"duration":264}},{"uid":"26657f25b2141e0c","status":"passed","time":{"start":1709281749991,"stop":1709281750238,"duration":247}},{"uid":"eda141c6fb03dbd8","status":"passed","time":{"start":1709195310544,"stop":1709195310797,"duration":253}},{"uid":"fc5a04d8003a22b9","status":"passed","time":{"start":1709108952384,"stop":1709108952642,"duration":258}}]},"tags":[]},"source":"885f40754028d244.json","parameterValues":[]}