[31m[1mERROR   [0m pykwalify.core:core.py:190 validation.invalid
[31m[1mERROR   [0m pykwalify.core:core.py:191  --- All found errors ---
[31m[1mERROR   [0m pykwalify.core:core.py:192 ["Key 'off' was not defined. Path: ''"]
[31m[1mERROR   [0m tavern.schemas.files:files.py:108 Error validating {'e': 0, 'err_msg': '', 'off': ['x3000c0s6b0n0'], 'on': ['x1000c0s4b1n0']}
Traceback (most recent call last):
  File "/usr/lib/python3.9/site-packages/tavern/schemas/files.py", line 106, in verify_generic
    verifier.validate()
  File "/usr/lib/python3.9/site-packages/pykwalify/core.py", line 194, in validate
    raise SchemaError(u"Schema validation failed:\n - {error_msg}.".format(
pykwalify.errors.SchemaError: <SchemaError: error code 2: Schema validation failed:
 - Key 'off' was not defined. Path: ''.: Path: '/'>
[31m[1mERROR   [0m tavern.response.base:base.py:41 Error calling validate function '<function validate_pykwalify at 0x7f24c2db9820>':
    Traceback (most recent call last):
      File "/usr/lib/python3.9/site-packages/tavern/schemas/files.py", line 106, in verify_generic
        verifier.validate()
      File "/usr/lib/python3.9/site-packages/pykwalify/core.py", line 194, in validate
        raise SchemaError(u"Schema validation failed:\n - {error_msg}.".format(
    pykwalify.errors.SchemaError: <SchemaError: error code 2: Schema validation failed:
     - Key 'off' was not defined. Path: ''.: Path: '/'>

    The above exception was the direct cause of the following exception:

    Traceback (most recent call last):
      File "/usr/lib/python3.9/site-packages/tavern/response/base.py", line 152, in _maybe_run_validate_functions
        vf(response)
      File "/usr/lib/python3.9/site-packages/tavern/util/extfunctions.py", line 98, in inner
        result = func(response, *args, **kwargs)
      File "/usr/lib/python3.9/site-packages/tavern/testutils/helpers.py", line 103, in validate_pykwalify
        verify_generic(to_verify, schema)
      File "/usr/lib/python3.9/site-packages/tavern/schemas/files.py", line 109, in verify_generic
        raise BadSchemaError() from e
    tavern.util.exceptions.BadSchemaError
Traceback (most recent call last):
  File "/usr/lib/python3.9/site-packages/tavern/schemas/files.py", line 106, in verify_generic
    verifier.validate()
  File "/usr/lib/python3.9/site-packages/pykwalify/core.py", line 194, in validate
    raise SchemaError(u"Schema validation failed:\n - {error_msg}.".format(
pykwalify.errors.SchemaError: <SchemaError: error code 2: Schema validation failed:
 - Key 'off' was not defined. Path: ''.: Path: '/'>

The above exception was the direct cause of the following exception:

Traceback (most recent call last):
  File "/usr/lib/python3.9/site-packages/tavern/response/base.py", line 152, in _maybe_run_validate_functions
    vf(response)
  File "/usr/lib/python3.9/site-packages/tavern/util/extfunctions.py", line 98, in inner
    result = func(response, *args, **kwargs)
  File "/usr/lib/python3.9/site-packages/tavern/testutils/helpers.py", line 103, in validate_pykwalify
    verify_generic(to_verify, schema)
  File "/usr/lib/python3.9/site-packages/tavern/schemas/files.py", line 109, in verify_generic
    raise BadSchemaError() from e
tavern.util.exceptions.BadSchemaError
[31m[1mERROR   [0m pykwalify.core:core.py:190 validation.invalid
[31m[1mERROR   [0m pykwalify.core:core.py:191  --- All found errors ---
[31m[1mERROR   [0m pykwalify.core:core.py:192 ["Key 'off' was not defined. Path: ''"]
[31m[1mERROR   [0m tavern.schemas.files:files.py:108 Error validating {'e': 0, 'err_msg': '', 'off': ['x3000c0s6b0n0'], 'on': ['x1000c0s4b1n0']}
Traceback (most recent call last):
  File "/usr/lib/python3.9/site-packages/tavern/schemas/files.py", line 106, in verify_generic
    verifier.validate()
  File "/usr/lib/python3.9/site-packages/pykwalify/core.py", line 194, in validate
    raise SchemaError(u"Schema validation failed:\n - {error_msg}.".format(
pykwalify.errors.SchemaError: <SchemaError: error code 2: Schema validation failed:
 - Key 'off' was not defined. Path: ''.: Path: '/'>
[31m[1mERROR   [0m tavern.response.base:base.py:41 Error calling validate function '<function validate_pykwalify at 0x7f24c2db9820>':
    Traceback (most recent call last):
      File "/usr/lib/python3.9/site-packages/tavern/schemas/files.py", line 106, in verify_generic
        verifier.validate()
      File "/usr/lib/python3.9/site-packages/pykwalify/core.py", line 194, in validate
        raise SchemaError(u"Schema validation failed:\n - {error_msg}.".format(
    pykwalify.errors.SchemaError: <SchemaError: error code 2: Schema validation failed:
     - Key 'off' was not defined. Path: ''.: Path: '/'>

    The above exception was the direct cause of the following exception:

    Traceback (most recent call last):
      File "/usr/lib/python3.9/site-packages/tavern/response/base.py", line 152, in _maybe_run_validate_functions
        vf(response)
      File "/usr/lib/python3.9/site-packages/tavern/util/extfunctions.py", line 98, in inner
        result = func(response, *args, **kwargs)
      File "/usr/lib/python3.9/site-packages/tavern/testutils/helpers.py", line 103, in validate_pykwalify
        verify_generic(to_verify, schema)
      File "/usr/lib/python3.9/site-packages/tavern/schemas/files.py", line 109, in verify_generic
        raise BadSchemaError() from e
    tavern.util.exceptions.BadSchemaError
Traceback (most recent call last):
  File "/usr/lib/python3.9/site-packages/tavern/schemas/files.py", line 106, in verify_generic
    verifier.validate()
  File "/usr/lib/python3.9/site-packages/pykwalify/core.py", line 194, in validate
    raise SchemaError(u"Schema validation failed:\n - {error_msg}.".format(
pykwalify.errors.SchemaError: <SchemaError: error code 2: Schema validation failed:
 - Key 'off' was not defined. Path: ''.: Path: '/'>

The above exception was the direct cause of the following exception:

Traceback (most recent call last):
  File "/usr/lib/python3.9/site-packages/tavern/response/base.py", line 152, in _maybe_run_validate_functions
    vf(response)
  File "/usr/lib/python3.9/site-packages/tavern/util/extfunctions.py", line 98, in inner
    result = func(response, *args, **kwargs)
  File "/usr/lib/python3.9/site-packages/tavern/testutils/helpers.py", line 103, in validate_pykwalify
    verify_generic(to_verify, schema)
  File "/usr/lib/python3.9/site-packages/tavern/schemas/files.py", line 109, in verify_generic
    raise BadSchemaError() from e
tavern.util.exceptions.BadSchemaError
[31m[1mERROR   [0m pykwalify.core:core.py:190 validation.invalid
[31m[1mERROR   [0m pykwalify.core:core.py:191  --- All found errors ---
[31m[1mERROR   [0m pykwalify.core:core.py:192 ["Key 'off' was not defined. Path: ''"]
[31m[1mERROR   [0m tavern.schemas.files:files.py:108 Error validating {'e': 0, 'err_msg': '', 'off': ['x3000c0s6b0n0'], 'on': ['x1000c0s4b1n0']}
Traceback (most recent call last):
  File "/usr/lib/python3.9/site-packages/tavern/schemas/files.py", line 106, in verify_generic
    verifier.validate()
  File "/usr/lib/python3.9/site-packages/pykwalify/core.py", line 194, in validate
    raise SchemaError(u"Schema validation failed:\n - {error_msg}.".format(
pykwalify.errors.SchemaError: <SchemaError: error code 2: Schema validation failed:
 - Key 'off' was not defined. Path: ''.: Path: '/'>
[31m[1mERROR   [0m tavern.response.base:base.py:41 Error calling validate function '<function validate_pykwalify at 0x7f24c2db9820>':
    Traceback (most recent call last):
      File "/usr/lib/python3.9/site-packages/tavern/schemas/files.py", line 106, in verify_generic
        verifier.validate()
      File "/usr/lib/python3.9/site-packages/pykwalify/core.py", line 194, in validate
        raise SchemaError(u"Schema validation failed:\n - {error_msg}.".format(
    pykwalify.errors.SchemaError: <SchemaError: error code 2: Schema validation failed:
     - Key 'off' was not defined. Path: ''.: Path: '/'>

    The above exception was the direct cause of the following exception:

    Traceback (most recent call last):
      File "/usr/lib/python3.9/site-packages/tavern/response/base.py", line 152, in _maybe_run_validate_functions
        vf(response)
      File "/usr/lib/python3.9/site-packages/tavern/util/extfunctions.py", line 98, in inner
        result = func(response, *args, **kwargs)
      File "/usr/lib/python3.9/site-packages/tavern/testutils/helpers.py", line 103, in validate_pykwalify
        verify_generic(to_verify, schema)
      File "/usr/lib/python3.9/site-packages/tavern/schemas/files.py", line 109, in verify_generic
        raise BadSchemaError() from e
    tavern.util.exceptions.BadSchemaError
Traceback (most recent call last):
  File "/usr/lib/python3.9/site-packages/tavern/schemas/files.py", line 106, in verify_generic
    verifier.validate()
  File "/usr/lib/python3.9/site-packages/pykwalify/core.py", line 194, in validate
    raise SchemaError(u"Schema validation failed:\n - {error_msg}.".format(
pykwalify.errors.SchemaError: <SchemaError: error code 2: Schema validation failed:
 - Key 'off' was not defined. Path: ''.: Path: '/'>

The above exception was the direct cause of the following exception:

Traceback (most recent call last):
  File "/usr/lib/python3.9/site-packages/tavern/response/base.py", line 152, in _maybe_run_validate_functions
    vf(response)
  File "/usr/lib/python3.9/site-packages/tavern/util/extfunctions.py", line 98, in inner
    result = func(response, *args, **kwargs)
  File "/usr/lib/python3.9/site-packages/tavern/testutils/helpers.py", line 103, in validate_pykwalify
    verify_generic(to_verify, schema)
  File "/usr/lib/python3.9/site-packages/tavern/schemas/files.py", line 109, in verify_generic
    raise BadSchemaError() from e
tavern.util.exceptions.BadSchemaError
[31m[1mERROR   [0m pykwalify.core:core.py:190 validation.invalid
[31m[1mERROR   [0m pykwalify.core:core.py:191  --- All found errors ---
[31m[1mERROR   [0m pykwalify.core:core.py:192 ["Key 'off' was not defined. Path: ''"]
[31m[1mERROR   [0m tavern.schemas.files:files.py:108 Error validating {'e': 0, 'err_msg': '', 'off': ['x3000c0s6b0n0'], 'on': ['x1000c0s4b1n0']}
Traceback (most recent call last):
  File "/usr/lib/python3.9/site-packages/tavern/schemas/files.py", line 106, in verify_generic
    verifier.validate()
  File "/usr/lib/python3.9/site-packages/pykwalify/core.py", line 194, in validate
    raise SchemaError(u"Schema validation failed:\n - {error_msg}.".format(
pykwalify.errors.SchemaError: <SchemaError: error code 2: Schema validation failed:
 - Key 'off' was not defined. Path: ''.: Path: '/'>
[31m[1mERROR   [0m tavern.response.base:base.py:41 Error calling validate function '<function validate_pykwalify at 0x7f24c2db9820>':
    Traceback (most recent call last):
      File "/usr/lib/python3.9/site-packages/tavern/schemas/files.py", line 106, in verify_generic
        verifier.validate()
      File "/usr/lib/python3.9/site-packages/pykwalify/core.py", line 194, in validate
        raise SchemaError(u"Schema validation failed:\n - {error_msg}.".format(
    pykwalify.errors.SchemaError: <SchemaError: error code 2: Schema validation failed:
     - Key 'off' was not defined. Path: ''.: Path: '/'>

    The above exception was the direct cause of the following exception:

    Traceback (most recent call last):
      File "/usr/lib/python3.9/site-packages/tavern/response/base.py", line 152, in _maybe_run_validate_functions
        vf(response)
      File "/usr/lib/python3.9/site-packages/tavern/util/extfunctions.py", line 98, in inner
        result = func(response, *args, **kwargs)
      File "/usr/lib/python3.9/site-packages/tavern/testutils/helpers.py", line 103, in validate_pykwalify
        verify_generic(to_verify, schema)
      File "/usr/lib/python3.9/site-packages/tavern/schemas/files.py", line 109, in verify_generic
        raise BadSchemaError() from e
    tavern.util.exceptions.BadSchemaError
Traceback (most recent call last):
  File "/usr/lib/python3.9/site-packages/tavern/schemas/files.py", line 106, in verify_generic
    verifier.validate()
  File "/usr/lib/python3.9/site-packages/pykwalify/core.py", line 194, in validate
    raise SchemaError(u"Schema validation failed:\n - {error_msg}.".format(
pykwalify.errors.SchemaError: <SchemaError: error code 2: Schema validation failed:
 - Key 'off' was not defined. Path: ''.: Path: '/'>

The above exception was the direct cause of the following exception:

Traceback (most recent call last):
  File "/usr/lib/python3.9/site-packages/tavern/response/base.py", line 152, in _maybe_run_validate_functions
    vf(response)
  File "/usr/lib/python3.9/site-packages/tavern/util/extfunctions.py", line 98, in inner
    result = func(response, *args, **kwargs)
  File "/usr/lib/python3.9/site-packages/tavern/testutils/helpers.py", line 103, in validate_pykwalify
    verify_generic(to_verify, schema)
  File "/usr/lib/python3.9/site-packages/tavern/schemas/files.py", line 109, in verify_generic
    raise BadSchemaError() from e
tavern.util.exceptions.BadSchemaError
[31m[1mERROR   [0m pykwalify.core:core.py:190 validation.invalid
[31m[1mERROR   [0m pykwalify.core:core.py:191  --- All found errors ---
[31m[1mERROR   [0m pykwalify.core:core.py:192 ["Key 'off' was not defined. Path: ''"]
[31m[1mERROR   [0m tavern.schemas.files:files.py:108 Error validating {'e': 0, 'err_msg': '', 'off': ['x3000c0s6b0n0'], 'on': ['x1000c0s4b1n0']}
Traceback (most recent call last):
  File "/usr/lib/python3.9/site-packages/tavern/schemas/files.py", line 106, in verify_generic
    verifier.validate()
  File "/usr/lib/python3.9/site-packages/pykwalify/core.py", line 194, in validate
    raise SchemaError(u"Schema validation failed:\n - {error_msg}.".format(
pykwalify.errors.SchemaError: <SchemaError: error code 2: Schema validation failed:
 - Key 'off' was not defined. Path: ''.: Path: '/'>
[31m[1mERROR   [0m tavern.response.base:base.py:41 Error calling validate function '<function validate_pykwalify at 0x7f24c2db9820>':
    Traceback (most recent call last):
      File "/usr/lib/python3.9/site-packages/tavern/schemas/files.py", line 106, in verify_generic
        verifier.validate()
      File "/usr/lib/python3.9/site-packages/pykwalify/core.py", line 194, in validate
        raise SchemaError(u"Schema validation failed:\n - {error_msg}.".format(
    pykwalify.errors.SchemaError: <SchemaError: error code 2: Schema validation failed:
     - Key 'off' was not defined. Path: ''.: Path: '/'>

    The above exception was the direct cause of the following exception:

    Traceback (most recent call last):
      File "/usr/lib/python3.9/site-packages/tavern/response/base.py", line 152, in _maybe_run_validate_functions
        vf(response)
      File "/usr/lib/python3.9/site-packages/tavern/util/extfunctions.py", line 98, in inner
        result = func(response, *args, **kwargs)
      File "/usr/lib/python3.9/site-packages/tavern/testutils/helpers.py", line 103, in validate_pykwalify
        verify_generic(to_verify, schema)
      File "/usr/lib/python3.9/site-packages/tavern/schemas/files.py", line 109, in verify_generic
        raise BadSchemaError() from e
    tavern.util.exceptions.BadSchemaError
Traceback (most recent call last):
  File "/usr/lib/python3.9/site-packages/tavern/schemas/files.py", line 106, in verify_generic
    verifier.validate()
  File "/usr/lib/python3.9/site-packages/pykwalify/core.py", line 194, in validate
    raise SchemaError(u"Schema validation failed:\n - {error_msg}.".format(
pykwalify.errors.SchemaError: <SchemaError: error code 2: Schema validation failed:
 - Key 'off' was not defined. Path: ''.: Path: '/'>

The above exception was the direct cause of the following exception:

Traceback (most recent call last):
  File "/usr/lib/python3.9/site-packages/tavern/response/base.py", line 152, in _maybe_run_validate_functions
    vf(response)
  File "/usr/lib/python3.9/site-packages/tavern/util/extfunctions.py", line 98, in inner
    result = func(response, *args, **kwargs)
  File "/usr/lib/python3.9/site-packages/tavern/testutils/helpers.py", line 103, in validate_pykwalify
    verify_generic(to_verify, schema)
  File "/usr/lib/python3.9/site-packages/tavern/schemas/files.py", line 109, in verify_generic
    raise BadSchemaError() from e
tavern.util.exceptions.BadSchemaError
[31m[1mERROR   [0m pykwalify.core:core.py:190 validation.invalid
[31m[1mERROR   [0m pykwalify.core:core.py:191  --- All found errors ---
[31m[1mERROR   [0m pykwalify.core:core.py:192 ["Key 'off' was not defined. Path: ''"]
[31m[1mERROR   [0m tavern.schemas.files:files.py:108 Error validating {'e': 0, 'err_msg': '', 'off': ['x3000c0s6b0n0'], 'on': ['x1000c0s4b1n0']}
Traceback (most recent call last):
  File "/usr/lib/python3.9/site-packages/tavern/schemas/files.py", line 106, in verify_generic
    verifier.validate()
  File "/usr/lib/python3.9/site-packages/pykwalify/core.py", line 194, in validate
    raise SchemaError(u"Schema validation failed:\n - {error_msg}.".format(
pykwalify.errors.SchemaError: <SchemaError: error code 2: Schema validation failed:
 - Key 'off' was not defined. Path: ''.: Path: '/'>
[31m[1mERROR   [0m tavern.response.base:base.py:41 Error calling validate function '<function validate_pykwalify at 0x7f24c2db9820>':
    Traceback (most recent call last):
      File "/usr/lib/python3.9/site-packages/tavern/schemas/files.py", line 106, in verify_generic
        verifier.validate()
      File "/usr/lib/python3.9/site-packages/pykwalify/core.py", line 194, in validate
        raise SchemaError(u"Schema validation failed:\n - {error_msg}.".format(
    pykwalify.errors.SchemaError: <SchemaError: error code 2: Schema validation failed:
     - Key 'off' was not defined. Path: ''.: Path: '/'>

    The above exception was the direct cause of the following exception:

    Traceback (most recent call last):
      File "/usr/lib/python3.9/site-packages/tavern/response/base.py", line 152, in _maybe_run_validate_functions
        vf(response)
      File "/usr/lib/python3.9/site-packages/tavern/util/extfunctions.py", line 98, in inner
        result = func(response, *args, **kwargs)
      File "/usr/lib/python3.9/site-packages/tavern/testutils/helpers.py", line 103, in validate_pykwalify
        verify_generic(to_verify, schema)
      File "/usr/lib/python3.9/site-packages/tavern/schemas/files.py", line 109, in verify_generic
        raise BadSchemaError() from e
    tavern.util.exceptions.BadSchemaError
Traceback (most recent call last):
  File "/usr/lib/python3.9/site-packages/tavern/schemas/files.py", line 106, in verify_generic
    verifier.validate()
  File "/usr/lib/python3.9/site-packages/pykwalify/core.py", line 194, in validate
    raise SchemaError(u"Schema validation failed:\n - {error_msg}.".format(
pykwalify.errors.SchemaError: <SchemaError: error code 2: Schema validation failed:
 - Key 'off' was not defined. Path: ''.: Path: '/'>

The above exception was the direct cause of the following exception:

Traceback (most recent call last):
  File "/usr/lib/python3.9/site-packages/tavern/response/base.py", line 152, in _maybe_run_validate_functions
    vf(response)
  File "/usr/lib/python3.9/site-packages/tavern/util/extfunctions.py", line 98, in inner
    result = func(response, *args, **kwargs)
  File "/usr/lib/python3.9/site-packages/tavern/testutils/helpers.py", line 103, in validate_pykwalify
    verify_generic(to_verify, schema)
  File "/usr/lib/python3.9/site-packages/tavern/schemas/files.py", line 109, in verify_generic
    raise BadSchemaError() from e
tavern.util.exceptions.BadSchemaError
[31m[1mERROR   [0m pykwalify.core:core.py:190 validation.invalid
[31m[1mERROR   [0m pykwalify.core:core.py:191  --- All found errors ---
[31m[1mERROR   [0m pykwalify.core:core.py:192 ["Key 'off' was not defined. Path: ''"]
[31m[1mERROR   [0m tavern.schemas.files:files.py:108 Error validating {'e': 0, 'err_msg': '', 'off': ['x3000c0s6b0n0'], 'on': ['x1000c0s4b1n0']}
Traceback (most recent call last):
  File "/usr/lib/python3.9/site-packages/tavern/schemas/files.py", line 106, in verify_generic
    verifier.validate()
  File "/usr/lib/python3.9/site-packages/pykwalify/core.py", line 194, in validate
    raise SchemaError(u"Schema validation failed:\n - {error_msg}.".format(
pykwalify.errors.SchemaError: <SchemaError: error code 2: Schema validation failed:
 - Key 'off' was not defined. Path: ''.: Path: '/'>
[31m[1mERROR   [0m tavern.response.base:base.py:41 Error calling validate function '<function validate_pykwalify at 0x7f24c2db9820>':
    Traceback (most recent call last):
      File "/usr/lib/python3.9/site-packages/tavern/schemas/files.py", line 106, in verify_generic
        verifier.validate()
      File "/usr/lib/python3.9/site-packages/pykwalify/core.py", line 194, in validate
        raise SchemaError(u"Schema validation failed:\n - {error_msg}.".format(
    pykwalify.errors.SchemaError: <SchemaError: error code 2: Schema validation failed:
     - Key 'off' was not defined. Path: ''.: Path: '/'>

    The above exception was the direct cause of the following exception:

    Traceback (most recent call last):
      File "/usr/lib/python3.9/site-packages/tavern/response/base.py", line 152, in _maybe_run_validate_functions
        vf(response)
      File "/usr/lib/python3.9/site-packages/tavern/util/extfunctions.py", line 98, in inner
        result = func(response, *args, **kwargs)
      File "/usr/lib/python3.9/site-packages/tavern/testutils/helpers.py", line 103, in validate_pykwalify
        verify_generic(to_verify, schema)
      File "/usr/lib/python3.9/site-packages/tavern/schemas/files.py", line 109, in verify_generic
        raise BadSchemaError() from e
    tavern.util.exceptions.BadSchemaError
Traceback (most recent call last):
  File "/usr/lib/python3.9/site-packages/tavern/schemas/files.py", line 106, in verify_generic
    verifier.validate()
  File "/usr/lib/python3.9/site-packages/pykwalify/core.py", line 194, in validate
    raise SchemaError(u"Schema validation failed:\n - {error_msg}.".format(
pykwalify.errors.SchemaError: <SchemaError: error code 2: Schema validation failed:
 - Key 'off' was not defined. Path: ''.: Path: '/'>

The above exception was the direct cause of the following exception:

Traceback (most recent call last):
  File "/usr/lib/python3.9/site-packages/tavern/response/base.py", line 152, in _maybe_run_validate_functions
    vf(response)
  File "/usr/lib/python3.9/site-packages/tavern/util/extfunctions.py", line 98, in inner
    result = func(response, *args, **kwargs)
  File "/usr/lib/python3.9/site-packages/tavern/testutils/helpers.py", line 103, in validate_pykwalify
    verify_generic(to_verify, schema)
  File "/usr/lib/python3.9/site-packages/tavern/schemas/files.py", line 109, in verify_generic
    raise BadSchemaError() from e
tavern.util.exceptions.BadSchemaError
[31m[1mERROR   [0m pykwalify.core:core.py:190 validation.invalid
[31m[1mERROR   [0m pykwalify.core:core.py:191  --- All found errors ---
[31m[1mERROR   [0m pykwalify.core:core.py:192 ["Key 'off' was not defined. Path: ''"]
[31m[1mERROR   [0m tavern.schemas.files:files.py:108 Error validating {'e': 0, 'err_msg': '', 'off': ['x3000c0s6b0n0'], 'on': ['x1000c0s4b1n0']}
Traceback (most recent call last):
  File "/usr/lib/python3.9/site-packages/tavern/schemas/files.py", line 106, in verify_generic
    verifier.validate()
  File "/usr/lib/python3.9/site-packages/pykwalify/core.py", line 194, in validate
    raise SchemaError(u"Schema validation failed:\n - {error_msg}.".format(
pykwalify.errors.SchemaError: <SchemaError: error code 2: Schema validation failed:
 - Key 'off' was not defined. Path: ''.: Path: '/'>
[31m[1mERROR   [0m tavern.response.base:base.py:41 Error calling validate function '<function validate_pykwalify at 0x7f24c2db9820>':
    Traceback (most recent call last):
      File "/usr/lib/python3.9/site-packages/tavern/schemas/files.py", line 106, in verify_generic
        verifier.validate()
      File "/usr/lib/python3.9/site-packages/pykwalify/core.py", line 194, in validate
        raise SchemaError(u"Schema validation failed:\n - {error_msg}.".format(
    pykwalify.errors.SchemaError: <SchemaError: error code 2: Schema validation failed:
     - Key 'off' was not defined. Path: ''.: Path: '/'>

    The above exception was the direct cause of the following exception:

    Traceback (most recent call last):
      File "/usr/lib/python3.9/site-packages/tavern/response/base.py", line 152, in _maybe_run_validate_functions
        vf(response)
      File "/usr/lib/python3.9/site-packages/tavern/util/extfunctions.py", line 98, in inner
        result = func(response, *args, **kwargs)
      File "/usr/lib/python3.9/site-packages/tavern/testutils/helpers.py", line 103, in validate_pykwalify
        verify_generic(to_verify, schema)
      File "/usr/lib/python3.9/site-packages/tavern/schemas/files.py", line 109, in verify_generic
        raise BadSchemaError() from e
    tavern.util.exceptions.BadSchemaError
Traceback (most recent call last):
  File "/usr/lib/python3.9/site-packages/tavern/schemas/files.py", line 106, in verify_generic
    verifier.validate()
  File "/usr/lib/python3.9/site-packages/pykwalify/core.py", line 194, in validate
    raise SchemaError(u"Schema validation failed:\n - {error_msg}.".format(
pykwalify.errors.SchemaError: <SchemaError: error code 2: Schema validation failed:
 - Key 'off' was not defined. Path: ''.: Path: '/'>

The above exception was the direct cause of the following exception:

Traceback (most recent call last):
  File "/usr/lib/python3.9/site-packages/tavern/response/base.py", line 152, in _maybe_run_validate_functions
    vf(response)
  File "/usr/lib/python3.9/site-packages/tavern/util/extfunctions.py", line 98, in inner
    result = func(response, *args, **kwargs)
  File "/usr/lib/python3.9/site-packages/tavern/testutils/helpers.py", line 103, in validate_pykwalify
    verify_generic(to_verify, schema)
  File "/usr/lib/python3.9/site-packages/tavern/schemas/files.py", line 109, in verify_generic
    raise BadSchemaError() from e
tavern.util.exceptions.BadSchemaError
[31m[1mERROR   [0m pykwalify.core:core.py:190 validation.invalid
[31m[1mERROR   [0m pykwalify.core:core.py:191  --- All found errors ---
[31m[1mERROR   [0m pykwalify.core:core.py:192 ["Key 'off' was not defined. Path: ''"]
[31m[1mERROR   [0m tavern.schemas.files:files.py:108 Error validating {'e': 0, 'err_msg': '', 'off': ['x3000c0s6b0n0'], 'on': ['x1000c0s4b1n0']}
Traceback (most recent call last):
  File "/usr/lib/python3.9/site-packages/tavern/schemas/files.py", line 106, in verify_generic
    verifier.validate()
  File "/usr/lib/python3.9/site-packages/pykwalify/core.py", line 194, in validate
    raise SchemaError(u"Schema validation failed:\n - {error_msg}.".format(
pykwalify.errors.SchemaError: <SchemaError: error code 2: Schema validation failed:
 - Key 'off' was not defined. Path: ''.: Path: '/'>
[31m[1mERROR   [0m tavern.response.base:base.py:41 Error calling validate function '<function validate_pykwalify at 0x7f24c2db9820>':
    Traceback (most recent call last):
      File "/usr/lib/python3.9/site-packages/tavern/schemas/files.py", line 106, in verify_generic
        verifier.validate()
      File "/usr/lib/python3.9/site-packages/pykwalify/core.py", line 194, in validate
        raise SchemaError(u"Schema validation failed:\n - {error_msg}.".format(
    pykwalify.errors.SchemaError: <SchemaError: error code 2: Schema validation failed:
     - Key 'off' was not defined. Path: ''.: Path: '/'>

    The above exception was the direct cause of the following exception:

    Traceback (most recent call last):
      File "/usr/lib/python3.9/site-packages/tavern/response/base.py", line 152, in _maybe_run_validate_functions
        vf(response)
      File "/usr/lib/python3.9/site-packages/tavern/util/extfunctions.py", line 98, in inner
        result = func(response, *args, **kwargs)
      File "/usr/lib/python3.9/site-packages/tavern/testutils/helpers.py", line 103, in validate_pykwalify
        verify_generic(to_verify, schema)
      File "/usr/lib/python3.9/site-packages/tavern/schemas/files.py", line 109, in verify_generic
        raise BadSchemaError() from e
    tavern.util.exceptions.BadSchemaError
Traceback (most recent call last):
  File "/usr/lib/python3.9/site-packages/tavern/schemas/files.py", line 106, in verify_generic
    verifier.validate()
  File "/usr/lib/python3.9/site-packages/pykwalify/core.py", line 194, in validate
    raise SchemaError(u"Schema validation failed:\n - {error_msg}.".format(
pykwalify.errors.SchemaError: <SchemaError: error code 2: Schema validation failed:
 - Key 'off' was not defined. Path: ''.: Path: '/'>

The above exception was the direct cause of the following exception:

Traceback (most recent call last):
  File "/usr/lib/python3.9/site-packages/tavern/response/base.py", line 152, in _maybe_run_validate_functions
    vf(response)
  File "/usr/lib/python3.9/site-packages/tavern/util/extfunctions.py", line 98, in inner
    result = func(response, *args, **kwargs)
  File "/usr/lib/python3.9/site-packages/tavern/testutils/helpers.py", line 103, in validate_pykwalify
    verify_generic(to_verify, schema)
  File "/usr/lib/python3.9/site-packages/tavern/schemas/files.py", line 109, in verify_generic
    raise BadSchemaError() from e
tavern.util.exceptions.BadSchemaError
[31m[1mERROR   [0m pykwalify.core:core.py:190 validation.invalid
[31m[1mERROR   [0m pykwalify.core:core.py:191  --- All found errors ---
[31m[1mERROR   [0m pykwalify.core:core.py:192 ["Key 'off' was not defined. Path: ''"]
[31m[1mERROR   [0m tavern.schemas.files:files.py:108 Error validating {'e': 0, 'err_msg': '', 'off': ['x3000c0s6b0n0'], 'on': ['x1000c0s4b1n0']}
Traceback (most recent call last):
  File "/usr/lib/python3.9/site-packages/tavern/schemas/files.py", line 106, in verify_generic
    verifier.validate()
  File "/usr/lib/python3.9/site-packages/pykwalify/core.py", line 194, in validate
    raise SchemaError(u"Schema validation failed:\n - {error_msg}.".format(
pykwalify.errors.SchemaError: <SchemaError: error code 2: Schema validation failed:
 - Key 'off' was not defined. Path: ''.: Path: '/'>
[31m[1mERROR   [0m tavern.response.base:base.py:41 Error calling validate function '<function validate_pykwalify at 0x7f24c2db9820>':
    Traceback (most recent call last):
      File "/usr/lib/python3.9/site-packages/tavern/schemas/files.py", line 106, in verify_generic
        verifier.validate()
      File "/usr/lib/python3.9/site-packages/pykwalify/core.py", line 194, in validate
        raise SchemaError(u"Schema validation failed:\n - {error_msg}.".format(
    pykwalify.errors.SchemaError: <SchemaError: error code 2: Schema validation failed:
     - Key 'off' was not defined. Path: ''.: Path: '/'>

    The above exception was the direct cause of the following exception:

    Traceback (most recent call last):
      File "/usr/lib/python3.9/site-packages/tavern/response/base.py", line 152, in _maybe_run_validate_functions
        vf(response)
      File "/usr/lib/python3.9/site-packages/tavern/util/extfunctions.py", line 98, in inner
        result = func(response, *args, **kwargs)
      File "/usr/lib/python3.9/site-packages/tavern/testutils/helpers.py", line 103, in validate_pykwalify
        verify_generic(to_verify, schema)
      File "/usr/lib/python3.9/site-packages/tavern/schemas/files.py", line 109, in verify_generic
        raise BadSchemaError() from e
    tavern.util.exceptions.BadSchemaError
Traceback (most recent call last):
  File "/usr/lib/python3.9/site-packages/tavern/schemas/files.py", line 106, in verify_generic
    verifier.validate()
  File "/usr/lib/python3.9/site-packages/pykwalify/core.py", line 194, in validate
    raise SchemaError(u"Schema validation failed:\n - {error_msg}.".format(
pykwalify.errors.SchemaError: <SchemaError: error code 2: Schema validation failed:
 - Key 'off' was not defined. Path: ''.: Path: '/'>

The above exception was the direct cause of the following exception:

Traceback (most recent call last):
  File "/usr/lib/python3.9/site-packages/tavern/response/base.py", line 152, in _maybe_run_validate_functions
    vf(response)
  File "/usr/lib/python3.9/site-packages/tavern/util/extfunctions.py", line 98, in inner
    result = func(response, *args, **kwargs)
  File "/usr/lib/python3.9/site-packages/tavern/testutils/helpers.py", line 103, in validate_pykwalify
    verify_generic(to_verify, schema)
  File "/usr/lib/python3.9/site-packages/tavern/schemas/files.py", line 109, in verify_generic
    raise BadSchemaError() from e
tavern.util.exceptions.BadSchemaError
[31m[1mERROR   [0m pykwalify.core:core.py:190 validation.invalid
[31m[1mERROR   [0m pykwalify.core:core.py:191  --- All found errors ---
[31m[1mERROR   [0m pykwalify.core:core.py:192 ["Key 'off' was not defined. Path: ''"]
[31m[1mERROR   [0m tavern.schemas.files:files.py:108 Error validating {'e': 0, 'err_msg': '', 'off': ['x3000c0s6b0n0'], 'on': ['x1000c0s4b1n0']}
Traceback (most recent call last):
  File "/usr/lib/python3.9/site-packages/tavern/schemas/files.py", line 106, in verify_generic
    verifier.validate()
  File "/usr/lib/python3.9/site-packages/pykwalify/core.py", line 194, in validate
    raise SchemaError(u"Schema validation failed:\n - {error_msg}.".format(
pykwalify.errors.SchemaError: <SchemaError: error code 2: Schema validation failed:
 - Key 'off' was not defined. Path: ''.: Path: '/'>
[31m[1mERROR   [0m tavern.response.base:base.py:41 Error calling validate function '<function validate_pykwalify at 0x7f24c2db9820>':
    Traceback (most recent call last):
      File "/usr/lib/python3.9/site-packages/tavern/schemas/files.py", line 106, in verify_generic
        verifier.validate()
      File "/usr/lib/python3.9/site-packages/pykwalify/core.py", line 194, in validate
        raise SchemaError(u"Schema validation failed:\n - {error_msg}.".format(
    pykwalify.errors.SchemaError: <SchemaError: error code 2: Schema validation failed:
     - Key 'off' was not defined. Path: ''.: Path: '/'>

    The above exception was the direct cause of the following exception:

    Traceback (most recent call last):
      File "/usr/lib/python3.9/site-packages/tavern/response/base.py", line 152, in _maybe_run_validate_functions
        vf(response)
      File "/usr/lib/python3.9/site-packages/tavern/util/extfunctions.py", line 98, in inner
        result = func(response, *args, **kwargs)
      File "/usr/lib/python3.9/site-packages/tavern/testutils/helpers.py", line 103, in validate_pykwalify
        verify_generic(to_verify, schema)
      File "/usr/lib/python3.9/site-packages/tavern/schemas/files.py", line 109, in verify_generic
        raise BadSchemaError() from e
    tavern.util.exceptions.BadSchemaError
Traceback (most recent call last):
  File "/usr/lib/python3.9/site-packages/tavern/schemas/files.py", line 106, in verify_generic
    verifier.validate()
  File "/usr/lib/python3.9/site-packages/pykwalify/core.py", line 194, in validate
    raise SchemaError(u"Schema validation failed:\n - {error_msg}.".format(
pykwalify.errors.SchemaError: <SchemaError: error code 2: Schema validation failed:
 - Key 'off' was not defined. Path: ''.: Path: '/'>

The above exception was the direct cause of the following exception:

Traceback (most recent call last):
  File "/usr/lib/python3.9/site-packages/tavern/response/base.py", line 152, in _maybe_run_validate_functions
    vf(response)
  File "/usr/lib/python3.9/site-packages/tavern/util/extfunctions.py", line 98, in inner
    result = func(response, *args, **kwargs)
  File "/usr/lib/python3.9/site-packages/tavern/testutils/helpers.py", line 103, in validate_pykwalify
    verify_generic(to_verify, schema)
  File "/usr/lib/python3.9/site-packages/tavern/schemas/files.py", line 109, in verify_generic
    raise BadSchemaError() from e
tavern.util.exceptions.BadSchemaError
[31m[1mERROR   [0m pykwalify.core:core.py:190 validation.invalid
[31m[1mERROR   [0m pykwalify.core:core.py:191  --- All found errors ---
[31m[1mERROR   [0m pykwalify.core:core.py:192 ["Key 'off' was not defined. Path: ''"]
[31m[1mERROR   [0m tavern.schemas.files:files.py:108 Error validating {'e': 0, 'err_msg': '', 'off': ['x3000c0s6b0n0'], 'on': ['x1000c0s4b1n0']}
Traceback (most recent call last):
  File "/usr/lib/python3.9/site-packages/tavern/schemas/files.py", line 106, in verify_generic
    verifier.validate()
  File "/usr/lib/python3.9/site-packages/pykwalify/core.py", line 194, in validate
    raise SchemaError(u"Schema validation failed:\n - {error_msg}.".format(
pykwalify.errors.SchemaError: <SchemaError: error code 2: Schema validation failed:
 - Key 'off' was not defined. Path: ''.: Path: '/'>
[31m[1mERROR   [0m tavern.response.base:base.py:41 Error calling validate function '<function validate_pykwalify at 0x7f24c2db9820>':
    Traceback (most recent call last):
      File "/usr/lib/python3.9/site-packages/tavern/schemas/files.py", line 106, in verify_generic
        verifier.validate()
      File "/usr/lib/python3.9/site-packages/pykwalify/core.py", line 194, in validate
        raise SchemaError(u"Schema validation failed:\n - {error_msg}.".format(
    pykwalify.errors.SchemaError: <SchemaError: error code 2: Schema validation failed:
     - Key 'off' was not defined. Path: ''.: Path: '/'>

    The above exception was the direct cause of the following exception:

    Traceback (most recent call last):
      File "/usr/lib/python3.9/site-packages/tavern/response/base.py", line 152, in _maybe_run_validate_functions
        vf(response)
      File "/usr/lib/python3.9/site-packages/tavern/util/extfunctions.py", line 98, in inner
        result = func(response, *args, **kwargs)
      File "/usr/lib/python3.9/site-packages/tavern/testutils/helpers.py", line 103, in validate_pykwalify
        verify_generic(to_verify, schema)
      File "/usr/lib/python3.9/site-packages/tavern/schemas/files.py", line 109, in verify_generic
        raise BadSchemaError() from e
    tavern.util.exceptions.BadSchemaError
Traceback (most recent call last):
  File "/usr/lib/python3.9/site-packages/tavern/schemas/files.py", line 106, in verify_generic
    verifier.validate()
  File "/usr/lib/python3.9/site-packages/pykwalify/core.py", line 194, in validate
    raise SchemaError(u"Schema validation failed:\n - {error_msg}.".format(
pykwalify.errors.SchemaError: <SchemaError: error code 2: Schema validation failed:
 - Key 'off' was not defined. Path: ''.: Path: '/'>

The above exception was the direct cause of the following exception:

Traceback (most recent call last):
  File "/usr/lib/python3.9/site-packages/tavern/response/base.py", line 152, in _maybe_run_validate_functions
    vf(response)
  File "/usr/lib/python3.9/site-packages/tavern/util/extfunctions.py", line 98, in inner
    result = func(response, *args, **kwargs)
  File "/usr/lib/python3.9/site-packages/tavern/testutils/helpers.py", line 103, in validate_pykwalify
    verify_generic(to_verify, schema)
  File "/usr/lib/python3.9/site-packages/tavern/schemas/files.py", line 109, in verify_generic
    raise BadSchemaError() from e
tavern.util.exceptions.BadSchemaError
[31m[1mERROR   [0m pykwalify.core:core.py:190 validation.invalid
[31m[1mERROR   [0m pykwalify.core:core.py:191  --- All found errors ---
[31m[1mERROR   [0m pykwalify.core:core.py:192 ["Key 'off' was not defined. Path: ''"]
[31m[1mERROR   [0m tavern.schemas.files:files.py:108 Error validating {'e': 0, 'err_msg': '', 'off': ['x3000c0s6b0n0'], 'on': ['x1000c0s4b1n0']}
Traceback (most recent call last):
  File "/usr/lib/python3.9/site-packages/tavern/schemas/files.py", line 106, in verify_generic
    verifier.validate()
  File "/usr/lib/python3.9/site-packages/pykwalify/core.py", line 194, in validate
    raise SchemaError(u"Schema validation failed:\n - {error_msg}.".format(
pykwalify.errors.SchemaError: <SchemaError: error code 2: Schema validation failed:
 - Key 'off' was not defined. Path: ''.: Path: '/'>
[31m[1mERROR   [0m tavern.response.base:base.py:41 Error calling validate function '<function validate_pykwalify at 0x7f24c2db9820>':
    Traceback (most recent call last):
      File "/usr/lib/python3.9/site-packages/tavern/schemas/files.py", line 106, in verify_generic
        verifier.validate()
      File "/usr/lib/python3.9/site-packages/pykwalify/core.py", line 194, in validate
        raise SchemaError(u"Schema validation failed:\n - {error_msg}.".format(
    pykwalify.errors.SchemaError: <SchemaError: error code 2: Schema validation failed:
     - Key 'off' was not defined. Path: ''.: Path: '/'>

    The above exception was the direct cause of the following exception:

    Traceback (most recent call last):
      File "/usr/lib/python3.9/site-packages/tavern/response/base.py", line 152, in _maybe_run_validate_functions
        vf(response)
      File "/usr/lib/python3.9/site-packages/tavern/util/extfunctions.py", line 98, in inner
        result = func(response, *args, **kwargs)
      File "/usr/lib/python3.9/site-packages/tavern/testutils/helpers.py", line 103, in validate_pykwalify
        verify_generic(to_verify, schema)
      File "/usr/lib/python3.9/site-packages/tavern/schemas/files.py", line 109, in verify_generic
        raise BadSchemaError() from e
    tavern.util.exceptions.BadSchemaError
Traceback (most recent call last):
  File "/usr/lib/python3.9/site-packages/tavern/schemas/files.py", line 106, in verify_generic
    verifier.validate()
  File "/usr/lib/python3.9/site-packages/pykwalify/core.py", line 194, in validate
    raise SchemaError(u"Schema validation failed:\n - {error_msg}.".format(
pykwalify.errors.SchemaError: <SchemaError: error code 2: Schema validation failed:
 - Key 'off' was not defined. Path: ''.: Path: '/'>

The above exception was the direct cause of the following exception:

Traceback (most recent call last):
  File "/usr/lib/python3.9/site-packages/tavern/response/base.py", line 152, in _maybe_run_validate_functions
    vf(response)
  File "/usr/lib/python3.9/site-packages/tavern/util/extfunctions.py", line 98, in inner
    result = func(response, *args, **kwargs)
  File "/usr/lib/python3.9/site-packages/tavern/testutils/helpers.py", line 103, in validate_pykwalify
    verify_generic(to_verify, schema)
  File "/usr/lib/python3.9/site-packages/tavern/schemas/files.py", line 109, in verify_generic
    raise BadSchemaError() from e
tavern.util.exceptions.BadSchemaError
[31m[1mERROR   [0m pykwalify.core:core.py:190 validation.invalid
[31m[1mERROR   [0m pykwalify.core:core.py:191  --- All found errors ---
[31m[1mERROR   [0m pykwalify.core:core.py:192 ["Key 'off' was not defined. Path: ''"]
[31m[1mERROR   [0m tavern.schemas.files:files.py:108 Error validating {'e': 0, 'err_msg': '', 'off': ['x3000c0s6b0n0'], 'on': ['x1000c0s4b1n0']}
Traceback (most recent call last):
  File "/usr/lib/python3.9/site-packages/tavern/schemas/files.py", line 106, in verify_generic
    verifier.validate()
  File "/usr/lib/python3.9/site-packages/pykwalify/core.py", line 194, in validate
    raise SchemaError(u"Schema validation failed:\n - {error_msg}.".format(
pykwalify.errors.SchemaError: <SchemaError: error code 2: Schema validation failed:
 - Key 'off' was not defined. Path: ''.: Path: '/'>
[31m[1mERROR   [0m tavern.response.base:base.py:41 Error calling validate function '<function validate_pykwalify at 0x7f24c2db9820>':
    Traceback (most recent call last):
      File "/usr/lib/python3.9/site-packages/tavern/schemas/files.py", line 106, in verify_generic
        verifier.validate()
      File "/usr/lib/python3.9/site-packages/pykwalify/core.py", line 194, in validate
        raise SchemaError(u"Schema validation failed:\n - {error_msg}.".format(
    pykwalify.errors.SchemaError: <SchemaError: error code 2: Schema validation failed:
     - Key 'off' was not defined. Path: ''.: Path: '/'>

    The above exception was the direct cause of the following exception:

    Traceback (most recent call last):
      File "/usr/lib/python3.9/site-packages/tavern/response/base.py", line 152, in _maybe_run_validate_functions
        vf(response)
      File "/usr/lib/python3.9/site-packages/tavern/util/extfunctions.py", line 98, in inner
        result = func(response, *args, **kwargs)
      File "/usr/lib/python3.9/site-packages/tavern/testutils/helpers.py", line 103, in validate_pykwalify
        verify_generic(to_verify, schema)
      File "/usr/lib/python3.9/site-packages/tavern/schemas/files.py", line 109, in verify_generic
        raise BadSchemaError() from e
    tavern.util.exceptions.BadSchemaError
Traceback (most recent call last):
  File "/usr/lib/python3.9/site-packages/tavern/schemas/files.py", line 106, in verify_generic
    verifier.validate()
  File "/usr/lib/python3.9/site-packages/pykwalify/core.py", line 194, in validate
    raise SchemaError(u"Schema validation failed:\n - {error_msg}.".format(
pykwalify.errors.SchemaError: <SchemaError: error code 2: Schema validation failed:
 - Key 'off' was not defined. Path: ''.: Path: '/'>

The above exception was the direct cause of the following exception:

Traceback (most recent call last):
  File "/usr/lib/python3.9/site-packages/tavern/response/base.py", line 152, in _maybe_run_validate_functions
    vf(response)
  File "/usr/lib/python3.9/site-packages/tavern/util/extfunctions.py", line 98, in inner
    result = func(response, *args, **kwargs)
  File "/usr/lib/python3.9/site-packages/tavern/testutils/helpers.py", line 103, in validate_pykwalify
    verify_generic(to_verify, schema)
  File "/usr/lib/python3.9/site-packages/tavern/schemas/files.py", line 109, in verify_generic
    raise BadSchemaError() from e
tavern.util.exceptions.BadSchemaError
[31m[1mERROR   [0m pykwalify.core:core.py:190 validation.invalid
[31m[1mERROR   [0m pykwalify.core:core.py:191  --- All found errors ---
[31m[1mERROR   [0m pykwalify.core:core.py:192 ["Key 'off' was not defined. Path: ''"]
[31m[1mERROR   [0m tavern.schemas.files:files.py:108 Error validating {'e': 0, 'err_msg': '', 'off': ['x3000c0s6b0n0'], 'on': ['x1000c0s4b1n0']}
Traceback (most recent call last):
  File "/usr/lib/python3.9/site-packages/tavern/schemas/files.py", line 106, in verify_generic
    verifier.validate()
  File "/usr/lib/python3.9/site-packages/pykwalify/core.py", line 194, in validate
    raise SchemaError(u"Schema validation failed:\n - {error_msg}.".format(
pykwalify.errors.SchemaError: <SchemaError: error code 2: Schema validation failed:
 - Key 'off' was not defined. Path: ''.: Path: '/'>
[31m[1mERROR   [0m tavern.response.base:base.py:41 Error calling validate function '<function validate_pykwalify at 0x7f24c2db9820>':
    Traceback (most recent call last):
      File "/usr/lib/python3.9/site-packages/tavern/schemas/files.py", line 106, in verify_generic
        verifier.validate()
      File "/usr/lib/python3.9/site-packages/pykwalify/core.py", line 194, in validate
        raise SchemaError(u"Schema validation failed:\n - {error_msg}.".format(
    pykwalify.errors.SchemaError: <SchemaError: error code 2: Schema validation failed:
     - Key 'off' was not defined. Path: ''.: Path: '/'>

    The above exception was the direct cause of the following exception:

    Traceback (most recent call last):
      File "/usr/lib/python3.9/site-packages/tavern/response/base.py", line 152, in _maybe_run_validate_functions
        vf(response)
      File "/usr/lib/python3.9/site-packages/tavern/util/extfunctions.py", line 98, in inner
        result = func(response, *args, **kwargs)
      File "/usr/lib/python3.9/site-packages/tavern/testutils/helpers.py", line 103, in validate_pykwalify
        verify_generic(to_verify, schema)
      File "/usr/lib/python3.9/site-packages/tavern/schemas/files.py", line 109, in verify_generic
        raise BadSchemaError() from e
    tavern.util.exceptions.BadSchemaError
Traceback (most recent call last):
  File "/usr/lib/python3.9/site-packages/tavern/schemas/files.py", line 106, in verify_generic
    verifier.validate()
  File "/usr/lib/python3.9/site-packages/pykwalify/core.py", line 194, in validate
    raise SchemaError(u"Schema validation failed:\n - {error_msg}.".format(
pykwalify.errors.SchemaError: <SchemaError: error code 2: Schema validation failed:
 - Key 'off' was not defined. Path: ''.: Path: '/'>

The above exception was the direct cause of the following exception:

Traceback (most recent call last):
  File "/usr/lib/python3.9/site-packages/tavern/response/base.py", line 152, in _maybe_run_validate_functions
    vf(response)
  File "/usr/lib/python3.9/site-packages/tavern/util/extfunctions.py", line 98, in inner
    result = func(response, *args, **kwargs)
  File "/usr/lib/python3.9/site-packages/tavern/testutils/helpers.py", line 103, in validate_pykwalify
    verify_generic(to_verify, schema)
  File "/usr/lib/python3.9/site-packages/tavern/schemas/files.py", line 109, in verify_generic
    raise BadSchemaError() from e
tavern.util.exceptions.BadSchemaError
[31m[1mERROR   [0m pykwalify.core:core.py:190 validation.invalid
[31m[1mERROR   [0m pykwalify.core:core.py:191  --- All found errors ---
[31m[1mERROR   [0m pykwalify.core:core.py:192 ["Key 'off' was not defined. Path: ''"]
[31m[1mERROR   [0m tavern.schemas.files:files.py:108 Error validating {'e': 0, 'err_msg': '', 'off': ['x3000c0s6b0n0'], 'on': ['x1000c0s4b1n0']}
Traceback (most recent call last):
  File "/usr/lib/python3.9/site-packages/tavern/schemas/files.py", line 106, in verify_generic
    verifier.validate()
  File "/usr/lib/python3.9/site-packages/pykwalify/core.py", line 194, in validate
    raise SchemaError(u"Schema validation failed:\n - {error_msg}.".format(
pykwalify.errors.SchemaError: <SchemaError: error code 2: Schema validation failed:
 - Key 'off' was not defined. Path: ''.: Path: '/'>
[31m[1mERROR   [0m tavern.response.base:base.py:41 Error calling validate function '<function validate_pykwalify at 0x7f24c2db9820>':
    Traceback (most recent call last):
      File "/usr/lib/python3.9/site-packages/tavern/schemas/files.py", line 106, in verify_generic
        verifier.validate()
      File "/usr/lib/python3.9/site-packages/pykwalify/core.py", line 194, in validate
        raise SchemaError(u"Schema validation failed:\n - {error_msg}.".format(
    pykwalify.errors.SchemaError: <SchemaError: error code 2: Schema validation failed:
     - Key 'off' was not defined. Path: ''.: Path: '/'>

    The above exception was the direct cause of the following exception:

    Traceback (most recent call last):
      File "/usr/lib/python3.9/site-packages/tavern/response/base.py", line 152, in _maybe_run_validate_functions
        vf(response)
      File "/usr/lib/python3.9/site-packages/tavern/util/extfunctions.py", line 98, in inner
        result = func(response, *args, **kwargs)
      File "/usr/lib/python3.9/site-packages/tavern/testutils/helpers.py", line 103, in validate_pykwalify
        verify_generic(to_verify, schema)
      File "/usr/lib/python3.9/site-packages/tavern/schemas/files.py", line 109, in verify_generic
        raise BadSchemaError() from e
    tavern.util.exceptions.BadSchemaError
Traceback (most recent call last):
  File "/usr/lib/python3.9/site-packages/tavern/schemas/files.py", line 106, in verify_generic
    verifier.validate()
  File "/usr/lib/python3.9/site-packages/pykwalify/core.py", line 194, in validate
    raise SchemaError(u"Schema validation failed:\n - {error_msg}.".format(
pykwalify.errors.SchemaError: <SchemaError: error code 2: Schema validation failed:
 - Key 'off' was not defined. Path: ''.: Path: '/'>

The above exception was the direct cause of the following exception:

Traceback (most recent call last):
  File "/usr/lib/python3.9/site-packages/tavern/response/base.py", line 152, in _maybe_run_validate_functions
    vf(response)
  File "/usr/lib/python3.9/site-packages/tavern/util/extfunctions.py", line 98, in inner
    result = func(response, *args, **kwargs)
  File "/usr/lib/python3.9/site-packages/tavern/testutils/helpers.py", line 103, in validate_pykwalify
    verify_generic(to_verify, schema)
  File "/usr/lib/python3.9/site-packages/tavern/schemas/files.py", line 109, in verify_generic
    raise BadSchemaError() from e
tavern.util.exceptions.BadSchemaError
[31m[1mERROR   [0m pykwalify.core:core.py:190 validation.invalid
[31m[1mERROR   [0m pykwalify.core:core.py:191  --- All found errors ---
[31m[1mERROR   [0m pykwalify.core:core.py:192 ["Key 'off' was not defined. Path: ''"]
[31m[1mERROR   [0m tavern.schemas.files:files.py:108 Error validating {'e': 0, 'err_msg': '', 'off': ['x3000c0s6b0n0'], 'on': ['x1000c0s4b1n0']}
Traceback (most recent call last):
  File "/usr/lib/python3.9/site-packages/tavern/schemas/files.py", line 106, in verify_generic
    verifier.validate()
  File "/usr/lib/python3.9/site-packages/pykwalify/core.py", line 194, in validate
    raise SchemaError(u"Schema validation failed:\n - {error_msg}.".format(
pykwalify.errors.SchemaError: <SchemaError: error code 2: Schema validation failed:
 - Key 'off' was not defined. Path: ''.: Path: '/'>
[31m[1mERROR   [0m tavern.response.base:base.py:41 Error calling validate function '<function validate_pykwalify at 0x7f24c2db9820>':
    Traceback (most recent call last):
      File "/usr/lib/python3.9/site-packages/tavern/schemas/files.py", line 106, in verify_generic
        verifier.validate()
      File "/usr/lib/python3.9/site-packages/pykwalify/core.py", line 194, in validate
        raise SchemaError(u"Schema validation failed:\n - {error_msg}.".format(
    pykwalify.errors.SchemaError: <SchemaError: error code 2: Schema validation failed:
     - Key 'off' was not defined. Path: ''.: Path: '/'>

    The above exception was the direct cause of the following exception:

    Traceback (most recent call last):
      File "/usr/lib/python3.9/site-packages/tavern/response/base.py", line 152, in _maybe_run_validate_functions
        vf(response)
      File "/usr/lib/python3.9/site-packages/tavern/util/extfunctions.py", line 98, in inner
        result = func(response, *args, **kwargs)
      File "/usr/lib/python3.9/site-packages/tavern/testutils/helpers.py", line 103, in validate_pykwalify
        verify_generic(to_verify, schema)
      File "/usr/lib/python3.9/site-packages/tavern/schemas/files.py", line 109, in verify_generic
        raise BadSchemaError() from e
    tavern.util.exceptions.BadSchemaError
Traceback (most recent call last):
  File "/usr/lib/python3.9/site-packages/tavern/schemas/files.py", line 106, in verify_generic
    verifier.validate()
  File "/usr/lib/python3.9/site-packages/pykwalify/core.py", line 194, in validate
    raise SchemaError(u"Schema validation failed:\n - {error_msg}.".format(
pykwalify.errors.SchemaError: <SchemaError: error code 2: Schema validation failed:
 - Key 'off' was not defined. Path: ''.: Path: '/'>

The above exception was the direct cause of the following exception:

Traceback (most recent call last):
  File "/usr/lib/python3.9/site-packages/tavern/response/base.py", line 152, in _maybe_run_validate_functions
    vf(response)
  File "/usr/lib/python3.9/site-packages/tavern/util/extfunctions.py", line 98, in inner
    result = func(response, *args, **kwargs)
  File "/usr/lib/python3.9/site-packages/tavern/testutils/helpers.py", line 103, in validate_pykwalify
    verify_generic(to_verify, schema)
  File "/usr/lib/python3.9/site-packages/tavern/schemas/files.py", line 109, in verify_generic
    raise BadSchemaError() from e
tavern.util.exceptions.BadSchemaError
[31m[1mERROR   [0m pykwalify.core:core.py:190 validation.invalid
[31m[1mERROR   [0m pykwalify.core:core.py:191  --- All found errors ---
[31m[1mERROR   [0m pykwalify.core:core.py:192 ["Key 'off' was not defined. Path: ''"]
[31m[1mERROR   [0m tavern.schemas.files:files.py:108 Error validating {'e': 0, 'err_msg': '', 'off': ['x3000c0s6b0n0'], 'on': ['x1000c0s4b1n0']}
Traceback (most recent call last):
  File "/usr/lib/python3.9/site-packages/tavern/schemas/files.py", line 106, in verify_generic
    verifier.validate()
  File "/usr/lib/python3.9/site-packages/pykwalify/core.py", line 194, in validate
    raise SchemaError(u"Schema validation failed:\n - {error_msg}.".format(
pykwalify.errors.SchemaError: <SchemaError: error code 2: Schema validation failed:
 - Key 'off' was not defined. Path: ''.: Path: '/'>
[31m[1mERROR   [0m tavern.response.base:base.py:41 Error calling validate function '<function validate_pykwalify at 0x7f24c2db9820>':
    Traceback (most recent call last):
      File "/usr/lib/python3.9/site-packages/tavern/schemas/files.py", line 106, in verify_generic
        verifier.validate()
      File "/usr/lib/python3.9/site-packages/pykwalify/core.py", line 194, in validate
        raise SchemaError(u"Schema validation failed:\n - {error_msg}.".format(
    pykwalify.errors.SchemaError: <SchemaError: error code 2: Schema validation failed:
     - Key 'off' was not defined. Path: ''.: Path: '/'>

    The above exception was the direct cause of the following exception:

    Traceback (most recent call last):
      File "/usr/lib/python3.9/site-packages/tavern/response/base.py", line 152, in _maybe_run_validate_functions
        vf(response)
      File "/usr/lib/python3.9/site-packages/tavern/util/extfunctions.py", line 98, in inner
        result = func(response, *args, **kwargs)
      File "/usr/lib/python3.9/site-packages/tavern/testutils/helpers.py", line 103, in validate_pykwalify
        verify_generic(to_verify, schema)
      File "/usr/lib/python3.9/site-packages/tavern/schemas/files.py", line 109, in verify_generic
        raise BadSchemaError() from e
    tavern.util.exceptions.BadSchemaError
Traceback (most recent call last):
  File "/usr/lib/python3.9/site-packages/tavern/schemas/files.py", line 106, in verify_generic
    verifier.validate()
  File "/usr/lib/python3.9/site-packages/pykwalify/core.py", line 194, in validate
    raise SchemaError(u"Schema validation failed:\n - {error_msg}.".format(
pykwalify.errors.SchemaError: <SchemaError: error code 2: Schema validation failed:
 - Key 'off' was not defined. Path: ''.: Path: '/'>

The above exception was the direct cause of the following exception:

Traceback (most recent call last):
  File "/usr/lib/python3.9/site-packages/tavern/response/base.py", line 152, in _maybe_run_validate_functions
    vf(response)
  File "/usr/lib/python3.9/site-packages/tavern/util/extfunctions.py", line 98, in inner
    result = func(response, *args, **kwargs)
  File "/usr/lib/python3.9/site-packages/tavern/testutils/helpers.py", line 103, in validate_pykwalify
    verify_generic(to_verify, schema)
  File "/usr/lib/python3.9/site-packages/tavern/schemas/files.py", line 109, in verify_generic
    raise BadSchemaError() from e
tavern.util.exceptions.BadSchemaError
[31m[1mERROR   [0m pykwalify.core:core.py:190 validation.invalid
[31m[1mERROR   [0m pykwalify.core:core.py:191  --- All found errors ---
[31m[1mERROR   [0m pykwalify.core:core.py:192 ["Key 'off' was not defined. Path: ''"]
[31m[1mERROR   [0m tavern.schemas.files:files.py:108 Error validating {'e': 0, 'err_msg': '', 'off': ['x3000c0s6b0n0'], 'on': ['x1000c0s4b1n0']}
Traceback (most recent call last):
  File "/usr/lib/python3.9/site-packages/tavern/schemas/files.py", line 106, in verify_generic
    verifier.validate()
  File "/usr/lib/python3.9/site-packages/pykwalify/core.py", line 194, in validate
    raise SchemaError(u"Schema validation failed:\n - {error_msg}.".format(
pykwalify.errors.SchemaError: <SchemaError: error code 2: Schema validation failed:
 - Key 'off' was not defined. Path: ''.: Path: '/'>
[31m[1mERROR   [0m tavern.response.base:base.py:41 Error calling validate function '<function validate_pykwalify at 0x7f24c2db9820>':
    Traceback (most recent call last):
      File "/usr/lib/python3.9/site-packages/tavern/schemas/files.py", line 106, in verify_generic
        verifier.validate()
      File "/usr/lib/python3.9/site-packages/pykwalify/core.py", line 194, in validate
        raise SchemaError(u"Schema validation failed:\n - {error_msg}.".format(
    pykwalify.errors.SchemaError: <SchemaError: error code 2: Schema validation failed:
     - Key 'off' was not defined. Path: ''.: Path: '/'>

    The above exception was the direct cause of the following exception:

    Traceback (most recent call last):
      File "/usr/lib/python3.9/site-packages/tavern/response/base.py", line 152, in _maybe_run_validate_functions
        vf(response)
      File "/usr/lib/python3.9/site-packages/tavern/util/extfunctions.py", line 98, in inner
        result = func(response, *args, **kwargs)
      File "/usr/lib/python3.9/site-packages/tavern/testutils/helpers.py", line 103, in validate_pykwalify
        verify_generic(to_verify, schema)
      File "/usr/lib/python3.9/site-packages/tavern/schemas/files.py", line 109, in verify_generic
        raise BadSchemaError() from e
    tavern.util.exceptions.BadSchemaError
Traceback (most recent call last):
  File "/usr/lib/python3.9/site-packages/tavern/schemas/files.py", line 106, in verify_generic
    verifier.validate()
  File "/usr/lib/python3.9/site-packages/pykwalify/core.py", line 194, in validate
    raise SchemaError(u"Schema validation failed:\n - {error_msg}.".format(
pykwalify.errors.SchemaError: <SchemaError: error code 2: Schema validation failed:
 - Key 'off' was not defined. Path: ''.: Path: '/'>

The above exception was the direct cause of the following exception:

Traceback (most recent call last):
  File "/usr/lib/python3.9/site-packages/tavern/response/base.py", line 152, in _maybe_run_validate_functions
    vf(response)
  File "/usr/lib/python3.9/site-packages/tavern/util/extfunctions.py", line 98, in inner
    result = func(response, *args, **kwargs)
  File "/usr/lib/python3.9/site-packages/tavern/testutils/helpers.py", line 103, in validate_pykwalify
    verify_generic(to_verify, schema)
  File "/usr/lib/python3.9/site-packages/tavern/schemas/files.py", line 109, in verify_generic
    raise BadSchemaError() from e
tavern.util.exceptions.BadSchemaError
[31m[1mERROR   [0m pykwalify.core:core.py:190 validation.invalid
[31m[1mERROR   [0m pykwalify.core:core.py:191  --- All found errors ---
[31m[1mERROR   [0m pykwalify.core:core.py:192 ["Key 'off' was not defined. Path: ''"]
[31m[1mERROR   [0m tavern.schemas.files:files.py:108 Error validating {'e': 0, 'err_msg': '', 'off': ['x3000c0s6b0n0'], 'on': ['x1000c0s4b1n0']}
Traceback (most recent call last):
  File "/usr/lib/python3.9/site-packages/tavern/schemas/files.py", line 106, in verify_generic
    verifier.validate()
  File "/usr/lib/python3.9/site-packages/pykwalify/core.py", line 194, in validate
    raise SchemaError(u"Schema validation failed:\n - {error_msg}.".format(
pykwalify.errors.SchemaError: <SchemaError: error code 2: Schema validation failed:
 - Key 'off' was not defined. Path: ''.: Path: '/'>
[31m[1mERROR   [0m tavern.response.base:base.py:41 Error calling validate function '<function validate_pykwalify at 0x7f24c2db9820>':
    Traceback (most recent call last):
      File "/usr/lib/python3.9/site-packages/tavern/schemas/files.py", line 106, in verify_generic
        verifier.validate()
      File "/usr/lib/python3.9/site-packages/pykwalify/core.py", line 194, in validate
        raise SchemaError(u"Schema validation failed:\n - {error_msg}.".format(
    pykwalify.errors.SchemaError: <SchemaError: error code 2: Schema validation failed:
     - Key 'off' was not defined. Path: ''.: Path: '/'>

    The above exception was the direct cause of the following exception:

    Traceback (most recent call last):
      File "/usr/lib/python3.9/site-packages/tavern/response/base.py", line 152, in _maybe_run_validate_functions
        vf(response)
      File "/usr/lib/python3.9/site-packages/tavern/util/extfunctions.py", line 98, in inner
        result = func(response, *args, **kwargs)
      File "/usr/lib/python3.9/site-packages/tavern/testutils/helpers.py", line 103, in validate_pykwalify
        verify_generic(to_verify, schema)
      File "/usr/lib/python3.9/site-packages/tavern/schemas/files.py", line 109, in verify_generic
        raise BadSchemaError() from e
    tavern.util.exceptions.BadSchemaError
Traceback (most recent call last):
  File "/usr/lib/python3.9/site-packages/tavern/schemas/files.py", line 106, in verify_generic
    verifier.validate()
  File "/usr/lib/python3.9/site-packages/pykwalify/core.py", line 194, in validate
    raise SchemaError(u"Schema validation failed:\n - {error_msg}.".format(
pykwalify.errors.SchemaError: <SchemaError: error code 2: Schema validation failed:
 - Key 'off' was not defined. Path: ''.: Path: '/'>

The above exception was the direct cause of the following exception:

Traceback (most recent call last):
  File "/usr/lib/python3.9/site-packages/tavern/response/base.py", line 152, in _maybe_run_validate_functions
    vf(response)
  File "/usr/lib/python3.9/site-packages/tavern/util/extfunctions.py", line 98, in inner
    result = func(response, *args, **kwargs)
  File "/usr/lib/python3.9/site-packages/tavern/testutils/helpers.py", line 103, in validate_pykwalify
    verify_generic(to_verify, schema)
  File "/usr/lib/python3.9/site-packages/tavern/schemas/files.py", line 109, in verify_generic
    raise BadSchemaError() from e
tavern.util.exceptions.BadSchemaError
[31m[1mERROR   [0m pykwalify.core:core.py:190 validation.invalid
[31m[1mERROR   [0m pykwalify.core:core.py:191  --- All found errors ---
[31m[1mERROR   [0m pykwalify.core:core.py:192 ["Key 'off' was not defined. Path: ''"]
[31m[1mERROR   [0m tavern.schemas.files:files.py:108 Error validating {'e': 0, 'err_msg': '', 'off': ['x3000c0s6b0n0'], 'on': ['x1000c0s4b1n0']}
Traceback (most recent call last):
  File "/usr/lib/python3.9/site-packages/tavern/schemas/files.py", line 106, in verify_generic
    verifier.validate()
  File "/usr/lib/python3.9/site-packages/pykwalify/core.py", line 194, in validate
    raise SchemaError(u"Schema validation failed:\n - {error_msg}.".format(
pykwalify.errors.SchemaError: <SchemaError: error code 2: Schema validation failed:
 - Key 'off' was not defined. Path: ''.: Path: '/'>
[31m[1mERROR   [0m tavern.response.base:base.py:41 Error calling validate function '<function validate_pykwalify at 0x7f24c2db9820>':
    Traceback (most recent call last):
      File "/usr/lib/python3.9/site-packages/tavern/schemas/files.py", line 106, in verify_generic
        verifier.validate()
      File "/usr/lib/python3.9/site-packages/pykwalify/core.py", line 194, in validate
        raise SchemaError(u"Schema validation failed:\n - {error_msg}.".format(
    pykwalify.errors.SchemaError: <SchemaError: error code 2: Schema validation failed:
     - Key 'off' was not defined. Path: ''.: Path: '/'>

    The above exception was the direct cause of the following exception:

    Traceback (most recent call last):
      File "/usr/lib/python3.9/site-packages/tavern/response/base.py", line 152, in _maybe_run_validate_functions
        vf(response)
      File "/usr/lib/python3.9/site-packages/tavern/util/extfunctions.py", line 98, in inner
        result = func(response, *args, **kwargs)
      File "/usr/lib/python3.9/site-packages/tavern/testutils/helpers.py", line 103, in validate_pykwalify
        verify_generic(to_verify, schema)
      File "/usr/lib/python3.9/site-packages/tavern/schemas/files.py", line 109, in verify_generic
        raise BadSchemaError() from e
    tavern.util.exceptions.BadSchemaError
Traceback (most recent call last):
  File "/usr/lib/python3.9/site-packages/tavern/schemas/files.py", line 106, in verify_generic
    verifier.validate()
  File "/usr/lib/python3.9/site-packages/pykwalify/core.py", line 194, in validate
    raise SchemaError(u"Schema validation failed:\n - {error_msg}.".format(
pykwalify.errors.SchemaError: <SchemaError: error code 2: Schema validation failed:
 - Key 'off' was not defined. Path: ''.: Path: '/'>

The above exception was the direct cause of the following exception:

Traceback (most recent call last):
  File "/usr/lib/python3.9/site-packages/tavern/response/base.py", line 152, in _maybe_run_validate_functions
    vf(response)
  File "/usr/lib/python3.9/site-packages/tavern/util/extfunctions.py", line 98, in inner
    result = func(response, *args, **kwargs)
  File "/usr/lib/python3.9/site-packages/tavern/testutils/helpers.py", line 103, in validate_pykwalify
    verify_generic(to_verify, schema)
  File "/usr/lib/python3.9/site-packages/tavern/schemas/files.py", line 109, in verify_generic
    raise BadSchemaError() from e
tavern.util.exceptions.BadSchemaError
[31m[1mERROR   [0m pykwalify.core:core.py:190 validation.invalid
[31m[1mERROR   [0m pykwalify.core:core.py:191  --- All found errors ---
[31m[1mERROR   [0m pykwalify.core:core.py:192 ["Key 'off' was not defined. Path: ''"]
[31m[1mERROR   [0m tavern.schemas.files:files.py:108 Error validating {'e': 0, 'err_msg': '', 'off': ['x3000c0s6b0n0'], 'on': ['x1000c0s4b1n0']}
Traceback (most recent call last):
  File "/usr/lib/python3.9/site-packages/tavern/schemas/files.py", line 106, in verify_generic
    verifier.validate()
  File "/usr/lib/python3.9/site-packages/pykwalify/core.py", line 194, in validate
    raise SchemaError(u"Schema validation failed:\n - {error_msg}.".format(
pykwalify.errors.SchemaError: <SchemaError: error code 2: Schema validation failed:
 - Key 'off' was not defined. Path: ''.: Path: '/'>
[31m[1mERROR   [0m tavern.response.base:base.py:41 Error calling validate function '<function validate_pykwalify at 0x7f24c2db9820>':
    Traceback (most recent call last):
      File "/usr/lib/python3.9/site-packages/tavern/schemas/files.py", line 106, in verify_generic
        verifier.validate()
      File "/usr/lib/python3.9/site-packages/pykwalify/core.py", line 194, in validate
        raise SchemaError(u"Schema validation failed:\n - {error_msg}.".format(
    pykwalify.errors.SchemaError: <SchemaError: error code 2: Schema validation failed:
     - Key 'off' was not defined. Path: ''.: Path: '/'>

    The above exception was the direct cause of the following exception:

    Traceback (most recent call last):
      File "/usr/lib/python3.9/site-packages/tavern/response/base.py", line 152, in _maybe_run_validate_functions
        vf(response)
      File "/usr/lib/python3.9/site-packages/tavern/util/extfunctions.py", line 98, in inner
        result = func(response, *args, **kwargs)
      File "/usr/lib/python3.9/site-packages/tavern/testutils/helpers.py", line 103, in validate_pykwalify
        verify_generic(to_verify, schema)
      File "/usr/lib/python3.9/site-packages/tavern/schemas/files.py", line 109, in verify_generic
        raise BadSchemaError() from e
    tavern.util.exceptions.BadSchemaError
Traceback (most recent call last):
  File "/usr/lib/python3.9/site-packages/tavern/schemas/files.py", line 106, in verify_generic
    verifier.validate()
  File "/usr/lib/python3.9/site-packages/pykwalify/core.py", line 194, in validate
    raise SchemaError(u"Schema validation failed:\n - {error_msg}.".format(
pykwalify.errors.SchemaError: <SchemaError: error code 2: Schema validation failed:
 - Key 'off' was not defined. Path: ''.: Path: '/'>

The above exception was the direct cause of the following exception:

Traceback (most recent call last):
  File "/usr/lib/python3.9/site-packages/tavern/response/base.py", line 152, in _maybe_run_validate_functions
    vf(response)
  File "/usr/lib/python3.9/site-packages/tavern/util/extfunctions.py", line 98, in inner
    result = func(response, *args, **kwargs)
  File "/usr/lib/python3.9/site-packages/tavern/testutils/helpers.py", line 103, in validate_pykwalify
    verify_generic(to_verify, schema)
  File "/usr/lib/python3.9/site-packages/tavern/schemas/files.py", line 109, in verify_generic
    raise BadSchemaError() from e
tavern.util.exceptions.BadSchemaError
[31m[1mERROR   [0m pykwalify.core:core.py:190 validation.invalid
[31m[1mERROR   [0m pykwalify.core:core.py:191  --- All found errors ---
[31m[1mERROR   [0m pykwalify.core:core.py:192 ["Key 'off' was not defined. Path: ''"]
[31m[1mERROR   [0m tavern.schemas.files:files.py:108 Error validating {'e': 0, 'err_msg': '', 'off': ['x3000c0s6b0n0'], 'on': ['x1000c0s4b1n0']}
Traceback (most recent call last):
  File "/usr/lib/python3.9/site-packages/tavern/schemas/files.py", line 106, in verify_generic
    verifier.validate()
  File "/usr/lib/python3.9/site-packages/pykwalify/core.py", line 194, in validate
    raise SchemaError(u"Schema validation failed:\n - {error_msg}.".format(
pykwalify.errors.SchemaError: <SchemaError: error code 2: Schema validation failed:
 - Key 'off' was not defined. Path: ''.: Path: '/'>
[31m[1mERROR   [0m tavern.response.base:base.py:41 Error calling validate function '<function validate_pykwalify at 0x7f24c2db9820>':
    Traceback (most recent call last):
      File "/usr/lib/python3.9/site-packages/tavern/schemas/files.py", line 106, in verify_generic
        verifier.validate()
      File "/usr/lib/python3.9/site-packages/pykwalify/core.py", line 194, in validate
        raise SchemaError(u"Schema validation failed:\n - {error_msg}.".format(
    pykwalify.errors.SchemaError: <SchemaError: error code 2: Schema validation failed:
     - Key 'off' was not defined. Path: ''.: Path: '/'>

    The above exception was the direct cause of the following exception:

    Traceback (most recent call last):
      File "/usr/lib/python3.9/site-packages/tavern/response/base.py", line 152, in _maybe_run_validate_functions
        vf(response)
      File "/usr/lib/python3.9/site-packages/tavern/util/extfunctions.py", line 98, in inner
        result = func(response, *args, **kwargs)
      File "/usr/lib/python3.9/site-packages/tavern/testutils/helpers.py", line 103, in validate_pykwalify
        verify_generic(to_verify, schema)
      File "/usr/lib/python3.9/site-packages/tavern/schemas/files.py", line 109, in verify_generic
        raise BadSchemaError() from e
    tavern.util.exceptions.BadSchemaError
Traceback (most recent call last):
  File "/usr/lib/python3.9/site-packages/tavern/schemas/files.py", line 106, in verify_generic
    verifier.validate()
  File "/usr/lib/python3.9/site-packages/pykwalify/core.py", line 194, in validate
    raise SchemaError(u"Schema validation failed:\n - {error_msg}.".format(
pykwalify.errors.SchemaError: <SchemaError: error code 2: Schema validation failed:
 - Key 'off' was not defined. Path: ''.: Path: '/'>

The above exception was the direct cause of the following exception:

Traceback (most recent call last):
  File "/usr/lib/python3.9/site-packages/tavern/response/base.py", line 152, in _maybe_run_validate_functions
    vf(response)
  File "/usr/lib/python3.9/site-packages/tavern/util/extfunctions.py", line 98, in inner
    result = func(response, *args, **kwargs)
  File "/usr/lib/python3.9/site-packages/tavern/testutils/helpers.py", line 103, in validate_pykwalify
    verify_generic(to_verify, schema)
  File "/usr/lib/python3.9/site-packages/tavern/schemas/files.py", line 109, in verify_generic
    raise BadSchemaError() from e
tavern.util.exceptions.BadSchemaError
[31m[1mERROR   [0m pykwalify.core:core.py:190 validation.invalid
[31m[1mERROR   [0m pykwalify.core:core.py:191  --- All found errors ---
[31m[1mERROR   [0m pykwalify.core:core.py:192 ["Key 'off' was not defined. Path: ''"]
[31m[1mERROR   [0m tavern.schemas.files:files.py:108 Error validating {'e': 0, 'err_msg': '', 'off': ['x3000c0s6b0n0'], 'on': ['x1000c0s4b1n0']}
Traceback (most recent call last):
  File "/usr/lib/python3.9/site-packages/tavern/schemas/files.py", line 106, in verify_generic
    verifier.validate()
  File "/usr/lib/python3.9/site-packages/pykwalify/core.py", line 194, in validate
    raise SchemaError(u"Schema validation failed:\n - {error_msg}.".format(
pykwalify.errors.SchemaError: <SchemaError: error code 2: Schema validation failed:
 - Key 'off' was not defined. Path: ''.: Path: '/'>
[31m[1mERROR   [0m tavern.response.base:base.py:41 Error calling validate function '<function validate_pykwalify at 0x7f24c2db9820>':
    Traceback (most recent call last):
      File "/usr/lib/python3.9/site-packages/tavern/schemas/files.py", line 106, in verify_generic
        verifier.validate()
      File "/usr/lib/python3.9/site-packages/pykwalify/core.py", line 194, in validate
        raise SchemaError(u"Schema validation failed:\n - {error_msg}.".format(
    pykwalify.errors.SchemaError: <SchemaError: error code 2: Schema validation failed:
     - Key 'off' was not defined. Path: ''.: Path: '/'>

    The above exception was the direct cause of the following exception:

    Traceback (most recent call last):
      File "/usr/lib/python3.9/site-packages/tavern/response/base.py", line 152, in _maybe_run_validate_functions
        vf(response)
      File "/usr/lib/python3.9/site-packages/tavern/util/extfunctions.py", line 98, in inner
        result = func(response, *args, **kwargs)
      File "/usr/lib/python3.9/site-packages/tavern/testutils/helpers.py", line 103, in validate_pykwalify
        verify_generic(to_verify, schema)
      File "/usr/lib/python3.9/site-packages/tavern/schemas/files.py", line 109, in verify_generic
        raise BadSchemaError() from e
    tavern.util.exceptions.BadSchemaError
Traceback (most recent call last):
  File "/usr/lib/python3.9/site-packages/tavern/schemas/files.py", line 106, in verify_generic
    verifier.validate()
  File "/usr/lib/python3.9/site-packages/pykwalify/core.py", line 194, in validate
    raise SchemaError(u"Schema validation failed:\n - {error_msg}.".format(
pykwalify.errors.SchemaError: <SchemaError: error code 2: Schema validation failed:
 - Key 'off' was not defined. Path: ''.: Path: '/'>

The above exception was the direct cause of the following exception:

Traceback (most recent call last):
  File "/usr/lib/python3.9/site-packages/tavern/response/base.py", line 152, in _maybe_run_validate_functions
    vf(response)
  File "/usr/lib/python3.9/site-packages/tavern/util/extfunctions.py", line 98, in inner
    result = func(response, *args, **kwargs)
  File "/usr/lib/python3.9/site-packages/tavern/testutils/helpers.py", line 103, in validate_pykwalify
    verify_generic(to_verify, schema)
  File "/usr/lib/python3.9/site-packages/tavern/schemas/files.py", line 109, in verify_generic
    raise BadSchemaError() from e
tavern.util.exceptions.BadSchemaError
[31m[1mERROR   [0m pykwalify.core:core.py:190 validation.invalid
[31m[1mERROR   [0m pykwalify.core:core.py:191  --- All found errors ---
[31m[1mERROR   [0m pykwalify.core:core.py:192 ["Key 'off' was not defined. Path: ''"]
[31m[1mERROR   [0m tavern.schemas.files:files.py:108 Error validating {'e': 0, 'err_msg': '', 'off': ['x3000c0s6b0n0'], 'on': ['x1000c0s4b1n0']}
Traceback (most recent call last):
  File "/usr/lib/python3.9/site-packages/tavern/schemas/files.py", line 106, in verify_generic
    verifier.validate()
  File "/usr/lib/python3.9/site-packages/pykwalify/core.py", line 194, in validate
    raise SchemaError(u"Schema validation failed:\n - {error_msg}.".format(
pykwalify.errors.SchemaError: <SchemaError: error code 2: Schema validation failed:
 - Key 'off' was not defined. Path: ''.: Path: '/'>
[31m[1mERROR   [0m tavern.response.base:base.py:41 Error calling validate function '<function validate_pykwalify at 0x7f24c2db9820>':
    Traceback (most recent call last):
      File "/usr/lib/python3.9/site-packages/tavern/schemas/files.py", line 106, in verify_generic
        verifier.validate()
      File "/usr/lib/python3.9/site-packages/pykwalify/core.py", line 194, in validate
        raise SchemaError(u"Schema validation failed:\n - {error_msg}.".format(
    pykwalify.errors.SchemaError: <SchemaError: error code 2: Schema validation failed:
     - Key 'off' was not defined. Path: ''.: Path: '/'>

    The above exception was the direct cause of the following exception:

    Traceback (most recent call last):
      File "/usr/lib/python3.9/site-packages/tavern/response/base.py", line 152, in _maybe_run_validate_functions
        vf(response)
      File "/usr/lib/python3.9/site-packages/tavern/util/extfunctions.py", line 98, in inner
        result = func(response, *args, **kwargs)
      File "/usr/lib/python3.9/site-packages/tavern/testutils/helpers.py", line 103, in validate_pykwalify
        verify_generic(to_verify, schema)
      File "/usr/lib/python3.9/site-packages/tavern/schemas/files.py", line 109, in verify_generic
        raise BadSchemaError() from e
    tavern.util.exceptions.BadSchemaError
Traceback (most recent call last):
  File "/usr/lib/python3.9/site-packages/tavern/schemas/files.py", line 106, in verify_generic
    verifier.validate()
  File "/usr/lib/python3.9/site-packages/pykwalify/core.py", line 194, in validate
    raise SchemaError(u"Schema validation failed:\n - {error_msg}.".format(
pykwalify.errors.SchemaError: <SchemaError: error code 2: Schema validation failed:
 - Key 'off' was not defined. Path: ''.: Path: '/'>

The above exception was the direct cause of the following exception:

Traceback (most recent call last):
  File "/usr/lib/python3.9/site-packages/tavern/response/base.py", line 152, in _maybe_run_validate_functions
    vf(response)
  File "/usr/lib/python3.9/site-packages/tavern/util/extfunctions.py", line 98, in inner
    result = func(response, *args, **kwargs)
  File "/usr/lib/python3.9/site-packages/tavern/testutils/helpers.py", line 103, in validate_pykwalify
    verify_generic(to_verify, schema)
  File "/usr/lib/python3.9/site-packages/tavern/schemas/files.py", line 109, in verify_generic
    raise BadSchemaError() from e
tavern.util.exceptions.BadSchemaError
[31m[1mERROR   [0m pykwalify.core:core.py:190 validation.invalid
[31m[1mERROR   [0m pykwalify.core:core.py:191  --- All found errors ---
[31m[1mERROR   [0m pykwalify.core:core.py:192 ["Key 'off' was not defined. Path: ''"]
[31m[1mERROR   [0m tavern.schemas.files:files.py:108 Error validating {'e': 0, 'err_msg': '', 'off': ['x3000c0s6b0n0'], 'on': ['x1000c0s4b1n0']}
Traceback (most recent call last):
  File "/usr/lib/python3.9/site-packages/tavern/schemas/files.py", line 106, in verify_generic
    verifier.validate()
  File "/usr/lib/python3.9/site-packages/pykwalify/core.py", line 194, in validate
    raise SchemaError(u"Schema validation failed:\n - {error_msg}.".format(
pykwalify.errors.SchemaError: <SchemaError: error code 2: Schema validation failed:
 - Key 'off' was not defined. Path: ''.: Path: '/'>
[31m[1mERROR   [0m tavern.response.base:base.py:41 Error calling validate function '<function validate_pykwalify at 0x7f24c2db9820>':
    Traceback (most recent call last):
      File "/usr/lib/python3.9/site-packages/tavern/schemas/files.py", line 106, in verify_generic
        verifier.validate()
      File "/usr/lib/python3.9/site-packages/pykwalify/core.py", line 194, in validate
        raise SchemaError(u"Schema validation failed:\n - {error_msg}.".format(
    pykwalify.errors.SchemaError: <SchemaError: error code 2: Schema validation failed:
     - Key 'off' was not defined. Path: ''.: Path: '/'>

    The above exception was the direct cause of the following exception:

    Traceback (most recent call last):
      File "/usr/lib/python3.9/site-packages/tavern/response/base.py", line 152, in _maybe_run_validate_functions
        vf(response)
      File "/usr/lib/python3.9/site-packages/tavern/util/extfunctions.py", line 98, in inner
        result = func(response, *args, **kwargs)
      File "/usr/lib/python3.9/site-packages/tavern/testutils/helpers.py", line 103, in validate_pykwalify
        verify_generic(to_verify, schema)
      File "/usr/lib/python3.9/site-packages/tavern/schemas/files.py", line 109, in verify_generic
        raise BadSchemaError() from e
    tavern.util.exceptions.BadSchemaError
Traceback (most recent call last):
  File "/usr/lib/python3.9/site-packages/tavern/schemas/files.py", line 106, in verify_generic
    verifier.validate()
  File "/usr/lib/python3.9/site-packages/pykwalify/core.py", line 194, in validate
    raise SchemaError(u"Schema validation failed:\n - {error_msg}.".format(
pykwalify.errors.SchemaError: <SchemaError: error code 2: Schema validation failed:
 - Key 'off' was not defined. Path: ''.: Path: '/'>

The above exception was the direct cause of the following exception:

Traceback (most recent call last):
  File "/usr/lib/python3.9/site-packages/tavern/response/base.py", line 152, in _maybe_run_validate_functions
    vf(response)
  File "/usr/lib/python3.9/site-packages/tavern/util/extfunctions.py", line 98, in inner
    result = func(response, *args, **kwargs)
  File "/usr/lib/python3.9/site-packages/tavern/testutils/helpers.py", line 103, in validate_pykwalify
    verify_generic(to_verify, schema)
  File "/usr/lib/python3.9/site-packages/tavern/schemas/files.py", line 109, in verify_generic
    raise BadSchemaError() from e
tavern.util.exceptions.BadSchemaError
[31m[1mERROR   [0m pykwalify.core:core.py:190 validation.invalid
[31m[1mERROR   [0m pykwalify.core:core.py:191  --- All found errors ---
[31m[1mERROR   [0m pykwalify.core:core.py:192 ["Key 'off' was not defined. Path: ''"]
[31m[1mERROR   [0m tavern.schemas.files:files.py:108 Error validating {'e': 0, 'err_msg': '', 'off': ['x3000c0s6b0n0'], 'on': ['x1000c0s4b1n0']}
Traceback (most recent call last):
  File "/usr/lib/python3.9/site-packages/tavern/schemas/files.py", line 106, in verify_generic
    verifier.validate()
  File "/usr/lib/python3.9/site-packages/pykwalify/core.py", line 194, in validate
    raise SchemaError(u"Schema validation failed:\n - {error_msg}.".format(
pykwalify.errors.SchemaError: <SchemaError: error code 2: Schema validation failed:
 - Key 'off' was not defined. Path: ''.: Path: '/'>
[31m[1mERROR   [0m tavern.response.base:base.py:41 Error calling validate function '<function validate_pykwalify at 0x7f24c2db9820>':
    Traceback (most recent call last):
      File "/usr/lib/python3.9/site-packages/tavern/schemas/files.py", line 106, in verify_generic
        verifier.validate()
      File "/usr/lib/python3.9/site-packages/pykwalify/core.py", line 194, in validate
        raise SchemaError(u"Schema validation failed:\n - {error_msg}.".format(
    pykwalify.errors.SchemaError: <SchemaError: error code 2: Schema validation failed:
     - Key 'off' was not defined. Path: ''.: Path: '/'>

    The above exception was the direct cause of the following exception:

    Traceback (most recent call last):
      File "/usr/lib/python3.9/site-packages/tavern/response/base.py", line 152, in _maybe_run_validate_functions
        vf(response)
      File "/usr/lib/python3.9/site-packages/tavern/util/extfunctions.py", line 98, in inner
        result = func(response, *args, **kwargs)
      File "/usr/lib/python3.9/site-packages/tavern/testutils/helpers.py", line 103, in validate_pykwalify
        verify_generic(to_verify, schema)
      File "/usr/lib/python3.9/site-packages/tavern/schemas/files.py", line 109, in verify_generic
        raise BadSchemaError() from e
    tavern.util.exceptions.BadSchemaError
Traceback (most recent call last):
  File "/usr/lib/python3.9/site-packages/tavern/schemas/files.py", line 106, in verify_generic
    verifier.validate()
  File "/usr/lib/python3.9/site-packages/pykwalify/core.py", line 194, in validate
    raise SchemaError(u"Schema validation failed:\n - {error_msg}.".format(
pykwalify.errors.SchemaError: <SchemaError: error code 2: Schema validation failed:
 - Key 'off' was not defined. Path: ''.: Path: '/'>

The above exception was the direct cause of the following exception:

Traceback (most recent call last):
  File "/usr/lib/python3.9/site-packages/tavern/response/base.py", line 152, in _maybe_run_validate_functions
    vf(response)
  File "/usr/lib/python3.9/site-packages/tavern/util/extfunctions.py", line 98, in inner
    result = func(response, *args, **kwargs)
  File "/usr/lib/python3.9/site-packages/tavern/testutils/helpers.py", line 103, in validate_pykwalify
    verify_generic(to_verify, schema)
  File "/usr/lib/python3.9/site-packages/tavern/schemas/files.py", line 109, in verify_generic
    raise BadSchemaError() from e
tavern.util.exceptions.BadSchemaError
[31m[1mERROR   [0m pykwalify.core:core.py:190 validation.invalid
[31m[1mERROR   [0m pykwalify.core:core.py:191  --- All found errors ---
[31m[1mERROR   [0m pykwalify.core:core.py:192 ["Cannot find required key 'off'. Path: ''", "Key 'on' was not defined. Path: ''"]
[31m[1mERROR   [0m tavern.schemas.files:files.py:108 Error validating {'e': 0, 'err_msg': '', 'on': ['x1000c0s4b1n0', 'x3000c0s6b0n0']}
Traceback (most recent call last):
  File "/usr/lib/python3.9/site-packages/tavern/schemas/files.py", line 106, in verify_generic
    verifier.validate()
  File "/usr/lib/python3.9/site-packages/pykwalify/core.py", line 194, in validate
    raise SchemaError(u"Schema validation failed:\n - {error_msg}.".format(
pykwalify.errors.SchemaError: <SchemaError: error code 2: Schema validation failed:
 - Cannot find required key 'off'. Path: ''.
 - Key 'on' was not defined. Path: ''.: Path: '/'>
[31m[1mERROR   [0m tavern.response.base:base.py:41 Error calling validate function '<function validate_pykwalify at 0x7f24c2db9820>':
    Traceback (most recent call last):
      File "/usr/lib/python3.9/site-packages/tavern/schemas/files.py", line 106, in verify_generic
        verifier.validate()
      File "/usr/lib/python3.9/site-packages/pykwalify/core.py", line 194, in validate
        raise SchemaError(u"Schema validation failed:\n - {error_msg}.".format(
    pykwalify.errors.SchemaError: <SchemaError: error code 2: Schema validation failed:
     - Cannot find required key 'off'. Path: ''.
     - Key 'on' was not defined. Path: ''.: Path: '/'>

    The above exception was the direct cause of the following exception:

    Traceback (most recent call last):
      File "/usr/lib/python3.9/site-packages/tavern/response/base.py", line 152, in _maybe_run_validate_functions
        vf(response)
      File "/usr/lib/python3.9/site-packages/tavern/util/extfunctions.py", line 98, in inner
        result = func(response, *args, **kwargs)
      File "/usr/lib/python3.9/site-packages/tavern/testutils/helpers.py", line 103, in validate_pykwalify
        verify_generic(to_verify, schema)
      File "/usr/lib/python3.9/site-packages/tavern/schemas/files.py", line 109, in verify_generic
        raise BadSchemaError() from e
    tavern.util.exceptions.BadSchemaError
Traceback (most recent call last):
  File "/usr/lib/python3.9/site-packages/tavern/schemas/files.py", line 106, in verify_generic
    verifier.validate()
  File "/usr/lib/python3.9/site-packages/pykwalify/core.py", line 194, in validate
    raise SchemaError(u"Schema validation failed:\n - {error_msg}.".format(
pykwalify.errors.SchemaError: <SchemaError: error code 2: Schema validation failed:
 - Cannot find required key 'off'. Path: ''.
 - Key 'on' was not defined. Path: ''.: Path: '/'>

The above exception was the direct cause of the following exception:

Traceback (most recent call last):
  File "/usr/lib/python3.9/site-packages/tavern/response/base.py", line 152, in _maybe_run_validate_functions
    vf(response)
  File "/usr/lib/python3.9/site-packages/tavern/util/extfunctions.py", line 98, in inner
    result = func(response, *args, **kwargs)
  File "/usr/lib/python3.9/site-packages/tavern/testutils/helpers.py", line 103, in validate_pykwalify
    verify_generic(to_verify, schema)
  File "/usr/lib/python3.9/site-packages/tavern/schemas/files.py", line 109, in verify_generic
    raise BadSchemaError() from e
tavern.util.exceptions.BadSchemaError
[31m[1mERROR   [0m pykwalify.core:core.py:190 validation.invalid
[31m[1mERROR   [0m pykwalify.core:core.py:191  --- All found errors ---
[31m[1mERROR   [0m pykwalify.core:core.py:192 ["Cannot find required key 'off'. Path: ''", "Key 'on' was not defined. Path: ''"]
[31m[1mERROR   [0m tavern.schemas.files:files.py:108 Error validating {'e': 0, 'err_msg': '', 'on': ['x1000c0s4b1n0', 'x3000c0s6b0n0']}
Traceback (most recent call last):
  File "/usr/lib/python3.9/site-packages/tavern/schemas/files.py", line 106, in verify_generic
    verifier.validate()
  File "/usr/lib/python3.9/site-packages/pykwalify/core.py", line 194, in validate
    raise SchemaError(u"Schema validation failed:\n - {error_msg}.".format(
pykwalify.errors.SchemaError: <SchemaError: error code 2: Schema validation failed:
 - Cannot find required key 'off'. Path: ''.
 - Key 'on' was not defined. Path: ''.: Path: '/'>
[31m[1mERROR   [0m tavern.response.base:base.py:41 Error calling validate function '<function validate_pykwalify at 0x7f24c2db9820>':
    Traceback (most recent call last):
      File "/usr/lib/python3.9/site-packages/tavern/schemas/files.py", line 106, in verify_generic
        verifier.validate()
      File "/usr/lib/python3.9/site-packages/pykwalify/core.py", line 194, in validate
        raise SchemaError(u"Schema validation failed:\n - {error_msg}.".format(
    pykwalify.errors.SchemaError: <SchemaError: error code 2: Schema validation failed:
     - Cannot find required key 'off'. Path: ''.
     - Key 'on' was not defined. Path: ''.: Path: '/'>

    The above exception was the direct cause of the following exception:

    Traceback (most recent call last):
      File "/usr/lib/python3.9/site-packages/tavern/response/base.py", line 152, in _maybe_run_validate_functions
        vf(response)
      File "/usr/lib/python3.9/site-packages/tavern/util/extfunctions.py", line 98, in inner
        result = func(response, *args, **kwargs)
      File "/usr/lib/python3.9/site-packages/tavern/testutils/helpers.py", line 103, in validate_pykwalify
        verify_generic(to_verify, schema)
      File "/usr/lib/python3.9/site-packages/tavern/schemas/files.py", line 109, in verify_generic
        raise BadSchemaError() from e
    tavern.util.exceptions.BadSchemaError
Traceback (most recent call last):
  File "/usr/lib/python3.9/site-packages/tavern/schemas/files.py", line 106, in verify_generic
    verifier.validate()
  File "/usr/lib/python3.9/site-packages/pykwalify/core.py", line 194, in validate
    raise SchemaError(u"Schema validation failed:\n - {error_msg}.".format(
pykwalify.errors.SchemaError: <SchemaError: error code 2: Schema validation failed:
 - Cannot find required key 'off'. Path: ''.
 - Key 'on' was not defined. Path: ''.: Path: '/'>

The above exception was the direct cause of the following exception:

Traceback (most recent call last):
  File "/usr/lib/python3.9/site-packages/tavern/response/base.py", line 152, in _maybe_run_validate_functions
    vf(response)
  File "/usr/lib/python3.9/site-packages/tavern/util/extfunctions.py", line 98, in inner
    result = func(response, *args, **kwargs)
  File "/usr/lib/python3.9/site-packages/tavern/testutils/helpers.py", line 103, in validate_pykwalify
    verify_generic(to_verify, schema)
  File "/usr/lib/python3.9/site-packages/tavern/schemas/files.py", line 109, in verify_generic
    raise BadSchemaError() from e
tavern.util.exceptions.BadSchemaError
[31m[1mERROR   [0m pykwalify.core:core.py:190 validation.invalid
[31m[1mERROR   [0m pykwalify.core:core.py:191  --- All found errors ---
[31m[1mERROR   [0m pykwalify.core:core.py:192 ["Cannot find required key 'off'. Path: ''", "Key 'on' was not defined. Path: ''"]
[31m[1mERROR   [0m tavern.schemas.files:files.py:108 Error validating {'e': 0, 'err_msg': '', 'on': ['x1000c0s4b1n0', 'x3000c0s6b0n0']}
Traceback (most recent call last):
  File "/usr/lib/python3.9/site-packages/tavern/schemas/files.py", line 106, in verify_generic
    verifier.validate()
  File "/usr/lib/python3.9/site-packages/pykwalify/core.py", line 194, in validate
    raise SchemaError(u"Schema validation failed:\n - {error_msg}.".format(
pykwalify.errors.SchemaError: <SchemaError: error code 2: Schema validation failed:
 - Cannot find required key 'off'. Path: ''.
 - Key 'on' was not defined. Path: ''.: Path: '/'>
[31m[1mERROR   [0m tavern.response.base:base.py:41 Error calling validate function '<function validate_pykwalify at 0x7f24c2db9820>':
    Traceback (most recent call last):
      File "/usr/lib/python3.9/site-packages/tavern/schemas/files.py", line 106, in verify_generic
        verifier.validate()
      File "/usr/lib/python3.9/site-packages/pykwalify/core.py", line 194, in validate
        raise SchemaError(u"Schema validation failed:\n - {error_msg}.".format(
    pykwalify.errors.SchemaError: <SchemaError: error code 2: Schema validation failed:
     - Cannot find required key 'off'. Path: ''.
     - Key 'on' was not defined. Path: ''.: Path: '/'>

    The above exception was the direct cause of the following exception:

    Traceback (most recent call last):
      File "/usr/lib/python3.9/site-packages/tavern/response/base.py", line 152, in _maybe_run_validate_functions
        vf(response)
      File "/usr/lib/python3.9/site-packages/tavern/util/extfunctions.py", line 98, in inner
        result = func(response, *args, **kwargs)
      File "/usr/lib/python3.9/site-packages/tavern/testutils/helpers.py", line 103, in validate_pykwalify
        verify_generic(to_verify, schema)
      File "/usr/lib/python3.9/site-packages/tavern/schemas/files.py", line 109, in verify_generic
        raise BadSchemaError() from e
    tavern.util.exceptions.BadSchemaError
Traceback (most recent call last):
  File "/usr/lib/python3.9/site-packages/tavern/schemas/files.py", line 106, in verify_generic
    verifier.validate()
  File "/usr/lib/python3.9/site-packages/pykwalify/core.py", line 194, in validate
    raise SchemaError(u"Schema validation failed:\n - {error_msg}.".format(
pykwalify.errors.SchemaError: <SchemaError: error code 2: Schema validation failed:
 - Cannot find required key 'off'. Path: ''.
 - Key 'on' was not defined. Path: ''.: Path: '/'>

The above exception was the direct cause of the following exception:

Traceback (most recent call last):
  File "/usr/lib/python3.9/site-packages/tavern/response/base.py", line 152, in _maybe_run_validate_functions
    vf(response)
  File "/usr/lib/python3.9/site-packages/tavern/util/extfunctions.py", line 98, in inner
    result = func(response, *args, **kwargs)
  File "/usr/lib/python3.9/site-packages/tavern/testutils/helpers.py", line 103, in validate_pykwalify
    verify_generic(to_verify, schema)
  File "/usr/lib/python3.9/site-packages/tavern/schemas/files.py", line 109, in verify_generic
    raise BadSchemaError() from e
tavern.util.exceptions.BadSchemaError
[31m[1mERROR   [0m pykwalify.core:core.py:190 validation.invalid
[31m[1mERROR   [0m pykwalify.core:core.py:191  --- All found errors ---
[31m[1mERROR   [0m pykwalify.core:core.py:192 ["Cannot find required key 'off'. Path: ''", "Key 'on' was not defined. Path: ''"]
[31m[1mERROR   [0m tavern.schemas.files:files.py:108 Error validating {'e': 0, 'err_msg': '', 'on': ['x1000c0s4b1n0', 'x3000c0s6b0n0']}
Traceback (most recent call last):
  File "/usr/lib/python3.9/site-packages/tavern/schemas/files.py", line 106, in verify_generic
    verifier.validate()
  File "/usr/lib/python3.9/site-packages/pykwalify/core.py", line 194, in validate
    raise SchemaError(u"Schema validation failed:\n - {error_msg}.".format(
pykwalify.errors.SchemaError: <SchemaError: error code 2: Schema validation failed:
 - Cannot find required key 'off'. Path: ''.
 - Key 'on' was not defined. Path: ''.: Path: '/'>
[31m[1mERROR   [0m tavern.response.base:base.py:41 Error calling validate function '<function validate_pykwalify at 0x7f24c2db9820>':
    Traceback (most recent call last):
      File "/usr/lib/python3.9/site-packages/tavern/schemas/files.py", line 106, in verify_generic
        verifier.validate()
      File "/usr/lib/python3.9/site-packages/pykwalify/core.py", line 194, in validate
        raise SchemaError(u"Schema validation failed:\n - {error_msg}.".format(
    pykwalify.errors.SchemaError: <SchemaError: error code 2: Schema validation failed:
     - Cannot find required key 'off'. Path: ''.
     - Key 'on' was not defined. Path: ''.: Path: '/'>

    The above exception was the direct cause of the following exception:

    Traceback (most recent call last):
      File "/usr/lib/python3.9/site-packages/tavern/response/base.py", line 152, in _maybe_run_validate_functions
        vf(response)
      File "/usr/lib/python3.9/site-packages/tavern/util/extfunctions.py", line 98, in inner
        result = func(response, *args, **kwargs)
      File "/usr/lib/python3.9/site-packages/tavern/testutils/helpers.py", line 103, in validate_pykwalify
        verify_generic(to_verify, schema)
      File "/usr/lib/python3.9/site-packages/tavern/schemas/files.py", line 109, in verify_generic
        raise BadSchemaError() from e
    tavern.util.exceptions.BadSchemaError
Traceback (most recent call last):
  File "/usr/lib/python3.9/site-packages/tavern/schemas/files.py", line 106, in verify_generic
    verifier.validate()
  File "/usr/lib/python3.9/site-packages/pykwalify/core.py", line 194, in validate
    raise SchemaError(u"Schema validation failed:\n - {error_msg}.".format(
pykwalify.errors.SchemaError: <SchemaError: error code 2: Schema validation failed:
 - Cannot find required key 'off'. Path: ''.
 - Key 'on' was not defined. Path: ''.: Path: '/'>

The above exception was the direct cause of the following exception:

Traceback (most recent call last):
  File "/usr/lib/python3.9/site-packages/tavern/response/base.py", line 152, in _maybe_run_validate_functions
    vf(response)
  File "/usr/lib/python3.9/site-packages/tavern/util/extfunctions.py", line 98, in inner
    result = func(response, *args, **kwargs)
  File "/usr/lib/python3.9/site-packages/tavern/testutils/helpers.py", line 103, in validate_pykwalify
    verify_generic(to_verify, schema)
  File "/usr/lib/python3.9/site-packages/tavern/schemas/files.py", line 109, in verify_generic
    raise BadSchemaError() from e
tavern.util.exceptions.BadSchemaError
[31m[1mERROR   [0m pykwalify.core:core.py:190 validation.invalid
[31m[1mERROR   [0m pykwalify.core:core.py:191  --- All found errors ---
[31m[1mERROR   [0m pykwalify.core:core.py:192 ["Cannot find required key 'off'. Path: ''", "Key 'on' was not defined. Path: ''"]
[31m[1mERROR   [0m tavern.schemas.files:files.py:108 Error validating {'e': 0, 'err_msg': '', 'on': ['x1000c0s4b1n0', 'x3000c0s6b0n0']}
Traceback (most recent call last):
  File "/usr/lib/python3.9/site-packages/tavern/schemas/files.py", line 106, in verify_generic
    verifier.validate()
  File "/usr/lib/python3.9/site-packages/pykwalify/core.py", line 194, in validate
    raise SchemaError(u"Schema validation failed:\n - {error_msg}.".format(
pykwalify.errors.SchemaError: <SchemaError: error code 2: Schema validation failed:
 - Cannot find required key 'off'. Path: ''.
 - Key 'on' was not defined. Path: ''.: Path: '/'>
[31m[1mERROR   [0m tavern.response.base:base.py:41 Error calling validate function '<function validate_pykwalify at 0x7f24c2db9820>':
    Traceback (most recent call last):
      File "/usr/lib/python3.9/site-packages/tavern/schemas/files.py", line 106, in verify_generic
        verifier.validate()
      File "/usr/lib/python3.9/site-packages/pykwalify/core.py", line 194, in validate
        raise SchemaError(u"Schema validation failed:\n - {error_msg}.".format(
    pykwalify.errors.SchemaError: <SchemaError: error code 2: Schema validation failed:
     - Cannot find required key 'off'. Path: ''.
     - Key 'on' was not defined. Path: ''.: Path: '/'>

    The above exception was the direct cause of the following exception:

    Traceback (most recent call last):
      File "/usr/lib/python3.9/site-packages/tavern/response/base.py", line 152, in _maybe_run_validate_functions
        vf(response)
      File "/usr/lib/python3.9/site-packages/tavern/util/extfunctions.py", line 98, in inner
        result = func(response, *args, **kwargs)
      File "/usr/lib/python3.9/site-packages/tavern/testutils/helpers.py", line 103, in validate_pykwalify
        verify_generic(to_verify, schema)
      File "/usr/lib/python3.9/site-packages/tavern/schemas/files.py", line 109, in verify_generic
        raise BadSchemaError() from e
    tavern.util.exceptions.BadSchemaError
Traceback (most recent call last):
  File "/usr/lib/python3.9/site-packages/tavern/schemas/files.py", line 106, in verify_generic
    verifier.validate()
  File "/usr/lib/python3.9/site-packages/pykwalify/core.py", line 194, in validate
    raise SchemaError(u"Schema validation failed:\n - {error_msg}.".format(
pykwalify.errors.SchemaError: <SchemaError: error code 2: Schema validation failed:
 - Cannot find required key 'off'. Path: ''.
 - Key 'on' was not defined. Path: ''.: Path: '/'>

The above exception was the direct cause of the following exception:

Traceback (most recent call last):
  File "/usr/lib/python3.9/site-packages/tavern/response/base.py", line 152, in _maybe_run_validate_functions
    vf(response)
  File "/usr/lib/python3.9/site-packages/tavern/util/extfunctions.py", line 98, in inner
    result = func(response, *args, **kwargs)
  File "/usr/lib/python3.9/site-packages/tavern/testutils/helpers.py", line 103, in validate_pykwalify
    verify_generic(to_verify, schema)
  File "/usr/lib/python3.9/site-packages/tavern/schemas/files.py", line 109, in verify_generic
    raise BadSchemaError() from e
tavern.util.exceptions.BadSchemaError
[31m[1mERROR   [0m pykwalify.core:core.py:190 validation.invalid
[31m[1mERROR   [0m pykwalify.core:core.py:191  --- All found errors ---
[31m[1mERROR   [0m pykwalify.core:core.py:192 ["Cannot find required key 'off'. Path: ''", "Key 'on' was not defined. Path: ''"]
[31m[1mERROR   [0m tavern.schemas.files:files.py:108 Error validating {'e': 0, 'err_msg': '', 'on': ['x1000c0s4b1n0', 'x3000c0s6b0n0']}
Traceback (most recent call last):
  File "/usr/lib/python3.9/site-packages/tavern/schemas/files.py", line 106, in verify_generic
    verifier.validate()
  File "/usr/lib/python3.9/site-packages/pykwalify/core.py", line 194, in validate
    raise SchemaError(u"Schema validation failed:\n - {error_msg}.".format(
pykwalify.errors.SchemaError: <SchemaError: error code 2: Schema validation failed:
 - Cannot find required key 'off'. Path: ''.
 - Key 'on' was not defined. Path: ''.: Path: '/'>
[31m[1mERROR   [0m tavern.response.base:base.py:41 Error calling validate function '<function validate_pykwalify at 0x7f24c2db9820>':
    Traceback (most recent call last):
      File "/usr/lib/python3.9/site-packages/tavern/schemas/files.py", line 106, in verify_generic
        verifier.validate()
      File "/usr/lib/python3.9/site-packages/pykwalify/core.py", line 194, in validate
        raise SchemaError(u"Schema validation failed:\n - {error_msg}.".format(
    pykwalify.errors.SchemaError: <SchemaError: error code 2: Schema validation failed:
     - Cannot find required key 'off'. Path: ''.
     - Key 'on' was not defined. Path: ''.: Path: '/'>

    The above exception was the direct cause of the following exception:

    Traceback (most recent call last):
      File "/usr/lib/python3.9/site-packages/tavern/response/base.py", line 152, in _maybe_run_validate_functions
        vf(response)
      File "/usr/lib/python3.9/site-packages/tavern/util/extfunctions.py", line 98, in inner
        result = func(response, *args, **kwargs)
      File "/usr/lib/python3.9/site-packages/tavern/testutils/helpers.py", line 103, in validate_pykwalify
        verify_generic(to_verify, schema)
      File "/usr/lib/python3.9/site-packages/tavern/schemas/files.py", line 109, in verify_generic
        raise BadSchemaError() from e
    tavern.util.exceptions.BadSchemaError
Traceback (most recent call last):
  File "/usr/lib/python3.9/site-packages/tavern/schemas/files.py", line 106, in verify_generic
    verifier.validate()
  File "/usr/lib/python3.9/site-packages/pykwalify/core.py", line 194, in validate
    raise SchemaError(u"Schema validation failed:\n - {error_msg}.".format(
pykwalify.errors.SchemaError: <SchemaError: error code 2: Schema validation failed:
 - Cannot find required key 'off'. Path: ''.
 - Key 'on' was not defined. Path: ''.: Path: '/'>

The above exception was the direct cause of the following exception:

Traceback (most recent call last):
  File "/usr/lib/python3.9/site-packages/tavern/response/base.py", line 152, in _maybe_run_validate_functions
    vf(response)
  File "/usr/lib/python3.9/site-packages/tavern/util/extfunctions.py", line 98, in inner
    result = func(response, *args, **kwargs)
  File "/usr/lib/python3.9/site-packages/tavern/testutils/helpers.py", line 103, in validate_pykwalify
    verify_generic(to_verify, schema)
  File "/usr/lib/python3.9/site-packages/tavern/schemas/files.py", line 109, in verify_generic
    raise BadSchemaError() from e
tavern.util.exceptions.BadSchemaError
[31m[1mERROR   [0m pykwalify.core:core.py:190 validation.invalid
[31m[1mERROR   [0m pykwalify.core:core.py:191  --- All found errors ---
[31m[1mERROR   [0m pykwalify.core:core.py:192 ["Cannot find required key 'off'. Path: ''", "Key 'on' was not defined. Path: ''"]
[31m[1mERROR   [0m tavern.schemas.files:files.py:108 Error validating {'e': 0, 'err_msg': '', 'on': ['x1000c0s4b1n0', 'x3000c0s6b0n0']}
Traceback (most recent call last):
  File "/usr/lib/python3.9/site-packages/tavern/schemas/files.py", line 106, in verify_generic
    verifier.validate()
  File "/usr/lib/python3.9/site-packages/pykwalify/core.py", line 194, in validate
    raise SchemaError(u"Schema validation failed:\n - {error_msg}.".format(
pykwalify.errors.SchemaError: <SchemaError: error code 2: Schema validation failed:
 - Cannot find required key 'off'. Path: ''.
 - Key 'on' was not defined. Path: ''.: Path: '/'>
[31m[1mERROR   [0m tavern.response.base:base.py:41 Error calling validate function '<function validate_pykwalify at 0x7f24c2db9820>':
    Traceback (most recent call last):
      File "/usr/lib/python3.9/site-packages/tavern/schemas/files.py", line 106, in verify_generic
        verifier.validate()
      File "/usr/lib/python3.9/site-packages/pykwalify/core.py", line 194, in validate
        raise SchemaError(u"Schema validation failed:\n - {error_msg}.".format(
    pykwalify.errors.SchemaError: <SchemaError: error code 2: Schema validation failed:
     - Cannot find required key 'off'. Path: ''.
     - Key 'on' was not defined. Path: ''.: Path: '/'>

    The above exception was the direct cause of the following exception:

    Traceback (most recent call last):
      File "/usr/lib/python3.9/site-packages/tavern/response/base.py", line 152, in _maybe_run_validate_functions
        vf(response)
      File "/usr/lib/python3.9/site-packages/tavern/util/extfunctions.py", line 98, in inner
        result = func(response, *args, **kwargs)
      File "/usr/lib/python3.9/site-packages/tavern/testutils/helpers.py", line 103, in validate_pykwalify
        verify_generic(to_verify, schema)
      File "/usr/lib/python3.9/site-packages/tavern/schemas/files.py", line 109, in verify_generic
        raise BadSchemaError() from e
    tavern.util.exceptions.BadSchemaError
Traceback (most recent call last):
  File "/usr/lib/python3.9/site-packages/tavern/schemas/files.py", line 106, in verify_generic
    verifier.validate()
  File "/usr/lib/python3.9/site-packages/pykwalify/core.py", line 194, in validate
    raise SchemaError(u"Schema validation failed:\n - {error_msg}.".format(
pykwalify.errors.SchemaError: <SchemaError: error code 2: Schema validation failed:
 - Cannot find required key 'off'. Path: ''.
 - Key 'on' was not defined. Path: ''.: Path: '/'>

The above exception was the direct cause of the following exception:

Traceback (most recent call last):
  File "/usr/lib/python3.9/site-packages/tavern/response/base.py", line 152, in _maybe_run_validate_functions
    vf(response)
  File "/usr/lib/python3.9/site-packages/tavern/util/extfunctions.py", line 98, in inner
    result = func(response, *args, **kwargs)
  File "/usr/lib/python3.9/site-packages/tavern/testutils/helpers.py", line 103, in validate_pykwalify
    verify_generic(to_verify, schema)
  File "/usr/lib/python3.9/site-packages/tavern/schemas/files.py", line 109, in verify_generic
    raise BadSchemaError() from e
tavern.util.exceptions.BadSchemaError
[31m[1mERROR   [0m pykwalify.core:core.py:190 validation.invalid
[31m[1mERROR   [0m pykwalify.core:core.py:191  --- All found errors ---
[31m[1mERROR   [0m pykwalify.core:core.py:192 ["Cannot find required key 'off'. Path: ''", "Key 'on' was not defined. Path: ''"]
[31m[1mERROR   [0m tavern.schemas.files:files.py:108 Error validating {'e': 0, 'err_msg': '', 'on': ['x1000c0s4b1n0', 'x3000c0s6b0n0']}
Traceback (most recent call last):
  File "/usr/lib/python3.9/site-packages/tavern/schemas/files.py", line 106, in verify_generic
    verifier.validate()
  File "/usr/lib/python3.9/site-packages/pykwalify/core.py", line 194, in validate
    raise SchemaError(u"Schema validation failed:\n - {error_msg}.".format(
pykwalify.errors.SchemaError: <SchemaError: error code 2: Schema validation failed:
 - Cannot find required key 'off'. Path: ''.
 - Key 'on' was not defined. Path: ''.: Path: '/'>
[31m[1mERROR   [0m tavern.response.base:base.py:41 Error calling validate function '<function validate_pykwalify at 0x7f24c2db9820>':
    Traceback (most recent call last):
      File "/usr/lib/python3.9/site-packages/tavern/schemas/files.py", line 106, in verify_generic
        verifier.validate()
      File "/usr/lib/python3.9/site-packages/pykwalify/core.py", line 194, in validate
        raise SchemaError(u"Schema validation failed:\n - {error_msg}.".format(
    pykwalify.errors.SchemaError: <SchemaError: error code 2: Schema validation failed:
     - Cannot find required key 'off'. Path: ''.
     - Key 'on' was not defined. Path: ''.: Path: '/'>

    The above exception was the direct cause of the following exception:

    Traceback (most recent call last):
      File "/usr/lib/python3.9/site-packages/tavern/response/base.py", line 152, in _maybe_run_validate_functions
        vf(response)
      File "/usr/lib/python3.9/site-packages/tavern/util/extfunctions.py", line 98, in inner
        result = func(response, *args, **kwargs)
      File "/usr/lib/python3.9/site-packages/tavern/testutils/helpers.py", line 103, in validate_pykwalify
        verify_generic(to_verify, schema)
      File "/usr/lib/python3.9/site-packages/tavern/schemas/files.py", line 109, in verify_generic
        raise BadSchemaError() from e
    tavern.util.exceptions.BadSchemaError
Traceback (most recent call last):
  File "/usr/lib/python3.9/site-packages/tavern/schemas/files.py", line 106, in verify_generic
    verifier.validate()
  File "/usr/lib/python3.9/site-packages/pykwalify/core.py", line 194, in validate
    raise SchemaError(u"Schema validation failed:\n - {error_msg}.".format(
pykwalify.errors.SchemaError: <SchemaError: error code 2: Schema validation failed:
 - Cannot find required key 'off'. Path: ''.
 - Key 'on' was not defined. Path: ''.: Path: '/'>

The above exception was the direct cause of the following exception:

Traceback (most recent call last):
  File "/usr/lib/python3.9/site-packages/tavern/response/base.py", line 152, in _maybe_run_validate_functions
    vf(response)
  File "/usr/lib/python3.9/site-packages/tavern/util/extfunctions.py", line 98, in inner
    result = func(response, *args, **kwargs)
  File "/usr/lib/python3.9/site-packages/tavern/testutils/helpers.py", line 103, in validate_pykwalify
    verify_generic(to_verify, schema)
  File "/usr/lib/python3.9/site-packages/tavern/schemas/files.py", line 109, in verify_generic
    raise BadSchemaError() from e
tavern.util.exceptions.BadSchemaError
[31m[1mERROR   [0m pykwalify.core:core.py:190 validation.invalid
[31m[1mERROR   [0m pykwalify.core:core.py:191  --- All found errors ---
[31m[1mERROR   [0m pykwalify.core:core.py:192 ["Cannot find required key 'off'. Path: ''", "Key 'on' was not defined. Path: ''"]
[31m[1mERROR   [0m tavern.schemas.files:files.py:108 Error validating {'e': 0, 'err_msg': '', 'on': ['x1000c0s4b1n0', 'x3000c0s6b0n0']}
Traceback (most recent call last):
  File "/usr/lib/python3.9/site-packages/tavern/schemas/files.py", line 106, in verify_generic
    verifier.validate()
  File "/usr/lib/python3.9/site-packages/pykwalify/core.py", line 194, in validate
    raise SchemaError(u"Schema validation failed:\n - {error_msg}.".format(
pykwalify.errors.SchemaError: <SchemaError: error code 2: Schema validation failed:
 - Cannot find required key 'off'. Path: ''.
 - Key 'on' was not defined. Path: ''.: Path: '/'>
[31m[1mERROR   [0m tavern.response.base:base.py:41 Error calling validate function '<function validate_pykwalify at 0x7f24c2db9820>':
    Traceback (most recent call last):
      File "/usr/lib/python3.9/site-packages/tavern/schemas/files.py", line 106, in verify_generic
        verifier.validate()
      File "/usr/lib/python3.9/site-packages/pykwalify/core.py", line 194, in validate
        raise SchemaError(u"Schema validation failed:\n - {error_msg}.".format(
    pykwalify.errors.SchemaError: <SchemaError: error code 2: Schema validation failed:
     - Cannot find required key 'off'. Path: ''.
     - Key 'on' was not defined. Path: ''.: Path: '/'>

    The above exception was the direct cause of the following exception:

    Traceback (most recent call last):
      File "/usr/lib/python3.9/site-packages/tavern/response/base.py", line 152, in _maybe_run_validate_functions
        vf(response)
      File "/usr/lib/python3.9/site-packages/tavern/util/extfunctions.py", line 98, in inner
        result = func(response, *args, **kwargs)
      File "/usr/lib/python3.9/site-packages/tavern/testutils/helpers.py", line 103, in validate_pykwalify
        verify_generic(to_verify, schema)
      File "/usr/lib/python3.9/site-packages/tavern/schemas/files.py", line 109, in verify_generic
        raise BadSchemaError() from e
    tavern.util.exceptions.BadSchemaError
Traceback (most recent call last):
  File "/usr/lib/python3.9/site-packages/tavern/schemas/files.py", line 106, in verify_generic
    verifier.validate()
  File "/usr/lib/python3.9/site-packages/pykwalify/core.py", line 194, in validate
    raise SchemaError(u"Schema validation failed:\n - {error_msg}.".format(
pykwalify.errors.SchemaError: <SchemaError: error code 2: Schema validation failed:
 - Cannot find required key 'off'. Path: ''.
 - Key 'on' was not defined. Path: ''.: Path: '/'>

The above exception was the direct cause of the following exception:

Traceback (most recent call last):
  File "/usr/lib/python3.9/site-packages/tavern/response/base.py", line 152, in _maybe_run_validate_functions
    vf(response)
  File "/usr/lib/python3.9/site-packages/tavern/util/extfunctions.py", line 98, in inner
    result = func(response, *args, **kwargs)
  File "/usr/lib/python3.9/site-packages/tavern/testutils/helpers.py", line 103, in validate_pykwalify
    verify_generic(to_verify, schema)
  File "/usr/lib/python3.9/site-packages/tavern/schemas/files.py", line 109, in verify_generic
    raise BadSchemaError() from e
tavern.util.exceptions.BadSchemaError
[31m[1mERROR   [0m pykwalify.core:core.py:190 validation.invalid
[31m[1mERROR   [0m pykwalify.core:core.py:191  --- All found errors ---
[31m[1mERROR   [0m pykwalify.core:core.py:192 ["Cannot find required key 'off'. Path: ''", "Key 'on' was not defined. Path: ''"]
[31m[1mERROR   [0m tavern.schemas.files:files.py:108 Error validating {'e': 0, 'err_msg': '', 'on': ['x1000c0s4b1n0', 'x3000c0s6b0n0']}
Traceback (most recent call last):
  File "/usr/lib/python3.9/site-packages/tavern/schemas/files.py", line 106, in verify_generic
    verifier.validate()
  File "/usr/lib/python3.9/site-packages/pykwalify/core.py", line 194, in validate
    raise SchemaError(u"Schema validation failed:\n - {error_msg}.".format(
pykwalify.errors.SchemaError: <SchemaError: error code 2: Schema validation failed:
 - Cannot find required key 'off'. Path: ''.
 - Key 'on' was not defined. Path: ''.: Path: '/'>
[31m[1mERROR   [0m tavern.response.base:base.py:41 Error calling validate function '<function validate_pykwalify at 0x7f24c2db9820>':
    Traceback (most recent call last):
      File "/usr/lib/python3.9/site-packages/tavern/schemas/files.py", line 106, in verify_generic
        verifier.validate()
      File "/usr/lib/python3.9/site-packages/pykwalify/core.py", line 194, in validate
        raise SchemaError(u"Schema validation failed:\n - {error_msg}.".format(
    pykwalify.errors.SchemaError: <SchemaError: error code 2: Schema validation failed:
     - Cannot find required key 'off'. Path: ''.
     - Key 'on' was not defined. Path: ''.: Path: '/'>

    The above exception was the direct cause of the following exception:

    Traceback (most recent call last):
      File "/usr/lib/python3.9/site-packages/tavern/response/base.py", line 152, in _maybe_run_validate_functions
        vf(response)
      File "/usr/lib/python3.9/site-packages/tavern/util/extfunctions.py", line 98, in inner
        result = func(response, *args, **kwargs)
      File "/usr/lib/python3.9/site-packages/tavern/testutils/helpers.py", line 103, in validate_pykwalify
        verify_generic(to_verify, schema)
      File "/usr/lib/python3.9/site-packages/tavern/schemas/files.py", line 109, in verify_generic
        raise BadSchemaError() from e
    tavern.util.exceptions.BadSchemaError
Traceback (most recent call last):
  File "/usr/lib/python3.9/site-packages/tavern/schemas/files.py", line 106, in verify_generic
    verifier.validate()
  File "/usr/lib/python3.9/site-packages/pykwalify/core.py", line 194, in validate
    raise SchemaError(u"Schema validation failed:\n - {error_msg}.".format(
pykwalify.errors.SchemaError: <SchemaError: error code 2: Schema validation failed:
 - Cannot find required key 'off'. Path: ''.
 - Key 'on' was not defined. Path: ''.: Path: '/'>

The above exception was the direct cause of the following exception:

Traceback (most recent call last):
  File "/usr/lib/python3.9/site-packages/tavern/response/base.py", line 152, in _maybe_run_validate_functions
    vf(response)
  File "/usr/lib/python3.9/site-packages/tavern/util/extfunctions.py", line 98, in inner
    result = func(response, *args, **kwargs)
  File "/usr/lib/python3.9/site-packages/tavern/testutils/helpers.py", line 103, in validate_pykwalify
    verify_generic(to_verify, schema)
  File "/usr/lib/python3.9/site-packages/tavern/schemas/files.py", line 109, in verify_generic
    raise BadSchemaError() from e
tavern.util.exceptions.BadSchemaError
[31m[1mERROR   [0m pykwalify.core:core.py:190 validation.invalid
[31m[1mERROR   [0m pykwalify.core:core.py:191  --- All found errors ---
[31m[1mERROR   [0m pykwalify.core:core.py:192 ["Cannot find required key 'off'. Path: ''", "Key 'on' was not defined. Path: ''"]
[31m[1mERROR   [0m tavern.schemas.files:files.py:108 Error validating {'e': 0, 'err_msg': '', 'on': ['x1000c0s4b1n0', 'x3000c0s6b0n0']}
Traceback (most recent call last):
  File "/usr/lib/python3.9/site-packages/tavern/schemas/files.py", line 106, in verify_generic
    verifier.validate()
  File "/usr/lib/python3.9/site-packages/pykwalify/core.py", line 194, in validate
    raise SchemaError(u"Schema validation failed:\n - {error_msg}.".format(
pykwalify.errors.SchemaError: <SchemaError: error code 2: Schema validation failed:
 - Cannot find required key 'off'. Path: ''.
 - Key 'on' was not defined. Path: ''.: Path: '/'>
[31m[1mERROR   [0m tavern.response.base:base.py:41 Error calling validate function '<function validate_pykwalify at 0x7f24c2db9820>':
    Traceback (most recent call last):
      File "/usr/lib/python3.9/site-packages/tavern/schemas/files.py", line 106, in verify_generic
        verifier.validate()
      File "/usr/lib/python3.9/site-packages/pykwalify/core.py", line 194, in validate
        raise SchemaError(u"Schema validation failed:\n - {error_msg}.".format(
    pykwalify.errors.SchemaError: <SchemaError: error code 2: Schema validation failed:
     - Cannot find required key 'off'. Path: ''.
     - Key 'on' was not defined. Path: ''.: Path: '/'>

    The above exception was the direct cause of the following exception:

    Traceback (most recent call last):
      File "/usr/lib/python3.9/site-packages/tavern/response/base.py", line 152, in _maybe_run_validate_functions
        vf(response)
      File "/usr/lib/python3.9/site-packages/tavern/util/extfunctions.py", line 98, in inner
        result = func(response, *args, **kwargs)
      File "/usr/lib/python3.9/site-packages/tavern/testutils/helpers.py", line 103, in validate_pykwalify
        verify_generic(to_verify, schema)
      File "/usr/lib/python3.9/site-packages/tavern/schemas/files.py", line 109, in verify_generic
        raise BadSchemaError() from e
    tavern.util.exceptions.BadSchemaError
Traceback (most recent call last):
  File "/usr/lib/python3.9/site-packages/tavern/schemas/files.py", line 106, in verify_generic
    verifier.validate()
  File "/usr/lib/python3.9/site-packages/pykwalify/core.py", line 194, in validate
    raise SchemaError(u"Schema validation failed:\n - {error_msg}.".format(
pykwalify.errors.SchemaError: <SchemaError: error code 2: Schema validation failed:
 - Cannot find required key 'off'. Path: ''.
 - Key 'on' was not defined. Path: ''.: Path: '/'>

The above exception was the direct cause of the following exception:

Traceback (most recent call last):
  File "/usr/lib/python3.9/site-packages/tavern/response/base.py", line 152, in _maybe_run_validate_functions
    vf(response)
  File "/usr/lib/python3.9/site-packages/tavern/util/extfunctions.py", line 98, in inner
    result = func(response, *args, **kwargs)
  File "/usr/lib/python3.9/site-packages/tavern/testutils/helpers.py", line 103, in validate_pykwalify
    verify_generic(to_verify, schema)
  File "/usr/lib/python3.9/site-packages/tavern/schemas/files.py", line 109, in verify_generic
    raise BadSchemaError() from e
tavern.util.exceptions.BadSchemaError
[31m[1mERROR   [0m pykwalify.core:core.py:190 validation.invalid
[31m[1mERROR   [0m pykwalify.core:core.py:191  --- All found errors ---
[31m[1mERROR   [0m pykwalify.core:core.py:192 ["Cannot find required key 'off'. Path: ''", "Key 'on' was not defined. Path: ''"]
[31m[1mERROR   [0m tavern.schemas.files:files.py:108 Error validating {'e': 0, 'err_msg': '', 'on': ['x1000c0s4b1n0', 'x3000c0s6b0n0']}
Traceback (most recent call last):
  File "/usr/lib/python3.9/site-packages/tavern/schemas/files.py", line 106, in verify_generic
    verifier.validate()
  File "/usr/lib/python3.9/site-packages/pykwalify/core.py", line 194, in validate
    raise SchemaError(u"Schema validation failed:\n - {error_msg}.".format(
pykwalify.errors.SchemaError: <SchemaError: error code 2: Schema validation failed:
 - Cannot find required key 'off'. Path: ''.
 - Key 'on' was not defined. Path: ''.: Path: '/'>
[31m[1mERROR   [0m tavern.response.base:base.py:41 Error calling validate function '<function validate_pykwalify at 0x7f24c2db9820>':
    Traceback (most recent call last):
      File "/usr/lib/python3.9/site-packages/tavern/schemas/files.py", line 106, in verify_generic
        verifier.validate()
      File "/usr/lib/python3.9/site-packages/pykwalify/core.py", line 194, in validate
        raise SchemaError(u"Schema validation failed:\n - {error_msg}.".format(
    pykwalify.errors.SchemaError: <SchemaError: error code 2: Schema validation failed:
     - Cannot find required key 'off'. Path: ''.
     - Key 'on' was not defined. Path: ''.: Path: '/'>

    The above exception was the direct cause of the following exception:

    Traceback (most recent call last):
      File "/usr/lib/python3.9/site-packages/tavern/response/base.py", line 152, in _maybe_run_validate_functions
        vf(response)
      File "/usr/lib/python3.9/site-packages/tavern/util/extfunctions.py", line 98, in inner
        result = func(response, *args, **kwargs)
      File "/usr/lib/python3.9/site-packages/tavern/testutils/helpers.py", line 103, in validate_pykwalify
        verify_generic(to_verify, schema)
      File "/usr/lib/python3.9/site-packages/tavern/schemas/files.py", line 109, in verify_generic
        raise BadSchemaError() from e
    tavern.util.exceptions.BadSchemaError
Traceback (most recent call last):
  File "/usr/lib/python3.9/site-packages/tavern/schemas/files.py", line 106, in verify_generic
    verifier.validate()
  File "/usr/lib/python3.9/site-packages/pykwalify/core.py", line 194, in validate
    raise SchemaError(u"Schema validation failed:\n - {error_msg}.".format(
pykwalify.errors.SchemaError: <SchemaError: error code 2: Schema validation failed:
 - Cannot find required key 'off'. Path: ''.
 - Key 'on' was not defined. Path: ''.: Path: '/'>

The above exception was the direct cause of the following exception:

Traceback (most recent call last):
  File "/usr/lib/python3.9/site-packages/tavern/response/base.py", line 152, in _maybe_run_validate_functions
    vf(response)
  File "/usr/lib/python3.9/site-packages/tavern/util/extfunctions.py", line 98, in inner
    result = func(response, *args, **kwargs)
  File "/usr/lib/python3.9/site-packages/tavern/testutils/helpers.py", line 103, in validate_pykwalify
    verify_generic(to_verify, schema)
  File "/usr/lib/python3.9/site-packages/tavern/schemas/files.py", line 109, in verify_generic
    raise BadSchemaError() from e
tavern.util.exceptions.BadSchemaError
[31m[1mERROR   [0m pykwalify.core:core.py:190 validation.invalid
[31m[1mERROR   [0m pykwalify.core:core.py:191  --- All found errors ---
[31m[1mERROR   [0m pykwalify.core:core.py:192 ["Cannot find required key 'off'. Path: ''", "Key 'on' was not defined. Path: ''"]
[31m[1mERROR   [0m tavern.schemas.files:files.py:108 Error validating {'e': 0, 'err_msg': '', 'on': ['x1000c0s4b1n0', 'x3000c0s6b0n0']}
Traceback (most recent call last):
  File "/usr/lib/python3.9/site-packages/tavern/schemas/files.py", line 106, in verify_generic
    verifier.validate()
  File "/usr/lib/python3.9/site-packages/pykwalify/core.py", line 194, in validate
    raise SchemaError(u"Schema validation failed:\n - {error_msg}.".format(
pykwalify.errors.SchemaError: <SchemaError: error code 2: Schema validation failed:
 - Cannot find required key 'off'. Path: ''.
 - Key 'on' was not defined. Path: ''.: Path: '/'>
[31m[1mERROR   [0m tavern.response.base:base.py:41 Error calling validate function '<function validate_pykwalify at 0x7f24c2db9820>':
    Traceback (most recent call last):
      File "/usr/lib/python3.9/site-packages/tavern/schemas/files.py", line 106, in verify_generic
        verifier.validate()
      File "/usr/lib/python3.9/site-packages/pykwalify/core.py", line 194, in validate
        raise SchemaError(u"Schema validation failed:\n - {error_msg}.".format(
    pykwalify.errors.SchemaError: <SchemaError: error code 2: Schema validation failed:
     - Cannot find required key 'off'. Path: ''.
     - Key 'on' was not defined. Path: ''.: Path: '/'>

    The above exception was the direct cause of the following exception:

    Traceback (most recent call last):
      File "/usr/lib/python3.9/site-packages/tavern/response/base.py", line 152, in _maybe_run_validate_functions
        vf(response)
      File "/usr/lib/python3.9/site-packages/tavern/util/extfunctions.py", line 98, in inner
        result = func(response, *args, **kwargs)
      File "/usr/lib/python3.9/site-packages/tavern/testutils/helpers.py", line 103, in validate_pykwalify
        verify_generic(to_verify, schema)
      File "/usr/lib/python3.9/site-packages/tavern/schemas/files.py", line 109, in verify_generic
        raise BadSchemaError() from e
    tavern.util.exceptions.BadSchemaError
Traceback (most recent call last):
  File "/usr/lib/python3.9/site-packages/tavern/schemas/files.py", line 106, in verify_generic
    verifier.validate()
  File "/usr/lib/python3.9/site-packages/pykwalify/core.py", line 194, in validate
    raise SchemaError(u"Schema validation failed:\n - {error_msg}.".format(
pykwalify.errors.SchemaError: <SchemaError: error code 2: Schema validation failed:
 - Cannot find required key 'off'. Path: ''.
 - Key 'on' was not defined. Path: ''.: Path: '/'>

The above exception was the direct cause of the following exception:

Traceback (most recent call last):
  File "/usr/lib/python3.9/site-packages/tavern/response/base.py", line 152, in _maybe_run_validate_functions
    vf(response)
  File "/usr/lib/python3.9/site-packages/tavern/util/extfunctions.py", line 98, in inner
    result = func(response, *args, **kwargs)
  File "/usr/lib/python3.9/site-packages/tavern/testutils/helpers.py", line 103, in validate_pykwalify
    verify_generic(to_verify, schema)
  File "/usr/lib/python3.9/site-packages/tavern/schemas/files.py", line 109, in verify_generic
    raise BadSchemaError() from e
tavern.util.exceptions.BadSchemaError
[31m[1mERROR   [0m pykwalify.core:core.py:190 validation.invalid
[31m[1mERROR   [0m pykwalify.core:core.py:191  --- All found errors ---
[31m[1mERROR   [0m pykwalify.core:core.py:192 ["Cannot find required key 'off'. Path: ''", "Key 'on' was not defined. Path: ''"]
[31m[1mERROR   [0m tavern.schemas.files:files.py:108 Error validating {'e': 0, 'err_msg': '', 'on': ['x1000c0s4b1n0', 'x3000c0s6b0n0']}
Traceback (most recent call last):
  File "/usr/lib/python3.9/site-packages/tavern/schemas/files.py", line 106, in verify_generic
    verifier.validate()
  File "/usr/lib/python3.9/site-packages/pykwalify/core.py", line 194, in validate
    raise SchemaError(u"Schema validation failed:\n - {error_msg}.".format(
pykwalify.errors.SchemaError: <SchemaError: error code 2: Schema validation failed:
 - Cannot find required key 'off'. Path: ''.
 - Key 'on' was not defined. Path: ''.: Path: '/'>
[31m[1mERROR   [0m tavern.response.base:base.py:41 Error calling validate function '<function validate_pykwalify at 0x7f24c2db9820>':
    Traceback (most recent call last):
      File "/usr/lib/python3.9/site-packages/tavern/schemas/files.py", line 106, in verify_generic
        verifier.validate()
      File "/usr/lib/python3.9/site-packages/pykwalify/core.py", line 194, in validate
        raise SchemaError(u"Schema validation failed:\n - {error_msg}.".format(
    pykwalify.errors.SchemaError: <SchemaError: error code 2: Schema validation failed:
     - Cannot find required key 'off'. Path: ''.
     - Key 'on' was not defined. Path: ''.: Path: '/'>

    The above exception was the direct cause of the following exception:

    Traceback (most recent call last):
      File "/usr/lib/python3.9/site-packages/tavern/response/base.py", line 152, in _maybe_run_validate_functions
        vf(response)
      File "/usr/lib/python3.9/site-packages/tavern/util/extfunctions.py", line 98, in inner
        result = func(response, *args, **kwargs)
      File "/usr/lib/python3.9/site-packages/tavern/testutils/helpers.py", line 103, in validate_pykwalify
        verify_generic(to_verify, schema)
      File "/usr/lib/python3.9/site-packages/tavern/schemas/files.py", line 109, in verify_generic
        raise BadSchemaError() from e
    tavern.util.exceptions.BadSchemaError
Traceback (most recent call last):
  File "/usr/lib/python3.9/site-packages/tavern/schemas/files.py", line 106, in verify_generic
    verifier.validate()
  File "/usr/lib/python3.9/site-packages/pykwalify/core.py", line 194, in validate
    raise SchemaError(u"Schema validation failed:\n - {error_msg}.".format(
pykwalify.errors.SchemaError: <SchemaError: error code 2: Schema validation failed:
 - Cannot find required key 'off'. Path: ''.
 - Key 'on' was not defined. Path: ''.: Path: '/'>

The above exception was the direct cause of the following exception:

Traceback (most recent call last):
  File "/usr/lib/python3.9/site-packages/tavern/response/base.py", line 152, in _maybe_run_validate_functions
    vf(response)
  File "/usr/lib/python3.9/site-packages/tavern/util/extfunctions.py", line 98, in inner
    result = func(response, *args, **kwargs)
  File "/usr/lib/python3.9/site-packages/tavern/testutils/helpers.py", line 103, in validate_pykwalify
    verify_generic(to_verify, schema)
  File "/usr/lib/python3.9/site-packages/tavern/schemas/files.py", line 109, in verify_generic
    raise BadSchemaError() from e
tavern.util.exceptions.BadSchemaError
[31m[1mERROR   [0m pykwalify.core:core.py:190 validation.invalid
[31m[1mERROR   [0m pykwalify.core:core.py:191  --- All found errors ---
[31m[1mERROR   [0m pykwalify.core:core.py:192 ["Cannot find required key 'off'. Path: ''", "Key 'on' was not defined. Path: ''"]
[31m[1mERROR   [0m tavern.schemas.files:files.py:108 Error validating {'e': 0, 'err_msg': '', 'on': ['x1000c0s4b1n0', 'x3000c0s6b0n0']}
Traceback (most recent call last):
  File "/usr/lib/python3.9/site-packages/tavern/schemas/files.py", line 106, in verify_generic
    verifier.validate()
  File "/usr/lib/python3.9/site-packages/pykwalify/core.py", line 194, in validate
    raise SchemaError(u"Schema validation failed:\n - {error_msg}.".format(
pykwalify.errors.SchemaError: <SchemaError: error code 2: Schema validation failed:
 - Cannot find required key 'off'. Path: ''.
 - Key 'on' was not defined. Path: ''.: Path: '/'>
[31m[1mERROR   [0m tavern.response.base:base.py:41 Error calling validate function '<function validate_pykwalify at 0x7f24c2db9820>':
    Traceback (most recent call last):
      File "/usr/lib/python3.9/site-packages/tavern/schemas/files.py", line 106, in verify_generic
        verifier.validate()
      File "/usr/lib/python3.9/site-packages/pykwalify/core.py", line 194, in validate
        raise SchemaError(u"Schema validation failed:\n - {error_msg}.".format(
    pykwalify.errors.SchemaError: <SchemaError: error code 2: Schema validation failed:
     - Cannot find required key 'off'. Path: ''.
     - Key 'on' was not defined. Path: ''.: Path: '/'>

    The above exception was the direct cause of the following exception:

    Traceback (most recent call last):
      File "/usr/lib/python3.9/site-packages/tavern/response/base.py", line 152, in _maybe_run_validate_functions
        vf(response)
      File "/usr/lib/python3.9/site-packages/tavern/util/extfunctions.py", line 98, in inner
        result = func(response, *args, **kwargs)
      File "/usr/lib/python3.9/site-packages/tavern/testutils/helpers.py", line 103, in validate_pykwalify
        verify_generic(to_verify, schema)
      File "/usr/lib/python3.9/site-packages/tavern/schemas/files.py", line 109, in verify_generic
        raise BadSchemaError() from e
    tavern.util.exceptions.BadSchemaError
Traceback (most recent call last):
  File "/usr/lib/python3.9/site-packages/tavern/schemas/files.py", line 106, in verify_generic
    verifier.validate()
  File "/usr/lib/python3.9/site-packages/pykwalify/core.py", line 194, in validate
    raise SchemaError(u"Schema validation failed:\n - {error_msg}.".format(
pykwalify.errors.SchemaError: <SchemaError: error code 2: Schema validation failed:
 - Cannot find required key 'off'. Path: ''.
 - Key 'on' was not defined. Path: ''.: Path: '/'>

The above exception was the direct cause of the following exception:

Traceback (most recent call last):
  File "/usr/lib/python3.9/site-packages/tavern/response/base.py", line 152, in _maybe_run_validate_functions
    vf(response)
  File "/usr/lib/python3.9/site-packages/tavern/util/extfunctions.py", line 98, in inner
    result = func(response, *args, **kwargs)
  File "/usr/lib/python3.9/site-packages/tavern/testutils/helpers.py", line 103, in validate_pykwalify
    verify_generic(to_verify, schema)
  File "/usr/lib/python3.9/site-packages/tavern/schemas/files.py", line 109, in verify_generic
    raise BadSchemaError() from e
tavern.util.exceptions.BadSchemaError
[31m[1mERROR   [0m pykwalify.core:core.py:190 validation.invalid
[31m[1mERROR   [0m pykwalify.core:core.py:191  --- All found errors ---
[31m[1mERROR   [0m pykwalify.core:core.py:192 ["Cannot find required key 'off'. Path: ''", "Key 'on' was not defined. Path: ''"]
[31m[1mERROR   [0m tavern.schemas.files:files.py:108 Error validating {'e': 0, 'err_msg': '', 'on': ['x1000c0s4b1n0', 'x3000c0s6b0n0']}
Traceback (most recent call last):
  File "/usr/lib/python3.9/site-packages/tavern/schemas/files.py", line 106, in verify_generic
    verifier.validate()
  File "/usr/lib/python3.9/site-packages/pykwalify/core.py", line 194, in validate
    raise SchemaError(u"Schema validation failed:\n - {error_msg}.".format(
pykwalify.errors.SchemaError: <SchemaError: error code 2: Schema validation failed:
 - Cannot find required key 'off'. Path: ''.
 - Key 'on' was not defined. Path: ''.: Path: '/'>
[31m[1mERROR   [0m tavern.response.base:base.py:41 Error calling validate function '<function validate_pykwalify at 0x7f24c2db9820>':
    Traceback (most recent call last):
      File "/usr/lib/python3.9/site-packages/tavern/schemas/files.py", line 106, in verify_generic
        verifier.validate()
      File "/usr/lib/python3.9/site-packages/pykwalify/core.py", line 194, in validate
        raise SchemaError(u"Schema validation failed:\n - {error_msg}.".format(
    pykwalify.errors.SchemaError: <SchemaError: error code 2: Schema validation failed:
     - Cannot find required key 'off'. Path: ''.
     - Key 'on' was not defined. Path: ''.: Path: '/'>

    The above exception was the direct cause of the following exception:

    Traceback (most recent call last):
      File "/usr/lib/python3.9/site-packages/tavern/response/base.py", line 152, in _maybe_run_validate_functions
        vf(response)
      File "/usr/lib/python3.9/site-packages/tavern/util/extfunctions.py", line 98, in inner
        result = func(response, *args, **kwargs)
      File "/usr/lib/python3.9/site-packages/tavern/testutils/helpers.py", line 103, in validate_pykwalify
        verify_generic(to_verify, schema)
      File "/usr/lib/python3.9/site-packages/tavern/schemas/files.py", line 109, in verify_generic
        raise BadSchemaError() from e
    tavern.util.exceptions.BadSchemaError
Traceback (most recent call last):
  File "/usr/lib/python3.9/site-packages/tavern/schemas/files.py", line 106, in verify_generic
    verifier.validate()
  File "/usr/lib/python3.9/site-packages/pykwalify/core.py", line 194, in validate
    raise SchemaError(u"Schema validation failed:\n - {error_msg}.".format(
pykwalify.errors.SchemaError: <SchemaError: error code 2: Schema validation failed:
 - Cannot find required key 'off'. Path: ''.
 - Key 'on' was not defined. Path: ''.: Path: '/'>

The above exception was the direct cause of the following exception:

Traceback (most recent call last):
  File "/usr/lib/python3.9/site-packages/tavern/response/base.py", line 152, in _maybe_run_validate_functions
    vf(response)
  File "/usr/lib/python3.9/site-packages/tavern/util/extfunctions.py", line 98, in inner
    result = func(response, *args, **kwargs)
  File "/usr/lib/python3.9/site-packages/tavern/testutils/helpers.py", line 103, in validate_pykwalify
    verify_generic(to_verify, schema)
  File "/usr/lib/python3.9/site-packages/tavern/schemas/files.py", line 109, in verify_generic
    raise BadSchemaError() from e
tavern.util.exceptions.BadSchemaError
[31m[1mERROR   [0m pykwalify.core:core.py:190 validation.invalid
[31m[1mERROR   [0m pykwalify.core:core.py:191  --- All found errors ---
[31m[1mERROR   [0m pykwalify.core:core.py:192 ["Cannot find required key 'off'. Path: ''", "Key 'on' was not defined. Path: ''"]
[31m[1mERROR   [0m tavern.schemas.files:files.py:108 Error validating {'e': 0, 'err_msg': '', 'on': ['x1000c0s4b1n0', 'x3000c0s6b0n0']}
Traceback (most recent call last):
  File "/usr/lib/python3.9/site-packages/tavern/schemas/files.py", line 106, in verify_generic
    verifier.validate()
  File "/usr/lib/python3.9/site-packages/pykwalify/core.py", line 194, in validate
    raise SchemaError(u"Schema validation failed:\n - {error_msg}.".format(
pykwalify.errors.SchemaError: <SchemaError: error code 2: Schema validation failed:
 - Cannot find required key 'off'. Path: ''.
 - Key 'on' was not defined. Path: ''.: Path: '/'>
[31m[1mERROR   [0m tavern.response.base:base.py:41 Error calling validate function '<function validate_pykwalify at 0x7f24c2db9820>':
    Traceback (most recent call last):
      File "/usr/lib/python3.9/site-packages/tavern/schemas/files.py", line 106, in verify_generic
        verifier.validate()
      File "/usr/lib/python3.9/site-packages/pykwalify/core.py", line 194, in validate
        raise SchemaError(u"Schema validation failed:\n - {error_msg}.".format(
    pykwalify.errors.SchemaError: <SchemaError: error code 2: Schema validation failed:
     - Cannot find required key 'off'. Path: ''.
     - Key 'on' was not defined. Path: ''.: Path: '/'>

    The above exception was the direct cause of the following exception:

    Traceback (most recent call last):
      File "/usr/lib/python3.9/site-packages/tavern/response/base.py", line 152, in _maybe_run_validate_functions
        vf(response)
      File "/usr/lib/python3.9/site-packages/tavern/util/extfunctions.py", line 98, in inner
        result = func(response, *args, **kwargs)
      File "/usr/lib/python3.9/site-packages/tavern/testutils/helpers.py", line 103, in validate_pykwalify
        verify_generic(to_verify, schema)
      File "/usr/lib/python3.9/site-packages/tavern/schemas/files.py", line 109, in verify_generic
        raise BadSchemaError() from e
    tavern.util.exceptions.BadSchemaError
Traceback (most recent call last):
  File "/usr/lib/python3.9/site-packages/tavern/schemas/files.py", line 106, in verify_generic
    verifier.validate()
  File "/usr/lib/python3.9/site-packages/pykwalify/core.py", line 194, in validate
    raise SchemaError(u"Schema validation failed:\n - {error_msg}.".format(
pykwalify.errors.SchemaError: <SchemaError: error code 2: Schema validation failed:
 - Cannot find required key 'off'. Path: ''.
 - Key 'on' was not defined. Path: ''.: Path: '/'>

The above exception was the direct cause of the following exception:

Traceback (most recent call last):
  File "/usr/lib/python3.9/site-packages/tavern/response/base.py", line 152, in _maybe_run_validate_functions
    vf(response)
  File "/usr/lib/python3.9/site-packages/tavern/util/extfunctions.py", line 98, in inner
    result = func(response, *args, **kwargs)
  File "/usr/lib/python3.9/site-packages/tavern/testutils/helpers.py", line 103, in validate_pykwalify
    verify_generic(to_verify, schema)
  File "/usr/lib/python3.9/site-packages/tavern/schemas/files.py", line 109, in verify_generic
    raise BadSchemaError() from e
tavern.util.exceptions.BadSchemaError
[31m[1mERROR   [0m pykwalify.core:core.py:190 validation.invalid
[31m[1mERROR   [0m pykwalify.core:core.py:191  --- All found errors ---
[31m[1mERROR   [0m pykwalify.core:core.py:192 ["Cannot find required key 'off'. Path: ''", "Key 'on' was not defined. Path: ''"]
[31m[1mERROR   [0m tavern.schemas.files:files.py:108 Error validating {'e': 0, 'err_msg': '', 'on': ['x1000c0s4b1n0', 'x3000c0s6b0n0']}
Traceback (most recent call last):
  File "/usr/lib/python3.9/site-packages/tavern/schemas/files.py", line 106, in verify_generic
    verifier.validate()
  File "/usr/lib/python3.9/site-packages/pykwalify/core.py", line 194, in validate
    raise SchemaError(u"Schema validation failed:\n - {error_msg}.".format(
pykwalify.errors.SchemaError: <SchemaError: error code 2: Schema validation failed:
 - Cannot find required key 'off'. Path: ''.
 - Key 'on' was not defined. Path: ''.: Path: '/'>
[31m[1mERROR   [0m tavern.response.base:base.py:41 Error calling validate function '<function validate_pykwalify at 0x7f24c2db9820>':
    Traceback (most recent call last):
      File "/usr/lib/python3.9/site-packages/tavern/schemas/files.py", line 106, in verify_generic
        verifier.validate()
      File "/usr/lib/python3.9/site-packages/pykwalify/core.py", line 194, in validate
        raise SchemaError(u"Schema validation failed:\n - {error_msg}.".format(
    pykwalify.errors.SchemaError: <SchemaError: error code 2: Schema validation failed:
     - Cannot find required key 'off'. Path: ''.
     - Key 'on' was not defined. Path: ''.: Path: '/'>

    The above exception was the direct cause of the following exception:

    Traceback (most recent call last):
      File "/usr/lib/python3.9/site-packages/tavern/response/base.py", line 152, in _maybe_run_validate_functions
        vf(response)
      File "/usr/lib/python3.9/site-packages/tavern/util/extfunctions.py", line 98, in inner
        result = func(response, *args, **kwargs)
      File "/usr/lib/python3.9/site-packages/tavern/testutils/helpers.py", line 103, in validate_pykwalify
        verify_generic(to_verify, schema)
      File "/usr/lib/python3.9/site-packages/tavern/schemas/files.py", line 109, in verify_generic
        raise BadSchemaError() from e
    tavern.util.exceptions.BadSchemaError
Traceback (most recent call last):
  File "/usr/lib/python3.9/site-packages/tavern/schemas/files.py", line 106, in verify_generic
    verifier.validate()
  File "/usr/lib/python3.9/site-packages/pykwalify/core.py", line 194, in validate
    raise SchemaError(u"Schema validation failed:\n - {error_msg}.".format(
pykwalify.errors.SchemaError: <SchemaError: error code 2: Schema validation failed:
 - Cannot find required key 'off'. Path: ''.
 - Key 'on' was not defined. Path: ''.: Path: '/'>

The above exception was the direct cause of the following exception:

Traceback (most recent call last):
  File "/usr/lib/python3.9/site-packages/tavern/response/base.py", line 152, in _maybe_run_validate_functions
    vf(response)
  File "/usr/lib/python3.9/site-packages/tavern/util/extfunctions.py", line 98, in inner
    result = func(response, *args, **kwargs)
  File "/usr/lib/python3.9/site-packages/tavern/testutils/helpers.py", line 103, in validate_pykwalify
    verify_generic(to_verify, schema)
  File "/usr/lib/python3.9/site-packages/tavern/schemas/files.py", line 109, in verify_generic
    raise BadSchemaError() from e
tavern.util.exceptions.BadSchemaError
[31m[1mERROR   [0m pykwalify.core:core.py:190 validation.invalid
[31m[1mERROR   [0m pykwalify.core:core.py:191  --- All found errors ---
[31m[1mERROR   [0m pykwalify.core:core.py:192 ["Cannot find required key 'off'. Path: ''", "Key 'on' was not defined. Path: ''"]
[31m[1mERROR   [0m tavern.schemas.files:files.py:108 Error validating {'e': 0, 'err_msg': '', 'on': ['x1000c0s4b1n0', 'x3000c0s6b0n0']}
Traceback (most recent call last):
  File "/usr/lib/python3.9/site-packages/tavern/schemas/files.py", line 106, in verify_generic
    verifier.validate()
  File "/usr/lib/python3.9/site-packages/pykwalify/core.py", line 194, in validate
    raise SchemaError(u"Schema validation failed:\n - {error_msg}.".format(
pykwalify.errors.SchemaError: <SchemaError: error code 2: Schema validation failed:
 - Cannot find required key 'off'. Path: ''.
 - Key 'on' was not defined. Path: ''.: Path: '/'>
[31m[1mERROR   [0m tavern.response.base:base.py:41 Error calling validate function '<function validate_pykwalify at 0x7f24c2db9820>':
    Traceback (most recent call last):
      File "/usr/lib/python3.9/site-packages/tavern/schemas/files.py", line 106, in verify_generic
        verifier.validate()
      File "/usr/lib/python3.9/site-packages/pykwalify/core.py", line 194, in validate
        raise SchemaError(u"Schema validation failed:\n - {error_msg}.".format(
    pykwalify.errors.SchemaError: <SchemaError: error code 2: Schema validation failed:
     - Cannot find required key 'off'. Path: ''.
     - Key 'on' was not defined. Path: ''.: Path: '/'>

    The above exception was the direct cause of the following exception:

    Traceback (most recent call last):
      File "/usr/lib/python3.9/site-packages/tavern/response/base.py", line 152, in _maybe_run_validate_functions
        vf(response)
      File "/usr/lib/python3.9/site-packages/tavern/util/extfunctions.py", line 98, in inner
        result = func(response, *args, **kwargs)
      File "/usr/lib/python3.9/site-packages/tavern/testutils/helpers.py", line 103, in validate_pykwalify
        verify_generic(to_verify, schema)
      File "/usr/lib/python3.9/site-packages/tavern/schemas/files.py", line 109, in verify_generic
        raise BadSchemaError() from e
    tavern.util.exceptions.BadSchemaError
Traceback (most recent call last):
  File "/usr/lib/python3.9/site-packages/tavern/schemas/files.py", line 106, in verify_generic
    verifier.validate()
  File "/usr/lib/python3.9/site-packages/pykwalify/core.py", line 194, in validate
    raise SchemaError(u"Schema validation failed:\n - {error_msg}.".format(
pykwalify.errors.SchemaError: <SchemaError: error code 2: Schema validation failed:
 - Cannot find required key 'off'. Path: ''.
 - Key 'on' was not defined. Path: ''.: Path: '/'>

The above exception was the direct cause of the following exception:

Traceback (most recent call last):
  File "/usr/lib/python3.9/site-packages/tavern/response/base.py", line 152, in _maybe_run_validate_functions
    vf(response)
  File "/usr/lib/python3.9/site-packages/tavern/util/extfunctions.py", line 98, in inner
    result = func(response, *args, **kwargs)
  File "/usr/lib/python3.9/site-packages/tavern/testutils/helpers.py", line 103, in validate_pykwalify
    verify_generic(to_verify, schema)
  File "/usr/lib/python3.9/site-packages/tavern/schemas/files.py", line 109, in verify_generic
    raise BadSchemaError() from e
tavern.util.exceptions.BadSchemaError
[31m[1mERROR   [0m pykwalify.core:core.py:190 validation.invalid
[31m[1mERROR   [0m pykwalify.core:core.py:191  --- All found errors ---
[31m[1mERROR   [0m pykwalify.core:core.py:192 ["Cannot find required key 'off'. Path: ''", "Key 'on' was not defined. Path: ''"]
[31m[1mERROR   [0m tavern.schemas.files:files.py:108 Error validating {'e': 0, 'err_msg': '', 'on': ['x1000c0s4b1n0', 'x3000c0s6b0n0']}
Traceback (most recent call last):
  File "/usr/lib/python3.9/site-packages/tavern/schemas/files.py", line 106, in verify_generic
    verifier.validate()
  File "/usr/lib/python3.9/site-packages/pykwalify/core.py", line 194, in validate
    raise SchemaError(u"Schema validation failed:\n - {error_msg}.".format(
pykwalify.errors.SchemaError: <SchemaError: error code 2: Schema validation failed:
 - Cannot find required key 'off'. Path: ''.
 - Key 'on' was not defined. Path: ''.: Path: '/'>
[31m[1mERROR   [0m tavern.response.base:base.py:41 Error calling validate function '<function validate_pykwalify at 0x7f24c2db9820>':
    Traceback (most recent call last):
      File "/usr/lib/python3.9/site-packages/tavern/schemas/files.py", line 106, in verify_generic
        verifier.validate()
      File "/usr/lib/python3.9/site-packages/pykwalify/core.py", line 194, in validate
        raise SchemaError(u"Schema validation failed:\n - {error_msg}.".format(
    pykwalify.errors.SchemaError: <SchemaError: error code 2: Schema validation failed:
     - Cannot find required key 'off'. Path: ''.
     - Key 'on' was not defined. Path: ''.: Path: '/'>

    The above exception was the direct cause of the following exception:

    Traceback (most recent call last):
      File "/usr/lib/python3.9/site-packages/tavern/response/base.py", line 152, in _maybe_run_validate_functions
        vf(response)
      File "/usr/lib/python3.9/site-packages/tavern/util/extfunctions.py", line 98, in inner
        result = func(response, *args, **kwargs)
      File "/usr/lib/python3.9/site-packages/tavern/testutils/helpers.py", line 103, in validate_pykwalify
        verify_generic(to_verify, schema)
      File "/usr/lib/python3.9/site-packages/tavern/schemas/files.py", line 109, in verify_generic
        raise BadSchemaError() from e
    tavern.util.exceptions.BadSchemaError
Traceback (most recent call last):
  File "/usr/lib/python3.9/site-packages/tavern/schemas/files.py", line 106, in verify_generic
    verifier.validate()
  File "/usr/lib/python3.9/site-packages/pykwalify/core.py", line 194, in validate
    raise SchemaError(u"Schema validation failed:\n - {error_msg}.".format(
pykwalify.errors.SchemaError: <SchemaError: error code 2: Schema validation failed:
 - Cannot find required key 'off'. Path: ''.
 - Key 'on' was not defined. Path: ''.: Path: '/'>

The above exception was the direct cause of the following exception:

Traceback (most recent call last):
  File "/usr/lib/python3.9/site-packages/tavern/response/base.py", line 152, in _maybe_run_validate_functions
    vf(response)
  File "/usr/lib/python3.9/site-packages/tavern/util/extfunctions.py", line 98, in inner
    result = func(response, *args, **kwargs)
  File "/usr/lib/python3.9/site-packages/tavern/testutils/helpers.py", line 103, in validate_pykwalify
    verify_generic(to_verify, schema)
  File "/usr/lib/python3.9/site-packages/tavern/schemas/files.py", line 109, in verify_generic
    raise BadSchemaError() from e
tavern.util.exceptions.BadSchemaError
[31m[1mERROR   [0m pykwalify.core:core.py:190 validation.invalid
[31m[1mERROR   [0m pykwalify.core:core.py:191  --- All found errors ---
[31m[1mERROR   [0m pykwalify.core:core.py:192 ["Cannot find required key 'off'. Path: ''", "Key 'on' was not defined. Path: ''"]
[31m[1mERROR   [0m tavern.schemas.files:files.py:108 Error validating {'e': 0, 'err_msg': '', 'on': ['x1000c0s4b1n0', 'x3000c0s6b0n0']}
Traceback (most recent call last):
  File "/usr/lib/python3.9/site-packages/tavern/schemas/files.py", line 106, in verify_generic
    verifier.validate()
  File "/usr/lib/python3.9/site-packages/pykwalify/core.py", line 194, in validate
    raise SchemaError(u"Schema validation failed:\n - {error_msg}.".format(
pykwalify.errors.SchemaError: <SchemaError: error code 2: Schema validation failed:
 - Cannot find required key 'off'. Path: ''.
 - Key 'on' was not defined. Path: ''.: Path: '/'>
[31m[1mERROR   [0m tavern.response.base:base.py:41 Error calling validate function '<function validate_pykwalify at 0x7f24c2db9820>':
    Traceback (most recent call last):
      File "/usr/lib/python3.9/site-packages/tavern/schemas/files.py", line 106, in verify_generic
        verifier.validate()
      File "/usr/lib/python3.9/site-packages/pykwalify/core.py", line 194, in validate
        raise SchemaError(u"Schema validation failed:\n - {error_msg}.".format(
    pykwalify.errors.SchemaError: <SchemaError: error code 2: Schema validation failed:
     - Cannot find required key 'off'. Path: ''.
     - Key 'on' was not defined. Path: ''.: Path: '/'>

    The above exception was the direct cause of the following exception:

    Traceback (most recent call last):
      File "/usr/lib/python3.9/site-packages/tavern/response/base.py", line 152, in _maybe_run_validate_functions
        vf(response)
      File "/usr/lib/python3.9/site-packages/tavern/util/extfunctions.py", line 98, in inner
        result = func(response, *args, **kwargs)
      File "/usr/lib/python3.9/site-packages/tavern/testutils/helpers.py", line 103, in validate_pykwalify
        verify_generic(to_verify, schema)
      File "/usr/lib/python3.9/site-packages/tavern/schemas/files.py", line 109, in verify_generic
        raise BadSchemaError() from e
    tavern.util.exceptions.BadSchemaError
Traceback (most recent call last):
  File "/usr/lib/python3.9/site-packages/tavern/schemas/files.py", line 106, in verify_generic
    verifier.validate()
  File "/usr/lib/python3.9/site-packages/pykwalify/core.py", line 194, in validate
    raise SchemaError(u"Schema validation failed:\n - {error_msg}.".format(
pykwalify.errors.SchemaError: <SchemaError: error code 2: Schema validation failed:
 - Cannot find required key 'off'. Path: ''.
 - Key 'on' was not defined. Path: ''.: Path: '/'>

The above exception was the direct cause of the following exception:

Traceback (most recent call last):
  File "/usr/lib/python3.9/site-packages/tavern/response/base.py", line 152, in _maybe_run_validate_functions
    vf(response)
  File "/usr/lib/python3.9/site-packages/tavern/util/extfunctions.py", line 98, in inner
    result = func(response, *args, **kwargs)
  File "/usr/lib/python3.9/site-packages/tavern/testutils/helpers.py", line 103, in validate_pykwalify
    verify_generic(to_verify, schema)
  File "/usr/lib/python3.9/site-packages/tavern/schemas/files.py", line 109, in verify_generic
    raise BadSchemaError() from e
tavern.util.exceptions.BadSchemaError
[31m[1mERROR   [0m pykwalify.core:core.py:190 validation.invalid
[31m[1mERROR   [0m pykwalify.core:core.py:191  --- All found errors ---
[31m[1mERROR   [0m pykwalify.core:core.py:192 ["Cannot find required key 'off'. Path: ''", "Key 'on' was not defined. Path: ''"]
[31m[1mERROR   [0m tavern.schemas.files:files.py:108 Error validating {'e': 0, 'err_msg': '', 'on': ['x1000c0s4b1n0', 'x3000c0s6b0n0']}
Traceback (most recent call last):
  File "/usr/lib/python3.9/site-packages/tavern/schemas/files.py", line 106, in verify_generic
    verifier.validate()
  File "/usr/lib/python3.9/site-packages/pykwalify/core.py", line 194, in validate
    raise SchemaError(u"Schema validation failed:\n - {error_msg}.".format(
pykwalify.errors.SchemaError: <SchemaError: error code 2: Schema validation failed:
 - Cannot find required key 'off'. Path: ''.
 - Key 'on' was not defined. Path: ''.: Path: '/'>
[31m[1mERROR   [0m tavern.response.base:base.py:41 Error calling validate function '<function validate_pykwalify at 0x7f24c2db9820>':
    Traceback (most recent call last):
      File "/usr/lib/python3.9/site-packages/tavern/schemas/files.py", line 106, in verify_generic
        verifier.validate()
      File "/usr/lib/python3.9/site-packages/pykwalify/core.py", line 194, in validate
        raise SchemaError(u"Schema validation failed:\n - {error_msg}.".format(
    pykwalify.errors.SchemaError: <SchemaError: error code 2: Schema validation failed:
     - Cannot find required key 'off'. Path: ''.
     - Key 'on' was not defined. Path: ''.: Path: '/'>

    The above exception was the direct cause of the following exception:

    Traceback (most recent call last):
      File "/usr/lib/python3.9/site-packages/tavern/response/base.py", line 152, in _maybe_run_validate_functions
        vf(response)
      File "/usr/lib/python3.9/site-packages/tavern/util/extfunctions.py", line 98, in inner
        result = func(response, *args, **kwargs)
      File "/usr/lib/python3.9/site-packages/tavern/testutils/helpers.py", line 103, in validate_pykwalify
        verify_generic(to_verify, schema)
      File "/usr/lib/python3.9/site-packages/tavern/schemas/files.py", line 109, in verify_generic
        raise BadSchemaError() from e
    tavern.util.exceptions.BadSchemaError
Traceback (most recent call last):
  File "/usr/lib/python3.9/site-packages/tavern/schemas/files.py", line 106, in verify_generic
    verifier.validate()
  File "/usr/lib/python3.9/site-packages/pykwalify/core.py", line 194, in validate
    raise SchemaError(u"Schema validation failed:\n - {error_msg}.".format(
pykwalify.errors.SchemaError: <SchemaError: error code 2: Schema validation failed:
 - Cannot find required key 'off'. Path: ''.
 - Key 'on' was not defined. Path: ''.: Path: '/'>

The above exception was the direct cause of the following exception:

Traceback (most recent call last):
  File "/usr/lib/python3.9/site-packages/tavern/response/base.py", line 152, in _maybe_run_validate_functions
    vf(response)
  File "/usr/lib/python3.9/site-packages/tavern/util/extfunctions.py", line 98, in inner
    result = func(response, *args, **kwargs)
  File "/usr/lib/python3.9/site-packages/tavern/testutils/helpers.py", line 103, in validate_pykwalify
    verify_generic(to_verify, schema)
  File "/usr/lib/python3.9/site-packages/tavern/schemas/files.py", line 109, in verify_generic
    raise BadSchemaError() from e
tavern.util.exceptions.BadSchemaError
[31m[1mERROR   [0m pykwalify.core:core.py:190 validation.invalid
[31m[1mERROR   [0m pykwalify.core:core.py:191  --- All found errors ---
[31m[1mERROR   [0m pykwalify.core:core.py:192 ["Cannot find required key 'off'. Path: ''", "Key 'on' was not defined. Path: ''"]
[31m[1mERROR   [0m tavern.schemas.files:files.py:108 Error validating {'e': 0, 'err_msg': '', 'on': ['x1000c0s4b1n0', 'x3000c0s6b0n0']}
Traceback (most recent call last):
  File "/usr/lib/python3.9/site-packages/tavern/schemas/files.py", line 106, in verify_generic
    verifier.validate()
  File "/usr/lib/python3.9/site-packages/pykwalify/core.py", line 194, in validate
    raise SchemaError(u"Schema validation failed:\n - {error_msg}.".format(
pykwalify.errors.SchemaError: <SchemaError: error code 2: Schema validation failed:
 - Cannot find required key 'off'. Path: ''.
 - Key 'on' was not defined. Path: ''.: Path: '/'>
[31m[1mERROR   [0m tavern.response.base:base.py:41 Error calling validate function '<function validate_pykwalify at 0x7f24c2db9820>':
    Traceback (most recent call last):
      File "/usr/lib/python3.9/site-packages/tavern/schemas/files.py", line 106, in verify_generic
        verifier.validate()
      File "/usr/lib/python3.9/site-packages/pykwalify/core.py", line 194, in validate
        raise SchemaError(u"Schema validation failed:\n - {error_msg}.".format(
    pykwalify.errors.SchemaError: <SchemaError: error code 2: Schema validation failed:
     - Cannot find required key 'off'. Path: ''.
     - Key 'on' was not defined. Path: ''.: Path: '/'>

    The above exception was the direct cause of the following exception:

    Traceback (most recent call last):
      File "/usr/lib/python3.9/site-packages/tavern/response/base.py", line 152, in _maybe_run_validate_functions
        vf(response)
      File "/usr/lib/python3.9/site-packages/tavern/util/extfunctions.py", line 98, in inner
        result = func(response, *args, **kwargs)
      File "/usr/lib/python3.9/site-packages/tavern/testutils/helpers.py", line 103, in validate_pykwalify
        verify_generic(to_verify, schema)
      File "/usr/lib/python3.9/site-packages/tavern/schemas/files.py", line 109, in verify_generic
        raise BadSchemaError() from e
    tavern.util.exceptions.BadSchemaError
Traceback (most recent call last):
  File "/usr/lib/python3.9/site-packages/tavern/schemas/files.py", line 106, in verify_generic
    verifier.validate()
  File "/usr/lib/python3.9/site-packages/pykwalify/core.py", line 194, in validate
    raise SchemaError(u"Schema validation failed:\n - {error_msg}.".format(
pykwalify.errors.SchemaError: <SchemaError: error code 2: Schema validation failed:
 - Cannot find required key 'off'. Path: ''.
 - Key 'on' was not defined. Path: ''.: Path: '/'>

The above exception was the direct cause of the following exception:

Traceback (most recent call last):
  File "/usr/lib/python3.9/site-packages/tavern/response/base.py", line 152, in _maybe_run_validate_functions
    vf(response)
  File "/usr/lib/python3.9/site-packages/tavern/util/extfunctions.py", line 98, in inner
    result = func(response, *args, **kwargs)
  File "/usr/lib/python3.9/site-packages/tavern/testutils/helpers.py", line 103, in validate_pykwalify
    verify_generic(to_verify, schema)
  File "/usr/lib/python3.9/site-packages/tavern/schemas/files.py", line 109, in verify_generic
    raise BadSchemaError() from e
tavern.util.exceptions.BadSchemaError
[31m[1mERROR   [0m pykwalify.core:core.py:190 validation.invalid
[31m[1mERROR   [0m pykwalify.core:core.py:191  --- All found errors ---
[31m[1mERROR   [0m pykwalify.core:core.py:192 ["Cannot find required key 'off'. Path: ''", "Key 'on' was not defined. Path: ''"]
[31m[1mERROR   [0m tavern.schemas.files:files.py:108 Error validating {'e': 0, 'err_msg': '', 'on': ['x1000c0s4b1n0', 'x3000c0s6b0n0']}
Traceback (most recent call last):
  File "/usr/lib/python3.9/site-packages/tavern/schemas/files.py", line 106, in verify_generic
    verifier.validate()
  File "/usr/lib/python3.9/site-packages/pykwalify/core.py", line 194, in validate
    raise SchemaError(u"Schema validation failed:\n - {error_msg}.".format(
pykwalify.errors.SchemaError: <SchemaError: error code 2: Schema validation failed:
 - Cannot find required key 'off'. Path: ''.
 - Key 'on' was not defined. Path: ''.: Path: '/'>
[31m[1mERROR   [0m tavern.response.base:base.py:41 Error calling validate function '<function validate_pykwalify at 0x7f24c2db9820>':
    Traceback (most recent call last):
      File "/usr/lib/python3.9/site-packages/tavern/schemas/files.py", line 106, in verify_generic
        verifier.validate()
      File "/usr/lib/python3.9/site-packages/pykwalify/core.py", line 194, in validate
        raise SchemaError(u"Schema validation failed:\n - {error_msg}.".format(
    pykwalify.errors.SchemaError: <SchemaError: error code 2: Schema validation failed:
     - Cannot find required key 'off'. Path: ''.
     - Key 'on' was not defined. Path: ''.: Path: '/'>

    The above exception was the direct cause of the following exception:

    Traceback (most recent call last):
      File "/usr/lib/python3.9/site-packages/tavern/response/base.py", line 152, in _maybe_run_validate_functions
        vf(response)
      File "/usr/lib/python3.9/site-packages/tavern/util/extfunctions.py", line 98, in inner
        result = func(response, *args, **kwargs)
      File "/usr/lib/python3.9/site-packages/tavern/testutils/helpers.py", line 103, in validate_pykwalify
        verify_generic(to_verify, schema)
      File "/usr/lib/python3.9/site-packages/tavern/schemas/files.py", line 109, in verify_generic
        raise BadSchemaError() from e
    tavern.util.exceptions.BadSchemaError
Traceback (most recent call last):
  File "/usr/lib/python3.9/site-packages/tavern/schemas/files.py", line 106, in verify_generic
    verifier.validate()
  File "/usr/lib/python3.9/site-packages/pykwalify/core.py", line 194, in validate
    raise SchemaError(u"Schema validation failed:\n - {error_msg}.".format(
pykwalify.errors.SchemaError: <SchemaError: error code 2: Schema validation failed:
 - Cannot find required key 'off'. Path: ''.
 - Key 'on' was not defined. Path: ''.: Path: '/'>

The above exception was the direct cause of the following exception:

Traceback (most recent call last):
  File "/usr/lib/python3.9/site-packages/tavern/response/base.py", line 152, in _maybe_run_validate_functions
    vf(response)
  File "/usr/lib/python3.9/site-packages/tavern/util/extfunctions.py", line 98, in inner
    result = func(response, *args, **kwargs)
  File "/usr/lib/python3.9/site-packages/tavern/testutils/helpers.py", line 103, in validate_pykwalify
    verify_generic(to_verify, schema)
  File "/usr/lib/python3.9/site-packages/tavern/schemas/files.py", line 109, in verify_generic
    raise BadSchemaError() from e
tavern.util.exceptions.BadSchemaError
[31m[1mERROR   [0m pykwalify.core:core.py:190 validation.invalid
[31m[1mERROR   [0m pykwalify.core:core.py:191  --- All found errors ---
[31m[1mERROR   [0m pykwalify.core:core.py:192 ["Cannot find required key 'off'. Path: ''", "Key 'on' was not defined. Path: ''"]
[31m[1mERROR   [0m tavern.schemas.files:files.py:108 Error validating {'e': 0, 'err_msg': '', 'on': ['x1000c0s4b1n0', 'x3000c0s6b0n0']}
Traceback (most recent call last):
  File "/usr/lib/python3.9/site-packages/tavern/schemas/files.py", line 106, in verify_generic
    verifier.validate()
  File "/usr/lib/python3.9/site-packages/pykwalify/core.py", line 194, in validate
    raise SchemaError(u"Schema validation failed:\n - {error_msg}.".format(
pykwalify.errors.SchemaError: <SchemaError: error code 2: Schema validation failed:
 - Cannot find required key 'off'. Path: ''.
 - Key 'on' was not defined. Path: ''.: Path: '/'>
[31m[1mERROR   [0m tavern.response.base:base.py:41 Error calling validate function '<function validate_pykwalify at 0x7f24c2db9820>':
    Traceback (most recent call last):
      File "/usr/lib/python3.9/site-packages/tavern/schemas/files.py", line 106, in verify_generic
        verifier.validate()
      File "/usr/lib/python3.9/site-packages/pykwalify/core.py", line 194, in validate
        raise SchemaError(u"Schema validation failed:\n - {error_msg}.".format(
    pykwalify.errors.SchemaError: <SchemaError: error code 2: Schema validation failed:
     - Cannot find required key 'off'. Path: ''.
     - Key 'on' was not defined. Path: ''.: Path: '/'>

    The above exception was the direct cause of the following exception:

    Traceback (most recent call last):
      File "/usr/lib/python3.9/site-packages/tavern/response/base.py", line 152, in _maybe_run_validate_functions
        vf(response)
      File "/usr/lib/python3.9/site-packages/tavern/util/extfunctions.py", line 98, in inner
        result = func(response, *args, **kwargs)
      File "/usr/lib/python3.9/site-packages/tavern/testutils/helpers.py", line 103, in validate_pykwalify
        verify_generic(to_verify, schema)
      File "/usr/lib/python3.9/site-packages/tavern/schemas/files.py", line 109, in verify_generic
        raise BadSchemaError() from e
    tavern.util.exceptions.BadSchemaError
Traceback (most recent call last):
  File "/usr/lib/python3.9/site-packages/tavern/schemas/files.py", line 106, in verify_generic
    verifier.validate()
  File "/usr/lib/python3.9/site-packages/pykwalify/core.py", line 194, in validate
    raise SchemaError(u"Schema validation failed:\n - {error_msg}.".format(
pykwalify.errors.SchemaError: <SchemaError: error code 2: Schema validation failed:
 - Cannot find required key 'off'. Path: ''.
 - Key 'on' was not defined. Path: ''.: Path: '/'>

The above exception was the direct cause of the following exception:

Traceback (most recent call last):
  File "/usr/lib/python3.9/site-packages/tavern/response/base.py", line 152, in _maybe_run_validate_functions
    vf(response)
  File "/usr/lib/python3.9/site-packages/tavern/util/extfunctions.py", line 98, in inner
    result = func(response, *args, **kwargs)
  File "/usr/lib/python3.9/site-packages/tavern/testutils/helpers.py", line 103, in validate_pykwalify
    verify_generic(to_verify, schema)
  File "/usr/lib/python3.9/site-packages/tavern/schemas/files.py", line 109, in verify_generic
    raise BadSchemaError() from e
tavern.util.exceptions.BadSchemaError
[31m[1mERROR   [0m pykwalify.core:core.py:190 validation.invalid
[31m[1mERROR   [0m pykwalify.core:core.py:191  --- All found errors ---
[31m[1mERROR   [0m pykwalify.core:core.py:192 ["Cannot find required key 'off'. Path: ''", "Key 'on' was not defined. Path: ''"]
[31m[1mERROR   [0m tavern.schemas.files:files.py:108 Error validating {'e': 0, 'err_msg': '', 'on': ['x1000c0s4b1n0', 'x3000c0s6b0n0']}
Traceback (most recent call last):
  File "/usr/lib/python3.9/site-packages/tavern/schemas/files.py", line 106, in verify_generic
    verifier.validate()
  File "/usr/lib/python3.9/site-packages/pykwalify/core.py", line 194, in validate
    raise SchemaError(u"Schema validation failed:\n - {error_msg}.".format(
pykwalify.errors.SchemaError: <SchemaError: error code 2: Schema validation failed:
 - Cannot find required key 'off'. Path: ''.
 - Key 'on' was not defined. Path: ''.: Path: '/'>
[31m[1mERROR   [0m tavern.response.base:base.py:41 Error calling validate function '<function validate_pykwalify at 0x7f24c2db9820>':
    Traceback (most recent call last):
      File "/usr/lib/python3.9/site-packages/tavern/schemas/files.py", line 106, in verify_generic
        verifier.validate()
      File "/usr/lib/python3.9/site-packages/pykwalify/core.py", line 194, in validate
        raise SchemaError(u"Schema validation failed:\n - {error_msg}.".format(
    pykwalify.errors.SchemaError: <SchemaError: error code 2: Schema validation failed:
     - Cannot find required key 'off'. Path: ''.
     - Key 'on' was not defined. Path: ''.: Path: '/'>

    The above exception was the direct cause of the following exception:

    Traceback (most recent call last):
      File "/usr/lib/python3.9/site-packages/tavern/response/base.py", line 152, in _maybe_run_validate_functions
        vf(response)
      File "/usr/lib/python3.9/site-packages/tavern/util/extfunctions.py", line 98, in inner
        result = func(response, *args, **kwargs)
      File "/usr/lib/python3.9/site-packages/tavern/testutils/helpers.py", line 103, in validate_pykwalify
        verify_generic(to_verify, schema)
      File "/usr/lib/python3.9/site-packages/tavern/schemas/files.py", line 109, in verify_generic
        raise BadSchemaError() from e
    tavern.util.exceptions.BadSchemaError
Traceback (most recent call last):
  File "/usr/lib/python3.9/site-packages/tavern/schemas/files.py", line 106, in verify_generic
    verifier.validate()
  File "/usr/lib/python3.9/site-packages/pykwalify/core.py", line 194, in validate
    raise SchemaError(u"Schema validation failed:\n - {error_msg}.".format(
pykwalify.errors.SchemaError: <SchemaError: error code 2: Schema validation failed:
 - Cannot find required key 'off'. Path: ''.
 - Key 'on' was not defined. Path: ''.: Path: '/'>

The above exception was the direct cause of the following exception:

Traceback (most recent call last):
  File "/usr/lib/python3.9/site-packages/tavern/response/base.py", line 152, in _maybe_run_validate_functions
    vf(response)
  File "/usr/lib/python3.9/site-packages/tavern/util/extfunctions.py", line 98, in inner
    result = func(response, *args, **kwargs)
  File "/usr/lib/python3.9/site-packages/tavern/testutils/helpers.py", line 103, in validate_pykwalify
    verify_generic(to_verify, schema)
  File "/usr/lib/python3.9/site-packages/tavern/schemas/files.py", line 109, in verify_generic
    raise BadSchemaError() from e
tavern.util.exceptions.BadSchemaError