[1m[31mERROR   [0m pykwalify.core:core.py:190 validation.invalid
[1m[31mERROR   [0m pykwalify.core:core.py:191  --- All found errors ---
[1m[31mERROR   [0m pykwalify.core:core.py:192 ["Enum 'in-progress' does not exist. Path: '/taskStatus' Enum: ['completed']"]
[1m[31mERROR   [0m tavern.schemas.files:files.py:108 Error validating {'taskID': '63b0da2b-34f6-4145-ac06-bed8c197737b', 'type': 'snapshot', 'taskCreateTime': '2023-07-17T20:49:16.899766688Z', 'automaticExpirationTime': '2023-07-18T20:49:16.899766688Z', 'taskStatus': 'in-progress', 'taskCounts': {'total': 2, 'new': 0, 'in-progress': 2, 'failed': 0, 'succeeded': 0, 'un-supported': 0}, 'components': [{'xname': 'x1000c0s3b0n0'}, {'xname': 'x1000c0s7b0n1'}]}
Traceback (most recent call last):
  File "/usr/lib/python3.9/site-packages/tavern/schemas/files.py", line 106, in verify_generic
    verifier.validate()
  File "/usr/lib/python3.9/site-packages/pykwalify/core.py", line 194, in validate
    raise SchemaError(u"Schema validation failed:\n - {error_msg}.".format(
pykwalify.errors.SchemaError: <SchemaError: error code 2: Schema validation failed:
 - Enum 'in-progress' does not exist. Path: '/taskStatus' Enum: ['completed'].: Path: '/'>
[1m[31mERROR   [0m tavern.response.base:base.py:41 Error calling validate function '<function validate_pykwalify at 0x7f52b7f12430>':
    Traceback (most recent call last):
      File "/usr/lib/python3.9/site-packages/tavern/schemas/files.py", line 106, in verify_generic
        verifier.validate()
      File "/usr/lib/python3.9/site-packages/pykwalify/core.py", line 194, in validate
        raise SchemaError(u"Schema validation failed:\n - {error_msg}.".format(
    pykwalify.errors.SchemaError: <SchemaError: error code 2: Schema validation failed:
     - Enum 'in-progress' does not exist. Path: '/taskStatus' Enum: ['completed'].: Path: '/'>

    The above exception was the direct cause of the following exception:

    Traceback (most recent call last):
      File "/usr/lib/python3.9/site-packages/tavern/response/base.py", line 152, in _maybe_run_validate_functions
        vf(response)
      File "/usr/lib/python3.9/site-packages/tavern/util/extfunctions.py", line 98, in inner
        result = func(response, *args, **kwargs)
      File "/usr/lib/python3.9/site-packages/tavern/testutils/helpers.py", line 103, in validate_pykwalify
        verify_generic(to_verify, schema)
      File "/usr/lib/python3.9/site-packages/tavern/schemas/files.py", line 109, in verify_generic
        raise BadSchemaError() from e
    tavern.util.exceptions.BadSchemaError
Traceback (most recent call last):
  File "/usr/lib/python3.9/site-packages/tavern/schemas/files.py", line 106, in verify_generic
    verifier.validate()
  File "/usr/lib/python3.9/site-packages/pykwalify/core.py", line 194, in validate
    raise SchemaError(u"Schema validation failed:\n - {error_msg}.".format(
pykwalify.errors.SchemaError: <SchemaError: error code 2: Schema validation failed:
 - Enum 'in-progress' does not exist. Path: '/taskStatus' Enum: ['completed'].: Path: '/'>

The above exception was the direct cause of the following exception:

Traceback (most recent call last):
  File "/usr/lib/python3.9/site-packages/tavern/response/base.py", line 152, in _maybe_run_validate_functions
    vf(response)
  File "/usr/lib/python3.9/site-packages/tavern/util/extfunctions.py", line 98, in inner
    result = func(response, *args, **kwargs)
  File "/usr/lib/python3.9/site-packages/tavern/testutils/helpers.py", line 103, in validate_pykwalify
    verify_generic(to_verify, schema)
  File "/usr/lib/python3.9/site-packages/tavern/schemas/files.py", line 109, in verify_generic
    raise BadSchemaError() from e
tavern.util.exceptions.BadSchemaError