{"uid":"4b4757e66a1912dae1a509f688f20b0f","children":[{"name":"Product defects","children":[{"name":"tavern.util.exceptions.TestFailError: Test 'hsmAPIinventoryHardwareGET - Retrieve multiple Hardware Inventory entries using GET.' failed:\n- Error calling validate function '<function validate_pykwalify at 0x7f9a6d52f670>':\n    Traceback (most recent call last):\n      File \"/usr/lib/python3.9/site-packages/tavern/schemas/files.py\", line 106, in verify_generic\n        verifier.validate()\n      File \"/usr/lib/python3.9/site-packages/pykwalify/core.py\", line 194, in validate\n        raise SchemaError(u\"Schema validation failed:\\n - {error_msg}.\".format(\n    pykwalify.errors.SchemaError: <SchemaError: error code 2: Schema validation failed:\n     - Cannot find required key 'PopulatedFRU'. Path: '/6'.\n     - Cannot find required key 'PopulatedFRU'. Path: '/9'.\n     - Cannot find required key 'PopulatedFRU'. Path: '/11'.\n     - Cannot find required key 'PopulatedFRU'. Path: '/12'.\n     - Cannot find required key 'PopulatedFRU'. Path: '/13'.\n     - Cannot find required key 'PopulatedFRU'. Path: '/14'.\n     - Cannot find required key 'PopulatedFRU'. Path: '/15'.\n     - Cannot find required key 'PopulatedFRU'. Path: '/16'.\n     - Cannot find required key 'PopulatedFRU'. Path: '/17'.\n     - Cannot find required key 'PopulatedFRU'. Path: '/18'.\n     - Cannot find required key 'PopulatedFRU'. Path: '/19'.\n     - Cannot find required key 'PopulatedFRU'. Path: '/20'.\n     - Cannot find required key 'PopulatedFRU'. Path: '/25'.\n     - Cannot find required key 'PopulatedFRU'. Path: '/26'.\n     - Cannot find required key 'PopulatedFRU'. Path: '/43'.\n     - Cannot find required key 'PopulatedFRU'. Path: '/44'.\n     - Cannot find required key 'PopulatedFRU'. Path: '/46'.\n     - Cannot find required key 'PopulatedFRU'. Path: '/47'.\n     - Cannot find required key 'PopulatedFRU'. Path: '/48'.\n     - Cannot find required key 'PopulatedFRU'. Path: '/49'.\n     - Cannot find required key 'PopulatedFRU'. Path: '/53'.\n     - Cannot find required key 'PopulatedFRU'. Path: '/55'.\n     - Cannot find required key 'PopulatedFRU'. Path: '/56'.\n     - Cannot find required key 'PopulatedFRU'. Path: '/58'.\n     - Cannot find required key 'PopulatedFRU'. Path: '/59'.\n     - Cannot find required key 'PopulatedFRU'. Path: '/65'.\n     - Cannot find required key 'PopulatedFRU'. Path: '/67'.\n     - Cannot find required key 'PopulatedFRU'. Path: '/69'.\n     - Cannot find required key 'PopulatedFRU'. Path: '/70'.\n     - Cannot find required key 'PopulatedFRU'. Path: '/73'.\n     - Cannot find required key 'PopulatedFRU'. Path: '/530'.\n     - Cannot find required key 'PopulatedFRU'. Path: '/533'.\n     - Cannot find required key 'PopulatedFRU'. Path: '/539'.\n     - Cannot find required key 'PopulatedFRU'. Path: '/540'.: Path: '/'>\n\n    The above exception was the direct cause of the following exception:\n\n    Traceback (most recent call last):\n      File \"/usr/lib/python3.9/site-packages/tavern/response/base.py\", line 152, in _maybe_run_validate_functions\n        vf(response)\n      File \"/usr/lib/python3.9/site-packages/tavern/util/extfunctions.py\", line 98, in inner\n        result = func(response, *args, **kwargs)\n      File \"/usr/lib/python3.9/site-packages/tavern/testutils/helpers.py\", line 103, in validate_pykwalify\n        verify_generic(to_verify, schema)\n      File \"/usr/lib/python3.9/site-packages/tavern/schemas/files.py\", line 109, in verify_generic\n        raise BadSchemaError() from e\n    tavern.util.exceptions.BadSchemaError","children":[{"name":"hsmAPIinventoryHardwareDisruptive","uid":"7445331cb2d0bd8b","parentUid":"0331f7e886936dd29af64c0bca302cc0","status":"failed","time":{"start":1676400974254,"stop":1676400978144,"duration":3890},"flaky":false,"newFailed":false,"newPassed":false,"newBroken":false,"retriesCount":0,"retriesStatusChange":false,"parameters":[],"tags":[]}],"uid":"0331f7e886936dd29af64c0bca302cc0"},{"name":"tavern.util.exceptions.TestFailError: Test 'hsmAPIinventoryHardwareQueryXnameGETnonExistentNode - Attempt to query for Node Hardware Inventory entries with an xname that doesn't exist using GET.' failed:\n- Error calling validate function '<function validate_pykwalify at 0x7f9a6d52f670>':\n    Traceback (most recent call last):\n      File \"/usr/lib/python3.9/site-packages/tavern/schemas/files.py\", line 106, in verify_generic\n        verifier.validate()\n      File \"/usr/lib/python3.9/site-packages/pykwalify/core.py\", line 194, in validate\n        raise SchemaError(u\"Schema validation failed:\\n - {error_msg}.\".format(\n    pykwalify.errors.SchemaError: <SchemaError: error code 2: Schema validation failed:\n     - Key 'Nodes' was not defined. Path: ''.: Path: '/'>\n\n    The above exception was the direct cause of the following exception:\n\n    Traceback (most recent call last):\n      File \"/usr/lib/python3.9/site-packages/tavern/response/base.py\", line 152, in _maybe_run_validate_functions\n        vf(response)\n      File \"/usr/lib/python3.9/site-packages/tavern/util/extfunctions.py\", line 98, in inner\n        result = func(response, *args, **kwargs)\n      File \"/usr/lib/python3.9/site-packages/tavern/testutils/helpers.py\", line 103, in validate_pykwalify\n        verify_generic(to_verify, schema)\n      File \"/usr/lib/python3.9/site-packages/tavern/schemas/files.py\", line 109, in verify_generic\n        raise BadSchemaError() from e\n    tavern.util.exceptions.BadSchemaError","children":[{"name":"hsmAPIinventoryHardwareNegative","uid":"3bc441f675c4cf66","parentUid":"98740f4c7d2aaa30bfda7f3572abeb4a","status":"failed","time":{"start":1676400978244,"stop":1676400978408,"duration":164},"flaky":false,"newFailed":false,"newPassed":false,"newBroken":false,"retriesCount":0,"retriesStatusChange":false,"parameters":[],"tags":[]}],"uid":"98740f4c7d2aaa30bfda7f3572abeb4a"},{"name":"tavern.util.exceptions.TestFailError: Test 'Query bootscript by xname' failed:\n- Error calling validate function '<function better_validate_regex at 0x7f16a3e37820>':\n    Traceback (most recent call last):\n      File \"/usr/lib/python3.9/site-packages/tavern/response/base.py\", line 152, in _maybe_run_validate_functions\n        vf(response)\n      File \"/usr/lib/python3.9/site-packages/tavern/util/extfunctions.py\", line 98, in inner\n        result = func(response, *args, **kwargs)\n      File \"/src/libs/bss_test_utils.py\", line 65, in better_validate_regex\n        raise exceptions.RegexAccessError(f\"No match for regex '{expression}' in response:\\n{response.text}\")\n    tavern.util.exceptions.RegexAccessError: No match for regex 'kernel http[s]?:\\/\\/.+/boot-images/00000000-0000-0000-0000-000000000000\\/kernel' in response:\n    #!ipxe\n    sleep 10\n    chain https://api-gw-service-nmn.local/apis/bss/boot/v1/bootscript?mac=00:40:a6:70:b5:52&retry=1\n\n\n\n- Error calling validate function '<function better_validate_regex at 0x7f16a3e37820>':\n    Traceback (most recent call last):\n      File \"/usr/lib/python3.9/site-packages/tavern/response/base.py\", line 152, in _maybe_run_validate_functions\n        vf(response)\n      File \"/usr/lib/python3.9/site-packages/tavern/util/extfunctions.py\", line 98, in inner\n        result = func(response, *args, **kwargs)\n      File \"/src/libs/bss_test_utils.py\", line 65, in better_validate_regex\n        raise exceptions.RegexAccessError(f\"No match for regex '{expression}' in response:\\n{response.text}\")\n    tavern.util.exceptions.RegexAccessError: No match for regex 'initrd http[s]?:\\/\\/.+/boot-images/00000000-0000-0000-0000-000000000000\\/initrd' in response:\n    #!ipxe\n    sleep 10\n    chain https://api-gw-service-nmn.local/apis/bss/boot/v1/bootscript?mac=00:40:a6:70:b5:52&retry=1\n\n\n\n- Error calling validate function '<function better_validate_regex at 0x7f16a3e37820>':\n    Traceback (most recent call last):\n      File \"/usr/lib/python3.9/site-packages/tavern/response/base.py\", line 152, in _maybe_run_validate_functions\n        vf(response)\n      File \"/usr/lib/python3.9/site-packages/tavern/util/extfunctions.py\", line 98, in inner\n        result = func(response, *args, **kwargs)\n      File \"/src/libs/bss_test_utils.py\", line 65, in better_validate_regex\n        raise exceptions.RegexAccessError(f\"No match for regex '{expression}' in response:\\n{response.text}\")\n    tavern.util.exceptions.RegexAccessError: No match for regex 'kernel --name .+console.tty0' in response:\n    #!ipxe\n    sleep 10\n    chain https://api-gw-service-nmn.local/apis/bss/boot/v1/bootscript?mac=00:40:a6:70:b5:52&retry=1\n\n\n\n- Error calling validate function '<function better_validate_regex at 0x7f16a3e37820>':\n    Traceback (most recent call last):\n      File \"/usr/lib/python3.9/site-packages/tavern/response/base.py\", line 152, in _maybe_run_validate_functions\n        vf(response)\n      File \"/usr/lib/python3.9/site-packages/tavern/util/extfunctions.py\", line 98, in inner\n        result = func(response, *args, **kwargs)\n      File \"/src/libs/bss_test_utils.py\", line 65, in better_validate_regex\n        raise exceptions.RegexAccessError(f\"No match for regex '{expression}' in response:\\n{response.text}\")\n    tavern.util.exceptions.RegexAccessError: No match for regex 'kernel --name .+xname=x1000c0s3b0n0' in response:\n    #!ipxe\n    sleep 10\n    chain https://api-gw-service-nmn.local/apis/bss/boot/v1/bootscript?mac=00:40:a6:70:b5:52&retry=1\n\n\n\n- Error calling validate function '<function better_validate_regex at 0x7f16a3e37820>':\n    Traceback (most recent call last):\n      File \"/usr/lib/python3.9/site-packages/tavern/response/base.py\", line 152, in _maybe_run_validate_functions\n        vf(response)\n      File \"/usr/lib/python3.9/site-packages/tavern/util/extfunctions.py\", line 98, in inner\n        result = func(response, *args, **kwargs)\n      File \"/src/libs/bss_test_utils.py\", line 65, in better_validate_regex\n        raise exceptions.RegexAccessError(f\"No match for regex '{expression}' in response:\\n{response.text}\")\n    tavern.util.exceptions.RegexAccessError: No match for regex 'kernel --name .+nid=1012' in response:\n    #!ipxe\n    sleep 10\n    chain https://api-gw-service-nmn.local/apis/bss/boot/v1/bootscript?mac=00:40:a6:70:b5:52&retry=1\n\n\n\n- Error calling validate function '<function better_validate_regex at 0x7f16a3e37820>':\n    Traceback (most recent call last):\n      File \"/usr/lib/python3.9/site-packages/tavern/response/base.py\", line 152, in _maybe_run_validate_functions\n        vf(response)\n      File \"/usr/lib/python3.9/site-packages/tavern/util/extfunctions.py\", line 98, in inner\n        result = func(response, *args, **kwargs)\n      File \"/src/libs/bss_test_utils.py\", line 65, in better_validate_regex\n        raise exceptions.RegexAccessError(f\"No match for regex '{expression}' in response:\\n{response.text}\")\n    tavern.util.exceptions.RegexAccessError: No match for regex 'kernel --name .+bss_referral_token=' in response:\n    #!ipxe\n    sleep 10\n    chain https://api-gw-service-nmn.local/apis/bss/boot/v1/bootscript?mac=00:40:a6:70:b5:52&retry=1","children":[{"name":"bssAPIbootscript","uid":"82191a86dcf415e1","parentUid":"dbc38bfd33749abbb7d71b025d3b405c","status":"failed","time":{"start":1676401430210,"stop":1676401430324,"duration":114},"flaky":false,"newFailed":false,"newPassed":false,"newBroken":false,"retriesCount":0,"retriesStatusChange":false,"parameters":[],"tags":[]}],"uid":"dbc38bfd33749abbb7d71b025d3b405c"}],"uid":"8fb3a91ba5aaf9de24cc8a92edc82b5d"}],"name":"categories"}