{"uid":"4b4757e66a1912dae1a509f688f20b0f","children":[{"name":"Product defects","children":[{"name":"tavern.util.exceptions.TestFailError: Test 'hsmAPIinventoryHardwareGET - Retrieve multiple Hardware Inventory entries using GET.' failed:\n- Error calling validate function '<function validate_pykwalify at 0x7f66510c1e50>':\n    Traceback (most recent call last):\n      File \"/usr/lib/python3.9/site-packages/tavern/schemas/files.py\", line 106, in verify_generic\n        verifier.validate()\n      File \"/usr/lib/python3.9/site-packages/pykwalify/core.py\", line 194, in validate\n        raise SchemaError(u\"Schema validation failed:\\n - {error_msg}.\".format(\n    pykwalify.errors.SchemaError: <SchemaError: error code 2: Schema validation failed:\n     - Cannot find required key 'PopulatedFRU'. Path: '/6'.\n     - Cannot find required key 'PopulatedFRU'. Path: '/7'.\n     - Cannot find required key 'PopulatedFRU'. Path: '/8'.\n     - Cannot find required key 'PopulatedFRU'. Path: '/9'.\n     - Cannot find required key 'PopulatedFRU'. Path: '/10'.\n     - Cannot find required key 'PopulatedFRU'. Path: '/11'.\n     - Cannot find required key 'PopulatedFRU'. Path: '/13'.\n     - Cannot find required key 'PopulatedFRU'. Path: '/15'.\n     - Cannot find required key 'PopulatedFRU'. Path: '/17'.\n     - Cannot find required key 'PopulatedFRU'. Path: '/18'.\n     - Cannot find required key 'PopulatedFRU'. Path: '/19'.\n     - Cannot find required key 'PopulatedFRU'. Path: '/20'.\n     - Cannot find required key 'PopulatedFRU'. Path: '/25'.\n     - Cannot find required key 'PopulatedFRU'. Path: '/26'.\n     - Cannot find required key 'PopulatedFRU'. Path: '/42'.\n     - Cannot find required key 'PopulatedFRU'. Path: '/43'.\n     - Cannot find required key 'PopulatedFRU'. Path: '/47'.\n     - Cannot find required key 'PopulatedFRU'. Path: '/50'.\n     - Cannot find required key 'PopulatedFRU'. Path: '/53'.\n     - Cannot find required key 'PopulatedFRU'. Path: '/54'.\n     - Cannot find required key 'PopulatedFRU'. Path: '/55'.\n     - Cannot find required key 'PopulatedFRU'. Path: '/57'.\n     - Cannot find required key 'PopulatedFRU'. Path: '/61'.\n     - Cannot find required key 'PopulatedFRU'. Path: '/65'.\n     - Cannot find required key 'PopulatedFRU'. Path: '/66'.\n     - Cannot find required key 'PopulatedFRU'. Path: '/67'.\n     - Cannot find required key 'PopulatedFRU'. Path: '/68'.\n     - Cannot find required key 'PopulatedFRU'. Path: '/69'.\n     - Cannot find required key 'PopulatedFRU'. Path: '/70'.\n     - Cannot find required key 'PopulatedFRU'. Path: '/73'.\n     - Cannot find required key 'PopulatedFRU'. Path: '/283'.\n     - Cannot find required key 'PopulatedFRU'. Path: '/284'.\n     - Cannot find required key 'PopulatedFRU'. Path: '/285'.\n     - Cannot find required key 'PopulatedFRU'. Path: '/287'.: Path: '/'>\n\n    The above exception was the direct cause of the following exception:\n\n    Traceback (most recent call last):\n      File \"/usr/lib/python3.9/site-packages/tavern/response/base.py\", line 152, in _maybe_run_validate_functions\n        vf(response)\n      File \"/usr/lib/python3.9/site-packages/tavern/util/extfunctions.py\", line 98, in inner\n        result = func(response, *args, **kwargs)\n      File \"/usr/lib/python3.9/site-packages/tavern/testutils/helpers.py\", line 103, in validate_pykwalify\n        verify_generic(to_verify, schema)\n      File \"/usr/lib/python3.9/site-packages/tavern/schemas/files.py\", line 109, in verify_generic\n        raise BadSchemaError() from e\n    tavern.util.exceptions.BadSchemaError","children":[{"name":"hsmAPIinventoryHardwareDisruptive","uid":"4e171e34e025803e","parentUid":"818ec6ff359a129e00e68f249ecb2a09","status":"failed","time":{"start":1711095553571,"stop":1711095555863,"duration":2292},"flaky":false,"newFailed":false,"newPassed":false,"newBroken":false,"retriesCount":0,"retriesStatusChange":false,"parameters":[],"tags":[]}],"uid":"818ec6ff359a129e00e68f249ecb2a09"},{"name":"tavern.util.exceptions.TestFailError: Test 'hsmAPIinventoryHardwareQueryXnameGETnonExistentNode - Attempt to query for Node Hardware Inventory entries with an xname that doesn't exist using GET.' failed:\n- Error calling validate function '<function validate_pykwalify at 0x7f66510c1e50>':\n    Traceback (most recent call last):\n      File \"/usr/lib/python3.9/site-packages/tavern/schemas/files.py\", line 106, in verify_generic\n        verifier.validate()\n      File \"/usr/lib/python3.9/site-packages/pykwalify/core.py\", line 194, in validate\n        raise SchemaError(u\"Schema validation failed:\\n - {error_msg}.\".format(\n    pykwalify.errors.SchemaError: <SchemaError: error code 2: Schema validation failed:\n     - Key 'Nodes' was not defined. Path: ''.: Path: '/'>\n\n    The above exception was the direct cause of the following exception:\n\n    Traceback (most recent call last):\n      File \"/usr/lib/python3.9/site-packages/tavern/response/base.py\", line 152, in _maybe_run_validate_functions\n        vf(response)\n      File \"/usr/lib/python3.9/site-packages/tavern/util/extfunctions.py\", line 98, in inner\n        result = func(response, *args, **kwargs)\n      File \"/usr/lib/python3.9/site-packages/tavern/testutils/helpers.py\", line 103, in validate_pykwalify\n        verify_generic(to_verify, schema)\n      File \"/usr/lib/python3.9/site-packages/tavern/schemas/files.py\", line 109, in verify_generic\n        raise BadSchemaError() from e\n    tavern.util.exceptions.BadSchemaError","children":[{"name":"hsmAPIinventoryHardwareNegative","uid":"98c0532a994d256c","parentUid":"6fea2fdb85e3fd15f8a0ff5f6df57fa0","status":"failed","time":{"start":1711095555925,"stop":1711095556018,"duration":93},"flaky":false,"newFailed":false,"newPassed":false,"newBroken":false,"retriesCount":0,"retriesStatusChange":false,"parameters":[],"tags":[]}],"uid":"6fea2fdb85e3fd15f8a0ff5f6df57fa0"},{"name":"tavern.util.exceptions.TestFailError: Test 'Query bootscript by xname' failed:\n- Error calling validate function '<function better_validate_regex at 0x7fd6a03af310>':\n    Traceback (most recent call last):\n      File \"/usr/lib/python3.9/site-packages/tavern/response/base.py\", line 152, in _maybe_run_validate_functions\n        vf(response)\n      File \"/usr/lib/python3.9/site-packages/tavern/util/extfunctions.py\", line 98, in inner\n        result = func(response, *args, **kwargs)\n      File \"/src/libs/bss_test_utils.py\", line 65, in better_validate_regex\n        raise exceptions.RegexAccessError(f\"No match for regex '{expression}' in response:\\n{response.text}\")\n    tavern.util.exceptions.RegexAccessError: No match for regex 'kernel http[s]?:\\/\\/.+/boot-images/00000000-0000-0000-0000-000000000000\\/kernel' in response:\n    #!ipxe\n    sleep 10\n    chain https://api-gw-service-nmn.local/apis/bss/boot/v1/bootscript?mac=00:40:a6:4b:d2:da&retry=1\n\n\n\n- Error calling validate function '<function better_validate_regex at 0x7fd6a03af310>':\n    Traceback (most recent call last):\n      File \"/usr/lib/python3.9/site-packages/tavern/response/base.py\", line 152, in _maybe_run_validate_functions\n        vf(response)\n      File \"/usr/lib/python3.9/site-packages/tavern/util/extfunctions.py\", line 98, in inner\n        result = func(response, *args, **kwargs)\n      File \"/src/libs/bss_test_utils.py\", line 65, in better_validate_regex\n        raise exceptions.RegexAccessError(f\"No match for regex '{expression}' in response:\\n{response.text}\")\n    tavern.util.exceptions.RegexAccessError: No match for regex 'initrd http[s]?:\\/\\/.+/boot-images/00000000-0000-0000-0000-000000000000\\/initrd' in response:\n    #!ipxe\n    sleep 10\n    chain https://api-gw-service-nmn.local/apis/bss/boot/v1/bootscript?mac=00:40:a6:4b:d2:da&retry=1\n\n\n\n- Error calling validate function '<function better_validate_regex at 0x7fd6a03af310>':\n    Traceback (most recent call last):\n      File \"/usr/lib/python3.9/site-packages/tavern/response/base.py\", line 152, in _maybe_run_validate_functions\n        vf(response)\n      File \"/usr/lib/python3.9/site-packages/tavern/util/extfunctions.py\", line 98, in inner\n        result = func(response, *args, **kwargs)\n      File \"/src/libs/bss_test_utils.py\", line 65, in better_validate_regex\n        raise exceptions.RegexAccessError(f\"No match for regex '{expression}' in response:\\n{response.text}\")\n    tavern.util.exceptions.RegexAccessError: No match for regex 'kernel --name .+console.tty0' in response:\n    #!ipxe\n    sleep 10\n    chain https://api-gw-service-nmn.local/apis/bss/boot/v1/bootscript?mac=00:40:a6:4b:d2:da&retry=1\n\n\n\n- Error calling validate function '<function better_validate_regex at 0x7fd6a03af310>':\n    Traceback (most recent call last):\n      File \"/usr/lib/python3.9/site-packages/tavern/response/base.py\", line 152, in _maybe_run_validate_functions\n        vf(response)\n      File \"/usr/lib/python3.9/site-packages/tavern/util/extfunctions.py\", line 98, in inner\n        result = func(response, *args, **kwargs)\n      File \"/src/libs/bss_test_utils.py\", line 65, in better_validate_regex\n        raise exceptions.RegexAccessError(f\"No match for regex '{expression}' in response:\\n{response.text}\")\n    tavern.util.exceptions.RegexAccessError: No match for regex 'kernel --name .+xname=x1000c0s6b0n1' in response:\n    #!ipxe\n    sleep 10\n    chain https://api-gw-service-nmn.local/apis/bss/boot/v1/bootscript?mac=00:40:a6:4b:d2:da&retry=1\n\n\n\n- Error calling validate function '<function better_validate_regex at 0x7fd6a03af310>':\n    Traceback (most recent call last):\n      File \"/usr/lib/python3.9/site-packages/tavern/response/base.py\", line 152, in _maybe_run_validate_functions\n        vf(response)\n      File \"/usr/lib/python3.9/site-packages/tavern/util/extfunctions.py\", line 98, in inner\n        result = func(response, *args, **kwargs)\n      File \"/src/libs/bss_test_utils.py\", line 65, in better_validate_regex\n        raise exceptions.RegexAccessError(f\"No match for regex '{expression}' in response:\\n{response.text}\")\n    tavern.util.exceptions.RegexAccessError: No match for regex 'kernel --name .+nid=1025' in response:\n    #!ipxe\n    sleep 10\n    chain https://api-gw-service-nmn.local/apis/bss/boot/v1/bootscript?mac=00:40:a6:4b:d2:da&retry=1\n\n\n\n- Error calling validate function '<function better_validate_regex at 0x7fd6a03af310>':\n    Traceback (most recent call last):\n      File \"/usr/lib/python3.9/site-packages/tavern/response/base.py\", line 152, in _maybe_run_validate_functions\n        vf(response)\n      File \"/usr/lib/python3.9/site-packages/tavern/util/extfunctions.py\", line 98, in inner\n        result = func(response, *args, **kwargs)\n      File \"/src/libs/bss_test_utils.py\", line 65, in better_validate_regex\n        raise exceptions.RegexAccessError(f\"No match for regex '{expression}' in response:\\n{response.text}\")\n    tavern.util.exceptions.RegexAccessError: No match for regex 'kernel --name .+bss_referral_token=' in response:\n    #!ipxe\n    sleep 10\n    chain https://api-gw-service-nmn.local/apis/bss/boot/v1/bootscript?mac=00:40:a6:4b:d2:da&retry=1","children":[{"name":"bssAPIbootscript","uid":"3391b245f2026dc8","parentUid":"fccf139c6c40fc827e1bfa6a84e38bcc","status":"failed","time":{"start":1711096555872,"stop":1711096555944,"duration":72},"flaky":false,"newFailed":false,"newPassed":false,"newBroken":false,"retriesCount":0,"retriesStatusChange":false,"parameters":[],"tags":[]}],"uid":"fccf139c6c40fc827e1bfa6a84e38bcc"}],"uid":"8fb3a91ba5aaf9de24cc8a92edc82b5d"}],"name":"categories"}