[1m[31mERROR   [0m pykwalify.core:core.py:190 validation.invalid
[1m[31mERROR   [0m pykwalify.core:core.py:191  --- All found errors ---
[1m[31mERROR   [0m pykwalify.core:core.py:192 ["Enum 'new' does not exist. Path: '/taskStatus' Enum: ['completed']"]
[1m[31mERROR   [0m tavern.schemas.files:files.py:108 Error validating {'taskID': '0169876f-1e08-4c48-a132-9d8cce59b14a', 'type': 'patch', 'taskCreateTime': '2024-03-27T08:35:41.806277586Z', 'automaticExpirationTime': '2024-03-28T08:35:41.806277646Z', 'taskStatus': 'new', 'taskCounts': {'total': 0, 'new': 0, 'in-progress': 0, 'failed': 0, 'succeeded': 0, 'un-supported': 0}}
Traceback (most recent call last):
  File "/usr/lib/python3.9/site-packages/tavern/schemas/files.py", line 106, in verify_generic
    verifier.validate()
  File "/usr/lib/python3.9/site-packages/pykwalify/core.py", line 194, in validate
    raise SchemaError(u"Schema validation failed:\n - {error_msg}.".format(
pykwalify.errors.SchemaError: <SchemaError: error code 2: Schema validation failed:
 - Enum 'new' does not exist. Path: '/taskStatus' Enum: ['completed'].: Path: '/'>
[1m[31mERROR   [0m tavern.response.base:base.py:41 Error calling validate function '<function validate_pykwalify at 0x7f136f1cce50>':
    Traceback (most recent call last):
      File "/usr/lib/python3.9/site-packages/tavern/schemas/files.py", line 106, in verify_generic
        verifier.validate()
      File "/usr/lib/python3.9/site-packages/pykwalify/core.py", line 194, in validate
        raise SchemaError(u"Schema validation failed:\n - {error_msg}.".format(
    pykwalify.errors.SchemaError: <SchemaError: error code 2: Schema validation failed:
     - Enum 'new' does not exist. Path: '/taskStatus' Enum: ['completed'].: Path: '/'>

    The above exception was the direct cause of the following exception:

    Traceback (most recent call last):
      File "/usr/lib/python3.9/site-packages/tavern/response/base.py", line 152, in _maybe_run_validate_functions
        vf(response)
      File "/usr/lib/python3.9/site-packages/tavern/util/extfunctions.py", line 98, in inner
        result = func(response, *args, **kwargs)
      File "/usr/lib/python3.9/site-packages/tavern/testutils/helpers.py", line 103, in validate_pykwalify
        verify_generic(to_verify, schema)
      File "/usr/lib/python3.9/site-packages/tavern/schemas/files.py", line 109, in verify_generic
        raise BadSchemaError() from e
    tavern.util.exceptions.BadSchemaError
Traceback (most recent call last):
  File "/usr/lib/python3.9/site-packages/tavern/schemas/files.py", line 106, in verify_generic
    verifier.validate()
  File "/usr/lib/python3.9/site-packages/pykwalify/core.py", line 194, in validate
    raise SchemaError(u"Schema validation failed:\n - {error_msg}.".format(
pykwalify.errors.SchemaError: <SchemaError: error code 2: Schema validation failed:
 - Enum 'new' does not exist. Path: '/taskStatus' Enum: ['completed'].: Path: '/'>

The above exception was the direct cause of the following exception:

Traceback (most recent call last):
  File "/usr/lib/python3.9/site-packages/tavern/response/base.py", line 152, in _maybe_run_validate_functions
    vf(response)
  File "/usr/lib/python3.9/site-packages/tavern/util/extfunctions.py", line 98, in inner
    result = func(response, *args, **kwargs)
  File "/usr/lib/python3.9/site-packages/tavern/testutils/helpers.py", line 103, in validate_pykwalify
    verify_generic(to_verify, schema)
  File "/usr/lib/python3.9/site-packages/tavern/schemas/files.py", line 109, in verify_generic
    raise BadSchemaError() from e
tavern.util.exceptions.BadSchemaError