{"uid":"3c7e360d7a4c161e","name":"capmcAPISetPowerCap","fullName":"api.4-build-pipeline-only.test_set_power_cap.tavern#capmcAPISetPowerCap","historyId":"dd408b17f7b8e55258fcff9f663cd89b","time":{"start":1711355444310,"stop":1711355444453,"duration":143},"status":"failed","statusMessage":"tavern.util.exceptions.TestFailError: Test 'capmcAPISetPowerCap - test2 - set_power_cap for two ready nodes' failed:\n- Error calling validate function '<function validate_pykwalify at 0x7f6cccffe5e0>':\n    Traceback (most recent call last):\n      File \"/usr/lib/python3.9/site-packages/tavern/schemas/files.py\", line 106, in verify_generic\n        verifier.validate()\n      File \"/usr/lib/python3.9/site-packages/pykwalify/core.py\", line 194, in validate\n        raise SchemaError(u\"Schema validation failed:\\n - {error_msg}.\".format(\n    pykwalify.errors.SchemaError: <SchemaError: error code 2: Schema validation failed:\n     - Enum '22' does not exist. Path: '/e' Enum: [0].\n     - Value '[{'nid': 1005, 'e': 22, 'err_msg': 'Control (Node Power Limit) value (5036) is greater than maximum (925)'}, {'nid': 20, 'e': 22, 'err_msg': 'No NID supported controls specified'}]' is not of type 'none'. Path: '/nids'.: Path: '/'>\n\n    The above exception was the direct cause of the following exception:\n\n    Traceback (most recent call last):\n      File \"/usr/lib/python3.9/site-packages/tavern/response/base.py\", line 152, in _maybe_run_validate_functions\n        vf(response)\n      File \"/usr/lib/python3.9/site-packages/tavern/util/extfunctions.py\", line 98, in inner\n        result = func(response, *args, **kwargs)\n      File \"/usr/lib/python3.9/site-packages/tavern/testutils/helpers.py\", line 103, in validate_pykwalify\n        verify_generic(to_verify, schema)\n      File \"/usr/lib/python3.9/site-packages/tavern/schemas/files.py\", line 109, in verify_generic\n        raise BadSchemaError() from e\n    tavern.util.exceptions.BadSchemaError","statusTrace":"Format variables:\n  capmc_base_url = 'http://cray-capmc:27777'\n  nid0:d = '1005'\n  min0:d = '5036'\n  nid1:d = '20'\n  min1:d = '5036'\n  verify = 'False'\n\nSource test stage (line 184):\n  - name: capmcAPISetPowerCap - test2 - set_power_cap for two ready nodes\n    request:\n      url: \"{capmc_base_url}/capmc/v1/set_power_cap\"\n      json:\n        nids:\n          - nid: !int \"{nid0:d}\"\n            controls:\n              - name: Node Power Limit\n                val: !int \"{min0:d}\"\n          - nid: !int \"{nid1:d}\"\n            controls:\n              - name: Node Power Limit\n                val: !int \"{min1:d}\"\n      method: POST\n      verify: !bool \"{verify}\"\n    response:\n      status_code: 200\n      verify_response_with:\n        function: tavern.testutils.helpers:validate_pykwalify\n        extra_kwargs:\n\n\n\n\n\n\n          schema:\n            type: map\n            mapping:\n              e:\n                type: int\n                required: True\n                enum:\n                  - 0\n              err_msg:\n                type: str\n                required: True\n              nids:\n                type: none\n                required: False\n\n\nFormatted stage:\n  name: capmcAPISetPowerCap - test2 - set_power_cap for two ready nodes\n  request:\n    json:\n      nids:\n      - controls:\n        - name: Node Power Limit\n          val: !int '5036'\n        nid: !int '1005'\n      - controls:\n        - name: Node Power Limit\n          val: !int '5036'\n        nid: !int '20'\n    method: POST\n    url: 'http://cray-capmc:27777/capmc/v1/set_power_cap'\n    verify: !bool 'False'\n  response:\n    status_code: 200\n    verify_response_with:\n      extra_kwargs:\n        schema:\n          mapping:\n            e:\n              enum:\n              - 0\n              required: true\n              type: int\n            err_msg:\n              required: true\n              type: str\n            nids:\n              required: false\n              type: none\n          type: map\n      function: tavern.testutils.helpers:validate_pykwalify\n\nErrors:\nE   tavern.util.exceptions.TestFailError: Test 'capmcAPISetPowerCap - test2 - set_power_cap for two ready nodes' failed:\n    - Error calling validate function '<function validate_pykwalify at 0x7f6cccffe5e0>':\n        Traceback (most recent call last):\n          File \"/usr/lib/python3.9/site-packages/tavern/schemas/files.py\", line 106, in verify_generic\n            verifier.validate()\n          File \"/usr/lib/python3.9/site-packages/pykwalify/core.py\", line 194, in validate\n            raise SchemaError(u\"Schema validation failed:\\n - {error_msg}.\".format(\n        pykwalify.errors.SchemaError: <SchemaError: error code 2: Schema validation failed:\n         - Enum '22' does not exist. Path: '/e' Enum: [0].\n         - Value '[{'nid': 1005, 'e': 22, 'err_msg': 'Control (Node Power Limit) value (5036) is greater than maximum (925)'}, {'nid': 20, 'e': 22, 'err_msg': 'No NID supported controls specified'}]' is not of type 'none'. Path: '/nids'.: Path: '/'>\n    \n        The above exception was the direct cause of the following exception:\n    \n        Traceback (most recent call last):\n          File \"/usr/lib/python3.9/site-packages/tavern/response/base.py\", line 152, in _maybe_run_validate_functions\n            vf(response)\n          File \"/usr/lib/python3.9/site-packages/tavern/util/extfunctions.py\", line 98, in inner\n            result = func(response, *args, **kwargs)\n          File \"/usr/lib/python3.9/site-packages/tavern/testutils/helpers.py\", line 103, in validate_pykwalify\n            verify_generic(to_verify, schema)\n          File \"/usr/lib/python3.9/site-packages/tavern/schemas/files.py\", line 109, in verify_generic\n            raise BadSchemaError() from e\n        tavern.util.exceptions.BadSchemaError","flaky":true,"newFailed":true,"newBroken":false,"newPassed":false,"retriesCount":0,"retriesStatusChange":false,"beforeStages":[],"testStage":{"status":"failed","statusMessage":"tavern.util.exceptions.TestFailError: Test 'capmcAPISetPowerCap - test2 - set_power_cap for two ready nodes' failed:\n- Error calling validate function '<function validate_pykwalify at 0x7f6cccffe5e0>':\n    Traceback (most recent call last):\n      File \"/usr/lib/python3.9/site-packages/tavern/schemas/files.py\", line 106, in verify_generic\n        verifier.validate()\n      File \"/usr/lib/python3.9/site-packages/pykwalify/core.py\", line 194, in validate\n        raise SchemaError(u\"Schema validation failed:\\n - {error_msg}.\".format(\n    pykwalify.errors.SchemaError: <SchemaError: error code 2: Schema validation failed:\n     - Enum '22' does not exist. Path: '/e' Enum: [0].\n     - Value '[{'nid': 1005, 'e': 22, 'err_msg': 'Control (Node Power Limit) value (5036) is greater than maximum (925)'}, {'nid': 20, 'e': 22, 'err_msg': 'No NID supported controls specified'}]' is not of type 'none'. Path: '/nids'.: Path: '/'>\n\n    The above exception was the direct cause of the following exception:\n\n    Traceback (most recent call last):\n      File \"/usr/lib/python3.9/site-packages/tavern/response/base.py\", line 152, in _maybe_run_validate_functions\n        vf(response)\n      File \"/usr/lib/python3.9/site-packages/tavern/util/extfunctions.py\", line 98, in inner\n        result = func(response, *args, **kwargs)\n      File \"/usr/lib/python3.9/site-packages/tavern/testutils/helpers.py\", line 103, in validate_pykwalify\n        verify_generic(to_verify, schema)\n      File \"/usr/lib/python3.9/site-packages/tavern/schemas/files.py\", line 109, in verify_generic\n        raise BadSchemaError() from e\n    tavern.util.exceptions.BadSchemaError","statusTrace":"Format variables:\n  capmc_base_url = 'http://cray-capmc:27777'\n  nid0:d = '1005'\n  min0:d = '5036'\n  nid1:d = '20'\n  min1:d = '5036'\n  verify = 'False'\n\nSource test stage (line 184):\n  - name: capmcAPISetPowerCap - test2 - set_power_cap for two ready nodes\n    request:\n      url: \"{capmc_base_url}/capmc/v1/set_power_cap\"\n      json:\n        nids:\n          - nid: !int \"{nid0:d}\"\n            controls:\n              - name: Node Power Limit\n                val: !int \"{min0:d}\"\n          - nid: !int \"{nid1:d}\"\n            controls:\n              - name: Node Power Limit\n                val: !int \"{min1:d}\"\n      method: POST\n      verify: !bool \"{verify}\"\n    response:\n      status_code: 200\n      verify_response_with:\n        function: tavern.testutils.helpers:validate_pykwalify\n        extra_kwargs:\n\n\n\n\n\n\n          schema:\n            type: map\n            mapping:\n              e:\n                type: int\n                required: True\n                enum:\n                  - 0\n              err_msg:\n                type: str\n                required: True\n              nids:\n                type: none\n                required: False\n\n\nFormatted stage:\n  name: capmcAPISetPowerCap - test2 - set_power_cap for two ready nodes\n  request:\n    json:\n      nids:\n      - controls:\n        - name: Node Power Limit\n          val: !int '5036'\n        nid: !int '1005'\n      - controls:\n        - name: Node Power Limit\n          val: !int '5036'\n        nid: !int '20'\n    method: POST\n    url: 'http://cray-capmc:27777/capmc/v1/set_power_cap'\n    verify: !bool 'False'\n  response:\n    status_code: 200\n    verify_response_with:\n      extra_kwargs:\n        schema:\n          mapping:\n            e:\n              enum:\n              - 0\n              required: true\n              type: int\n            err_msg:\n              required: true\n              type: str\n            nids:\n              required: false\n              type: none\n          type: map\n      function: tavern.testutils.helpers:validate_pykwalify\n\nErrors:\nE   tavern.util.exceptions.TestFailError: Test 'capmcAPISetPowerCap - test2 - set_power_cap for two ready nodes' failed:\n    - Error calling validate function '<function validate_pykwalify at 0x7f6cccffe5e0>':\n        Traceback (most recent call last):\n          File \"/usr/lib/python3.9/site-packages/tavern/schemas/files.py\", line 106, in verify_generic\n            verifier.validate()\n          File \"/usr/lib/python3.9/site-packages/pykwalify/core.py\", line 194, in validate\n            raise SchemaError(u\"Schema validation failed:\\n - {error_msg}.\".format(\n        pykwalify.errors.SchemaError: <SchemaError: error code 2: Schema validation failed:\n         - Enum '22' does not exist. Path: '/e' Enum: [0].\n         - Value '[{'nid': 1005, 'e': 22, 'err_msg': 'Control (Node Power Limit) value (5036) is greater than maximum (925)'}, {'nid': 20, 'e': 22, 'err_msg': 'No NID supported controls specified'}]' is not of type 'none'. Path: '/nids'.: Path: '/'>\n    \n        The above exception was the direct cause of the following exception:\n    \n        Traceback (most recent call last):\n          File \"/usr/lib/python3.9/site-packages/tavern/response/base.py\", line 152, in _maybe_run_validate_functions\n            vf(response)\n          File \"/usr/lib/python3.9/site-packages/tavern/util/extfunctions.py\", line 98, in inner\n            result = func(response, *args, **kwargs)\n          File \"/usr/lib/python3.9/site-packages/tavern/testutils/helpers.py\", line 103, in validate_pykwalify\n            verify_generic(to_verify, schema)\n          File \"/usr/lib/python3.9/site-packages/tavern/schemas/files.py\", line 109, in verify_generic\n            raise BadSchemaError() from e\n        tavern.util.exceptions.BadSchemaError","steps":[{"name":"Stage 0: capmcAPISetPowerCap - setup1 - Get HSM Nodes","time":{"start":1711355444320,"stop":1711355444349,"duration":29},"status":"passed","steps":[],"attachments":[{"uid":"1a29df49abc5a795","name":"stage_yaml","source":"1a29df49abc5a795.yaml","type":"application/yaml","size":457},{"uid":"83261a9f59daf294","name":"rest_request","source":"83261a9f59daf294.yaml","type":"application/yaml","size":149},{"uid":"e7ba77b0c8f02c7c","name":"rest_response","source":"e7ba77b0c8f02c7c.yaml","type":"application/yaml","size":5770}],"parameters":[],"stepsCount":0,"attachmentsCount":3,"shouldDisplayMessage":false,"hasContent":true},{"name":"Stage 1: capmcAPISetPowerCap - setup2 - get_power_cap_capabilities","time":{"start":1711355444349,"stop":1711355444389,"duration":40},"status":"passed","steps":[],"attachments":[{"uid":"d6b54e4335e0bb41","name":"stage_yaml","source":"d6b54e4335e0bb41.yaml","type":"application/yaml","size":472},{"uid":"b6d60f6aad0969b8","name":"rest_request","source":"b6d60f6aad0969b8.yaml","type":"application/yaml","size":171},{"uid":"6f8caa99fc1d1683","name":"rest_response","source":"6f8caa99fc1d1683.yaml","type":"application/yaml","size":980}],"parameters":[],"stepsCount":0,"attachmentsCount":3,"shouldDisplayMessage":false,"hasContent":true},{"name":"Stage 2: capmcAPISetPowerCap - setup3 - Set HSM Node 0 to Off","time":{"start":1711355444390,"stop":1711355444397,"duration":7},"status":"passed","steps":[],"attachments":[{"uid":"ca6ee71a05b2894e","name":"stage_yaml","source":"ca6ee71a05b2894e.yaml","type":"application/yaml","size":247},{"uid":"7ce3f3035f7b4fd3","name":"rest_request","source":"7ce3f3035f7b4fd3.yaml","type":"application/yaml","size":173},{"uid":"4bac9398a05c8aef","name":"rest_response","source":"4bac9398a05c8aef.yaml","type":"application/yaml","size":134}],"parameters":[],"stepsCount":0,"attachmentsCount":3,"shouldDisplayMessage":false,"hasContent":true},{"name":"Stage 3: capmcAPISetPowerCap - setup4 - Set HSM Node 1 to Off","time":{"start":1711355444398,"stop":1711355444405,"duration":7},"status":"passed","steps":[],"attachments":[{"uid":"e9a9615ab6d7df6d","name":"stage_yaml","source":"e9a9615ab6d7df6d.yaml","type":"application/yaml","size":247},{"uid":"588dc435de4c7e9","name":"rest_request","source":"588dc435de4c7e9.yaml","type":"application/yaml","size":173},{"uid":"a60b3fa4d056093c","name":"rest_response","source":"a60b3fa4d056093c.yaml","type":"application/yaml","size":134}],"parameters":[],"stepsCount":0,"attachmentsCount":3,"shouldDisplayMessage":false,"hasContent":true},{"name":"Stage 4: capmcAPISetPowerCap - test1 - POST set_power_cap for powered off node - failure test","time":{"start":1711355444406,"stop":1711355444420,"duration":14},"status":"passed","steps":[],"attachments":[{"uid":"13388c6dc2495569","name":"stage_yaml","source":"13388c6dc2495569.yaml","type":"application/yaml","size":1395},{"uid":"bf367c2462532340","name":"rest_request","source":"bf367c2462532340.yaml","type":"application/yaml","size":214},{"uid":"a13d4c97665bdee9","name":"rest_response","source":"a13d4c97665bdee9.yaml","type":"application/yaml","size":287}],"parameters":[],"stepsCount":0,"attachmentsCount":3,"shouldDisplayMessage":false,"hasContent":true},{"name":"Stage 5: capmcAPISetPowerCap - setup5 - Set HSM Node 0 to Ready","time":{"start":1711355444421,"stop":1711355444429,"duration":8},"status":"passed","steps":[],"attachments":[{"uid":"d5383b9960d98b1a","name":"stage_yaml","source":"d5383b9960d98b1a.yaml","type":"application/yaml","size":251},{"uid":"cf2d02b566853f6b","name":"rest_request","source":"cf2d02b566853f6b.yaml","type":"application/yaml","size":173},{"uid":"e2ce225e048c2d53","name":"rest_response","source":"e2ce225e048c2d53.yaml","type":"application/yaml","size":134}],"parameters":[],"stepsCount":0,"attachmentsCount":3,"shouldDisplayMessage":false,"hasContent":true},{"name":"Stage 6: capmcAPISetPowerCap - setup6 - Set HSM Node 1 to Ready","time":{"start":1711355444429,"stop":1711355444436,"duration":7},"status":"passed","steps":[],"attachments":[{"uid":"def6cb2e6bdaada5","name":"stage_yaml","source":"def6cb2e6bdaada5.yaml","type":"application/yaml","size":251},{"uid":"53d431e6f00a6d92","name":"rest_request","source":"53d431e6f00a6d92.yaml","type":"application/yaml","size":173},{"uid":"770bfe9874b32bc0","name":"rest_response","source":"770bfe9874b32bc0.yaml","type":"application/yaml","size":134}],"parameters":[],"stepsCount":0,"attachmentsCount":3,"shouldDisplayMessage":false,"hasContent":true},{"name":"Stage 7: capmcAPISetPowerCap - test2 - set_power_cap for two ready nodes","time":{"start":1711355444437,"stop":1711355444452,"duration":15},"status":"failed","statusMessage":"tavern.util.exceptions.TestFailError: Test 'capmcAPISetPowerCap - test2 - set_power_cap for two ready nodes' failed:\n- Error calling validate function '<function validate_pykwalify at 0x7f6cccffe5e0>':\n    Traceback (most recent call last):\n      File \"/usr/lib/python3.9/site-packages/tavern/schemas/files.py\", line 106, in verify_generic\n        verifier.validate()\n      File \"/usr/lib/python3.9/site-packages/pykwalify/core.py\", line 194, in validate\n        raise SchemaError(u\"Schema validation failed:\\n - {error_msg}.\".format(\n    pykwalify.errors.SchemaError: <SchemaError: error code 2: Schema validation failed:\n     - Enum '22' does not exist. Path: '/e' Enum: [0].\n     - Value '[{'nid': 1005, 'e': 22, 'err_msg': 'Control (Node Power Limit) value (5036) is greater than maximum (925)'}, {'nid': 20, 'e': 22, 'err_msg': 'No NID supported controls specified'}]' is not of type 'none'. Path: '/nids'.: Path: '/'>\n\n    The above exception was the direct cause of the following exception:\n\n    Traceback (most recent call last):\n      File \"/usr/lib/python3.9/site-packages/tavern/response/base.py\", line 152, in _maybe_run_validate_functions\n        vf(response)\n      File \"/usr/lib/python3.9/site-packages/tavern/util/extfunctions.py\", line 98, in inner\n        result = func(response, *args, **kwargs)\n      File \"/usr/lib/python3.9/site-packages/tavern/testutils/helpers.py\", line 103, in validate_pykwalify\n        verify_generic(to_verify, schema)\n      File \"/usr/lib/python3.9/site-packages/tavern/schemas/files.py\", line 109, in verify_generic\n        raise BadSchemaError() from e\n    tavern.util.exceptions.BadSchemaError\n\n","statusTrace":"  File \"/usr/lib/python3.9/site-packages/allure_commons/_allure.py\", line 192, in impl\n    return func(*a, **kw)\n  File \"/usr/lib/python3.9/site-packages/tavern/util/retry.py\", line 31, in wrapped\n    res = fn(*args, **kwargs)\n  File \"/usr/lib/python3.9/site-packages/tavern/core.py\", line 270, in run_stage\n    saved = v.verify(response)\n  File \"/usr/lib/python3.9/site-packages/tavern/_plugins/rest/response.py\", line 201, in verify\n    raise exceptions.TestFailError(\n","steps":[],"attachments":[{"uid":"bb237cf50aa4b764","name":"stage_yaml","source":"bb237cf50aa4b764.yaml","type":"application/yaml","size":903},{"uid":"ed0bc4faa9b0ab0d","name":"rest_request","source":"ed0bc4faa9b0ab0d.yaml","type":"application/yaml","size":286},{"uid":"c772a7a989023f7c","name":"rest_response","source":"c772a7a989023f7c.yaml","type":"application/yaml","size":394}],"parameters":[],"stepsCount":0,"attachmentsCount":3,"shouldDisplayMessage":true,"hasContent":true}],"attachments":[{"uid":"bb217c24ad49325e","name":"error_output","source":"bb217c24ad49325e.attach","type":"text/plain","size":3773},{"uid":"dad0f595264b3662","name":"log","source":"dad0f595264b3662.txt","type":"text/plain","size":4427}],"parameters":[],"stepsCount":8,"attachmentsCount":26,"shouldDisplayMessage":true,"hasContent":true},"afterStages":[],"labels":[{"name":"parentSuite","value":"cray-capmc-hmth-test"},{"name":"suite","value":"build-pipeline-only"},{"name":"host","value":"da574fbce963"},{"name":"thread","value":"8-MainThread"},{"name":"framework","value":"pytest"},{"name":"language","value":"cpython3"},{"name":"package","value":"api.4-build-pipeline-only.test_set_power_cap.tavern"},{"name":"resultFormat","value":"allure2"}],"parameters":[],"links":[],"hidden":false,"retry":false,"extra":{"severity":"normal","retries":[],"categories":[{"name":"Product defects","matchedStatuses":[],"flaky":false}],"history":{"statistic":{"failed":39,"broken":0,"skipped":0,"passed":325,"unknown":0,"total":364},"items":[{"uid":"d53db36dc5a80b31","status":"passed","time":{"start":1711268932600,"stop":1711268932869,"duration":269}},{"uid":"7c70570d117a253f","status":"passed","time":{"start":1711182622051,"stop":1711182622322,"duration":271}},{"uid":"81e60bd7677737a2","status":"passed","time":{"start":1711096162978,"stop":1711096163236,"duration":258}},{"uid":"eecbe23d9948014f","status":"passed","time":{"start":1711009746512,"stop":1711009746769,"duration":257}},{"uid":"f20ca39ca5f69929","status":"failed","statusDetails":"tavern.util.exceptions.TestFailError: Test 'capmcAPISetPowerCap - test2 - set_power_cap for two ready nodes' failed:\n- Error calling validate function '<function validate_pykwalify at 0x7fcbf0aeb5e0>':\n    Traceback (most recent call last):\n      File \"/usr/lib/python3.9/site-packages/tavern/schemas/files.py\", line 106, in verify_generic\n        verifier.validate()\n      File \"/usr/lib/python3.9/site-packages/pykwalify/core.py\", line 194, in validate\n        raise SchemaError(u\"Schema validation failed:\\n - {error_msg}.\".format(\n    pykwalify.errors.SchemaError: <SchemaError: error code 2: Schema validation failed:\n     - Enum '22' does not exist. Path: '/e' Enum: [0].\n     - Value '[{'nid': 20, 'e': 22, 'err_msg': 'No NID supported controls specified'}, {'nid': 1017, 'e': 22, 'err_msg': 'Control (Node Power Limit) value (5036) is greater than maximum (925)'}]' is not of type 'none'. Path: '/nids'.: Path: '/'>\n\n    The above exception was the direct cause of the following exception:\n\n    Traceback (most recent call last):\n      File \"/usr/lib/python3.9/site-packages/tavern/response/base.py\", line 152, in _maybe_run_validate_functions\n        vf(response)\n      File \"/usr/lib/python3.9/site-packages/tavern/util/extfunctions.py\", line 98, in inner\n        result = func(response, *args, **kwargs)\n      File \"/usr/lib/python3.9/site-packages/tavern/testutils/helpers.py\", line 103, in validate_pykwalify\n        verify_generic(to_verify, schema)\n      File \"/usr/lib/python3.9/site-packages/tavern/schemas/files.py\", line 109, in verify_generic\n        raise BadSchemaError() from e\n    tavern.util.exceptions.BadSchemaError","time":{"start":1710923403557,"stop":1710923403698,"duration":141}},{"uid":"885f40754028d244","status":"failed","statusDetails":"tavern.util.exceptions.TestFailError: Test 'capmcAPISetPowerCap - test2 - set_power_cap for two ready nodes' failed:\n- Error calling validate function '<function validate_pykwalify at 0x78edf8f685e0>':\n    Traceback (most recent call last):\n      File \"/usr/lib/python3.9/site-packages/tavern/schemas/files.py\", line 106, in verify_generic\n        verifier.validate()\n      File \"/usr/lib/python3.9/site-packages/pykwalify/core.py\", line 194, in validate\n        raise SchemaError(u\"Schema validation failed:\\n - {error_msg}.\".format(\n    pykwalify.errors.SchemaError: <SchemaError: error code 2: Schema validation failed:\n     - Enum '22' does not exist. Path: '/e' Enum: [0].\n     - Value '[{'nid': 20, 'e': 22, 'err_msg': 'No NID supported controls specified'}, {'nid': 1018, 'e': 22, 'err_msg': 'Control (Node Power Limit) value (5036) is greater than maximum (925)'}]' is not of type 'none'. Path: '/nids'.: Path: '/'>\n\n    The above exception was the direct cause of the following exception:\n\n    Traceback (most recent call last):\n      File \"/usr/lib/python3.9/site-packages/tavern/response/base.py\", line 152, in _maybe_run_validate_functions\n        vf(response)\n      File \"/usr/lib/python3.9/site-packages/tavern/util/extfunctions.py\", line 98, in inner\n        result = func(response, *args, **kwargs)\n      File \"/usr/lib/python3.9/site-packages/tavern/testutils/helpers.py\", line 103, in validate_pykwalify\n        verify_generic(to_verify, schema)\n      File \"/usr/lib/python3.9/site-packages/tavern/schemas/files.py\", line 109, in verify_generic\n        raise BadSchemaError() from e\n    tavern.util.exceptions.BadSchemaError","time":{"start":1710836951201,"stop":1710836951347,"duration":146}},{"uid":"1d643dcc95c90dfe","status":"passed","time":{"start":1710750621824,"stop":1710750622104,"duration":280}},{"uid":"8a244bb04401595","status":"passed","time":{"start":1710664005401,"stop":1710664005657,"duration":256}},{"uid":"1e23a14ca4e891ae","status":"failed","statusDetails":"tavern.util.exceptions.TestFailError: Test 'capmcAPISetPowerCap - test2 - set_power_cap for two ready nodes' failed:\n- Error calling validate function '<function validate_pykwalify at 0x7492f42105e0>':\n    Traceback (most recent call last):\n      File \"/usr/lib/python3.9/site-packages/tavern/schemas/files.py\", line 106, in verify_generic\n        verifier.validate()\n      File \"/usr/lib/python3.9/site-packages/pykwalify/core.py\", line 194, in validate\n        raise SchemaError(u\"Schema validation failed:\\n - {error_msg}.\".format(\n    pykwalify.errors.SchemaError: <SchemaError: error code 2: Schema validation failed:\n     - Enum '22' does not exist. Path: '/e' Enum: [0].\n     - Value '[{'nid': 20, 'e': 22, 'err_msg': 'No NID supported controls specified'}, {'nid': 1021, 'e': 22, 'err_msg': 'Control (Node Power Limit) value (5036) is greater than maximum (925)'}]' is not of type 'none'. Path: '/nids'.: Path: '/'>\n\n    The above exception was the direct cause of the following exception:\n\n    Traceback (most recent call last):\n      File \"/usr/lib/python3.9/site-packages/tavern/response/base.py\", line 152, in _maybe_run_validate_functions\n        vf(response)\n      File \"/usr/lib/python3.9/site-packages/tavern/util/extfunctions.py\", line 98, in inner\n        result = func(response, *args, **kwargs)\n      File \"/usr/lib/python3.9/site-packages/tavern/testutils/helpers.py\", line 103, in validate_pykwalify\n        verify_generic(to_verify, schema)\n      File \"/usr/lib/python3.9/site-packages/tavern/schemas/files.py\", line 109, in verify_generic\n        raise BadSchemaError() from e\n    tavern.util.exceptions.BadSchemaError","time":{"start":1710577746155,"stop":1710577746292,"duration":137}},{"uid":"79547bbb0a87f717","status":"failed","statusDetails":"tavern.util.exceptions.TestFailError: Test 'capmcAPISetPowerCap - test2 - set_power_cap for two ready nodes' failed:\n- Error calling validate function '<function validate_pykwalify at 0x778b942d85e0>':\n    Traceback (most recent call last):\n      File \"/usr/lib/python3.9/site-packages/tavern/schemas/files.py\", line 106, in verify_generic\n        verifier.validate()\n      File \"/usr/lib/python3.9/site-packages/pykwalify/core.py\", line 194, in validate\n        raise SchemaError(u\"Schema validation failed:\\n - {error_msg}.\".format(\n    pykwalify.errors.SchemaError: <SchemaError: error code 2: Schema validation failed:\n     - Enum '22' does not exist. Path: '/e' Enum: [0].\n     - Value '[{'nid': 20, 'e': 22, 'err_msg': 'No NID supported controls specified'}, {'nid': 1005, 'e': 22, 'err_msg': 'Control (Node Power Limit) value (5036) is greater than maximum (925)'}]' is not of type 'none'. Path: '/nids'.: Path: '/'>\n\n    The above exception was the direct cause of the following exception:\n\n    Traceback (most recent call last):\n      File \"/usr/lib/python3.9/site-packages/tavern/response/base.py\", line 152, in _maybe_run_validate_functions\n        vf(response)\n      File \"/usr/lib/python3.9/site-packages/tavern/util/extfunctions.py\", line 98, in inner\n        result = func(response, *args, **kwargs)\n      File \"/usr/lib/python3.9/site-packages/tavern/testutils/helpers.py\", line 103, in validate_pykwalify\n        verify_generic(to_verify, schema)\n      File \"/usr/lib/python3.9/site-packages/tavern/schemas/files.py\", line 109, in verify_generic\n        raise BadSchemaError() from e\n    tavern.util.exceptions.BadSchemaError","time":{"start":1710491341499,"stop":1710491341646,"duration":147}},{"uid":"27a37366f179be8f","status":"failed","statusDetails":"tavern.util.exceptions.TestFailError: Test 'capmcAPISetPowerCap - test2 - set_power_cap for two ready nodes' failed:\n- Error calling validate function '<function validate_pykwalify at 0x7946947235e0>':\n    Traceback (most recent call last):\n      File \"/usr/lib/python3.9/site-packages/tavern/schemas/files.py\", line 106, in verify_generic\n        verifier.validate()\n      File \"/usr/lib/python3.9/site-packages/pykwalify/core.py\", line 194, in validate\n        raise SchemaError(u\"Schema validation failed:\\n - {error_msg}.\".format(\n    pykwalify.errors.SchemaError: <SchemaError: error code 2: Schema validation failed:\n     - Enum '22' does not exist. Path: '/e' Enum: [0].\n     - Value '[{'nid': 20, 'e': 22, 'err_msg': 'No NID supported controls specified'}, {'nid': 1010, 'e': 22, 'err_msg': 'Control (Node Power Limit) value (5036) is greater than maximum (925)'}]' is not of type 'none'. Path: '/nids'.: Path: '/'>\n\n    The above exception was the direct cause of the following exception:\n\n    Traceback (most recent call last):\n      File \"/usr/lib/python3.9/site-packages/tavern/response/base.py\", line 152, in _maybe_run_validate_functions\n        vf(response)\n      File \"/usr/lib/python3.9/site-packages/tavern/util/extfunctions.py\", line 98, in inner\n        result = func(response, *args, **kwargs)\n      File \"/usr/lib/python3.9/site-packages/tavern/testutils/helpers.py\", line 103, in validate_pykwalify\n        verify_generic(to_verify, schema)\n      File \"/usr/lib/python3.9/site-packages/tavern/schemas/files.py\", line 109, in verify_generic\n        raise BadSchemaError() from e\n    tavern.util.exceptions.BadSchemaError","time":{"start":1710404860415,"stop":1710404860555,"duration":140}},{"uid":"c68f0fcd398db721","status":"failed","statusDetails":"tavern.util.exceptions.TestFailError: Test 'capmcAPISetPowerCap - test2 - set_power_cap for two ready nodes' failed:\n- Error calling validate function '<function validate_pykwalify at 0x70c1dd9a45e0>':\n    Traceback (most recent call last):\n      File \"/usr/lib/python3.9/site-packages/tavern/schemas/files.py\", line 106, in verify_generic\n        verifier.validate()\n      File \"/usr/lib/python3.9/site-packages/pykwalify/core.py\", line 194, in validate\n        raise SchemaError(u\"Schema validation failed:\\n - {error_msg}.\".format(\n    pykwalify.errors.SchemaError: <SchemaError: error code 2: Schema validation failed:\n     - Enum '22' does not exist. Path: '/e' Enum: [0].\n     - Value '[{'nid': 1028, 'e': 22, 'err_msg': 'Control (Node Power Limit) value (5036) is greater than maximum (925)'}, {'nid': 20, 'e': 22, 'err_msg': 'No NID supported controls specified'}]' is not of type 'none'. Path: '/nids'.: Path: '/'>\n\n    The above exception was the direct cause of the following exception:\n\n    Traceback (most recent call last):\n      File \"/usr/lib/python3.9/site-packages/tavern/response/base.py\", line 152, in _maybe_run_validate_functions\n        vf(response)\n      File \"/usr/lib/python3.9/site-packages/tavern/util/extfunctions.py\", line 98, in inner\n        result = func(response, *args, **kwargs)\n      File \"/usr/lib/python3.9/site-packages/tavern/testutils/helpers.py\", line 103, in validate_pykwalify\n        verify_generic(to_verify, schema)\n      File \"/usr/lib/python3.9/site-packages/tavern/schemas/files.py\", line 109, in verify_generic\n        raise BadSchemaError() from e\n    tavern.util.exceptions.BadSchemaError","time":{"start":1710318531050,"stop":1710318531195,"duration":145}},{"uid":"bd4d10c14034b2a6","status":"passed","time":{"start":1710232059663,"stop":1710232059919,"duration":256}},{"uid":"8248955122190c98","status":"passed","time":{"start":1710145744726,"stop":1710145744982,"duration":256}},{"uid":"a53daacc38a34b92","status":"passed","time":{"start":1710059282287,"stop":1710059282543,"duration":256}},{"uid":"6cc094426a81dd9","status":"passed","time":{"start":1709972897626,"stop":1709972897875,"duration":249}},{"uid":"97ff3e54a763fdfb","status":"failed","statusDetails":"tavern.util.exceptions.TestFailError: Test 'capmcAPISetPowerCap - test2 - set_power_cap for two ready nodes' failed:\n- Error calling validate function '<function validate_pykwalify at 0x7f905718b5e0>':\n    Traceback (most recent call last):\n      File \"/usr/lib/python3.9/site-packages/tavern/schemas/files.py\", line 106, in verify_generic\n        verifier.validate()\n      File \"/usr/lib/python3.9/site-packages/pykwalify/core.py\", line 194, in validate\n        raise SchemaError(u\"Schema validation failed:\\n - {error_msg}.\".format(\n    pykwalify.errors.SchemaError: <SchemaError: error code 2: Schema validation failed:\n     - Enum '22' does not exist. Path: '/e' Enum: [0].\n     - Value '[{'nid': 20, 'e': 22, 'err_msg': 'No NID supported controls specified'}]' is not of type 'none'. Path: '/nids'.: Path: '/'>\n\n    The above exception was the direct cause of the following exception:\n\n    Traceback (most recent call last):\n      File \"/usr/lib/python3.9/site-packages/tavern/response/base.py\", line 152, in _maybe_run_validate_functions\n        vf(response)\n      File \"/usr/lib/python3.9/site-packages/tavern/util/extfunctions.py\", line 98, in inner\n        result = func(response, *args, **kwargs)\n      File \"/usr/lib/python3.9/site-packages/tavern/testutils/helpers.py\", line 103, in validate_pykwalify\n        verify_generic(to_verify, schema)\n      File \"/usr/lib/python3.9/site-packages/tavern/schemas/files.py\", line 109, in verify_generic\n        raise BadSchemaError() from e\n    tavern.util.exceptions.BadSchemaError","time":{"start":1709886526260,"stop":1709886526401,"duration":141}},{"uid":"b8d9bf0cca6e719c","status":"passed","time":{"start":1709800109297,"stop":1709800109546,"duration":249}},{"uid":"5fc2223786f9d2c","status":"passed","time":{"start":1709713809280,"stop":1709713809530,"duration":250}},{"uid":"1263a94f6d5a25fe","status":"passed","time":{"start":1709627296860,"stop":1709627297106,"duration":246}}]},"tags":[]},"source":"3c7e360d7a4c161e.json","parameterValues":[]}