{"uid":"bf56a2ce16d0469c","name":"capmcAPISetPowerCap","fullName":"api.4-build-pipeline-only.test_set_power_cap.tavern#capmcAPISetPowerCap","historyId":"dd408b17f7b8e55258fcff9f663cd89b","time":{"start":1711355507018,"stop":1711355507163,"duration":145},"status":"failed","statusMessage":"tavern.util.exceptions.TestFailError: Test 'capmcAPISetPowerCap - test2 - set_power_cap for two ready nodes' failed:\n- Error calling validate function '<function validate_pykwalify at 0x7f64aa4225e0>':\n    Traceback (most recent call last):\n      File \"/usr/lib/python3.9/site-packages/tavern/schemas/files.py\", line 106, in verify_generic\n        verifier.validate()\n      File \"/usr/lib/python3.9/site-packages/pykwalify/core.py\", line 194, in validate\n        raise SchemaError(u\"Schema validation failed:\\n - {error_msg}.\".format(\n    pykwalify.errors.SchemaError: <SchemaError: error code 2: Schema validation failed:\n     - Enum '22' does not exist. Path: '/e' Enum: [0].\n     - Value '[{'nid': 1026, 'e': 22, 'err_msg': 'Control (Node Power Limit) value (5036) is greater than maximum (925)'}, {'nid': 20, 'e': 22, 'err_msg': 'No NID supported controls specified'}]' is not of type 'none'. Path: '/nids'.: Path: '/'>\n\n    The above exception was the direct cause of the following exception:\n\n    Traceback (most recent call last):\n      File \"/usr/lib/python3.9/site-packages/tavern/response/base.py\", line 152, in _maybe_run_validate_functions\n        vf(response)\n      File \"/usr/lib/python3.9/site-packages/tavern/util/extfunctions.py\", line 98, in inner\n        result = func(response, *args, **kwargs)\n      File \"/usr/lib/python3.9/site-packages/tavern/testutils/helpers.py\", line 103, in validate_pykwalify\n        verify_generic(to_verify, schema)\n      File \"/usr/lib/python3.9/site-packages/tavern/schemas/files.py\", line 109, in verify_generic\n        raise BadSchemaError() from e\n    tavern.util.exceptions.BadSchemaError","statusTrace":"Format variables:\n  capmc_base_url = 'http://cray-capmc:27777'\n  nid0:d = '1026'\n  min0:d = '5036'\n  nid1:d = '20'\n  min1:d = '5036'\n  verify = 'False'\n\nSource test stage (line 184):\n  - name: capmcAPISetPowerCap - test2 - set_power_cap for two ready nodes\n    request:\n      url: \"{capmc_base_url}/capmc/v1/set_power_cap\"\n      json:\n        nids:\n          - nid: !int \"{nid0:d}\"\n            controls:\n              - name: Node Power Limit\n                val: !int \"{min0:d}\"\n          - nid: !int \"{nid1:d}\"\n            controls:\n              - name: Node Power Limit\n                val: !int \"{min1:d}\"\n      method: POST\n      verify: !bool \"{verify}\"\n    response:\n      status_code: 200\n      verify_response_with:\n        function: tavern.testutils.helpers:validate_pykwalify\n        extra_kwargs:\n\n\n\n\n\n\n          schema:\n            type: map\n            mapping:\n              e:\n                type: int\n                required: True\n                enum:\n                  - 0\n              err_msg:\n                type: str\n                required: True\n              nids:\n                type: none\n                required: False\n\n\nFormatted stage:\n  name: capmcAPISetPowerCap - test2 - set_power_cap for two ready nodes\n  request:\n    json:\n      nids:\n      - controls:\n        - name: Node Power Limit\n          val: !int '5036'\n        nid: !int '1026'\n      - controls:\n        - name: Node Power Limit\n          val: !int '5036'\n        nid: !int '20'\n    method: POST\n    url: 'http://cray-capmc:27777/capmc/v1/set_power_cap'\n    verify: !bool 'False'\n  response:\n    status_code: 200\n    verify_response_with:\n      extra_kwargs:\n        schema:\n          mapping:\n            e:\n              enum:\n              - 0\n              required: true\n              type: int\n            err_msg:\n              required: true\n              type: str\n            nids:\n              required: false\n              type: none\n          type: map\n      function: tavern.testutils.helpers:validate_pykwalify\n\nErrors:\nE   tavern.util.exceptions.TestFailError: Test 'capmcAPISetPowerCap - test2 - set_power_cap for two ready nodes' failed:\n    - Error calling validate function '<function validate_pykwalify at 0x7f64aa4225e0>':\n        Traceback (most recent call last):\n          File \"/usr/lib/python3.9/site-packages/tavern/schemas/files.py\", line 106, in verify_generic\n            verifier.validate()\n          File \"/usr/lib/python3.9/site-packages/pykwalify/core.py\", line 194, in validate\n            raise SchemaError(u\"Schema validation failed:\\n - {error_msg}.\".format(\n        pykwalify.errors.SchemaError: <SchemaError: error code 2: Schema validation failed:\n         - Enum '22' does not exist. Path: '/e' Enum: [0].\n         - Value '[{'nid': 1026, 'e': 22, 'err_msg': 'Control (Node Power Limit) value (5036) is greater than maximum (925)'}, {'nid': 20, 'e': 22, 'err_msg': 'No NID supported controls specified'}]' is not of type 'none'. Path: '/nids'.: Path: '/'>\n    \n        The above exception was the direct cause of the following exception:\n    \n        Traceback (most recent call last):\n          File \"/usr/lib/python3.9/site-packages/tavern/response/base.py\", line 152, in _maybe_run_validate_functions\n            vf(response)\n          File \"/usr/lib/python3.9/site-packages/tavern/util/extfunctions.py\", line 98, in inner\n            result = func(response, *args, **kwargs)\n          File \"/usr/lib/python3.9/site-packages/tavern/testutils/helpers.py\", line 103, in validate_pykwalify\n            verify_generic(to_verify, schema)\n          File \"/usr/lib/python3.9/site-packages/tavern/schemas/files.py\", line 109, in verify_generic\n            raise BadSchemaError() from e\n        tavern.util.exceptions.BadSchemaError","flaky":true,"newFailed":true,"newBroken":false,"newPassed":false,"retriesCount":0,"retriesStatusChange":false,"beforeStages":[],"testStage":{"status":"failed","statusMessage":"tavern.util.exceptions.TestFailError: Test 'capmcAPISetPowerCap - test2 - set_power_cap for two ready nodes' failed:\n- Error calling validate function '<function validate_pykwalify at 0x7f64aa4225e0>':\n    Traceback (most recent call last):\n      File \"/usr/lib/python3.9/site-packages/tavern/schemas/files.py\", line 106, in verify_generic\n        verifier.validate()\n      File \"/usr/lib/python3.9/site-packages/pykwalify/core.py\", line 194, in validate\n        raise SchemaError(u\"Schema validation failed:\\n - {error_msg}.\".format(\n    pykwalify.errors.SchemaError: <SchemaError: error code 2: Schema validation failed:\n     - Enum '22' does not exist. Path: '/e' Enum: [0].\n     - Value '[{'nid': 1026, 'e': 22, 'err_msg': 'Control (Node Power Limit) value (5036) is greater than maximum (925)'}, {'nid': 20, 'e': 22, 'err_msg': 'No NID supported controls specified'}]' is not of type 'none'. Path: '/nids'.: Path: '/'>\n\n    The above exception was the direct cause of the following exception:\n\n    Traceback (most recent call last):\n      File \"/usr/lib/python3.9/site-packages/tavern/response/base.py\", line 152, in _maybe_run_validate_functions\n        vf(response)\n      File \"/usr/lib/python3.9/site-packages/tavern/util/extfunctions.py\", line 98, in inner\n        result = func(response, *args, **kwargs)\n      File \"/usr/lib/python3.9/site-packages/tavern/testutils/helpers.py\", line 103, in validate_pykwalify\n        verify_generic(to_verify, schema)\n      File \"/usr/lib/python3.9/site-packages/tavern/schemas/files.py\", line 109, in verify_generic\n        raise BadSchemaError() from e\n    tavern.util.exceptions.BadSchemaError","statusTrace":"Format variables:\n  capmc_base_url = 'http://cray-capmc:27777'\n  nid0:d = '1026'\n  min0:d = '5036'\n  nid1:d = '20'\n  min1:d = '5036'\n  verify = 'False'\n\nSource test stage (line 184):\n  - name: capmcAPISetPowerCap - test2 - set_power_cap for two ready nodes\n    request:\n      url: \"{capmc_base_url}/capmc/v1/set_power_cap\"\n      json:\n        nids:\n          - nid: !int \"{nid0:d}\"\n            controls:\n              - name: Node Power Limit\n                val: !int \"{min0:d}\"\n          - nid: !int \"{nid1:d}\"\n            controls:\n              - name: Node Power Limit\n                val: !int \"{min1:d}\"\n      method: POST\n      verify: !bool \"{verify}\"\n    response:\n      status_code: 200\n      verify_response_with:\n        function: tavern.testutils.helpers:validate_pykwalify\n        extra_kwargs:\n\n\n\n\n\n\n          schema:\n            type: map\n            mapping:\n              e:\n                type: int\n                required: True\n                enum:\n                  - 0\n              err_msg:\n                type: str\n                required: True\n              nids:\n                type: none\n                required: False\n\n\nFormatted stage:\n  name: capmcAPISetPowerCap - test2 - set_power_cap for two ready nodes\n  request:\n    json:\n      nids:\n      - controls:\n        - name: Node Power Limit\n          val: !int '5036'\n        nid: !int '1026'\n      - controls:\n        - name: Node Power Limit\n          val: !int '5036'\n        nid: !int '20'\n    method: POST\n    url: 'http://cray-capmc:27777/capmc/v1/set_power_cap'\n    verify: !bool 'False'\n  response:\n    status_code: 200\n    verify_response_with:\n      extra_kwargs:\n        schema:\n          mapping:\n            e:\n              enum:\n              - 0\n              required: true\n              type: int\n            err_msg:\n              required: true\n              type: str\n            nids:\n              required: false\n              type: none\n          type: map\n      function: tavern.testutils.helpers:validate_pykwalify\n\nErrors:\nE   tavern.util.exceptions.TestFailError: Test 'capmcAPISetPowerCap - test2 - set_power_cap for two ready nodes' failed:\n    - Error calling validate function '<function validate_pykwalify at 0x7f64aa4225e0>':\n        Traceback (most recent call last):\n          File \"/usr/lib/python3.9/site-packages/tavern/schemas/files.py\", line 106, in verify_generic\n            verifier.validate()\n          File \"/usr/lib/python3.9/site-packages/pykwalify/core.py\", line 194, in validate\n            raise SchemaError(u\"Schema validation failed:\\n - {error_msg}.\".format(\n        pykwalify.errors.SchemaError: <SchemaError: error code 2: Schema validation failed:\n         - Enum '22' does not exist. Path: '/e' Enum: [0].\n         - Value '[{'nid': 1026, 'e': 22, 'err_msg': 'Control (Node Power Limit) value (5036) is greater than maximum (925)'}, {'nid': 20, 'e': 22, 'err_msg': 'No NID supported controls specified'}]' is not of type 'none'. Path: '/nids'.: Path: '/'>\n    \n        The above exception was the direct cause of the following exception:\n    \n        Traceback (most recent call last):\n          File \"/usr/lib/python3.9/site-packages/tavern/response/base.py\", line 152, in _maybe_run_validate_functions\n            vf(response)\n          File \"/usr/lib/python3.9/site-packages/tavern/util/extfunctions.py\", line 98, in inner\n            result = func(response, *args, **kwargs)\n          File \"/usr/lib/python3.9/site-packages/tavern/testutils/helpers.py\", line 103, in validate_pykwalify\n            verify_generic(to_verify, schema)\n          File \"/usr/lib/python3.9/site-packages/tavern/schemas/files.py\", line 109, in verify_generic\n            raise BadSchemaError() from e\n        tavern.util.exceptions.BadSchemaError","steps":[{"name":"Stage 0: capmcAPISetPowerCap - setup1 - Get HSM Nodes","time":{"start":1711355507028,"stop":1711355507057,"duration":29},"status":"passed","steps":[],"attachments":[{"uid":"f35181c0d6515be2","name":"stage_yaml","source":"f35181c0d6515be2.yaml","type":"application/yaml","size":457},{"uid":"257c9cd2b0085a16","name":"rest_request","source":"257c9cd2b0085a16.yaml","type":"application/yaml","size":149},{"uid":"85738087c7b0cb30","name":"rest_response","source":"85738087c7b0cb30.yaml","type":"application/yaml","size":5772}],"parameters":[],"stepsCount":0,"attachmentsCount":3,"shouldDisplayMessage":false,"hasContent":true},{"name":"Stage 1: capmcAPISetPowerCap - setup2 - get_power_cap_capabilities","time":{"start":1711355507058,"stop":1711355507098,"duration":40},"status":"passed","steps":[],"attachments":[{"uid":"77e92adf89a83a77","name":"stage_yaml","source":"77e92adf89a83a77.yaml","type":"application/yaml","size":472},{"uid":"130db3d1bb9e8e10","name":"rest_request","source":"130db3d1bb9e8e10.yaml","type":"application/yaml","size":171},{"uid":"a968565c5aa10708","name":"rest_response","source":"a968565c5aa10708.yaml","type":"application/yaml","size":980}],"parameters":[],"stepsCount":0,"attachmentsCount":3,"shouldDisplayMessage":false,"hasContent":true},{"name":"Stage 2: capmcAPISetPowerCap - setup3 - Set HSM Node 0 to Off","time":{"start":1711355507099,"stop":1711355507107,"duration":8},"status":"passed","steps":[],"attachments":[{"uid":"502d1240a647a280","name":"stage_yaml","source":"502d1240a647a280.yaml","type":"application/yaml","size":247},{"uid":"810b8bd1929c49b4","name":"rest_request","source":"810b8bd1929c49b4.yaml","type":"application/yaml","size":173},{"uid":"6067522e252d05cf","name":"rest_response","source":"6067522e252d05cf.yaml","type":"application/yaml","size":134}],"parameters":[],"stepsCount":0,"attachmentsCount":3,"shouldDisplayMessage":false,"hasContent":true},{"name":"Stage 3: capmcAPISetPowerCap - setup4 - Set HSM Node 1 to Off","time":{"start":1711355507108,"stop":1711355507116,"duration":8},"status":"passed","steps":[],"attachments":[{"uid":"33b46c02acc480a","name":"stage_yaml","source":"33b46c02acc480a.yaml","type":"application/yaml","size":247},{"uid":"f4602ea0d71629fd","name":"rest_request","source":"f4602ea0d71629fd.yaml","type":"application/yaml","size":173},{"uid":"760564fdc12fbd8f","name":"rest_response","source":"760564fdc12fbd8f.yaml","type":"application/yaml","size":134}],"parameters":[],"stepsCount":0,"attachmentsCount":3,"shouldDisplayMessage":false,"hasContent":true},{"name":"Stage 4: capmcAPISetPowerCap - test1 - POST set_power_cap for powered off node - failure test","time":{"start":1711355507116,"stop":1711355507130,"duration":14},"status":"passed","steps":[],"attachments":[{"uid":"4a757dccd119d516","name":"stage_yaml","source":"4a757dccd119d516.yaml","type":"application/yaml","size":1395},{"uid":"e607c3f76b7c7aa4","name":"rest_request","source":"e607c3f76b7c7aa4.yaml","type":"application/yaml","size":214},{"uid":"5a646cb778094dfb","name":"rest_response","source":"5a646cb778094dfb.yaml","type":"application/yaml","size":287}],"parameters":[],"stepsCount":0,"attachmentsCount":3,"shouldDisplayMessage":false,"hasContent":true},{"name":"Stage 5: capmcAPISetPowerCap - setup5 - Set HSM Node 0 to Ready","time":{"start":1711355507131,"stop":1711355507139,"duration":8},"status":"passed","steps":[],"attachments":[{"uid":"7c37cd5914ced90a","name":"stage_yaml","source":"7c37cd5914ced90a.yaml","type":"application/yaml","size":251},{"uid":"4d19d97221e63432","name":"rest_request","source":"4d19d97221e63432.yaml","type":"application/yaml","size":173},{"uid":"18abcc5df31886d9","name":"rest_response","source":"18abcc5df31886d9.yaml","type":"application/yaml","size":134}],"parameters":[],"stepsCount":0,"attachmentsCount":3,"shouldDisplayMessage":false,"hasContent":true},{"name":"Stage 6: capmcAPISetPowerCap - setup6 - Set HSM Node 1 to Ready","time":{"start":1711355507140,"stop":1711355507147,"duration":7},"status":"passed","steps":[],"attachments":[{"uid":"978837c7dfff1608","name":"stage_yaml","source":"978837c7dfff1608.yaml","type":"application/yaml","size":251},{"uid":"88e241794b0748b7","name":"rest_request","source":"88e241794b0748b7.yaml","type":"application/yaml","size":173},{"uid":"2a0b589bccfdc7eb","name":"rest_response","source":"2a0b589bccfdc7eb.yaml","type":"application/yaml","size":134}],"parameters":[],"stepsCount":0,"attachmentsCount":3,"shouldDisplayMessage":false,"hasContent":true},{"name":"Stage 7: capmcAPISetPowerCap - test2 - set_power_cap for two ready nodes","time":{"start":1711355507148,"stop":1711355507162,"duration":14},"status":"failed","statusMessage":"tavern.util.exceptions.TestFailError: Test 'capmcAPISetPowerCap - test2 - set_power_cap for two ready nodes' failed:\n- Error calling validate function '<function validate_pykwalify at 0x7f64aa4225e0>':\n    Traceback (most recent call last):\n      File \"/usr/lib/python3.9/site-packages/tavern/schemas/files.py\", line 106, in verify_generic\n        verifier.validate()\n      File \"/usr/lib/python3.9/site-packages/pykwalify/core.py\", line 194, in validate\n        raise SchemaError(u\"Schema validation failed:\\n - {error_msg}.\".format(\n    pykwalify.errors.SchemaError: <SchemaError: error code 2: Schema validation failed:\n     - Enum '22' does not exist. Path: '/e' Enum: [0].\n     - Value '[{'nid': 1026, 'e': 22, 'err_msg': 'Control (Node Power Limit) value (5036) is greater than maximum (925)'}, {'nid': 20, 'e': 22, 'err_msg': 'No NID supported controls specified'}]' is not of type 'none'. Path: '/nids'.: Path: '/'>\n\n    The above exception was the direct cause of the following exception:\n\n    Traceback (most recent call last):\n      File \"/usr/lib/python3.9/site-packages/tavern/response/base.py\", line 152, in _maybe_run_validate_functions\n        vf(response)\n      File \"/usr/lib/python3.9/site-packages/tavern/util/extfunctions.py\", line 98, in inner\n        result = func(response, *args, **kwargs)\n      File \"/usr/lib/python3.9/site-packages/tavern/testutils/helpers.py\", line 103, in validate_pykwalify\n        verify_generic(to_verify, schema)\n      File \"/usr/lib/python3.9/site-packages/tavern/schemas/files.py\", line 109, in verify_generic\n        raise BadSchemaError() from e\n    tavern.util.exceptions.BadSchemaError\n\n","statusTrace":"  File \"/usr/lib/python3.9/site-packages/allure_commons/_allure.py\", line 192, in impl\n    return func(*a, **kw)\n  File \"/usr/lib/python3.9/site-packages/tavern/util/retry.py\", line 31, in wrapped\n    res = fn(*args, **kwargs)\n  File \"/usr/lib/python3.9/site-packages/tavern/core.py\", line 270, in run_stage\n    saved = v.verify(response)\n  File \"/usr/lib/python3.9/site-packages/tavern/_plugins/rest/response.py\", line 201, in verify\n    raise exceptions.TestFailError(\n","steps":[],"attachments":[{"uid":"3f7754859acca4ea","name":"stage_yaml","source":"3f7754859acca4ea.yaml","type":"application/yaml","size":903},{"uid":"432f94666d5c4cdb","name":"rest_request","source":"432f94666d5c4cdb.yaml","type":"application/yaml","size":286},{"uid":"da088d06928963ca","name":"rest_response","source":"da088d06928963ca.yaml","type":"application/yaml","size":394}],"parameters":[],"stepsCount":0,"attachmentsCount":3,"shouldDisplayMessage":true,"hasContent":true}],"attachments":[{"uid":"961ee45d848d4d8","name":"error_output","source":"961ee45d848d4d8.attach","type":"text/plain","size":3773},{"uid":"848cffb662e2f124","name":"log","source":"848cffb662e2f124.txt","type":"text/plain","size":4427}],"parameters":[],"stepsCount":8,"attachmentsCount":26,"shouldDisplayMessage":true,"hasContent":true},"afterStages":[],"labels":[{"name":"parentSuite","value":"cray-capmc-hmth-test"},{"name":"suite","value":"build-pipeline-only"},{"name":"host","value":"4bf9307ad921"},{"name":"thread","value":"8-MainThread"},{"name":"framework","value":"pytest"},{"name":"language","value":"cpython3"},{"name":"package","value":"api.4-build-pipeline-only.test_set_power_cap.tavern"},{"name":"resultFormat","value":"allure2"}],"parameters":[],"links":[],"hidden":false,"retry":false,"extra":{"severity":"normal","retries":[],"categories":[{"name":"Product defects","matchedStatuses":[],"flaky":false}],"history":{"statistic":{"failed":23,"broken":0,"skipped":0,"passed":243,"unknown":0,"total":266},"items":[{"uid":"497f021d82fbe79","status":"passed","time":{"start":1711269018879,"stop":1711269019151,"duration":272}},{"uid":"8e6e5fe89fbf7180","status":"passed","time":{"start":1711182545242,"stop":1711182545500,"duration":258}},{"uid":"e358c7e1e1a12ac3","status":"passed","time":{"start":1711096285381,"stop":1711096285638,"duration":257}},{"uid":"e17b4a43ed05e23d","status":"passed","time":{"start":1711009788813,"stop":1711009789082,"duration":269}},{"uid":"c3c65a2b2bce27fd","status":"failed","statusDetails":"tavern.util.exceptions.TestFailError: Test 'capmcAPISetPowerCap - test2 - set_power_cap for two ready nodes' failed:\n- Error calling validate function '<function validate_pykwalify at 0x7506fa5475e0>':\n    Traceback (most recent call last):\n      File \"/usr/lib/python3.9/site-packages/tavern/schemas/files.py\", line 106, in verify_generic\n        verifier.validate()\n      File \"/usr/lib/python3.9/site-packages/pykwalify/core.py\", line 194, in validate\n        raise SchemaError(u\"Schema validation failed:\\n - {error_msg}.\".format(\n    pykwalify.errors.SchemaError: <SchemaError: error code 2: Schema validation failed:\n     - Enum '22' does not exist. Path: '/e' Enum: [0].\n     - Value '[{'nid': 1009, 'e': 22, 'err_msg': 'Control (Node Power Limit) value (5036) is greater than maximum (925)'}, {'nid': 20, 'e': 22, 'err_msg': 'No NID supported controls specified'}]' is not of type 'none'. Path: '/nids'.: Path: '/'>\n\n    The above exception was the direct cause of the following exception:\n\n    Traceback (most recent call last):\n      File \"/usr/lib/python3.9/site-packages/tavern/response/base.py\", line 152, in _maybe_run_validate_functions\n        vf(response)\n      File \"/usr/lib/python3.9/site-packages/tavern/util/extfunctions.py\", line 98, in inner\n        result = func(response, *args, **kwargs)\n      File \"/usr/lib/python3.9/site-packages/tavern/testutils/helpers.py\", line 103, in validate_pykwalify\n        verify_generic(to_verify, schema)\n      File \"/usr/lib/python3.9/site-packages/tavern/schemas/files.py\", line 109, in verify_generic\n        raise BadSchemaError() from e\n    tavern.util.exceptions.BadSchemaError","time":{"start":1710923392950,"stop":1710923393091,"duration":141}},{"uid":"ee8e50d7d4af3312","status":"passed","time":{"start":1710837046810,"stop":1710837047055,"duration":245}},{"uid":"cbefb440cfe38241","status":"passed","time":{"start":1710750590412,"stop":1710750590689,"duration":277}},{"uid":"c45065378dcf240f","status":"passed","time":{"start":1710664187598,"stop":1710664187862,"duration":264}},{"uid":"9da4aa01ce6b501d","status":"passed","time":{"start":1710577791486,"stop":1710577791736,"duration":250}},{"uid":"4bd9522959238fe1","status":"passed","time":{"start":1710491411779,"stop":1710491412035,"duration":256}},{"uid":"13cbf78d8b9d2e82","status":"passed","time":{"start":1710405054454,"stop":1710405054713,"duration":259}},{"uid":"6a537726d676452","status":"passed","time":{"start":1710318538117,"stop":1710318538387,"duration":270}},{"uid":"b50c7bcaa4735c3f","status":"passed","time":{"start":1710232062739,"stop":1710232062998,"duration":259}},{"uid":"6df7e9afde70b643","status":"failed","statusDetails":"tavern.util.exceptions.TestFailError: Test 'capmcAPISetPowerCap - test2 - set_power_cap for two ready nodes' failed:\n- Error calling validate function '<function validate_pykwalify at 0x7f5ef6d2e5e0>':\n    Traceback (most recent call last):\n      File \"/usr/lib/python3.9/site-packages/tavern/schemas/files.py\", line 106, in verify_generic\n        verifier.validate()\n      File \"/usr/lib/python3.9/site-packages/pykwalify/core.py\", line 194, in validate\n        raise SchemaError(u\"Schema validation failed:\\n - {error_msg}.\".format(\n    pykwalify.errors.SchemaError: <SchemaError: error code 2: Schema validation failed:\n     - Enum '22' does not exist. Path: '/e' Enum: [0].\n     - Value '[{'nid': 1002, 'e': 22, 'err_msg': 'Control (Node Power Limit) value (5036) is greater than maximum (925)'}, {'nid': 20, 'e': 22, 'err_msg': 'No NID supported controls specified'}]' is not of type 'none'. Path: '/nids'.: Path: '/'>\n\n    The above exception was the direct cause of the following exception:\n\n    Traceback (most recent call last):\n      File \"/usr/lib/python3.9/site-packages/tavern/response/base.py\", line 152, in _maybe_run_validate_functions\n        vf(response)\n      File \"/usr/lib/python3.9/site-packages/tavern/util/extfunctions.py\", line 98, in inner\n        result = func(response, *args, **kwargs)\n      File \"/usr/lib/python3.9/site-packages/tavern/testutils/helpers.py\", line 103, in validate_pykwalify\n        verify_generic(to_verify, schema)\n      File \"/usr/lib/python3.9/site-packages/tavern/schemas/files.py\", line 109, in verify_generic\n        raise BadSchemaError() from e\n    tavern.util.exceptions.BadSchemaError","time":{"start":1710145721922,"stop":1710145722062,"duration":140}},{"uid":"459dcbf5d2ad2880","status":"failed","statusDetails":"tavern.util.exceptions.TestFailError: Test 'capmcAPISetPowerCap - test2 - set_power_cap for two ready nodes' failed:\n- Error calling validate function '<function validate_pykwalify at 0x7f67983dd5e0>':\n    Traceback (most recent call last):\n      File \"/usr/lib/python3.9/site-packages/tavern/schemas/files.py\", line 106, in verify_generic\n        verifier.validate()\n      File \"/usr/lib/python3.9/site-packages/pykwalify/core.py\", line 194, in validate\n        raise SchemaError(u\"Schema validation failed:\\n - {error_msg}.\".format(\n    pykwalify.errors.SchemaError: <SchemaError: error code 2: Schema validation failed:\n     - Enum '22' does not exist. Path: '/e' Enum: [0].\n     - Value '[{'nid': 20, 'e': 22, 'err_msg': 'No NID supported controls specified'}]' is not of type 'none'. Path: '/nids'.: Path: '/'>\n\n    The above exception was the direct cause of the following exception:\n\n    Traceback (most recent call last):\n      File \"/usr/lib/python3.9/site-packages/tavern/response/base.py\", line 152, in _maybe_run_validate_functions\n        vf(response)\n      File \"/usr/lib/python3.9/site-packages/tavern/util/extfunctions.py\", line 98, in inner\n        result = func(response, *args, **kwargs)\n      File \"/usr/lib/python3.9/site-packages/tavern/testutils/helpers.py\", line 103, in validate_pykwalify\n        verify_generic(to_verify, schema)\n      File \"/usr/lib/python3.9/site-packages/tavern/schemas/files.py\", line 109, in verify_generic\n        raise BadSchemaError() from e\n    tavern.util.exceptions.BadSchemaError","time":{"start":1710059313258,"stop":1710059313395,"duration":137}},{"uid":"889267792ca3458d","status":"passed","time":{"start":1709972904673,"stop":1709972904922,"duration":249}},{"uid":"788b131ff6b0508e","status":"passed","time":{"start":1709886519565,"stop":1709886519818,"duration":253}},{"uid":"33a32eba2c71b3ef","status":"passed","time":{"start":1709800084235,"stop":1709800084492,"duration":257}},{"uid":"27dfabf5aa59718b","status":"passed","time":{"start":1709713783641,"stop":1709713783899,"duration":258}},{"uid":"2789bf6da54a1acb","status":"passed","time":{"start":1709627324890,"stop":1709627325159,"duration":269}}]},"tags":[]},"source":"bf56a2ce16d0469c.json","parameterValues":[]}