{"uid":"aafd16710bdca109","name":"capmcAPISetPowerCap","fullName":"api.4-build-pipeline-only.test_set_power_cap.tavern#capmcAPISetPowerCap","historyId":"dd408b17f7b8e55258fcff9f663cd89b","time":{"start":1711528187369,"stop":1711528187520,"duration":151},"status":"failed","statusMessage":"tavern.util.exceptions.TestFailError: Test 'capmcAPISetPowerCap - test2 - set_power_cap for two ready nodes' failed:\n- Error calling validate function '<function validate_pykwalify at 0x7f3b0b9605e0>':\n    Traceback (most recent call last):\n      File \"/usr/lib/python3.9/site-packages/tavern/schemas/files.py\", line 106, in verify_generic\n        verifier.validate()\n      File \"/usr/lib/python3.9/site-packages/pykwalify/core.py\", line 194, in validate\n        raise SchemaError(u\"Schema validation failed:\\n - {error_msg}.\".format(\n    pykwalify.errors.SchemaError: <SchemaError: error code 2: Schema validation failed:\n     - Enum '22' does not exist. Path: '/e' Enum: [0].\n     - Value '[{'nid': 1021, 'e': 22, 'err_msg': 'Control (Node Power Limit) value (5036) is greater than maximum (925)'}, {'nid': 20, 'e': 22, 'err_msg': 'No NID supported controls specified'}]' is not of type 'none'. Path: '/nids'.: Path: '/'>\n\n    The above exception was the direct cause of the following exception:\n\n    Traceback (most recent call last):\n      File \"/usr/lib/python3.9/site-packages/tavern/response/base.py\", line 152, in _maybe_run_validate_functions\n        vf(response)\n      File \"/usr/lib/python3.9/site-packages/tavern/util/extfunctions.py\", line 98, in inner\n        result = func(response, *args, **kwargs)\n      File \"/usr/lib/python3.9/site-packages/tavern/testutils/helpers.py\", line 103, in validate_pykwalify\n        verify_generic(to_verify, schema)\n      File \"/usr/lib/python3.9/site-packages/tavern/schemas/files.py\", line 109, in verify_generic\n        raise BadSchemaError() from e\n    tavern.util.exceptions.BadSchemaError","statusTrace":"Format variables:\n  capmc_base_url = 'http://cray-capmc:27777'\n  nid0:d = '1021'\n  min0:d = '5036'\n  nid1:d = '20'\n  min1:d = '5036'\n  verify = 'False'\n\nSource test stage (line 184):\n  - name: capmcAPISetPowerCap - test2 - set_power_cap for two ready nodes\n    request:\n      url: \"{capmc_base_url}/capmc/v1/set_power_cap\"\n      json:\n        nids:\n          - nid: !int \"{nid0:d}\"\n            controls:\n              - name: Node Power Limit\n                val: !int \"{min0:d}\"\n          - nid: !int \"{nid1:d}\"\n            controls:\n              - name: Node Power Limit\n                val: !int \"{min1:d}\"\n      method: POST\n      verify: !bool \"{verify}\"\n    response:\n      status_code: 200\n      verify_response_with:\n        function: tavern.testutils.helpers:validate_pykwalify\n        extra_kwargs:\n\n\n\n\n\n\n          schema:\n            type: map\n            mapping:\n              e:\n                type: int\n                required: True\n                enum:\n                  - 0\n              err_msg:\n                type: str\n                required: True\n              nids:\n                type: none\n                required: False\n\n\nFormatted stage:\n  name: capmcAPISetPowerCap - test2 - set_power_cap for two ready nodes\n  request:\n    json:\n      nids:\n      - controls:\n        - name: Node Power Limit\n          val: !int '5036'\n        nid: !int '1021'\n      - controls:\n        - name: Node Power Limit\n          val: !int '5036'\n        nid: !int '20'\n    method: POST\n    url: 'http://cray-capmc:27777/capmc/v1/set_power_cap'\n    verify: !bool 'False'\n  response:\n    status_code: 200\n    verify_response_with:\n      extra_kwargs:\n        schema:\n          mapping:\n            e:\n              enum:\n              - 0\n              required: true\n              type: int\n            err_msg:\n              required: true\n              type: str\n            nids:\n              required: false\n              type: none\n          type: map\n      function: tavern.testutils.helpers:validate_pykwalify\n\nErrors:\nE   tavern.util.exceptions.TestFailError: Test 'capmcAPISetPowerCap - test2 - set_power_cap for two ready nodes' failed:\n    - Error calling validate function '<function validate_pykwalify at 0x7f3b0b9605e0>':\n        Traceback (most recent call last):\n          File \"/usr/lib/python3.9/site-packages/tavern/schemas/files.py\", line 106, in verify_generic\n            verifier.validate()\n          File \"/usr/lib/python3.9/site-packages/pykwalify/core.py\", line 194, in validate\n            raise SchemaError(u\"Schema validation failed:\\n - {error_msg}.\".format(\n        pykwalify.errors.SchemaError: <SchemaError: error code 2: Schema validation failed:\n         - Enum '22' does not exist. Path: '/e' Enum: [0].\n         - Value '[{'nid': 1021, 'e': 22, 'err_msg': 'Control (Node Power Limit) value (5036) is greater than maximum (925)'}, {'nid': 20, 'e': 22, 'err_msg': 'No NID supported controls specified'}]' is not of type 'none'. Path: '/nids'.: Path: '/'>\n    \n        The above exception was the direct cause of the following exception:\n    \n        Traceback (most recent call last):\n          File \"/usr/lib/python3.9/site-packages/tavern/response/base.py\", line 152, in _maybe_run_validate_functions\n            vf(response)\n          File \"/usr/lib/python3.9/site-packages/tavern/util/extfunctions.py\", line 98, in inner\n            result = func(response, *args, **kwargs)\n          File \"/usr/lib/python3.9/site-packages/tavern/testutils/helpers.py\", line 103, in validate_pykwalify\n            verify_generic(to_verify, schema)\n          File \"/usr/lib/python3.9/site-packages/tavern/schemas/files.py\", line 109, in verify_generic\n            raise BadSchemaError() from e\n        tavern.util.exceptions.BadSchemaError","flaky":true,"newFailed":true,"newBroken":false,"newPassed":false,"retriesCount":0,"retriesStatusChange":false,"beforeStages":[],"testStage":{"status":"failed","statusMessage":"tavern.util.exceptions.TestFailError: Test 'capmcAPISetPowerCap - test2 - set_power_cap for two ready nodes' failed:\n- Error calling validate function '<function validate_pykwalify at 0x7f3b0b9605e0>':\n    Traceback (most recent call last):\n      File \"/usr/lib/python3.9/site-packages/tavern/schemas/files.py\", line 106, in verify_generic\n        verifier.validate()\n      File \"/usr/lib/python3.9/site-packages/pykwalify/core.py\", line 194, in validate\n        raise SchemaError(u\"Schema validation failed:\\n - {error_msg}.\".format(\n    pykwalify.errors.SchemaError: <SchemaError: error code 2: Schema validation failed:\n     - Enum '22' does not exist. Path: '/e' Enum: [0].\n     - Value '[{'nid': 1021, 'e': 22, 'err_msg': 'Control (Node Power Limit) value (5036) is greater than maximum (925)'}, {'nid': 20, 'e': 22, 'err_msg': 'No NID supported controls specified'}]' is not of type 'none'. Path: '/nids'.: Path: '/'>\n\n    The above exception was the direct cause of the following exception:\n\n    Traceback (most recent call last):\n      File \"/usr/lib/python3.9/site-packages/tavern/response/base.py\", line 152, in _maybe_run_validate_functions\n        vf(response)\n      File \"/usr/lib/python3.9/site-packages/tavern/util/extfunctions.py\", line 98, in inner\n        result = func(response, *args, **kwargs)\n      File \"/usr/lib/python3.9/site-packages/tavern/testutils/helpers.py\", line 103, in validate_pykwalify\n        verify_generic(to_verify, schema)\n      File \"/usr/lib/python3.9/site-packages/tavern/schemas/files.py\", line 109, in verify_generic\n        raise BadSchemaError() from e\n    tavern.util.exceptions.BadSchemaError","statusTrace":"Format variables:\n  capmc_base_url = 'http://cray-capmc:27777'\n  nid0:d = '1021'\n  min0:d = '5036'\n  nid1:d = '20'\n  min1:d = '5036'\n  verify = 'False'\n\nSource test stage (line 184):\n  - name: capmcAPISetPowerCap - test2 - set_power_cap for two ready nodes\n    request:\n      url: \"{capmc_base_url}/capmc/v1/set_power_cap\"\n      json:\n        nids:\n          - nid: !int \"{nid0:d}\"\n            controls:\n              - name: Node Power Limit\n                val: !int \"{min0:d}\"\n          - nid: !int \"{nid1:d}\"\n            controls:\n              - name: Node Power Limit\n                val: !int \"{min1:d}\"\n      method: POST\n      verify: !bool \"{verify}\"\n    response:\n      status_code: 200\n      verify_response_with:\n        function: tavern.testutils.helpers:validate_pykwalify\n        extra_kwargs:\n\n\n\n\n\n\n          schema:\n            type: map\n            mapping:\n              e:\n                type: int\n                required: True\n                enum:\n                  - 0\n              err_msg:\n                type: str\n                required: True\n              nids:\n                type: none\n                required: False\n\n\nFormatted stage:\n  name: capmcAPISetPowerCap - test2 - set_power_cap for two ready nodes\n  request:\n    json:\n      nids:\n      - controls:\n        - name: Node Power Limit\n          val: !int '5036'\n        nid: !int '1021'\n      - controls:\n        - name: Node Power Limit\n          val: !int '5036'\n        nid: !int '20'\n    method: POST\n    url: 'http://cray-capmc:27777/capmc/v1/set_power_cap'\n    verify: !bool 'False'\n  response:\n    status_code: 200\n    verify_response_with:\n      extra_kwargs:\n        schema:\n          mapping:\n            e:\n              enum:\n              - 0\n              required: true\n              type: int\n            err_msg:\n              required: true\n              type: str\n            nids:\n              required: false\n              type: none\n          type: map\n      function: tavern.testutils.helpers:validate_pykwalify\n\nErrors:\nE   tavern.util.exceptions.TestFailError: Test 'capmcAPISetPowerCap - test2 - set_power_cap for two ready nodes' failed:\n    - Error calling validate function '<function validate_pykwalify at 0x7f3b0b9605e0>':\n        Traceback (most recent call last):\n          File \"/usr/lib/python3.9/site-packages/tavern/schemas/files.py\", line 106, in verify_generic\n            verifier.validate()\n          File \"/usr/lib/python3.9/site-packages/pykwalify/core.py\", line 194, in validate\n            raise SchemaError(u\"Schema validation failed:\\n - {error_msg}.\".format(\n        pykwalify.errors.SchemaError: <SchemaError: error code 2: Schema validation failed:\n         - Enum '22' does not exist. Path: '/e' Enum: [0].\n         - Value '[{'nid': 1021, 'e': 22, 'err_msg': 'Control (Node Power Limit) value (5036) is greater than maximum (925)'}, {'nid': 20, 'e': 22, 'err_msg': 'No NID supported controls specified'}]' is not of type 'none'. Path: '/nids'.: Path: '/'>\n    \n        The above exception was the direct cause of the following exception:\n    \n        Traceback (most recent call last):\n          File \"/usr/lib/python3.9/site-packages/tavern/response/base.py\", line 152, in _maybe_run_validate_functions\n            vf(response)\n          File \"/usr/lib/python3.9/site-packages/tavern/util/extfunctions.py\", line 98, in inner\n            result = func(response, *args, **kwargs)\n          File \"/usr/lib/python3.9/site-packages/tavern/testutils/helpers.py\", line 103, in validate_pykwalify\n            verify_generic(to_verify, schema)\n          File \"/usr/lib/python3.9/site-packages/tavern/schemas/files.py\", line 109, in verify_generic\n            raise BadSchemaError() from e\n        tavern.util.exceptions.BadSchemaError","steps":[{"name":"Stage 0: capmcAPISetPowerCap - setup1 - Get HSM Nodes","time":{"start":1711528187379,"stop":1711528187408,"duration":29},"status":"passed","steps":[],"attachments":[{"uid":"4c62ce7c40ec9be1","name":"stage_yaml","source":"4c62ce7c40ec9be1.yaml","type":"application/yaml","size":457},{"uid":"2ab4c6a76f1cc953","name":"rest_request","source":"2ab4c6a76f1cc953.yaml","type":"application/yaml","size":149},{"uid":"ba87a248f35fc308","name":"rest_response","source":"ba87a248f35fc308.yaml","type":"application/yaml","size":5775}],"parameters":[],"stepsCount":0,"attachmentsCount":3,"shouldDisplayMessage":false,"hasContent":true},{"name":"Stage 1: capmcAPISetPowerCap - setup2 - get_power_cap_capabilities","time":{"start":1711528187408,"stop":1711528187452,"duration":44},"status":"passed","steps":[],"attachments":[{"uid":"bafcd7636940f3e2","name":"stage_yaml","source":"bafcd7636940f3e2.yaml","type":"application/yaml","size":472},{"uid":"4dc58776a67c3833","name":"rest_request","source":"4dc58776a67c3833.yaml","type":"application/yaml","size":171},{"uid":"4f470a2ef4adc284","name":"rest_response","source":"4f470a2ef4adc284.yaml","type":"application/yaml","size":980}],"parameters":[],"stepsCount":0,"attachmentsCount":3,"shouldDisplayMessage":false,"hasContent":true},{"name":"Stage 2: capmcAPISetPowerCap - setup3 - Set HSM Node 0 to Off","time":{"start":1711528187452,"stop":1711528187460,"duration":8},"status":"passed","steps":[],"attachments":[{"uid":"1211bd2943379009","name":"stage_yaml","source":"1211bd2943379009.yaml","type":"application/yaml","size":247},{"uid":"f41746ffed8a379b","name":"rest_request","source":"f41746ffed8a379b.yaml","type":"application/yaml","size":173},{"uid":"d39393727b67f62","name":"rest_response","source":"d39393727b67f62.yaml","type":"application/yaml","size":134}],"parameters":[],"stepsCount":0,"attachmentsCount":3,"shouldDisplayMessage":false,"hasContent":true},{"name":"Stage 3: capmcAPISetPowerCap - setup4 - Set HSM Node 1 to Off","time":{"start":1711528187461,"stop":1711528187469,"duration":8},"status":"passed","steps":[],"attachments":[{"uid":"a92a57ca610e07c6","name":"stage_yaml","source":"a92a57ca610e07c6.yaml","type":"application/yaml","size":247},{"uid":"879c162db4fc79bc","name":"rest_request","source":"879c162db4fc79bc.yaml","type":"application/yaml","size":173},{"uid":"4562b17f7630109f","name":"rest_response","source":"4562b17f7630109f.yaml","type":"application/yaml","size":134}],"parameters":[],"stepsCount":0,"attachmentsCount":3,"shouldDisplayMessage":false,"hasContent":true},{"name":"Stage 4: capmcAPISetPowerCap - test1 - POST set_power_cap for powered off node - failure test","time":{"start":1711528187470,"stop":1711528187484,"duration":14},"status":"passed","steps":[],"attachments":[{"uid":"ecc421ee8db394d9","name":"stage_yaml","source":"ecc421ee8db394d9.yaml","type":"application/yaml","size":1395},{"uid":"32d84a7e4b234799","name":"rest_request","source":"32d84a7e4b234799.yaml","type":"application/yaml","size":214},{"uid":"4c9c48800c846b0b","name":"rest_response","source":"4c9c48800c846b0b.yaml","type":"application/yaml","size":287}],"parameters":[],"stepsCount":0,"attachmentsCount":3,"shouldDisplayMessage":false,"hasContent":true},{"name":"Stage 5: capmcAPISetPowerCap - setup5 - Set HSM Node 0 to Ready","time":{"start":1711528187485,"stop":1711528187493,"duration":8},"status":"passed","steps":[],"attachments":[{"uid":"c7aace4ec7c964a2","name":"stage_yaml","source":"c7aace4ec7c964a2.yaml","type":"application/yaml","size":251},{"uid":"bfe896d9f33a48a8","name":"rest_request","source":"bfe896d9f33a48a8.yaml","type":"application/yaml","size":173},{"uid":"a59ba09d1e027eed","name":"rest_response","source":"a59ba09d1e027eed.yaml","type":"application/yaml","size":134}],"parameters":[],"stepsCount":0,"attachmentsCount":3,"shouldDisplayMessage":false,"hasContent":true},{"name":"Stage 6: capmcAPISetPowerCap - setup6 - Set HSM Node 1 to Ready","time":{"start":1711528187494,"stop":1711528187501,"duration":7},"status":"passed","steps":[],"attachments":[{"uid":"d905fa3cb2ea6f0f","name":"stage_yaml","source":"d905fa3cb2ea6f0f.yaml","type":"application/yaml","size":251},{"uid":"95ef8e99a314fa7d","name":"rest_request","source":"95ef8e99a314fa7d.yaml","type":"application/yaml","size":173},{"uid":"319c386bf5be085e","name":"rest_response","source":"319c386bf5be085e.yaml","type":"application/yaml","size":134}],"parameters":[],"stepsCount":0,"attachmentsCount":3,"shouldDisplayMessage":false,"hasContent":true},{"name":"Stage 7: capmcAPISetPowerCap - test2 - set_power_cap for two ready nodes","time":{"start":1711528187502,"stop":1711528187519,"duration":17},"status":"failed","statusMessage":"tavern.util.exceptions.TestFailError: Test 'capmcAPISetPowerCap - test2 - set_power_cap for two ready nodes' failed:\n- Error calling validate function '<function validate_pykwalify at 0x7f3b0b9605e0>':\n    Traceback (most recent call last):\n      File \"/usr/lib/python3.9/site-packages/tavern/schemas/files.py\", line 106, in verify_generic\n        verifier.validate()\n      File \"/usr/lib/python3.9/site-packages/pykwalify/core.py\", line 194, in validate\n        raise SchemaError(u\"Schema validation failed:\\n - {error_msg}.\".format(\n    pykwalify.errors.SchemaError: <SchemaError: error code 2: Schema validation failed:\n     - Enum '22' does not exist. Path: '/e' Enum: [0].\n     - Value '[{'nid': 1021, 'e': 22, 'err_msg': 'Control (Node Power Limit) value (5036) is greater than maximum (925)'}, {'nid': 20, 'e': 22, 'err_msg': 'No NID supported controls specified'}]' is not of type 'none'. Path: '/nids'.: Path: '/'>\n\n    The above exception was the direct cause of the following exception:\n\n    Traceback (most recent call last):\n      File \"/usr/lib/python3.9/site-packages/tavern/response/base.py\", line 152, in _maybe_run_validate_functions\n        vf(response)\n      File \"/usr/lib/python3.9/site-packages/tavern/util/extfunctions.py\", line 98, in inner\n        result = func(response, *args, **kwargs)\n      File \"/usr/lib/python3.9/site-packages/tavern/testutils/helpers.py\", line 103, in validate_pykwalify\n        verify_generic(to_verify, schema)\n      File \"/usr/lib/python3.9/site-packages/tavern/schemas/files.py\", line 109, in verify_generic\n        raise BadSchemaError() from e\n    tavern.util.exceptions.BadSchemaError\n\n","statusTrace":"  File \"/usr/lib/python3.9/site-packages/allure_commons/_allure.py\", line 192, in impl\n    return func(*a, **kw)\n  File \"/usr/lib/python3.9/site-packages/tavern/util/retry.py\", line 31, in wrapped\n    res = fn(*args, **kwargs)\n  File \"/usr/lib/python3.9/site-packages/tavern/core.py\", line 270, in run_stage\n    saved = v.verify(response)\n  File \"/usr/lib/python3.9/site-packages/tavern/_plugins/rest/response.py\", line 201, in verify\n    raise exceptions.TestFailError(\n","steps":[],"attachments":[{"uid":"9b7aec8f51532580","name":"stage_yaml","source":"9b7aec8f51532580.yaml","type":"application/yaml","size":903},{"uid":"d1b0c78927bae97d","name":"rest_request","source":"d1b0c78927bae97d.yaml","type":"application/yaml","size":286},{"uid":"9657167f47fa2d70","name":"rest_response","source":"9657167f47fa2d70.yaml","type":"application/yaml","size":394}],"parameters":[],"stepsCount":0,"attachmentsCount":3,"shouldDisplayMessage":true,"hasContent":true}],"attachments":[{"uid":"b9392297eb532850","name":"error_output","source":"b9392297eb532850.attach","type":"text/plain","size":3773},{"uid":"b21aa56020e9dae3","name":"log","source":"b21aa56020e9dae3.txt","type":"text/plain","size":4427}],"parameters":[],"stepsCount":8,"attachmentsCount":26,"shouldDisplayMessage":true,"hasContent":true},"afterStages":[],"labels":[{"name":"parentSuite","value":"cray-capmc-hmth-test"},{"name":"suite","value":"build-pipeline-only"},{"name":"host","value":"201f9f1c7b44"},{"name":"thread","value":"8-MainThread"},{"name":"framework","value":"pytest"},{"name":"language","value":"cpython3"},{"name":"package","value":"api.4-build-pipeline-only.test_set_power_cap.tavern"},{"name":"resultFormat","value":"allure2"}],"parameters":[],"links":[],"hidden":false,"retry":false,"extra":{"severity":"normal","retries":[],"categories":[{"name":"Product defects","matchedStatuses":[],"flaky":false}],"history":{"statistic":{"failed":74,"broken":0,"skipped":0,"passed":241,"unknown":0,"total":315},"items":[{"uid":"c3e999d3f07d6b7d","status":"passed","time":{"start":1711441811932,"stop":1711441812207,"duration":275}},{"uid":"3c16f37f4f121e95","status":"failed","statusDetails":"tavern.util.exceptions.TestFailError: Test 'capmcAPISetPowerCap - test2 - set_power_cap for two ready nodes' failed:\n- Error calling validate function '<function validate_pykwalify at 0x7fbbf22f55e0>':\n    Traceback (most recent call last):\n      File \"/usr/lib/python3.9/site-packages/tavern/schemas/files.py\", line 106, in verify_generic\n        verifier.validate()\n      File \"/usr/lib/python3.9/site-packages/pykwalify/core.py\", line 194, in validate\n        raise SchemaError(u\"Schema validation failed:\\n - {error_msg}.\".format(\n    pykwalify.errors.SchemaError: <SchemaError: error code 2: Schema validation failed:\n     - Enum '22' does not exist. Path: '/e' Enum: [0].\n     - Value '[{'nid': 20, 'e': 22, 'err_msg': 'No NID supported controls specified'}, {'nid': 1024, 'e': 22, 'err_msg': 'Control (Node Power Limit) value (5036) is greater than maximum (925)'}]' is not of type 'none'. Path: '/nids'.: Path: '/'>\n\n    The above exception was the direct cause of the following exception:\n\n    Traceback (most recent call last):\n      File \"/usr/lib/python3.9/site-packages/tavern/response/base.py\", line 152, in _maybe_run_validate_functions\n        vf(response)\n      File \"/usr/lib/python3.9/site-packages/tavern/util/extfunctions.py\", line 98, in inner\n        result = func(response, *args, **kwargs)\n      File \"/usr/lib/python3.9/site-packages/tavern/testutils/helpers.py\", line 103, in validate_pykwalify\n        verify_generic(to_verify, schema)\n      File \"/usr/lib/python3.9/site-packages/tavern/schemas/files.py\", line 109, in verify_generic\n        raise BadSchemaError() from e\n    tavern.util.exceptions.BadSchemaError","time":{"start":1711355414054,"stop":1711355414213,"duration":159}},{"uid":"b3f12ae7064e9422","status":"passed","time":{"start":1711268992434,"stop":1711268992697,"duration":263}},{"uid":"c9429c11098ad360","status":"passed","time":{"start":1711182476487,"stop":1711182476748,"duration":261}},{"uid":"36fc538a5d4f77bb","status":"passed","time":{"start":1711096308311,"stop":1711096308553,"duration":242}},{"uid":"27ff557d32ce1b71","status":"passed","time":{"start":1711009755561,"stop":1711009755838,"duration":277}},{"uid":"8139842e812b04c6","status":"passed","time":{"start":1710923367049,"stop":1710923367325,"duration":276}},{"uid":"2b23854ef41b88d2","status":"passed","time":{"start":1710836998775,"stop":1710836999047,"duration":272}},{"uid":"2b7e280c20356de6","status":"failed","statusDetails":"tavern.util.exceptions.TestFailError: Test 'capmcAPISetPowerCap - test2 - set_power_cap for two ready nodes' failed:\n- Error calling validate function '<function validate_pykwalify at 0x776e3d0b35e0>':\n    Traceback (most recent call last):\n      File \"/usr/lib/python3.9/site-packages/tavern/schemas/files.py\", line 106, in verify_generic\n        verifier.validate()\n      File \"/usr/lib/python3.9/site-packages/pykwalify/core.py\", line 194, in validate\n        raise SchemaError(u\"Schema validation failed:\\n - {error_msg}.\".format(\n    pykwalify.errors.SchemaError: <SchemaError: error code 2: Schema validation failed:\n     - Enum '22' does not exist. Path: '/e' Enum: [0].\n     - Value '[{'nid': 1014, 'e': 22, 'err_msg': 'Control (Node Power Limit) value (5036) is greater than maximum (925)'}, {'nid': 20, 'e': 22, 'err_msg': 'No NID supported controls specified'}]' is not of type 'none'. Path: '/nids'.: Path: '/'>\n\n    The above exception was the direct cause of the following exception:\n\n    Traceback (most recent call last):\n      File \"/usr/lib/python3.9/site-packages/tavern/response/base.py\", line 152, in _maybe_run_validate_functions\n        vf(response)\n      File \"/usr/lib/python3.9/site-packages/tavern/util/extfunctions.py\", line 98, in inner\n        result = func(response, *args, **kwargs)\n      File \"/usr/lib/python3.9/site-packages/tavern/testutils/helpers.py\", line 103, in validate_pykwalify\n        verify_generic(to_verify, schema)\n      File \"/usr/lib/python3.9/site-packages/tavern/schemas/files.py\", line 109, in verify_generic\n        raise BadSchemaError() from e\n    tavern.util.exceptions.BadSchemaError","time":{"start":1710750604529,"stop":1710750604679,"duration":150}},{"uid":"4b9a58e3a4b760ce","status":"passed","time":{"start":1710664141205,"stop":1710664141467,"duration":262}},{"uid":"60c4aa6860eb1ba7","status":"passed","time":{"start":1710577764984,"stop":1710577765241,"duration":257}},{"uid":"14f95c1d38fb4a0c","status":"passed","time":{"start":1710491330753,"stop":1710491331012,"duration":259}},{"uid":"6b4bb40cb2db2116","status":"passed","time":{"start":1710405001488,"stop":1710405001742,"duration":254}},{"uid":"3658e1313c1b654a","status":"passed","time":{"start":1710318520644,"stop":1710318520925,"duration":281}},{"uid":"2c9513a4420d5616","status":"failed","statusDetails":"tavern.util.exceptions.TestFailError: Test 'capmcAPISetPowerCap - test2 - set_power_cap for two ready nodes' failed:\n- Error calling validate function '<function validate_pykwalify at 0x7fede55fc5e0>':\n    Traceback (most recent call last):\n      File \"/usr/lib/python3.9/site-packages/tavern/schemas/files.py\", line 106, in verify_generic\n        verifier.validate()\n      File \"/usr/lib/python3.9/site-packages/pykwalify/core.py\", line 194, in validate\n        raise SchemaError(u\"Schema validation failed:\\n - {error_msg}.\".format(\n    pykwalify.errors.SchemaError: <SchemaError: error code 2: Schema validation failed:\n     - Enum '22' does not exist. Path: '/e' Enum: [0].\n     - Value '[{'nid': 20, 'e': 22, 'err_msg': 'No NID supported controls specified'}, {'nid': 1022, 'e': 22, 'err_msg': 'Control (Node Power Limit) value (5036) is greater than maximum (925)'}]' is not of type 'none'. Path: '/nids'.: Path: '/'>\n\n    The above exception was the direct cause of the following exception:\n\n    Traceback (most recent call last):\n      File \"/usr/lib/python3.9/site-packages/tavern/response/base.py\", line 152, in _maybe_run_validate_functions\n        vf(response)\n      File \"/usr/lib/python3.9/site-packages/tavern/util/extfunctions.py\", line 98, in inner\n        result = func(response, *args, **kwargs)\n      File \"/usr/lib/python3.9/site-packages/tavern/testutils/helpers.py\", line 103, in validate_pykwalify\n        verify_generic(to_verify, schema)\n      File \"/usr/lib/python3.9/site-packages/tavern/schemas/files.py\", line 109, in verify_generic\n        raise BadSchemaError() from e\n    tavern.util.exceptions.BadSchemaError","time":{"start":1710232127169,"stop":1710232127313,"duration":144}},{"uid":"ea8497bf1e94a25f","status":"passed","time":{"start":1710145716484,"stop":1710145716757,"duration":273}},{"uid":"f10ff2168818013c","status":"passed","time":{"start":1710059383821,"stop":1710059384087,"duration":266}},{"uid":"a5d1b68c98019f7a","status":"passed","time":{"start":1709972957987,"stop":1709972958238,"duration":251}},{"uid":"4aab072ddba5e1db","status":"failed","statusDetails":"tavern.util.exceptions.TestFailError: Test 'capmcAPISetPowerCap - test2 - set_power_cap for two ready nodes' failed:\n- Error calling validate function '<function validate_pykwalify at 0x7fc2a1eac5e0>':\n    Traceback (most recent call last):\n      File \"/usr/lib/python3.9/site-packages/tavern/schemas/files.py\", line 106, in verify_generic\n        verifier.validate()\n      File \"/usr/lib/python3.9/site-packages/pykwalify/core.py\", line 194, in validate\n        raise SchemaError(u\"Schema validation failed:\\n - {error_msg}.\".format(\n    pykwalify.errors.SchemaError: <SchemaError: error code 2: Schema validation failed:\n     - Enum '22' does not exist. Path: '/e' Enum: [0].\n     - Value '[{'nid': 1028, 'e': 22, 'err_msg': 'Control (Node Power Limit) value (5036) is greater than maximum (925)'}, {'nid': 20, 'e': 22, 'err_msg': 'No NID supported controls specified'}]' is not of type 'none'. Path: '/nids'.: Path: '/'>\n\n    The above exception was the direct cause of the following exception:\n\n    Traceback (most recent call last):\n      File \"/usr/lib/python3.9/site-packages/tavern/response/base.py\", line 152, in _maybe_run_validate_functions\n        vf(response)\n      File \"/usr/lib/python3.9/site-packages/tavern/util/extfunctions.py\", line 98, in inner\n        result = func(response, *args, **kwargs)\n      File \"/usr/lib/python3.9/site-packages/tavern/testutils/helpers.py\", line 103, in validate_pykwalify\n        verify_generic(to_verify, schema)\n      File \"/usr/lib/python3.9/site-packages/tavern/schemas/files.py\", line 109, in verify_generic\n        raise BadSchemaError() from e\n    tavern.util.exceptions.BadSchemaError","time":{"start":1709886581731,"stop":1709886581876,"duration":145}},{"uid":"858b3980aa32d164","status":"failed","statusDetails":"tavern.util.exceptions.TestFailError: Test 'capmcAPISetPowerCap - test2 - set_power_cap for two ready nodes' failed:\n- Error calling validate function '<function validate_pykwalify at 0x7f07a8b395e0>':\n    Traceback (most recent call last):\n      File \"/usr/lib/python3.9/site-packages/tavern/schemas/files.py\", line 106, in verify_generic\n        verifier.validate()\n      File \"/usr/lib/python3.9/site-packages/pykwalify/core.py\", line 194, in validate\n        raise SchemaError(u\"Schema validation failed:\\n - {error_msg}.\".format(\n    pykwalify.errors.SchemaError: <SchemaError: error code 2: Schema validation failed:\n     - Enum '22' does not exist. Path: '/e' Enum: [0].\n     - Value '[{'nid': 1017, 'e': 22, 'err_msg': 'Control (Node Power Limit) value (5036) is greater than maximum (925)'}, {'nid': 20, 'e': 22, 'err_msg': 'No NID supported controls specified'}]' is not of type 'none'. Path: '/nids'.: Path: '/'>\n\n    The above exception was the direct cause of the following exception:\n\n    Traceback (most recent call last):\n      File \"/usr/lib/python3.9/site-packages/tavern/response/base.py\", line 152, in _maybe_run_validate_functions\n        vf(response)\n      File \"/usr/lib/python3.9/site-packages/tavern/util/extfunctions.py\", line 98, in inner\n        result = func(response, *args, **kwargs)\n      File \"/usr/lib/python3.9/site-packages/tavern/testutils/helpers.py\", line 103, in validate_pykwalify\n        verify_generic(to_verify, schema)\n      File \"/usr/lib/python3.9/site-packages/tavern/schemas/files.py\", line 109, in verify_generic\n        raise BadSchemaError() from e\n    tavern.util.exceptions.BadSchemaError","time":{"start":1709800146564,"stop":1709800146709,"duration":145}}]},"tags":[]},"source":"aafd16710bdca109.json","parameterValues":[]}