{"uid":"b2a990844b3431b7","name":"hsmAPIinventoryHardwareNegative","fullName":"api.2-disruptive.test_hardware_negative.tavern#hsmAPIinventoryHardwareNegative","historyId":"e127ebad6b088b5556d273620f105351","time":{"start":1676325742601,"stop":1676325742715,"duration":114},"status":"failed","statusMessage":"tavern.util.exceptions.TestFailError: Test 'hsmAPIinventoryHardwareQueryXnameGETnonExistentNode - Attempt to query for Node Hardware Inventory entries with an xname that doesn't exist using GET.' failed:\n- Error calling validate function '<function validate_pykwalify at 0x7fe894082670>':\n    Traceback (most recent call last):\n      File \"/usr/lib/python3.9/site-packages/tavern/schemas/files.py\", line 106, in verify_generic\n        verifier.validate()\n      File \"/usr/lib/python3.9/site-packages/pykwalify/core.py\", line 194, in validate\n        raise SchemaError(u\"Schema validation failed:\\n - {error_msg}.\".format(\n    pykwalify.errors.SchemaError: <SchemaError: error code 2: Schema validation failed:\n     - Key 'Nodes' was not defined. Path: ''.: Path: '/'>\n\n    The above exception was the direct cause of the following exception:\n\n    Traceback (most recent call last):\n      File \"/usr/lib/python3.9/site-packages/tavern/response/base.py\", line 152, in _maybe_run_validate_functions\n        vf(response)\n      File \"/usr/lib/python3.9/site-packages/tavern/util/extfunctions.py\", line 98, in inner\n        result = func(response, *args, **kwargs)\n      File \"/usr/lib/python3.9/site-packages/tavern/testutils/helpers.py\", line 103, in validate_pykwalify\n        verify_generic(to_verify, schema)\n      File \"/usr/lib/python3.9/site-packages/tavern/schemas/files.py\", line 109, in verify_generic\n        raise BadSchemaError() from e\n    tavern.util.exceptions.BadSchemaError","statusTrace":"Format variables:\n  hsm_base_url = 'http://cray-smd:27779'\n  verify = 'False'\n\nSource test stage (line 480):\n  - name: hsmAPIinventoryHardwareQueryXnameGETnonExistentNode - Attempt to query for Node Hardware Inventory entries with an xname that doesn't exist using GET.\n    request:\n      url: \"{hsm_base_url}/hsm/v2/Inventory/Hardware/Query/x9999c7s9b9n9?children=False\"\n      method: GET\n      verify: !bool \"{verify}\"\n    response:\n      status_code: 200\n      verify_response_with:\n        function: tavern.testutils.helpers:validate_pykwalify\n        extra_kwargs:\n          schema:\n            type: map\n            required: True\n            mapping:\n              XName:\n                type: str\n                required: True\n                enum:\n                  - \"x9999c7s9b9n9\"\n              Format:\n                type: str\n                required: True\n                enum:\n                  - \"NestNodesOnly\"\n\n\n\n\nFormatted stage:\n  name: hsmAPIinventoryHardwareQueryXnameGETnonExistentNode - Attempt to query for Node\n    Hardware Inventory entries with an xname that doesn't exist using GET.\n  request:\n    method: GET\n    url: 'http://cray-smd:27779/hsm/v2/Inventory/Hardware/Query/x9999c7s9b9n9?children=False'\n    verify: !bool 'False'\n  response:\n    status_code: 200\n    verify_response_with:\n      extra_kwargs:\n        schema:\n          mapping:\n            Format:\n              enum:\n              - NestNodesOnly\n              required: true\n              type: str\n            XName:\n              enum:\n              - x9999c7s9b9n9\n              required: true\n              type: str\n          required: true\n          type: map\n      function: tavern.testutils.helpers:validate_pykwalify\n\nErrors:\nE   tavern.util.exceptions.TestFailError: Test 'hsmAPIinventoryHardwareQueryXnameGETnonExistentNode - Attempt to query for Node Hardware Inventory entries with an xname that doesn't exist using GET.' failed:\n    - Error calling validate function '<function validate_pykwalify at 0x7fe894082670>':\n        Traceback (most recent call last):\n          File \"/usr/lib/python3.9/site-packages/tavern/schemas/files.py\", line 106, in verify_generic\n            verifier.validate()\n          File \"/usr/lib/python3.9/site-packages/pykwalify/core.py\", line 194, in validate\n            raise SchemaError(u\"Schema validation failed:\\n - {error_msg}.\".format(\n        pykwalify.errors.SchemaError: <SchemaError: error code 2: Schema validation failed:\n         - Key 'Nodes' was not defined. Path: ''.: Path: '/'>\n    \n        The above exception was the direct cause of the following exception:\n    \n        Traceback (most recent call last):\n          File \"/usr/lib/python3.9/site-packages/tavern/response/base.py\", line 152, in _maybe_run_validate_functions\n            vf(response)\n          File \"/usr/lib/python3.9/site-packages/tavern/util/extfunctions.py\", line 98, in inner\n            result = func(response, *args, **kwargs)\n          File \"/usr/lib/python3.9/site-packages/tavern/testutils/helpers.py\", line 103, in validate_pykwalify\n            verify_generic(to_verify, schema)\n          File \"/usr/lib/python3.9/site-packages/tavern/schemas/files.py\", line 109, in verify_generic\n            raise BadSchemaError() from e\n        tavern.util.exceptions.BadSchemaError","flaky":false,"newFailed":false,"newBroken":false,"newPassed":false,"retriesCount":0,"retriesStatusChange":false,"beforeStages":[],"testStage":{"status":"failed","statusMessage":"tavern.util.exceptions.TestFailError: Test 'hsmAPIinventoryHardwareQueryXnameGETnonExistentNode - Attempt to query for Node Hardware Inventory entries with an xname that doesn't exist using GET.' failed:\n- Error calling validate function '<function validate_pykwalify at 0x7fe894082670>':\n    Traceback (most recent call last):\n      File \"/usr/lib/python3.9/site-packages/tavern/schemas/files.py\", line 106, in verify_generic\n        verifier.validate()\n      File \"/usr/lib/python3.9/site-packages/pykwalify/core.py\", line 194, in validate\n        raise SchemaError(u\"Schema validation failed:\\n - {error_msg}.\".format(\n    pykwalify.errors.SchemaError: <SchemaError: error code 2: Schema validation failed:\n     - Key 'Nodes' was not defined. Path: ''.: Path: '/'>\n\n    The above exception was the direct cause of the following exception:\n\n    Traceback (most recent call last):\n      File \"/usr/lib/python3.9/site-packages/tavern/response/base.py\", line 152, in _maybe_run_validate_functions\n        vf(response)\n      File \"/usr/lib/python3.9/site-packages/tavern/util/extfunctions.py\", line 98, in inner\n        result = func(response, *args, **kwargs)\n      File \"/usr/lib/python3.9/site-packages/tavern/testutils/helpers.py\", line 103, in validate_pykwalify\n        verify_generic(to_verify, schema)\n      File \"/usr/lib/python3.9/site-packages/tavern/schemas/files.py\", line 109, in verify_generic\n        raise BadSchemaError() from e\n    tavern.util.exceptions.BadSchemaError","statusTrace":"Format variables:\n  hsm_base_url = 'http://cray-smd:27779'\n  verify = 'False'\n\nSource test stage (line 480):\n  - name: hsmAPIinventoryHardwareQueryXnameGETnonExistentNode - Attempt to query for Node Hardware Inventory entries with an xname that doesn't exist using GET.\n    request:\n      url: \"{hsm_base_url}/hsm/v2/Inventory/Hardware/Query/x9999c7s9b9n9?children=False\"\n      method: GET\n      verify: !bool \"{verify}\"\n    response:\n      status_code: 200\n      verify_response_with:\n        function: tavern.testutils.helpers:validate_pykwalify\n        extra_kwargs:\n          schema:\n            type: map\n            required: True\n            mapping:\n              XName:\n                type: str\n                required: True\n                enum:\n                  - \"x9999c7s9b9n9\"\n              Format:\n                type: str\n                required: True\n                enum:\n                  - \"NestNodesOnly\"\n\n\n\n\nFormatted stage:\n  name: hsmAPIinventoryHardwareQueryXnameGETnonExistentNode - Attempt to query for Node\n    Hardware Inventory entries with an xname that doesn't exist using GET.\n  request:\n    method: GET\n    url: 'http://cray-smd:27779/hsm/v2/Inventory/Hardware/Query/x9999c7s9b9n9?children=False'\n    verify: !bool 'False'\n  response:\n    status_code: 200\n    verify_response_with:\n      extra_kwargs:\n        schema:\n          mapping:\n            Format:\n              enum:\n              - NestNodesOnly\n              required: true\n              type: str\n            XName:\n              enum:\n              - x9999c7s9b9n9\n              required: true\n              type: str\n          required: true\n          type: map\n      function: tavern.testutils.helpers:validate_pykwalify\n\nErrors:\nE   tavern.util.exceptions.TestFailError: Test 'hsmAPIinventoryHardwareQueryXnameGETnonExistentNode - Attempt to query for Node Hardware Inventory entries with an xname that doesn't exist using GET.' failed:\n    - Error calling validate function '<function validate_pykwalify at 0x7fe894082670>':\n        Traceback (most recent call last):\n          File \"/usr/lib/python3.9/site-packages/tavern/schemas/files.py\", line 106, in verify_generic\n            verifier.validate()\n          File \"/usr/lib/python3.9/site-packages/pykwalify/core.py\", line 194, in validate\n            raise SchemaError(u\"Schema validation failed:\\n - {error_msg}.\".format(\n        pykwalify.errors.SchemaError: <SchemaError: error code 2: Schema validation failed:\n         - Key 'Nodes' was not defined. Path: ''.: Path: '/'>\n    \n        The above exception was the direct cause of the following exception:\n    \n        Traceback (most recent call last):\n          File \"/usr/lib/python3.9/site-packages/tavern/response/base.py\", line 152, in _maybe_run_validate_functions\n            vf(response)\n          File \"/usr/lib/python3.9/site-packages/tavern/util/extfunctions.py\", line 98, in inner\n            result = func(response, *args, **kwargs)\n          File \"/usr/lib/python3.9/site-packages/tavern/testutils/helpers.py\", line 103, in validate_pykwalify\n            verify_generic(to_verify, schema)\n          File \"/usr/lib/python3.9/site-packages/tavern/schemas/files.py\", line 109, in verify_generic\n            raise BadSchemaError() from e\n        tavern.util.exceptions.BadSchemaError","steps":[{"name":"Stage 0: hsmAPIinventoryHardwarePOSTcmmRectifierMissingID - Attempt to create a CMMRectifier Hardware Inventory entry with a missing ID using POST.","time":{"start":1676325742611,"stop":1676325742624,"duration":13},"status":"passed","steps":[],"attachments":[{"uid":"afba135ce100412f","name":"stage_yaml","source":"afba135ce100412f.yaml","type":"application/yaml","size":1543},{"uid":"8ee5aee1724a6a5c","name":"rest_request","source":"8ee5aee1724a6a5c.yaml","type":"application/yaml","size":761},{"uid":"7a7c43f31bbde123","name":"rest_response","source":"7a7c43f31bbde123.yaml","type":"application/yaml","size":259}],"parameters":[],"stepsCount":0,"attachmentsCount":3,"shouldDisplayMessage":false,"hasContent":true},{"name":"Stage 1: hsmAPIinventoryHardwarePOSTchassisEmptyID - Attempt to create a Chassis Hardware Inventory entry with an empty ID using POST.","time":{"start":1676325742625,"stop":1676325742636,"duration":11},"status":"passed","steps":[],"attachments":[{"uid":"2994bff07d098062","name":"stage_yaml","source":"2994bff07d098062.yaml","type":"application/yaml","size":1575},{"uid":"14a8a9055c93f030","name":"rest_request","source":"14a8a9055c93f030.yaml","type":"application/yaml","size":726},{"uid":"f033a813ed254291","name":"rest_response","source":"f033a813ed254291.yaml","type":"application/yaml","size":259}],"parameters":[],"stepsCount":0,"attachmentsCount":3,"shouldDisplayMessage":false,"hasContent":true},{"name":"Stage 2: hsmAPIinventoryHardwarePOSTmemoryMissingPopulatedFRU - Attempt to create a Memory Hardware Inventory entry with missing PopulatedFRU data using POST.","time":{"start":1676325742637,"stop":1676325742645,"duration":8},"status":"passed","steps":[],"attachments":[{"uid":"1a4f8685d48303ee","name":"stage_yaml","source":"1a4f8685d48303ee.yaml","type":"application/yaml","size":1044},{"uid":"e98f98f01b67e44","name":"rest_request","source":"e98f98f01b67e44.yaml","type":"application/yaml","size":171},{"uid":"929dc6df4ef3bbe0","name":"rest_response","source":"929dc6df4ef3bbe0.yaml","type":"application/yaml","size":257}],"parameters":[],"stepsCount":0,"attachmentsCount":3,"shouldDisplayMessage":false,"hasContent":true},{"name":"Stage 3: hsmAPIinventoryHardwarePOSTnodeBMCmissingLocation - Attempt to create a NodeBMC Hardware Inventory entry with missing location data using POST.","time":{"start":1676325742646,"stop":1676325742656,"duration":10},"status":"passed","steps":[],"attachments":[{"uid":"a71c8d7d9018a","name":"stage_yaml","source":"a71c8d7d9018a.yaml","type":"application/yaml","size":1271},{"uid":"c8184cc97d6d5789","name":"rest_request","source":"c8184cc97d6d5789.yaml","type":"application/yaml","size":453},{"uid":"ca30bf1bb6c931e8","name":"rest_response","source":"ca30bf1bb6c931e8.yaml","type":"application/yaml","size":259}],"parameters":[],"stepsCount":0,"attachmentsCount":3,"shouldDisplayMessage":false,"hasContent":true},{"name":"Stage 4: hsmAPIinventoryHardwarePOSTnodeEnclosureEmptyPopulatedFRU - Attempt to create a NodeEnclosure Hardware Inventory entry with empty PopulatedFRU data using POST.","time":{"start":1676325742656,"stop":1676325742665,"duration":9},"status":"passed","steps":[],"attachments":[{"uid":"571a1d2a404ed1a5","name":"stage_yaml","source":"571a1d2a404ed1a5.yaml","type":"application/yaml","size":1196},{"uid":"8f58f1512fd217f","name":"rest_request","source":"8f58f1512fd217f.yaml","type":"application/yaml","size":338},{"uid":"f82a3721eef4c98","name":"rest_response","source":"f82a3721eef4c98.yaml","type":"application/yaml","size":243}],"parameters":[],"stepsCount":0,"attachmentsCount":3,"shouldDisplayMessage":false,"hasContent":true},{"name":"Stage 5: hsmAPIinventoryHardwarePOSTnodeHsnNicInvalidXname - Attempt to create a NodeHsnNic Hardware Inventory entry with an invalid xname using POST.","time":{"start":1676325742666,"stop":1676325742677,"duration":11},"status":"passed","steps":[],"attachments":[{"uid":"f3a92a88e7adc048","name":"stage_yaml","source":"f3a92a88e7adc048.yaml","type":"application/yaml","size":1497},{"uid":"68b94f64e4234d99","name":"rest_request","source":"68b94f64e4234d99.yaml","type":"application/yaml","size":686},{"uid":"ffa3a807f5b2405e","name":"rest_response","source":"ffa3a807f5b2405e.yaml","type":"application/yaml","size":259}],"parameters":[],"stepsCount":0,"attachmentsCount":3,"shouldDisplayMessage":false,"hasContent":true},{"name":"Stage 6: hsmAPIinventoryHardwareXnameGETnonExistentNode - Attempt to retrieve a Hardware Inventory entry for a node that doesn't exist using GET.","time":{"start":1676325742677,"stop":1676325742686,"duration":9},"status":"passed","steps":[],"attachments":[{"uid":"d366719cbc42564e","name":"stage_yaml","source":"d366719cbc42564e.yaml","type":"application/yaml","size":976},{"uid":"b85312fbd549501","name":"rest_request","source":"b85312fbd549501.yaml","type":"application/yaml","size":142},{"uid":"e10699241aad7658","name":"rest_response","source":"e10699241aad7658.yaml","type":"application/yaml","size":238}],"parameters":[],"stepsCount":0,"attachmentsCount":3,"shouldDisplayMessage":false,"hasContent":true},{"name":"Stage 7: hsmAPIinventoryHardwareGETidParamInvalid - Attempt to retrieve Hardware Inventory entries using GET with an invalid id query parameter.","time":{"start":1676325742686,"stop":1676325742694,"duration":8},"status":"passed","steps":[],"attachments":[{"uid":"bf6cbfddfa6300f2","name":"stage_yaml","source":"bf6cbfddfa6300f2.yaml","type":"application/yaml","size":970},{"uid":"5815c4c42c7555f7","name":"rest_request","source":"5815c4c42c7555f7.yaml","type":"application/yaml","size":136},{"uid":"d08b3a34b9a35925","name":"rest_response","source":"d08b3a34b9a35925.yaml","type":"application/yaml","size":239}],"parameters":[],"stepsCount":0,"attachmentsCount":3,"shouldDisplayMessage":false,"hasContent":true},{"name":"Stage 8: hsmAPIinventoryHardwareGETtypeParamInvalid - Attempt to retrieve Hardware Inventory entries using GET with an invalid type query parameter.","time":{"start":1676325742694,"stop":1676325742702,"duration":8},"status":"passed","steps":[],"attachments":[{"uid":"280d20211d2bb1e4","name":"stage_yaml","source":"280d20211d2bb1e4.yaml","type":"application/yaml","size":979},{"uid":"1e1fead740d87766","name":"rest_request","source":"1e1fead740d87766.yaml","type":"application/yaml","size":138},{"uid":"117e7f393b28cff4","name":"rest_response","source":"117e7f393b28cff4.yaml","type":"application/yaml","size":242}],"parameters":[],"stepsCount":0,"attachmentsCount":3,"shouldDisplayMessage":false,"hasContent":true},{"name":"Stage 9: hsmAPIinventoryHardwareQueryXnameGETnonExistentNode - Attempt to query for Node Hardware Inventory entries with an xname that doesn't exist using GET.","time":{"start":1676325742702,"stop":1676325742715,"duration":13},"status":"failed","statusMessage":"tavern.util.exceptions.TestFailError: Test 'hsmAPIinventoryHardwareQueryXnameGETnonExistentNode - Attempt to query for Node Hardware Inventory entries with an xname that doesn't exist using GET.' failed:\n- Error calling validate function '<function validate_pykwalify at 0x7fe894082670>':\n    Traceback (most recent call last):\n      File \"/usr/lib/python3.9/site-packages/tavern/schemas/files.py\", line 106, in verify_generic\n        verifier.validate()\n      File \"/usr/lib/python3.9/site-packages/pykwalify/core.py\", line 194, in validate\n        raise SchemaError(u\"Schema validation failed:\\n - {error_msg}.\".format(\n    pykwalify.errors.SchemaError: <SchemaError: error code 2: Schema validation failed:\n     - Key 'Nodes' was not defined. Path: ''.: Path: '/'>\n\n    The above exception was the direct cause of the following exception:\n\n    Traceback (most recent call last):\n      File \"/usr/lib/python3.9/site-packages/tavern/response/base.py\", line 152, in _maybe_run_validate_functions\n        vf(response)\n      File \"/usr/lib/python3.9/site-packages/tavern/util/extfunctions.py\", line 98, in inner\n        result = func(response, *args, **kwargs)\n      File \"/usr/lib/python3.9/site-packages/tavern/testutils/helpers.py\", line 103, in validate_pykwalify\n        verify_generic(to_verify, schema)\n      File \"/usr/lib/python3.9/site-packages/tavern/schemas/files.py\", line 109, in verify_generic\n        raise BadSchemaError() from e\n    tavern.util.exceptions.BadSchemaError\n\n","statusTrace":"  File \"/usr/lib/python3.9/site-packages/allure_commons/_allure.py\", line 192, in impl\n    return func(*a, **kw)\n  File \"/usr/lib/python3.9/site-packages/tavern/util/retry.py\", line 31, in wrapped\n    res = fn(*args, **kwargs)\n  File \"/usr/lib/python3.9/site-packages/tavern/core.py\", line 270, in run_stage\n    saved = v.verify(response)\n  File \"/usr/lib/python3.9/site-packages/tavern/_plugins/rest/response.py\", line 201, in verify\n    raise exceptions.TestFailError(\n","steps":[],"attachments":[{"uid":"3f14370edf1da7f9","name":"stage_yaml","source":"3f14370edf1da7f9.yaml","type":"application/yaml","size":776},{"uid":"d2962adcbbe7c42","name":"rest_request","source":"d2962adcbbe7c42.yaml","type":"application/yaml","size":163},{"uid":"ba8db2971179a054","name":"rest_response","source":"ba8db2971179a054.yaml","type":"application/yaml","size":1013}],"parameters":[],"stepsCount":0,"attachmentsCount":3,"shouldDisplayMessage":true,"hasContent":true}],"attachments":[{"uid":"23c22109cf584679","name":"error_output","source":"23c22109cf584679.attach","type":"text/plain","size":3309},{"uid":"35f24060d45976f8","name":"log","source":"35f24060d45976f8.txt","type":"text/plain","size":4032}],"parameters":[],"stepsCount":10,"attachmentsCount":32,"shouldDisplayMessage":true,"hasContent":true},"afterStages":[],"labels":[{"name":"parentSuite","value":"cray-smd-hmth-test"},{"name":"suite","value":"2-disruptive"},{"name":"host","value":"176358e92cf1"},{"name":"thread","value":"8-MainThread"},{"name":"framework","value":"pytest"},{"name":"language","value":"cpython3"},{"name":"package","value":"api.2-disruptive.test_hardware_negative.tavern"},{"name":"resultFormat","value":"allure2"}],"parameters":[],"links":[],"hidden":false,"retry":false,"extra":{"severity":"normal","retries":[],"categories":[{"name":"Product defects","matchedStatuses":[],"flaky":false}],"history":{"statistic":{"failed":9,"broken":0,"skipped":0,"passed":0,"unknown":0,"total":9},"items":[{"uid":"228e5084764c41d8","status":"failed","statusDetails":"tavern.util.exceptions.TestFailError: Test 'hsmAPIinventoryHardwareQueryXnameGETnonExistentNode - Attempt to query for Node Hardware Inventory entries with an xname that doesn't exist using GET.' failed:\n- Error calling validate function '<function validate_pykwalify at 0x7f8dbb859670>':\n    Traceback (most recent call last):\n      File \"/usr/lib/python3.9/site-packages/tavern/schemas/files.py\", line 106, in verify_generic\n        verifier.validate()\n      File \"/usr/lib/python3.9/site-packages/pykwalify/core.py\", line 194, in validate\n        raise SchemaError(u\"Schema validation failed:\\n - {error_msg}.\".format(\n    pykwalify.errors.SchemaError: <SchemaError: error code 2: Schema validation failed:\n     - Key 'Nodes' was not defined. Path: ''.: Path: '/'>\n\n    The above exception was the direct cause of the following exception:\n\n    Traceback (most recent call last):\n      File \"/usr/lib/python3.9/site-packages/tavern/response/base.py\", line 152, in _maybe_run_validate_functions\n        vf(response)\n      File \"/usr/lib/python3.9/site-packages/tavern/util/extfunctions.py\", line 98, in inner\n        result = func(response, *args, **kwargs)\n      File \"/usr/lib/python3.9/site-packages/tavern/testutils/helpers.py\", line 103, in validate_pykwalify\n        verify_generic(to_verify, schema)\n      File \"/usr/lib/python3.9/site-packages/tavern/schemas/files.py\", line 109, in verify_generic\n        raise BadSchemaError() from e\n    tavern.util.exceptions.BadSchemaError","time":{"start":1674515662991,"stop":1674515663111,"duration":120}},{"uid":"a264857ad554986c","status":"failed","statusDetails":"tavern.util.exceptions.TestFailError: Test 'hsmAPIinventoryHardwareQueryXnameGETnonExistentNode - Attempt to query for Node Hardware Inventory entries with an xname that doesn't exist using GET.' failed:\n- Error calling validate function '<function validate_pykwalify at 0x7fea16d93670>':\n    Traceback (most recent call last):\n      File \"/usr/lib/python3.9/site-packages/tavern/schemas/files.py\", line 106, in verify_generic\n        verifier.validate()\n      File \"/usr/lib/python3.9/site-packages/pykwalify/core.py\", line 194, in validate\n        raise SchemaError(u\"Schema validation failed:\\n - {error_msg}.\".format(\n    pykwalify.errors.SchemaError: <SchemaError: error code 2: Schema validation failed:\n     - Key 'Nodes' was not defined. Path: ''.: Path: '/'>\n\n    The above exception was the direct cause of the following exception:\n\n    Traceback (most recent call last):\n      File \"/usr/lib/python3.9/site-packages/tavern/response/base.py\", line 152, in _maybe_run_validate_functions\n        vf(response)\n      File \"/usr/lib/python3.9/site-packages/tavern/util/extfunctions.py\", line 98, in inner\n        result = func(response, *args, **kwargs)\n      File \"/usr/lib/python3.9/site-packages/tavern/testutils/helpers.py\", line 103, in validate_pykwalify\n        verify_generic(to_verify, schema)\n      File \"/usr/lib/python3.9/site-packages/tavern/schemas/files.py\", line 109, in verify_generic\n        raise BadSchemaError() from e\n    tavern.util.exceptions.BadSchemaError","time":{"start":1674505810582,"stop":1674505810721,"duration":139}},{"uid":"37fe971469c88bbf","status":"failed","statusDetails":"tavern.util.exceptions.TestFailError: Test 'hsmAPIinventoryHardwareQueryXnameGETnonExistentNode - Attempt to query for Node Hardware Inventory entries with an xname that doesn't exist using GET.' failed:\n- Error calling validate function '<function validate_pykwalify at 0x7fd84b340670>':\n    Traceback (most recent call last):\n      File \"/usr/lib/python3.9/site-packages/tavern/schemas/files.py\", line 106, in verify_generic\n        verifier.validate()\n      File \"/usr/lib/python3.9/site-packages/pykwalify/core.py\", line 194, in validate\n        raise SchemaError(u\"Schema validation failed:\\n - {error_msg}.\".format(\n    pykwalify.errors.SchemaError: <SchemaError: error code 2: Schema validation failed:\n     - Key 'Nodes' was not defined. Path: ''.: Path: '/'>\n\n    The above exception was the direct cause of the following exception:\n\n    Traceback (most recent call last):\n      File \"/usr/lib/python3.9/site-packages/tavern/response/base.py\", line 152, in _maybe_run_validate_functions\n        vf(response)\n      File \"/usr/lib/python3.9/site-packages/tavern/util/extfunctions.py\", line 98, in inner\n        result = func(response, *args, **kwargs)\n      File \"/usr/lib/python3.9/site-packages/tavern/testutils/helpers.py\", line 103, in validate_pykwalify\n        verify_generic(to_verify, schema)\n      File \"/usr/lib/python3.9/site-packages/tavern/schemas/files.py\", line 109, in verify_generic\n        raise BadSchemaError() from e\n    tavern.util.exceptions.BadSchemaError","time":{"start":1674500439042,"stop":1674500439180,"duration":138}},{"uid":"c1d624229232e087","status":"failed","statusDetails":"tavern.util.exceptions.TestFailError: Test 'hsmAPIinventoryHardwareQueryXnameGETnonExistentNode - Attempt to query for Node Hardware Inventory entries with an xname that doesn't exist using GET.' failed:\n- Error calling validate function '<function validate_pykwalify at 0x7f1abc08e670>':\n    Traceback (most recent call last):\n      File \"/usr/lib/python3.9/site-packages/tavern/schemas/files.py\", line 106, in verify_generic\n        verifier.validate()\n      File \"/usr/lib/python3.9/site-packages/pykwalify/core.py\", line 194, in validate\n        raise SchemaError(u\"Schema validation failed:\\n - {error_msg}.\".format(\n    pykwalify.errors.SchemaError: <SchemaError: error code 2: Schema validation failed:\n     - Key 'Nodes' was not defined. Path: ''.: Path: '/'>\n\n    The above exception was the direct cause of the following exception:\n\n    Traceback (most recent call last):\n      File \"/usr/lib/python3.9/site-packages/tavern/response/base.py\", line 152, in _maybe_run_validate_functions\n        vf(response)\n      File \"/usr/lib/python3.9/site-packages/tavern/util/extfunctions.py\", line 98, in inner\n        result = func(response, *args, **kwargs)\n      File \"/usr/lib/python3.9/site-packages/tavern/testutils/helpers.py\", line 103, in validate_pykwalify\n        verify_generic(to_verify, schema)\n      File \"/usr/lib/python3.9/site-packages/tavern/schemas/files.py\", line 109, in verify_generic\n        raise BadSchemaError() from e\n    tavern.util.exceptions.BadSchemaError","time":{"start":1674257933071,"stop":1674257933210,"duration":139}},{"uid":"ba316951e90ad21f","status":"failed","statusDetails":"tavern.util.exceptions.TestFailError: Test 'hsmAPIinventoryHardwareQueryXnameGETnonExistentNode - Attempt to query for Node Hardware Inventory entries with an xname that doesn't exist using GET.' failed:\n- Error calling validate function '<function validate_pykwalify at 0x7f875bc8b670>':\n    Traceback (most recent call last):\n      File \"/usr/lib/python3.9/site-packages/tavern/schemas/files.py\", line 106, in verify_generic\n        verifier.validate()\n      File \"/usr/lib/python3.9/site-packages/pykwalify/core.py\", line 194, in validate\n        raise SchemaError(u\"Schema validation failed:\\n - {error_msg}.\".format(\n    pykwalify.errors.SchemaError: <SchemaError: error code 2: Schema validation failed:\n     - Key 'Nodes' was not defined. Path: ''.: Path: '/'>\n\n    The above exception was the direct cause of the following exception:\n\n    Traceback (most recent call last):\n      File \"/usr/lib/python3.9/site-packages/tavern/response/base.py\", line 152, in _maybe_run_validate_functions\n        vf(response)\n      File \"/usr/lib/python3.9/site-packages/tavern/util/extfunctions.py\", line 98, in inner\n        result = func(response, *args, **kwargs)\n      File \"/usr/lib/python3.9/site-packages/tavern/testutils/helpers.py\", line 103, in validate_pykwalify\n        verify_generic(to_verify, schema)\n      File \"/usr/lib/python3.9/site-packages/tavern/schemas/files.py\", line 109, in verify_generic\n        raise BadSchemaError() from e\n    tavern.util.exceptions.BadSchemaError","time":{"start":1674255401112,"stop":1674255401283,"duration":171}},{"uid":"e8ba69c9d8b5e2b0","status":"failed","statusDetails":"tavern.util.exceptions.TestFailError: Test 'hsmAPIinventoryHardwareQueryXnameGETnonExistentNode - Attempt to query for Node Hardware Inventory entries with an xname that doesn't exist using GET.' failed:\n- Error calling validate function '<function validate_pykwalify at 0x7f6a576a8670>':\n    Traceback (most recent call last):\n      File \"/usr/lib/python3.9/site-packages/tavern/schemas/files.py\", line 106, in verify_generic\n        verifier.validate()\n      File \"/usr/lib/python3.9/site-packages/pykwalify/core.py\", line 194, in validate\n        raise SchemaError(u\"Schema validation failed:\\n - {error_msg}.\".format(\n    pykwalify.errors.SchemaError: <SchemaError: error code 2: Schema validation failed:\n     - Key 'Nodes' was not defined. Path: ''.: Path: '/'>\n\n    The above exception was the direct cause of the following exception:\n\n    Traceback (most recent call last):\n      File \"/usr/lib/python3.9/site-packages/tavern/response/base.py\", line 152, in _maybe_run_validate_functions\n        vf(response)\n      File \"/usr/lib/python3.9/site-packages/tavern/util/extfunctions.py\", line 98, in inner\n        result = func(response, *args, **kwargs)\n      File \"/usr/lib/python3.9/site-packages/tavern/testutils/helpers.py\", line 103, in validate_pykwalify\n        verify_generic(to_verify, schema)\n      File \"/usr/lib/python3.9/site-packages/tavern/schemas/files.py\", line 109, in verify_generic\n        raise BadSchemaError() from e\n    tavern.util.exceptions.BadSchemaError","time":{"start":1674080280028,"stop":1674080280180,"duration":152}},{"uid":"ffc24f6f35dfcbd4","status":"failed","statusDetails":"tavern.util.exceptions.TestFailError: Test 'hsmAPIinventoryHardwareQueryXnameGETnonExistentNode - Attempt to query for Node Hardware Inventory entries with an xname that doesn't exist using GET.' failed:\n- Error calling validate function '<function validate_pykwalify at 0x7f08457c6670>':\n    Traceback (most recent call last):\n      File \"/usr/lib/python3.9/site-packages/tavern/schemas/files.py\", line 106, in verify_generic\n        verifier.validate()\n      File \"/usr/lib/python3.9/site-packages/pykwalify/core.py\", line 194, in validate\n        raise SchemaError(u\"Schema validation failed:\\n - {error_msg}.\".format(\n    pykwalify.errors.SchemaError: <SchemaError: error code 2: Schema validation failed:\n     - Key 'Nodes' was not defined. Path: ''.: Path: '/'>\n\n    The above exception was the direct cause of the following exception:\n\n    Traceback (most recent call last):\n      File \"/usr/lib/python3.9/site-packages/tavern/response/base.py\", line 152, in _maybe_run_validate_functions\n        vf(response)\n      File \"/usr/lib/python3.9/site-packages/tavern/util/extfunctions.py\", line 98, in inner\n        result = func(response, *args, **kwargs)\n      File \"/usr/lib/python3.9/site-packages/tavern/testutils/helpers.py\", line 103, in validate_pykwalify\n        verify_generic(to_verify, schema)\n      File \"/usr/lib/python3.9/site-packages/tavern/schemas/files.py\", line 109, in verify_generic\n        raise BadSchemaError() from e\n    tavern.util.exceptions.BadSchemaError","time":{"start":1674074994530,"stop":1674074994685,"duration":155}},{"uid":"1506fd54376e2e65","status":"failed","statusDetails":"tavern.util.exceptions.TestFailError: Test 'hsmAPIinventoryHardwareQueryXnameGETnonExistentNode - Attempt to query for Node Hardware Inventory entries with an xname that doesn't exist using GET.' failed:\n- Error calling validate function '<function validate_pykwalify at 0x7f3b1a200670>':\n    Traceback (most recent call last):\n      File \"/usr/lib/python3.9/site-packages/tavern/schemas/files.py\", line 106, in verify_generic\n        verifier.validate()\n      File \"/usr/lib/python3.9/site-packages/pykwalify/core.py\", line 194, in validate\n        raise SchemaError(u\"Schema validation failed:\\n - {error_msg}.\".format(\n    pykwalify.errors.SchemaError: <SchemaError: error code 2: Schema validation failed:\n     - Key 'Nodes' was not defined. Path: ''.: Path: '/'>\n\n    The above exception was the direct cause of the following exception:\n\n    Traceback (most recent call last):\n      File \"/usr/lib/python3.9/site-packages/tavern/response/base.py\", line 152, in _maybe_run_validate_functions\n        vf(response)\n      File \"/usr/lib/python3.9/site-packages/tavern/util/extfunctions.py\", line 98, in inner\n        result = func(response, *args, **kwargs)\n      File \"/usr/lib/python3.9/site-packages/tavern/testutils/helpers.py\", line 103, in validate_pykwalify\n        verify_generic(to_verify, schema)\n      File \"/usr/lib/python3.9/site-packages/tavern/schemas/files.py\", line 109, in verify_generic\n        raise BadSchemaError() from e\n    tavern.util.exceptions.BadSchemaError","time":{"start":1674074614522,"stop":1674074614650,"duration":128}}]},"tags":[]},"source":"b2a990844b3431b7.json","parameterValues":[]}