{"uid":"2b7e280c20356de6","name":"capmcAPISetPowerCap","fullName":"api.4-build-pipeline-only.test_set_power_cap.tavern#capmcAPISetPowerCap","historyId":"dd408b17f7b8e55258fcff9f663cd89b","time":{"start":1710750604529,"stop":1710750604679,"duration":150},"status":"failed","statusMessage":"tavern.util.exceptions.TestFailError: Test 'capmcAPISetPowerCap - test2 - set_power_cap for two ready nodes' failed:\n- Error calling validate function '<function validate_pykwalify at 0x776e3d0b35e0>':\n    Traceback (most recent call last):\n      File \"/usr/lib/python3.9/site-packages/tavern/schemas/files.py\", line 106, in verify_generic\n        verifier.validate()\n      File \"/usr/lib/python3.9/site-packages/pykwalify/core.py\", line 194, in validate\n        raise SchemaError(u\"Schema validation failed:\\n - {error_msg}.\".format(\n    pykwalify.errors.SchemaError: <SchemaError: error code 2: Schema validation failed:\n     - Enum '22' does not exist. Path: '/e' Enum: [0].\n     - Value '[{'nid': 1014, 'e': 22, 'err_msg': 'Control (Node Power Limit) value (5036) is greater than maximum (925)'}, {'nid': 20, 'e': 22, 'err_msg': 'No NID supported controls specified'}]' is not of type 'none'. Path: '/nids'.: Path: '/'>\n\n    The above exception was the direct cause of the following exception:\n\n    Traceback (most recent call last):\n      File \"/usr/lib/python3.9/site-packages/tavern/response/base.py\", line 152, in _maybe_run_validate_functions\n        vf(response)\n      File \"/usr/lib/python3.9/site-packages/tavern/util/extfunctions.py\", line 98, in inner\n        result = func(response, *args, **kwargs)\n      File \"/usr/lib/python3.9/site-packages/tavern/testutils/helpers.py\", line 103, in validate_pykwalify\n        verify_generic(to_verify, schema)\n      File \"/usr/lib/python3.9/site-packages/tavern/schemas/files.py\", line 109, in verify_generic\n        raise BadSchemaError() from e\n    tavern.util.exceptions.BadSchemaError","statusTrace":"Format variables:\n  capmc_base_url = 'http://cray-capmc:27777'\n  nid0:d = '1014'\n  min0:d = '5036'\n  nid1:d = '20'\n  min1:d = '5036'\n  verify = 'False'\n\nSource test stage (line 184):\n  - name: capmcAPISetPowerCap - test2 - set_power_cap for two ready nodes\n    request:\n      url: \"{capmc_base_url}/capmc/v1/set_power_cap\"\n      json:\n        nids:\n          - nid: !int \"{nid0:d}\"\n            controls:\n              - name: Node Power Limit\n                val: !int \"{min0:d}\"\n          - nid: !int \"{nid1:d}\"\n            controls:\n              - name: Node Power Limit\n                val: !int \"{min1:d}\"\n      method: POST\n      verify: !bool \"{verify}\"\n    response:\n      status_code: 200\n      verify_response_with:\n        function: tavern.testutils.helpers:validate_pykwalify\n        extra_kwargs:\n\n\n\n\n\n\n          schema:\n            type: map\n            mapping:\n              e:\n                type: int\n                required: True\n                enum:\n                  - 0\n              err_msg:\n                type: str\n                required: True\n              nids:\n                type: none\n                required: False\n\n\nFormatted stage:\n  name: capmcAPISetPowerCap - test2 - set_power_cap for two ready nodes\n  request:\n    json:\n      nids:\n      - controls:\n        - name: Node Power Limit\n          val: !int '5036'\n        nid: !int '1014'\n      - controls:\n        - name: Node Power Limit\n          val: !int '5036'\n        nid: !int '20'\n    method: POST\n    url: 'http://cray-capmc:27777/capmc/v1/set_power_cap'\n    verify: !bool 'False'\n  response:\n    status_code: 200\n    verify_response_with:\n      extra_kwargs:\n        schema:\n          mapping:\n            e:\n              enum:\n              - 0\n              required: true\n              type: int\n            err_msg:\n              required: true\n              type: str\n            nids:\n              required: false\n              type: none\n          type: map\n      function: tavern.testutils.helpers:validate_pykwalify\n\nErrors:\nE   tavern.util.exceptions.TestFailError: Test 'capmcAPISetPowerCap - test2 - set_power_cap for two ready nodes' failed:\n    - Error calling validate function '<function validate_pykwalify at 0x776e3d0b35e0>':\n        Traceback (most recent call last):\n          File \"/usr/lib/python3.9/site-packages/tavern/schemas/files.py\", line 106, in verify_generic\n            verifier.validate()\n          File \"/usr/lib/python3.9/site-packages/pykwalify/core.py\", line 194, in validate\n            raise SchemaError(u\"Schema validation failed:\\n - {error_msg}.\".format(\n        pykwalify.errors.SchemaError: <SchemaError: error code 2: Schema validation failed:\n         - Enum '22' does not exist. Path: '/e' Enum: [0].\n         - Value '[{'nid': 1014, 'e': 22, 'err_msg': 'Control (Node Power Limit) value (5036) is greater than maximum (925)'}, {'nid': 20, 'e': 22, 'err_msg': 'No NID supported controls specified'}]' is not of type 'none'. Path: '/nids'.: Path: '/'>\n    \n        The above exception was the direct cause of the following exception:\n    \n        Traceback (most recent call last):\n          File \"/usr/lib/python3.9/site-packages/tavern/response/base.py\", line 152, in _maybe_run_validate_functions\n            vf(response)\n          File \"/usr/lib/python3.9/site-packages/tavern/util/extfunctions.py\", line 98, in inner\n            result = func(response, *args, **kwargs)\n          File \"/usr/lib/python3.9/site-packages/tavern/testutils/helpers.py\", line 103, in validate_pykwalify\n            verify_generic(to_verify, schema)\n          File \"/usr/lib/python3.9/site-packages/tavern/schemas/files.py\", line 109, in verify_generic\n            raise BadSchemaError() from e\n        tavern.util.exceptions.BadSchemaError","flaky":false,"newFailed":true,"newBroken":false,"newPassed":false,"retriesCount":0,"retriesStatusChange":false,"beforeStages":[],"testStage":{"status":"failed","statusMessage":"tavern.util.exceptions.TestFailError: Test 'capmcAPISetPowerCap - test2 - set_power_cap for two ready nodes' failed:\n- Error calling validate function '<function validate_pykwalify at 0x776e3d0b35e0>':\n    Traceback (most recent call last):\n      File \"/usr/lib/python3.9/site-packages/tavern/schemas/files.py\", line 106, in verify_generic\n        verifier.validate()\n      File \"/usr/lib/python3.9/site-packages/pykwalify/core.py\", line 194, in validate\n        raise SchemaError(u\"Schema validation failed:\\n - {error_msg}.\".format(\n    pykwalify.errors.SchemaError: <SchemaError: error code 2: Schema validation failed:\n     - Enum '22' does not exist. Path: '/e' Enum: [0].\n     - Value '[{'nid': 1014, 'e': 22, 'err_msg': 'Control (Node Power Limit) value (5036) is greater than maximum (925)'}, {'nid': 20, 'e': 22, 'err_msg': 'No NID supported controls specified'}]' is not of type 'none'. Path: '/nids'.: Path: '/'>\n\n    The above exception was the direct cause of the following exception:\n\n    Traceback (most recent call last):\n      File \"/usr/lib/python3.9/site-packages/tavern/response/base.py\", line 152, in _maybe_run_validate_functions\n        vf(response)\n      File \"/usr/lib/python3.9/site-packages/tavern/util/extfunctions.py\", line 98, in inner\n        result = func(response, *args, **kwargs)\n      File \"/usr/lib/python3.9/site-packages/tavern/testutils/helpers.py\", line 103, in validate_pykwalify\n        verify_generic(to_verify, schema)\n      File \"/usr/lib/python3.9/site-packages/tavern/schemas/files.py\", line 109, in verify_generic\n        raise BadSchemaError() from e\n    tavern.util.exceptions.BadSchemaError","statusTrace":"Format variables:\n  capmc_base_url = 'http://cray-capmc:27777'\n  nid0:d = '1014'\n  min0:d = '5036'\n  nid1:d = '20'\n  min1:d = '5036'\n  verify = 'False'\n\nSource test stage (line 184):\n  - name: capmcAPISetPowerCap - test2 - set_power_cap for two ready nodes\n    request:\n      url: \"{capmc_base_url}/capmc/v1/set_power_cap\"\n      json:\n        nids:\n          - nid: !int \"{nid0:d}\"\n            controls:\n              - name: Node Power Limit\n                val: !int \"{min0:d}\"\n          - nid: !int \"{nid1:d}\"\n            controls:\n              - name: Node Power Limit\n                val: !int \"{min1:d}\"\n      method: POST\n      verify: !bool \"{verify}\"\n    response:\n      status_code: 200\n      verify_response_with:\n        function: tavern.testutils.helpers:validate_pykwalify\n        extra_kwargs:\n\n\n\n\n\n\n          schema:\n            type: map\n            mapping:\n              e:\n                type: int\n                required: True\n                enum:\n                  - 0\n              err_msg:\n                type: str\n                required: True\n              nids:\n                type: none\n                required: False\n\n\nFormatted stage:\n  name: capmcAPISetPowerCap - test2 - set_power_cap for two ready nodes\n  request:\n    json:\n      nids:\n      - controls:\n        - name: Node Power Limit\n          val: !int '5036'\n        nid: !int '1014'\n      - controls:\n        - name: Node Power Limit\n          val: !int '5036'\n        nid: !int '20'\n    method: POST\n    url: 'http://cray-capmc:27777/capmc/v1/set_power_cap'\n    verify: !bool 'False'\n  response:\n    status_code: 200\n    verify_response_with:\n      extra_kwargs:\n        schema:\n          mapping:\n            e:\n              enum:\n              - 0\n              required: true\n              type: int\n            err_msg:\n              required: true\n              type: str\n            nids:\n              required: false\n              type: none\n          type: map\n      function: tavern.testutils.helpers:validate_pykwalify\n\nErrors:\nE   tavern.util.exceptions.TestFailError: Test 'capmcAPISetPowerCap - test2 - set_power_cap for two ready nodes' failed:\n    - Error calling validate function '<function validate_pykwalify at 0x776e3d0b35e0>':\n        Traceback (most recent call last):\n          File \"/usr/lib/python3.9/site-packages/tavern/schemas/files.py\", line 106, in verify_generic\n            verifier.validate()\n          File \"/usr/lib/python3.9/site-packages/pykwalify/core.py\", line 194, in validate\n            raise SchemaError(u\"Schema validation failed:\\n - {error_msg}.\".format(\n        pykwalify.errors.SchemaError: <SchemaError: error code 2: Schema validation failed:\n         - Enum '22' does not exist. Path: '/e' Enum: [0].\n         - Value '[{'nid': 1014, 'e': 22, 'err_msg': 'Control (Node Power Limit) value (5036) is greater than maximum (925)'}, {'nid': 20, 'e': 22, 'err_msg': 'No NID supported controls specified'}]' is not of type 'none'. Path: '/nids'.: Path: '/'>\n    \n        The above exception was the direct cause of the following exception:\n    \n        Traceback (most recent call last):\n          File \"/usr/lib/python3.9/site-packages/tavern/response/base.py\", line 152, in _maybe_run_validate_functions\n            vf(response)\n          File \"/usr/lib/python3.9/site-packages/tavern/util/extfunctions.py\", line 98, in inner\n            result = func(response, *args, **kwargs)\n          File \"/usr/lib/python3.9/site-packages/tavern/testutils/helpers.py\", line 103, in validate_pykwalify\n            verify_generic(to_verify, schema)\n          File \"/usr/lib/python3.9/site-packages/tavern/schemas/files.py\", line 109, in verify_generic\n            raise BadSchemaError() from e\n        tavern.util.exceptions.BadSchemaError","steps":[{"name":"Stage 0: capmcAPISetPowerCap - setup1 - Get HSM Nodes","time":{"start":1710750604539,"stop":1710750604568,"duration":29},"status":"passed","steps":[],"attachments":[{"uid":"31e7becd19333fda","name":"stage_yaml","source":"31e7becd19333fda.yaml","type":"application/yaml","size":457},{"uid":"7847df8dbc077c09","name":"rest_request","source":"7847df8dbc077c09.yaml","type":"application/yaml","size":149},{"uid":"a61c65718523d24f","name":"rest_response","source":"a61c65718523d24f.yaml","type":"application/yaml","size":5771}],"parameters":[],"stepsCount":0,"attachmentsCount":3,"shouldDisplayMessage":false,"hasContent":true},{"name":"Stage 1: capmcAPISetPowerCap - setup2 - get_power_cap_capabilities","time":{"start":1710750604568,"stop":1710750604613,"duration":45},"status":"passed","steps":[],"attachments":[{"uid":"aca6b03d63171386","name":"stage_yaml","source":"aca6b03d63171386.yaml","type":"application/yaml","size":472},{"uid":"f5c1f74d3e8ecac0","name":"rest_request","source":"f5c1f74d3e8ecac0.yaml","type":"application/yaml","size":171},{"uid":"bd94fbb9b0004c5e","name":"rest_response","source":"bd94fbb9b0004c5e.yaml","type":"application/yaml","size":980}],"parameters":[],"stepsCount":0,"attachmentsCount":3,"shouldDisplayMessage":false,"hasContent":true},{"name":"Stage 2: capmcAPISetPowerCap - setup3 - Set HSM Node 0 to Off","time":{"start":1710750604614,"stop":1710750604622,"duration":8},"status":"passed","steps":[],"attachments":[{"uid":"b1c3b9856f985e68","name":"stage_yaml","source":"b1c3b9856f985e68.yaml","type":"application/yaml","size":247},{"uid":"a079b26fd53bc06d","name":"rest_request","source":"a079b26fd53bc06d.yaml","type":"application/yaml","size":173},{"uid":"5e3b13be3434724d","name":"rest_response","source":"5e3b13be3434724d.yaml","type":"application/yaml","size":134}],"parameters":[],"stepsCount":0,"attachmentsCount":3,"shouldDisplayMessage":false,"hasContent":true},{"name":"Stage 3: capmcAPISetPowerCap - setup4 - Set HSM Node 1 to Off","time":{"start":1710750604623,"stop":1710750604631,"duration":8},"status":"passed","steps":[],"attachments":[{"uid":"3376e68ea1fbf380","name":"stage_yaml","source":"3376e68ea1fbf380.yaml","type":"application/yaml","size":247},{"uid":"6d0f7e421c8119df","name":"rest_request","source":"6d0f7e421c8119df.yaml","type":"application/yaml","size":173},{"uid":"a47fc0a472b85ff8","name":"rest_response","source":"a47fc0a472b85ff8.yaml","type":"application/yaml","size":134}],"parameters":[],"stepsCount":0,"attachmentsCount":3,"shouldDisplayMessage":false,"hasContent":true},{"name":"Stage 4: capmcAPISetPowerCap - test1 - POST set_power_cap for powered off node - failure test","time":{"start":1710750604632,"stop":1710750604645,"duration":13},"status":"passed","steps":[],"attachments":[{"uid":"1368634015473bca","name":"stage_yaml","source":"1368634015473bca.yaml","type":"application/yaml","size":1395},{"uid":"9ef292270c72805d","name":"rest_request","source":"9ef292270c72805d.yaml","type":"application/yaml","size":214},{"uid":"b464e217ad890d19","name":"rest_response","source":"b464e217ad890d19.yaml","type":"application/yaml","size":287}],"parameters":[],"stepsCount":0,"attachmentsCount":3,"shouldDisplayMessage":false,"hasContent":true},{"name":"Stage 5: capmcAPISetPowerCap - setup5 - Set HSM Node 0 to Ready","time":{"start":1710750604646,"stop":1710750604653,"duration":7},"status":"passed","steps":[],"attachments":[{"uid":"2f9a9a2d3cb27860","name":"stage_yaml","source":"2f9a9a2d3cb27860.yaml","type":"application/yaml","size":251},{"uid":"bb1b8d3083c16b69","name":"rest_request","source":"bb1b8d3083c16b69.yaml","type":"application/yaml","size":173},{"uid":"8cec18458839b066","name":"rest_response","source":"8cec18458839b066.yaml","type":"application/yaml","size":134}],"parameters":[],"stepsCount":0,"attachmentsCount":3,"shouldDisplayMessage":false,"hasContent":true},{"name":"Stage 6: capmcAPISetPowerCap - setup6 - Set HSM Node 1 to Ready","time":{"start":1710750604654,"stop":1710750604662,"duration":8},"status":"passed","steps":[],"attachments":[{"uid":"73aaf408aa7aafec","name":"stage_yaml","source":"73aaf408aa7aafec.yaml","type":"application/yaml","size":251},{"uid":"ae40a1f33f646d4e","name":"rest_request","source":"ae40a1f33f646d4e.yaml","type":"application/yaml","size":173},{"uid":"ed595368ae21f7e4","name":"rest_response","source":"ed595368ae21f7e4.yaml","type":"application/yaml","size":134}],"parameters":[],"stepsCount":0,"attachmentsCount":3,"shouldDisplayMessage":false,"hasContent":true},{"name":"Stage 7: capmcAPISetPowerCap - test2 - set_power_cap for two ready nodes","time":{"start":1710750604663,"stop":1710750604678,"duration":15},"status":"failed","statusMessage":"tavern.util.exceptions.TestFailError: Test 'capmcAPISetPowerCap - test2 - set_power_cap for two ready nodes' failed:\n- Error calling validate function '<function validate_pykwalify at 0x776e3d0b35e0>':\n    Traceback (most recent call last):\n      File \"/usr/lib/python3.9/site-packages/tavern/schemas/files.py\", line 106, in verify_generic\n        verifier.validate()\n      File \"/usr/lib/python3.9/site-packages/pykwalify/core.py\", line 194, in validate\n        raise SchemaError(u\"Schema validation failed:\\n - {error_msg}.\".format(\n    pykwalify.errors.SchemaError: <SchemaError: error code 2: Schema validation failed:\n     - Enum '22' does not exist. Path: '/e' Enum: [0].\n     - Value '[{'nid': 1014, 'e': 22, 'err_msg': 'Control (Node Power Limit) value (5036) is greater than maximum (925)'}, {'nid': 20, 'e': 22, 'err_msg': 'No NID supported controls specified'}]' is not of type 'none'. Path: '/nids'.: Path: '/'>\n\n    The above exception was the direct cause of the following exception:\n\n    Traceback (most recent call last):\n      File \"/usr/lib/python3.9/site-packages/tavern/response/base.py\", line 152, in _maybe_run_validate_functions\n        vf(response)\n      File \"/usr/lib/python3.9/site-packages/tavern/util/extfunctions.py\", line 98, in inner\n        result = func(response, *args, **kwargs)\n      File \"/usr/lib/python3.9/site-packages/tavern/testutils/helpers.py\", line 103, in validate_pykwalify\n        verify_generic(to_verify, schema)\n      File \"/usr/lib/python3.9/site-packages/tavern/schemas/files.py\", line 109, in verify_generic\n        raise BadSchemaError() from e\n    tavern.util.exceptions.BadSchemaError\n\n","statusTrace":"  File \"/usr/lib/python3.9/site-packages/allure_commons/_allure.py\", line 192, in impl\n    return func(*a, **kw)\n  File \"/usr/lib/python3.9/site-packages/tavern/util/retry.py\", line 31, in wrapped\n    res = fn(*args, **kwargs)\n  File \"/usr/lib/python3.9/site-packages/tavern/core.py\", line 270, in run_stage\n    saved = v.verify(response)\n  File \"/usr/lib/python3.9/site-packages/tavern/_plugins/rest/response.py\", line 201, in verify\n    raise exceptions.TestFailError(\n","steps":[],"attachments":[{"uid":"5de0b491866d52c6","name":"stage_yaml","source":"5de0b491866d52c6.yaml","type":"application/yaml","size":903},{"uid":"344af242ff358557","name":"rest_request","source":"344af242ff358557.yaml","type":"application/yaml","size":286},{"uid":"bbefde4e25e0e3f7","name":"rest_response","source":"bbefde4e25e0e3f7.yaml","type":"application/yaml","size":394}],"parameters":[],"stepsCount":0,"attachmentsCount":3,"shouldDisplayMessage":true,"hasContent":true}],"attachments":[{"uid":"6159d9df74c5bebd","name":"error_output","source":"6159d9df74c5bebd.attach","type":"text/plain","size":3773},{"uid":"957a2ceadfd755fa","name":"log","source":"957a2ceadfd755fa.txt","type":"text/plain","size":4427}],"parameters":[],"stepsCount":8,"attachmentsCount":26,"shouldDisplayMessage":true,"hasContent":true},"afterStages":[],"labels":[{"name":"parentSuite","value":"cray-capmc-hmth-test"},{"name":"suite","value":"build-pipeline-only"},{"name":"host","value":"3dbdd9f3054e"},{"name":"thread","value":"8-MainThread"},{"name":"framework","value":"pytest"},{"name":"language","value":"cpython3"},{"name":"package","value":"api.4-build-pipeline-only.test_set_power_cap.tavern"},{"name":"resultFormat","value":"allure2"}],"parameters":[],"links":[],"hidden":false,"retry":false,"extra":{"severity":"normal","retries":[],"categories":[{"name":"Product defects","matchedStatuses":[],"flaky":false}],"history":{"statistic":{"failed":72,"broken":0,"skipped":0,"passed":234,"unknown":0,"total":306},"items":[{"uid":"4b9a58e3a4b760ce","status":"passed","time":{"start":1710664141205,"stop":1710664141467,"duration":262}},{"uid":"60c4aa6860eb1ba7","status":"passed","time":{"start":1710577764984,"stop":1710577765241,"duration":257}},{"uid":"14f95c1d38fb4a0c","status":"passed","time":{"start":1710491330753,"stop":1710491331012,"duration":259}},{"uid":"6b4bb40cb2db2116","status":"passed","time":{"start":1710405001488,"stop":1710405001742,"duration":254}},{"uid":"3658e1313c1b654a","status":"passed","time":{"start":1710318520644,"stop":1710318520925,"duration":281}},{"uid":"2c9513a4420d5616","status":"failed","statusDetails":"tavern.util.exceptions.TestFailError: Test 'capmcAPISetPowerCap - test2 - set_power_cap for two ready nodes' failed:\n- Error calling validate function '<function validate_pykwalify at 0x7fede55fc5e0>':\n    Traceback (most recent call last):\n      File \"/usr/lib/python3.9/site-packages/tavern/schemas/files.py\", line 106, in verify_generic\n        verifier.validate()\n      File \"/usr/lib/python3.9/site-packages/pykwalify/core.py\", line 194, in validate\n        raise SchemaError(u\"Schema validation failed:\\n - {error_msg}.\".format(\n    pykwalify.errors.SchemaError: <SchemaError: error code 2: Schema validation failed:\n     - Enum '22' does not exist. Path: '/e' Enum: [0].\n     - Value '[{'nid': 20, 'e': 22, 'err_msg': 'No NID supported controls specified'}, {'nid': 1022, 'e': 22, 'err_msg': 'Control (Node Power Limit) value (5036) is greater than maximum (925)'}]' is not of type 'none'. Path: '/nids'.: Path: '/'>\n\n    The above exception was the direct cause of the following exception:\n\n    Traceback (most recent call last):\n      File \"/usr/lib/python3.9/site-packages/tavern/response/base.py\", line 152, in _maybe_run_validate_functions\n        vf(response)\n      File \"/usr/lib/python3.9/site-packages/tavern/util/extfunctions.py\", line 98, in inner\n        result = func(response, *args, **kwargs)\n      File \"/usr/lib/python3.9/site-packages/tavern/testutils/helpers.py\", line 103, in validate_pykwalify\n        verify_generic(to_verify, schema)\n      File \"/usr/lib/python3.9/site-packages/tavern/schemas/files.py\", line 109, in verify_generic\n        raise BadSchemaError() from e\n    tavern.util.exceptions.BadSchemaError","time":{"start":1710232127169,"stop":1710232127313,"duration":144}},{"uid":"ea8497bf1e94a25f","status":"passed","time":{"start":1710145716484,"stop":1710145716757,"duration":273}},{"uid":"f10ff2168818013c","status":"passed","time":{"start":1710059383821,"stop":1710059384087,"duration":266}},{"uid":"a5d1b68c98019f7a","status":"passed","time":{"start":1709972957987,"stop":1709972958238,"duration":251}},{"uid":"4aab072ddba5e1db","status":"failed","statusDetails":"tavern.util.exceptions.TestFailError: Test 'capmcAPISetPowerCap - test2 - set_power_cap for two ready nodes' failed:\n- Error calling validate function '<function validate_pykwalify at 0x7fc2a1eac5e0>':\n    Traceback (most recent call last):\n      File \"/usr/lib/python3.9/site-packages/tavern/schemas/files.py\", line 106, in verify_generic\n        verifier.validate()\n      File \"/usr/lib/python3.9/site-packages/pykwalify/core.py\", line 194, in validate\n        raise SchemaError(u\"Schema validation failed:\\n - {error_msg}.\".format(\n    pykwalify.errors.SchemaError: <SchemaError: error code 2: Schema validation failed:\n     - Enum '22' does not exist. Path: '/e' Enum: [0].\n     - Value '[{'nid': 1028, 'e': 22, 'err_msg': 'Control (Node Power Limit) value (5036) is greater than maximum (925)'}, {'nid': 20, 'e': 22, 'err_msg': 'No NID supported controls specified'}]' is not of type 'none'. Path: '/nids'.: Path: '/'>\n\n    The above exception was the direct cause of the following exception:\n\n    Traceback (most recent call last):\n      File \"/usr/lib/python3.9/site-packages/tavern/response/base.py\", line 152, in _maybe_run_validate_functions\n        vf(response)\n      File \"/usr/lib/python3.9/site-packages/tavern/util/extfunctions.py\", line 98, in inner\n        result = func(response, *args, **kwargs)\n      File \"/usr/lib/python3.9/site-packages/tavern/testutils/helpers.py\", line 103, in validate_pykwalify\n        verify_generic(to_verify, schema)\n      File \"/usr/lib/python3.9/site-packages/tavern/schemas/files.py\", line 109, in verify_generic\n        raise BadSchemaError() from e\n    tavern.util.exceptions.BadSchemaError","time":{"start":1709886581731,"stop":1709886581876,"duration":145}},{"uid":"858b3980aa32d164","status":"failed","statusDetails":"tavern.util.exceptions.TestFailError: Test 'capmcAPISetPowerCap - test2 - set_power_cap for two ready nodes' failed:\n- Error calling validate function '<function validate_pykwalify at 0x7f07a8b395e0>':\n    Traceback (most recent call last):\n      File \"/usr/lib/python3.9/site-packages/tavern/schemas/files.py\", line 106, in verify_generic\n        verifier.validate()\n      File \"/usr/lib/python3.9/site-packages/pykwalify/core.py\", line 194, in validate\n        raise SchemaError(u\"Schema validation failed:\\n - {error_msg}.\".format(\n    pykwalify.errors.SchemaError: <SchemaError: error code 2: Schema validation failed:\n     - Enum '22' does not exist. Path: '/e' Enum: [0].\n     - Value '[{'nid': 1017, 'e': 22, 'err_msg': 'Control (Node Power Limit) value (5036) is greater than maximum (925)'}, {'nid': 20, 'e': 22, 'err_msg': 'No NID supported controls specified'}]' is not of type 'none'. Path: '/nids'.: Path: '/'>\n\n    The above exception was the direct cause of the following exception:\n\n    Traceback (most recent call last):\n      File \"/usr/lib/python3.9/site-packages/tavern/response/base.py\", line 152, in _maybe_run_validate_functions\n        vf(response)\n      File \"/usr/lib/python3.9/site-packages/tavern/util/extfunctions.py\", line 98, in inner\n        result = func(response, *args, **kwargs)\n      File \"/usr/lib/python3.9/site-packages/tavern/testutils/helpers.py\", line 103, in validate_pykwalify\n        verify_generic(to_verify, schema)\n      File \"/usr/lib/python3.9/site-packages/tavern/schemas/files.py\", line 109, in verify_generic\n        raise BadSchemaError() from e\n    tavern.util.exceptions.BadSchemaError","time":{"start":1709800146564,"stop":1709800146709,"duration":145}},{"uid":"4be6612e0ce13459","status":"passed","time":{"start":1709713808019,"stop":1709713808276,"duration":257}},{"uid":"d24a0177e71351df","status":"passed","time":{"start":1709627374835,"stop":1709627375094,"duration":259}},{"uid":"9400b264330f5272","status":"passed","time":{"start":1709541701784,"stop":1709541702045,"duration":261}},{"uid":"49bb2dee1a4a3cbf","status":"passed","time":{"start":1709454561545,"stop":1709454561807,"duration":262}},{"uid":"db5f7da0f758a76b","status":"passed","time":{"start":1709368107162,"stop":1709368107402,"duration":240}},{"uid":"e8b3a90135659a6f","status":"failed","statusDetails":"tavern.util.exceptions.TestFailError: Test 'capmcAPISetPowerCap - test2 - set_power_cap for two ready nodes' failed:\n- Error calling validate function '<function validate_pykwalify at 0x7f5a07fcb4c0>':\n    Traceback (most recent call last):\n      File \"/usr/lib/python3.9/site-packages/tavern/schemas/files.py\", line 106, in verify_generic\n        verifier.validate()\n      File \"/usr/lib/python3.9/site-packages/pykwalify/core.py\", line 194, in validate\n        raise SchemaError(u\"Schema validation failed:\\n - {error_msg}.\".format(\n    pykwalify.errors.SchemaError: <SchemaError: error code 2: Schema validation failed:\n     - Enum '22' does not exist. Path: '/e' Enum: [0].\n     - Value '[{'nid': 20, 'e': 22, 'err_msg': 'No NID supported controls specified'}, {'nid': 1015, 'e': 22, 'err_msg': 'Control (Node Power Limit) value (5036) is greater than maximum (925)'}]' is not of type 'none'. Path: '/nids'.: Path: '/'>\n\n    The above exception was the direct cause of the following exception:\n\n    Traceback (most recent call last):\n      File \"/usr/lib/python3.9/site-packages/tavern/response/base.py\", line 152, in _maybe_run_validate_functions\n        vf(response)\n      File \"/usr/lib/python3.9/site-packages/tavern/util/extfunctions.py\", line 98, in inner\n        result = func(response, *args, **kwargs)\n      File \"/usr/lib/python3.9/site-packages/tavern/testutils/helpers.py\", line 103, in validate_pykwalify\n        verify_generic(to_verify, schema)\n      File \"/usr/lib/python3.9/site-packages/tavern/schemas/files.py\", line 109, in verify_generic\n        raise BadSchemaError() from e\n    tavern.util.exceptions.BadSchemaError","time":{"start":1709281787717,"stop":1709281787873,"duration":156}},{"uid":"99b697fb0ed75ebd","status":"passed","time":{"start":1709195373253,"stop":1709195373521,"duration":268}},{"uid":"84a6ec0165424456","status":"passed","time":{"start":1709108924457,"stop":1709108924720,"duration":263}},{"uid":"b03552351a30195b","status":"failed","statusDetails":"tavern.util.exceptions.TestFailError: Test 'capmcAPISetPowerCap - test2 - set_power_cap for two ready nodes' failed:\n- Error calling validate function '<function validate_pykwalify at 0x7f50ed9ec4c0>':\n    Traceback (most recent call last):\n      File \"/usr/lib/python3.9/site-packages/tavern/schemas/files.py\", line 106, in verify_generic\n        verifier.validate()\n      File \"/usr/lib/python3.9/site-packages/pykwalify/core.py\", line 194, in validate\n        raise SchemaError(u\"Schema validation failed:\\n - {error_msg}.\".format(\n    pykwalify.errors.SchemaError: <SchemaError: error code 2: Schema validation failed:\n     - Enum '22' does not exist. Path: '/e' Enum: [0].\n     - Value '[{'nid': 1026, 'e': 22, 'err_msg': 'Control (Node Power Limit) value (5036) is greater than maximum (925)'}, {'nid': 20, 'e': 22, 'err_msg': 'No NID supported controls specified'}]' is not of type 'none'. Path: '/nids'.: Path: '/'>\n\n    The above exception was the direct cause of the following exception:\n\n    Traceback (most recent call last):\n      File \"/usr/lib/python3.9/site-packages/tavern/response/base.py\", line 152, in _maybe_run_validate_functions\n        vf(response)\n      File \"/usr/lib/python3.9/site-packages/tavern/util/extfunctions.py\", line 98, in inner\n        result = func(response, *args, **kwargs)\n      File \"/usr/lib/python3.9/site-packages/tavern/testutils/helpers.py\", line 103, in validate_pykwalify\n        verify_generic(to_verify, schema)\n      File \"/usr/lib/python3.9/site-packages/tavern/schemas/files.py\", line 109, in verify_generic\n        raise BadSchemaError() from e\n    tavern.util.exceptions.BadSchemaError","time":{"start":1709022647998,"stop":1709022648150,"duration":152}}]},"tags":[]},"source":"2b7e280c20356de6.json","parameterValues":[]}