{"uid":"4b4757e66a1912dae1a509f688f20b0f","children":[{"name":"Product defects","children":[{"name":"tavern.util.exceptions.TestFailError: Test 'hsmAPIinventoryHardwareGET - Retrieve multiple Hardware Inventory entries using GET.' failed:\n- Error calling validate function '<function validate_pykwalify at 0x7f959a05be50>':\n    Traceback (most recent call last):\n      File \"/usr/lib/python3.9/site-packages/tavern/schemas/files.py\", line 106, in verify_generic\n        verifier.validate()\n      File \"/usr/lib/python3.9/site-packages/pykwalify/core.py\", line 194, in validate\n        raise SchemaError(u\"Schema validation failed:\\n - {error_msg}.\".format(\n    pykwalify.errors.SchemaError: <SchemaError: error code 2: Schema validation failed:\n     - Cannot find required key 'PopulatedFRU'. Path: '/5'.\n     - Cannot find required key 'PopulatedFRU'. Path: '/6'.\n     - Cannot find required key 'PopulatedFRU'. Path: '/9'.\n     - Cannot find required key 'PopulatedFRU'. Path: '/10'.\n     - Cannot find required key 'PopulatedFRU'. Path: '/11'.\n     - Cannot find required key 'PopulatedFRU'. Path: '/14'.\n     - Cannot find required key 'PopulatedFRU'. Path: '/15'.\n     - Cannot find required key 'PopulatedFRU'. Path: '/16'.\n     - Cannot find required key 'PopulatedFRU'. Path: '/17'.\n     - Cannot find required key 'PopulatedFRU'. Path: '/18'.\n     - Cannot find required key 'PopulatedFRU'. Path: '/19'.\n     - Cannot find required key 'PopulatedFRU'. Path: '/20'.\n     - Cannot find required key 'PopulatedFRU'. Path: '/26'.\n     - Cannot find required key 'PopulatedFRU'. Path: '/27'.\n     - Cannot find required key 'PopulatedFRU'. Path: '/42'.\n     - Cannot find required key 'PopulatedFRU'. Path: '/45'.\n     - Cannot find required key 'PopulatedFRU'. Path: '/47'.\n     - Cannot find required key 'PopulatedFRU'. Path: '/53'.\n     - Cannot find required key 'PopulatedFRU'. Path: '/57'.\n     - Cannot find required key 'PopulatedFRU'. Path: '/58'.\n     - Cannot find required key 'PopulatedFRU'. Path: '/59'.\n     - Cannot find required key 'PopulatedFRU'. Path: '/60'.\n     - Cannot find required key 'PopulatedFRU'. Path: '/61'.\n     - Cannot find required key 'PopulatedFRU'. Path: '/65'.\n     - Cannot find required key 'PopulatedFRU'. Path: '/66'.\n     - Cannot find required key 'PopulatedFRU'. Path: '/67'.\n     - Cannot find required key 'PopulatedFRU'. Path: '/69'.\n     - Cannot find required key 'PopulatedFRU'. Path: '/70'.\n     - Cannot find required key 'PopulatedFRU'. Path: '/72'.\n     - Cannot find required key 'PopulatedFRU'. Path: '/73'.\n     - Cannot find required key 'PopulatedFRU'. Path: '/406'.\n     - Cannot find required key 'PopulatedFRU'. Path: '/417'.\n     - Cannot find required key 'PopulatedFRU'. Path: '/421'.\n     - Cannot find required key 'PopulatedFRU'. Path: '/422'.: Path: '/'>\n\n    The above exception was the direct cause of the following exception:\n\n    Traceback (most recent call last):\n      File \"/usr/lib/python3.9/site-packages/tavern/response/base.py\", line 152, in _maybe_run_validate_functions\n        vf(response)\n      File \"/usr/lib/python3.9/site-packages/tavern/util/extfunctions.py\", line 98, in inner\n        result = func(response, *args, **kwargs)\n      File \"/usr/lib/python3.9/site-packages/tavern/testutils/helpers.py\", line 103, in validate_pykwalify\n        verify_generic(to_verify, schema)\n      File \"/usr/lib/python3.9/site-packages/tavern/schemas/files.py\", line 109, in verify_generic\n        raise BadSchemaError() from e\n    tavern.util.exceptions.BadSchemaError","children":[{"name":"hsmAPIinventoryHardwareDisruptive","uid":"60ca966767f710ac","parentUid":"e6e25fbfc06d9bf2104d72b676cd3f02","status":"failed","time":{"start":1710922762532,"stop":1710922764798,"duration":2266},"flaky":false,"newFailed":false,"newPassed":false,"newBroken":false,"retriesCount":0,"retriesStatusChange":false,"parameters":[],"tags":[]}],"uid":"e6e25fbfc06d9bf2104d72b676cd3f02"},{"name":"tavern.util.exceptions.TestFailError: Test 'hsmAPIinventoryHardwareQueryXnameGETnonExistentNode - Attempt to query for Node Hardware Inventory entries with an xname that doesn't exist using GET.' failed:\n- Error calling validate function '<function validate_pykwalify at 0x7f959a05be50>':\n    Traceback (most recent call last):\n      File \"/usr/lib/python3.9/site-packages/tavern/schemas/files.py\", line 106, in verify_generic\n        verifier.validate()\n      File \"/usr/lib/python3.9/site-packages/pykwalify/core.py\", line 194, in validate\n        raise SchemaError(u\"Schema validation failed:\\n - {error_msg}.\".format(\n    pykwalify.errors.SchemaError: <SchemaError: error code 2: Schema validation failed:\n     - Key 'Nodes' was not defined. Path: ''.: Path: '/'>\n\n    The above exception was the direct cause of the following exception:\n\n    Traceback (most recent call last):\n      File \"/usr/lib/python3.9/site-packages/tavern/response/base.py\", line 152, in _maybe_run_validate_functions\n        vf(response)\n      File \"/usr/lib/python3.9/site-packages/tavern/util/extfunctions.py\", line 98, in inner\n        result = func(response, *args, **kwargs)\n      File \"/usr/lib/python3.9/site-packages/tavern/testutils/helpers.py\", line 103, in validate_pykwalify\n        verify_generic(to_verify, schema)\n      File \"/usr/lib/python3.9/site-packages/tavern/schemas/files.py\", line 109, in verify_generic\n        raise BadSchemaError() from e\n    tavern.util.exceptions.BadSchemaError","children":[{"name":"hsmAPIinventoryHardwareNegative","uid":"1048e00e1d383ad9","parentUid":"e4852b4b134ab0e23aefa977da7add98","status":"failed","time":{"start":1710922764861,"stop":1710922764956,"duration":95},"flaky":false,"newFailed":false,"newPassed":false,"newBroken":false,"retriesCount":0,"retriesStatusChange":false,"parameters":[],"tags":[]}],"uid":"e4852b4b134ab0e23aefa977da7add98"},{"name":"tavern.util.exceptions.TestFailError: Test 'capmcAPISetPowerCap - test2 - set_power_cap for two ready nodes' failed:\n- Error calling validate function '<function validate_pykwalify at 0x7fcbf0aeb5e0>':\n    Traceback (most recent call last):\n      File \"/usr/lib/python3.9/site-packages/tavern/schemas/files.py\", line 106, in verify_generic\n        verifier.validate()\n      File \"/usr/lib/python3.9/site-packages/pykwalify/core.py\", line 194, in validate\n        raise SchemaError(u\"Schema validation failed:\\n - {error_msg}.\".format(\n    pykwalify.errors.SchemaError: <SchemaError: error code 2: Schema validation failed:\n     - Enum '22' does not exist. Path: '/e' Enum: [0].\n     - Value '[{'nid': 20, 'e': 22, 'err_msg': 'No NID supported controls specified'}, {'nid': 1017, 'e': 22, 'err_msg': 'Control (Node Power Limit) value (5036) is greater than maximum (925)'}]' is not of type 'none'. Path: '/nids'.: Path: '/'>\n\n    The above exception was the direct cause of the following exception:\n\n    Traceback (most recent call last):\n      File \"/usr/lib/python3.9/site-packages/tavern/response/base.py\", line 152, in _maybe_run_validate_functions\n        vf(response)\n      File \"/usr/lib/python3.9/site-packages/tavern/util/extfunctions.py\", line 98, in inner\n        result = func(response, *args, **kwargs)\n      File \"/usr/lib/python3.9/site-packages/tavern/testutils/helpers.py\", line 103, in validate_pykwalify\n        verify_generic(to_verify, schema)\n      File \"/usr/lib/python3.9/site-packages/tavern/schemas/files.py\", line 109, in verify_generic\n        raise BadSchemaError() from e\n    tavern.util.exceptions.BadSchemaError","children":[{"name":"capmcAPISetPowerCap","uid":"f20ca39ca5f69929","parentUid":"a4804193ee69203d2aeac3e94ebde75f","status":"failed","time":{"start":1710923403557,"stop":1710923403698,"duration":141},"flaky":true,"newFailed":false,"newPassed":false,"newBroken":false,"retriesCount":0,"retriesStatusChange":false,"parameters":[],"tags":[]}],"uid":"a4804193ee69203d2aeac3e94ebde75f"},{"name":"tavern.util.exceptions.TestFailError: Test 'Query bootscript by xname' failed:\n- Error calling validate function '<function better_validate_regex at 0x7fd9c3c55310>':\n    Traceback (most recent call last):\n      File \"/usr/lib/python3.9/site-packages/tavern/response/base.py\", line 152, in _maybe_run_validate_functions\n        vf(response)\n      File \"/usr/lib/python3.9/site-packages/tavern/util/extfunctions.py\", line 98, in inner\n        result = func(response, *args, **kwargs)\n      File \"/src/libs/bss_test_utils.py\", line 65, in better_validate_regex\n        raise exceptions.RegexAccessError(f\"No match for regex '{expression}' in response:\\n{response.text}\")\n    tavern.util.exceptions.RegexAccessError: No match for regex 'kernel http[s]?:\\/\\/.+/boot-images/00000000-0000-0000-0000-000000000000\\/kernel' in response:\n    #!ipxe\n    sleep 10\n    chain https://api-gw-service-nmn.local/apis/bss/boot/v1/bootscript?mac=00:40:a6:30:a6:72&retry=1\n\n\n\n- Error calling validate function '<function better_validate_regex at 0x7fd9c3c55310>':\n    Traceback (most recent call last):\n      File \"/usr/lib/python3.9/site-packages/tavern/response/base.py\", line 152, in _maybe_run_validate_functions\n        vf(response)\n      File \"/usr/lib/python3.9/site-packages/tavern/util/extfunctions.py\", line 98, in inner\n        result = func(response, *args, **kwargs)\n      File \"/src/libs/bss_test_utils.py\", line 65, in better_validate_regex\n        raise exceptions.RegexAccessError(f\"No match for regex '{expression}' in response:\\n{response.text}\")\n    tavern.util.exceptions.RegexAccessError: No match for regex 'initrd http[s]?:\\/\\/.+/boot-images/00000000-0000-0000-0000-000000000000\\/initrd' in response:\n    #!ipxe\n    sleep 10\n    chain https://api-gw-service-nmn.local/apis/bss/boot/v1/bootscript?mac=00:40:a6:30:a6:72&retry=1\n\n\n\n- Error calling validate function '<function better_validate_regex at 0x7fd9c3c55310>':\n    Traceback (most recent call last):\n      File \"/usr/lib/python3.9/site-packages/tavern/response/base.py\", line 152, in _maybe_run_validate_functions\n        vf(response)\n      File \"/usr/lib/python3.9/site-packages/tavern/util/extfunctions.py\", line 98, in inner\n        result = func(response, *args, **kwargs)\n      File \"/src/libs/bss_test_utils.py\", line 65, in better_validate_regex\n        raise exceptions.RegexAccessError(f\"No match for regex '{expression}' in response:\\n{response.text}\")\n    tavern.util.exceptions.RegexAccessError: No match for regex 'kernel --name .+console.tty0' in response:\n    #!ipxe\n    sleep 10\n    chain https://api-gw-service-nmn.local/apis/bss/boot/v1/bootscript?mac=00:40:a6:30:a6:72&retry=1\n\n\n\n- Error calling validate function '<function better_validate_regex at 0x7fd9c3c55310>':\n    Traceback (most recent call last):\n      File \"/usr/lib/python3.9/site-packages/tavern/response/base.py\", line 152, in _maybe_run_validate_functions\n        vf(response)\n      File \"/usr/lib/python3.9/site-packages/tavern/util/extfunctions.py\", line 98, in inner\n        result = func(response, *args, **kwargs)\n      File \"/src/libs/bss_test_utils.py\", line 65, in better_validate_regex\n        raise exceptions.RegexAccessError(f\"No match for regex '{expression}' in response:\\n{response.text}\")\n    tavern.util.exceptions.RegexAccessError: No match for regex 'kernel --name .+xname=x1000c0s6b0n0' in response:\n    #!ipxe\n    sleep 10\n    chain https://api-gw-service-nmn.local/apis/bss/boot/v1/bootscript?mac=00:40:a6:30:a6:72&retry=1\n\n\n\n- Error calling validate function '<function better_validate_regex at 0x7fd9c3c55310>':\n    Traceback (most recent call last):\n      File \"/usr/lib/python3.9/site-packages/tavern/response/base.py\", line 152, in _maybe_run_validate_functions\n        vf(response)\n      File \"/usr/lib/python3.9/site-packages/tavern/util/extfunctions.py\", line 98, in inner\n        result = func(response, *args, **kwargs)\n      File \"/src/libs/bss_test_utils.py\", line 65, in better_validate_regex\n        raise exceptions.RegexAccessError(f\"No match for regex '{expression}' in response:\\n{response.text}\")\n    tavern.util.exceptions.RegexAccessError: No match for regex 'kernel --name .+nid=1024' in response:\n    #!ipxe\n    sleep 10\n    chain https://api-gw-service-nmn.local/apis/bss/boot/v1/bootscript?mac=00:40:a6:30:a6:72&retry=1\n\n\n\n- Error calling validate function '<function better_validate_regex at 0x7fd9c3c55310>':\n    Traceback (most recent call last):\n      File \"/usr/lib/python3.9/site-packages/tavern/response/base.py\", line 152, in _maybe_run_validate_functions\n        vf(response)\n      File \"/usr/lib/python3.9/site-packages/tavern/util/extfunctions.py\", line 98, in inner\n        result = func(response, *args, **kwargs)\n      File \"/src/libs/bss_test_utils.py\", line 65, in better_validate_regex\n        raise exceptions.RegexAccessError(f\"No match for regex '{expression}' in response:\\n{response.text}\")\n    tavern.util.exceptions.RegexAccessError: No match for regex 'kernel --name .+bss_referral_token=' in response:\n    #!ipxe\n    sleep 10\n    chain https://api-gw-service-nmn.local/apis/bss/boot/v1/bootscript?mac=00:40:a6:30:a6:72&retry=1","children":[{"name":"bssAPIbootscript","uid":"53db1406ff01692c","parentUid":"f63ee7062b4b2507d7b475eed956a204","status":"failed","time":{"start":1710923765089,"stop":1710923765158,"duration":69},"flaky":false,"newFailed":false,"newPassed":false,"newBroken":false,"retriesCount":0,"retriesStatusChange":false,"parameters":[],"tags":[]}],"uid":"f63ee7062b4b2507d7b475eed956a204"}],"uid":"8fb3a91ba5aaf9de24cc8a92edc82b5d"}],"name":"categories"}